Workbook

Sheet DirectGrnGenUD
A1: Scenario : Local Purchase - Stock UOM and Purchase UOM (Similar)
A2: Purchase Request
A3: S. No. | B3: Item | C3: Item Desc. | D3: Stk. UOM | E3: Pur. UOM | F3: Qty | G3: Unit Cost | H3: Gross Amt.
A4: 1 | B4: RM1001 | C4: Raw Material - 1001 | D4: NOS | E4: NOS | F4: 25 | G4: 257.63 | H4: =F4*G4 -> 6440.75
A5: 2 | B5: RM1002 | C5: Raw Material - 1002 | D5: NOS | E5: NOS | F5: 35 | G5: 125.45 | H5: =F5*G5 -> 4390.75
A6: 3 | B6: RM1003 | C6: Raw Material - 1003 | D6: NOS | E6: NOS | F6: 45 | G6: 125.36 | H6: =F6*G6 -> 5641.2
A7: 4 | B7: RM1004 | C7: Raw Material - 1004 | D7: NOS | E7: NOS | F7: 55 | G7: 45.25 | H7: =F7*G7 -> 2488.75
A8: 5 | B8: RM1005 | C8: Raw Material - 1005 | D8: NOS | E8: NOS | F8: 60 | G8: 45.5 | H8: =F8*G8 -> 2730
A9: 6 | B9: RM1006 | C9: Raw Material - 1006 | D9: NOS | E9: NOS | F9: 75 | G9: 125.25 | H9: =F9*G9 -> 9393.75
A10: 7 | B10: RM1007 | C10: Raw Material - 1007 | D10: NOS | E10: NOS | F10: 28 | G10: 150.5 | H10: =F10*G10 -> 4214
A11: 8 | B11: RM1008 | C11: Raw Material - 1008 | D11: NOS | E11: NOS | F11: 30 | G11: 65.32 | H11: =F11*G11 -> 1959.6
A12: 9 | B12: RM1009 | C12: Raw Material - 1009 | D12: NOS | E12: NOS | F12: 25 | G12: 74.89 | H12: =F12*G12 -> 1872.25
A13: 10 | B13: RM1010 | C13: Raw Material - 1010 | D13: NOS | E13: NOS | F13: 28 | G13: 89.56 | H13: =F13*G13 -> 2507.68
A14: 11 | B14: RM1011 | C14: Raw Material - 1011 | D14: NOS | E14: NOS | F14: 37 | G14: 89.54 | H14: =F14*G14 -> 3312.98
A15: 12 | B15: RM1012 | C15: Raw Material - 1012 | D15: NOS | E15: NOS | F15: 39 | G15: 98.25 | H15: =F15*G15 -> 3831.75
A16: 13 | B16: RM1013 | C16: Raw Material - 1013 | D16: NOS | E16: NOS | F16: 70 | G16: 102.25 | H16: =F16*G16 -> 7157.5
A17: 14 | B17: RM1014 | C17: Raw Material - 1014 | D17: NOS | E17: NOS | F17: 100 | G17: 103.5 | H17: =F17*G17 -> 10350 | S17: 5858.27
A18: 15 | B18: RM1015 | C18: Raw Material - 1015 | D18: NOS | E18: NOS | F18: 85 | G18: 65.48 | H18: =F18*G18 -> 5565.8
B19: Total | H19: =SUM(H4:H18) -> 71856.76
A20: Purchase Order & GRN
A21: GST Purchase | C21: 1 | D21: (1 - Local Purchase,2 Interstate Purchase, 3 Import Purchase,4-UTGST) | I21: Cur. | J21: INR | L21: Ex. Rate | M21: 1 | O21: Apportion Basis | P21: 1 | Q21: 1 - Value Based, 2 Weight/Volume Based | V21: 1 | W21: (1 - Registered, 2 - Unregistered)
A22: S. No. | B22: Item | C22: Item Desc. | D22: Stk. UOM | E22: Pur. UOM | F22: Order Qty (Pur UOM) | G22: Unit Cost | H22: Gross Amt. | I22: TD% | J22: SD% | K22: CD% | L22: TD Asbl. Val. | M22: TD Amt. | N22: SD Asbl. Val. | O22: SD Amt. | P22: CD Asbl. Val. | Q22: CD Amt. | R22: Disc. Amt. | S22: Pur. Val. | T22: HSN | U22: Tax Rate | V22: CGST | W22: SGST | X22: IGST | Y22: UTGST | Z22: Cess% | AA22: CESS | AB22: Tax amt | AC22: Net Amt | AD22: Weight/Vol | AE22: Customs Duty | AF22: IGST (Import) | AG22: Packing & Forwarding | AH22: Freight | AI22: Pur Amt (BC) | AJ22: Chargeable Cost | AK22: Landed Cost | AL22: Conv. Factor | AM22: Eqv. Stock Qty | AN22: Pur. Unit Cost (chr) | AO22: Chrg. Unit Cost | AP22: Landed Cost Unit Cost | AQ22: Stock UOM | AR22: Unit Cost (Stock UOM) | AS22: Ins. WH | AT22: Stock UOM | AU22: Qty Before Post | AV22: Unit Cost Before Post | AW22: Receipt Qty | AX22: Receipt Unit cost | AY22: Qty After Post | AZ22: Unit Cost After Post | BA22: Result (Ok/Not OK) | BB22: Stock Transaction | BC22: Lot / Serial Type | BD22: LOT_NUMBER | BE22: SERIAL_NUMBER | BF22: Lot / Serial Trans | BG22: Locator Trans | BH22: Batch Stocks | BI22: Stock Ledger | BJ22: Stock As on Date (Qty) | BK22: Stock As on Date (Qty & vALUE) | BL22: Sou.WH | BM22: Unitcost Before Post For Source Warehouse | BN22: Qty Before Post For Source WareHouse | BO22: Unit Cost After Post | BP22: Qty After Post forSource Warehouse | BQ22: HSN | BR22: Cost
A23: 1 | B23: ROAU-RM-KDK-01 | C23: ROAU-RM-KDK-01 | D23: NOS | E23: NOS | F23: 2 | G23: 300 | H23: =F23*G23 -> 600 | I23: 1 | J23: 2 | K23: 3 | L23: =H23 -> 600 | M23: =ROUND(L23*I23%,2) -> 6 | N23: =H23-M23 -> 594 | O23: =ROUND(N23*J23%,2) -> 11.88 | P23: =ROUND(N23-O23,2) -> 582.12 | Q23: =ROUND(P23*K23%,2) -> 17.46 | R23: =M23+O23+Q23 -> 35.34 | S23: =(H23-R23) -> 564.66 | T23: HSN1 | U23: 0.18 | V23: =IF(OR($C$21=1,$C$21=4),ROUND(((S23*U23)/2),2),0) -> 50.82 | W23: =IF($C$21=1,ROUND(((S23*U23)/2),2),0) -> 50.82 | X23: =IF($C$21=2,ROUND(((S23*U23)),2),0) -> 0 | Y23: =IF($C$21=4,ROUND(((S23*U23)/2),2),0) -> 0 | Z23: 0 | AA23: =IF($C21=3,0,S23*Z23) -> 0 | AB23: =V23+W23+X23+Y23+AA23 -> 101.64 | AC23: =IF($V21=1,S23+AB23,S23) -> 666.3 | AD23: 120 | AE23: =IF($P$21=1,(S23/$S$24)*$E$35,AD23/$AD$24*$E$35) -> 0 | AG23: =IF($P$21=1,(S23/$S$24)*$E$37,AD23/$AD$24*$E$37) -> 0 | AH23: =IF($P$21=1,(S23/$S$24)*$E$37,AD23/$AD$24*$E$37) -> 0 | AI23: =S23*$M$21 -> 564.66 | AJ23: =IF($C$21=3,0,AG23+AH23) -> 0 | AK23: =IF($C$21=3,AE23+AG23+AH23,0) -> 0 | AL23: 1 | AM23: =F23/AL23 -> 2 | AN23: =AI23/AM23 -> 282.33 | AO23: =AJ23/AM23 -> 0 | AP23: =AK23/AM23 -> 0 | AQ23: NOS | AR23: =ROUND(AN23+AO23+AP23,5) -> 282.33 | AS23: INS | AT23: NOS | AU23: 0 | AV23: 186.32 | AW23: =AM23 -> 2 | AX23: =AR23 -> 282.33 | AY23: =AU23+AW23 -> 2 | AZ23: =ROUND(((AU23*AV23)+(AW23*AX23))/(AU23+AW23),5) -> 282.33 | BB23: Receipt Qty & Unit cost | BC23: LOT | BD23: RM | BE23: RMS | BL23: RM KD | BM23: 1148.22025 | BN23: 6790 | BO23: =ROUND((((AW23*AZ23)+(BN23*BM23))/(AW23+BN23)),5) -> 1381.5466 | BP23: =BN23+AW23 -> 4272 | BQ23: 88363222 | BR23: =G23+100 -> 400
D24: Total | H24: =SUM(H23:H23) -> 600 | R24: =SUM(R23:R23) -> 35.34 | S24: =SUM(S23:S23) -> 564.66 | V24: =SUM(V23:V23) -> 50.82 | W24: =SUM(W23:W23) -> 50.82 | X24: =SUM(X23:X23) -> 0 | AB24: =SUM(AB23:AB23) -> 101.64 | AC24: =SUM(AC23:AC23) -> 666.3 | AD24: =SUM(AD23:AD23) -> 120 | AE24: =SUM(AE23:AE23) -> 0 | AG24: =SUM(AG23:AG23) -> 0 | AH24: =SUM(AH23:AH23) -> 0 | AI24: =SUM(AI23:AI23) -> 564.66 | AJ24: =SUM(AJ23:AJ23) -> 0 | AK24: =SUM(AK23:AK23) -> 0

Sheet DirectGrnGenUDMulti
A1: Scenario : Local Purchase - Stock UOM and Purchase UOM (Similar)
A2: Purchase Request
A3: S. No. | B3: Item | C3: Item Desc. | D3: Stk. UOM | E3: Pur. UOM | F3: Qty | G3: Unit Cost | H3: Gross Amt.
A4: 1 | B4: RM1001 | C4: Raw Material - 1001 | D4: NOS | E4: NOS | F4: 25 | G4: 257.63 | H4: =F4*G4 -> 6440.75
A5: 2 | B5: RM1002 | C5: Raw Material - 1002 | D5: NOS | E5: NOS | F5: 35 | G5: 125.45 | H5: =F5*G5 -> 4390.75
A6: 3 | B6: RM1003 | C6: Raw Material - 1003 | D6: NOS | E6: NOS | F6: 45 | G6: 125.36 | H6: =F6*G6 -> 5641.2
A7: 4 | B7: RM1004 | C7: Raw Material - 1004 | D7: NOS | E7: NOS | F7: 55 | G7: 45.25 | H7: =F7*G7 -> 2488.75
A8: 5 | B8: RM1005 | C8: Raw Material - 1005 | D8: NOS | E8: NOS | F8: 60 | G8: 45.5 | H8: =F8*G8 -> 2730
A9: 6 | B9: RM1006 | C9: Raw Material - 1006 | D9: NOS | E9: NOS | F9: 75 | G9: 125.25 | H9: =F9*G9 -> 9393.75
A10: 7 | B10: RM1007 | C10: Raw Material - 1007 | D10: NOS | E10: NOS | F10: 28 | G10: 150.5 | H10: =F10*G10 -> 4214
A11: 8 | B11: RM1008 | C11: Raw Material - 1008 | D11: NOS | E11: NOS | F11: 30 | G11: 65.32 | H11: =F11*G11 -> 1959.6
A12: 9 | B12: RM1009 | C12: Raw Material - 1009 | D12: NOS | E12: NOS | F12: 25 | G12: 74.89 | H12: =F12*G12 -> 1872.25
A13: 10 | B13: RM1010 | C13: Raw Material - 1010 | D13: NOS | E13: NOS | F13: 28 | G13: 89.56 | H13: =F13*G13 -> 2507.68
A14: 11 | B14: RM1011 | C14: Raw Material - 1011 | D14: NOS | E14: NOS | F14: 37 | G14: 89.54 | H14: =F14*G14 -> 3312.98
A15: 12 | B15: RM1012 | C15: Raw Material - 1012 | D15: NOS | E15: NOS | F15: 39 | G15: 98.25 | H15: =F15*G15 -> 3831.75
A16: 13 | B16: RM1013 | C16: Raw Material - 1013 | D16: NOS | E16: NOS | F16: 70 | G16: 102.25 | H16: =F16*G16 -> 7157.5
A17: 14 | B17: RM1014 | C17: Raw Material - 1014 | D17: NOS | E17: NOS | F17: 100 | G17: 103.5 | H17: =F17*G17 -> 10350 | S17: 5858.27
A18: 15 | B18: RM1015 | C18: Raw Material - 1015 | D18: NOS | E18: NOS | F18: 85 | G18: 65.48 | H18: =F18*G18 -> 5565.8
B19: Total | H19: =SUM(H4:H18) -> 71856.76
A20: Purchase Order & GRN
A21: GST Purchase | C21: 1 | D21: (1 - Local Purchase,2 Interstate Purchase, 3 Import Purchase,4-UTGST) | I21: Cur. | J21: INR | L21: Ex. Rate | M21: 1 | O21: Apportion Basis | P21: 1 | Q21: 1 - Value Based, 2 Weight/Volume Based | V21: 1 | W21: (1 - Registered, 2 - Unregistered)
A22: S. No. | B22: Item | C22: Item Desc. | D22: Stk. UOM | E22: Pur. UOM | F22: Order Qty (Pur UOM) | G22: Unit Cost | H22: Gross Amt. | I22: TD% | J22: SD% | K22: CD% | L22: TD Asbl. Val. | M22: TD Amt. | N22: SD Asbl. Val. | O22: SD Amt. | P22: CD Asbl. Val. | Q22: CD Amt. | R22: Disc. Amt. | S22: Pur. Val. | T22: HSN | U22: Tax Rate | V22: CGST | W22: SGST | X22: IGST | Y22: UTGST | Z22: Cess% | AA22: CESS | AB22: Tax amt | AC22: Net Amt | AD22: Weight/Vol | AE22: Customs Duty | AF22: IGST (Import) | AG22: Packing & Forwarding | AH22: Freight | AI22: Pur Amt (BC) | AJ22: Chargeable Cost | AK22: Landed Cost | AL22: Conv. Factor | AM22: Eqv. Stock Qty | AN22: Pur. Unit Cost (chr) | AO22: Chrg. Unit Cost | AP22: Landed Cost Unit Cost | AQ22: Stock UOM | AR22: Unit Cost (Stock UOM) | AS22: Ins. WH | AT22: Stock UOM | AU22: Qty Before Post | AV22: Unit Cost Before Post | AW22: Receipt Qty | AX22: Receipt Unit cost | AY22: Qty After Post | AZ22: Unit Cost After Post | BA22: Result (Ok/Not OK) | BB22: Stock Transaction | BC22: Lot / Serial Type | BD22: LOT_NUMBER | BE22: SERIAL_NUMBER | BF22: Lot / Serial Trans | BG22: Locator Trans | BH22: Batch Stocks | BI22: Stock Ledger | BJ22: Stock As on Date (Qty) | BK22: Stock As on Date (Qty & vALUE) | BL22: Sou.WH | BM22: Unitcost Before Post For Source Warehouse | BN22: Qty Before Post For Source WareHouse | BO22: Unit Cost After Post | BP22: Qty After Post forSource Warehouse | BQ22: HSN
A23: 1 | B23: ROAU-RM-KDK-01 | C23: ROAU-RM-KDK-01 | D23: NOS | E23: NOS | F23: 2 | G23: 300 | H23: =F23*G23 -> 600 | I23: 1 | J23: 2 | K23: 3 | L23: =H23 -> 600 | M23: =ROUND(L23*I23%,2) -> 6 | N23: =H23-M23 -> 594 | O23: =ROUND(N23*J23%,2) -> 11.88 | P23: =ROUND(N23-O23,2) -> 582.12 | Q23: =ROUND(P23*K23%,2) -> 17.46 | R23: =M23+O23+Q23 -> 35.34 | S23: =(H23-R23) -> 564.66 | T23: HSN1 | U23: 0.18 | V23: =IF(OR($C$21=1,$C$21=4),ROUND(((S23*U23)/2),2),0) -> 50.82 | W23: =IF($C$21=1,ROUND(((S23*U23)/2),2),0) -> 50.82 | X23: =IF($C$21=2,ROUND(((S23*U23)),2),0) -> 0 | Y23: =IF($C$21=4,ROUND(((S23*U23)/2),2),0) -> 0 | Z23: 0 | AA23: =IF($C21=3,0,S23*Z23) -> 0 | AB23: =V23+W23+X23+Y23+AA23 -> 101.64 | AC23: =IF($V21=1,S23+AB23,S23) -> 666.3 | AD23: 120 | AE23: =IF($P$21=1,(S23/$S$25)*$E$36,AD23/$AD$25*$E$36) -> 0 | AG23: =IF($P$21=1,(S23/$S$25)*$E$38,AD23/$AD$25*$E$38) -> 0 | AH23: =IF($P$21=1,(S23/$S$25)*$E$38,AD23/$AD$25*$E$38) -> 0 | AI23: =S23*$M$21 -> 564.66 | AJ23: =IF($C$21=3,0,AG23+AH23) -> 0 | AK23: =IF($C$21=3,AE23+AG23+AH23,0) -> 0 | AL23: 1 | AM23: =F23/AL23 -> 2 | AN23: =AI23/AM23 -> 282.33 | AO23: =AJ23/AM23 -> 0 | AP23: =AK23/AM23 -> 0 | AQ23: NOS | AR23: =ROUND(AN23+AO23+AP23,5) -> 282.33 | AS23: INS | AT23: NOS | AU23: 0 | AV23: 282.33 | AW23: =AM23 -> 2 | AX23: =AR23 -> 282.33 | AY23: =AU23+AW23 -> 2 | AZ23: =ROUND(((AU23*AV23)+(AW23*AX23))/(AU23+AW23),5) -> 282.33 | BB23: Receipt Qty & Unit cost | BC23: LOT | BD23: RM | BE23: RMS | BL23: RM KD | BM23: 878.80347 | BN23: 1106 | BO23: =ROUND((((AW23*AZ23)+(BN23*BM23))/(AW23+BN23)),5) -> 877.7268 | BP23: =BN23+AW23 -> 1108 | BQ23: 88363222
A24: 2 | B24: ROAU-RM-KDK-02 | C24: ROAU-RM-KDK-02 | D24: NOS | E24: NOS | F24: 2 | G24: 300 | H24: =F24*G24 -> 600 | I24: 1 | J24: 2 | K24: 3 | L24: =H24 -> 600 | M24: =ROUND(L24*I24%,2) -> 6 | N24: =H24-M24 -> 594 | O24: =ROUND(N24*J24%,2) -> 11.88 | P24: =ROUND(N24-O24,2) -> 582.12 | Q24: =ROUND(P24*K24%,2) -> 17.46 | R24: =M24+O24+Q24 -> 35.34 | S24: =(H24-R24) -> 564.66 | T24: HSN1 | U24: 0.18 | V24: =IF(OR($C$21=1,$C$21=4),ROUND(((S24*U24)/2),2),0) -> 50.82 | W24: =IF($C$21=1,ROUND(((S24*U24)/2),2),0) -> 50.82 | X24: =IF($C$21=2,ROUND(((S24*U24)),2),0) -> 0 | Y24: =IF($C$21=4,ROUND(((S24*U24)/2),2),0) -> 0 | Z24: 0 | AA24: =IF($C22=3,0,S24*Z24) -> 0 | AB24: =V24+W24+X24+Y24+AA24 -> 101.64 | AC24: =IF($V22=1,S24+AB24,S24) -> 564.66 | AD24: 120 | AE24: =IF($P$21=1,(S24/$S$25)*$E$36,AD24/$AD$25*$E$36) -> 0 | AG24: =IF($P$21=1,(S24/$S$25)*$E$38,AD24/$AD$25*$E$38) -> 0 | AH24: =IF($P$21=1,(S24/$S$25)*$E$38,AD24/$AD$25*$E$38) -> 0 | AI24: =S24*$M$21 -> 564.66 | AJ24: =IF($C$21=3,0,AG24+AH24) -> 0 | AK24: =IF($C$21=3,AE24+AG24+AH24,0) -> 0 | AL24: 1 | AM24: =F24/AL24 -> 2 | AN24: =AI24/AM24 -> 282.33 | AO24: =AJ24/AM24 -> 0 | AP24: =AK24/AM24 -> 0 | AQ24: NOS | AR24: =ROUND(AN24+AO24+AP24,5) -> 282.33 | AS24: INS | AT24: NOS | AU24: 0 | AV24: 282.33 | AW24: =AM24 -> 2 | AX24: =AR24 -> 282.33 | AY24: =AU24+AW24 -> 2 | AZ24: =ROUND(((AU24*AV24)+(AW24*AX24))/(AU24+AW24),5) -> 282.33 | BB24: Receipt Qty & Unit cost | BC24: LOT | BD24: RM | BE24: RMS | BL24: RM KD | BM24: 1810.39779 | BN24: 386 | BO24: =ROUND((((AW24*AZ24)+(BN24*BM24))/(AW24+BN24)),5) -> 1802.5212 | BP24: =BN24+AW24 -> 388 | BQ24: 88363222
D25: Total | H25: =SUM(H23:H24) -> 1200 | R25: =SUM(R23:R24) -> 70.68 | S25: =SUM(S23:S24) -> 1129.32 | V25: =SUM(V23:V24) -> 101.64 | W25: =SUM(W23:W24) -> 101.64 | X25: =SUM(X23:X23) -> 0 | AB25: =SUM(AB23:AB24) -> 203.28 | AC25: =SUM(AC23:AC24) -> 1230.96 | AD25: =SUM(AD23:AD24) -> 240 | AE25: =SUM(AE23:AE23) -> 0 | AG25: =SUM(AG23:AG23) -> 0 | AH25: =SUM(AH23:AH23) -> 0 | AI25: =SUM(AI23:AI24) -> 1129.32 | AJ25: =SUM(AJ23:AJ23) -> 0 | AK25: =SUM(AK23:AK23) -> 0

Sheet DirectGrnGenUDMulti50
A1: Scenario : Local Purchase - Stock UOM and Purchase UOM (Similar)
A2: Purchase Request
A3: S. No. | B3: Item | C3: Item Desc. | D3: Stk. UOM | E3: Pur. UOM | F3: Qty | G3: Unit Cost | H3: Gross Amt.
A4: 1 | B4: RM1001 | C4: Raw Material - 1001 | D4: NOS | E4: NOS | F4: 25 | G4: 257.63 | H4: =F4*G4 -> 6440.75
A5: 2 | B5: RM1002 | C5: Raw Material - 1002 | D5: NOS | E5: NOS | F5: 35 | G5: 125.45 | H5: =F5*G5 -> 4390.75
A6: 3 | B6: RM1003 | C6: Raw Material - 1003 | D6: NOS | E6: NOS | F6: 45 | G6: 125.36 | H6: =F6*G6 -> 5641.2
A7: 4 | B7: RM1004 | C7: Raw Material - 1004 | D7: NOS | E7: NOS | F7: 55 | G7: 45.25 | H7: =F7*G7 -> 2488.75
A8: 5 | B8: RM1005 | C8: Raw Material - 1005 | D8: NOS | E8: NOS | F8: 60 | G8: 45.5 | H8: =F8*G8 -> 2730
A9: 6 | B9: RM1006 | C9: Raw Material - 1006 | D9: NOS | E9: NOS | F9: 75 | G9: 125.25 | H9: =F9*G9 -> 9393.75
A10: 7 | B10: RM1007 | C10: Raw Material - 1007 | D10: NOS | E10: NOS | F10: 28 | G10: 150.5 | H10: =F10*G10 -> 4214
A11: 8 | B11: RM1008 | C11: Raw Material - 1008 | D11: NOS | E11: NOS | F11: 30 | G11: 65.32 | H11: =F11*G11 -> 1959.6
A12: 9 | B12: RM1009 | C12: Raw Material - 1009 | D12: NOS | E12: NOS | F12: 25 | G12: 74.89 | H12: =F12*G12 -> 1872.25
A13: 10 | B13: RM1010 | C13: Raw Material - 1010 | D13: NOS | E13: NOS | F13: 28 | G13: 89.56 | H13: =F13*G13 -> 2507.68
A14: 11 | B14: RM1011 | C14: Raw Material - 1011 | D14: NOS | E14: NOS | F14: 37 | G14: 89.54 | H14: =F14*G14 -> 3312.98
A15: 12 | B15: RM1012 | C15: Raw Material - 1012 | D15: NOS | E15: NOS | F15: 39 | G15: 98.25 | H15: =F15*G15 -> 3831.75
A16: 13 | B16: RM1013 | C16: Raw Material - 1013 | D16: NOS | E16: NOS | F16: 70 | G16: 102.25 | H16: =F16*G16 -> 7157.5
A17: 14 | B17: RM1014 | C17: Raw Material - 1014 | D17: NOS | E17: NOS | F17: 100 | G17: 103.5 | H17: =F17*G17 -> 10350 | S17: 5858.27
A18: 15 | B18: RM1015 | C18: Raw Material - 1015 | D18: NOS | E18: NOS | F18: 85 | G18: 65.48 | H18: =F18*G18 -> 5565.8
B19: Total | H19: =SUM(H4:H18) -> 71856.76
A20: Purchase Order & GRN
A21: GST Purchase | C21: 1 | D21: (1 - Local Purchase,2 Interstate Purchase, 3 Import Purchase,4-UTGST) | I21: Cur. | J21: INR | L21: Ex. Rate | M21: 1 | O21: Apportion Basis | P21: 1 | Q21: 1 - Value Based, 2 Weight/Volume Based | V21: 1 | W21: (1 - Registered, 2 - Unregistered)
A22: S. No. | B22: Item | C22: Item Desc. | D22: Stk. UOM | E22: Pur. UOM | F22: Order Qty (Pur UOM) | G22: Unit Cost | H22: Gross Amt. | I22: TD% | J22: SD% | K22: CD% | L22: TD Asbl. Val. | M22: TD Amt. | N22: SD Asbl. Val. | O22: SD Amt. | P22: CD Asbl. Val. | Q22: CD Amt. | R22: Disc. Amt. | S22: Pur. Val. | T22: HSN | U22: Tax Rate | V22: CGST | W22: SGST | X22: IGST | Y22: UTGST | Z22: Cess% | AA22: CESS | AB22: Tax amt | AC22: Net Amt | AD22: Weight/Vol | AE22: Customs Duty | AF22: IGST (Import) | AG22: Packing & Forwarding | AH22: Freight | AI22: Pur Amt (BC) | AJ22: Chargeable Cost | AK22: Landed Cost | AL22: Conv. Factor | AM22: Eqv. Stock Qty | AN22: Pur. Unit Cost (chr) | AO22: Chrg. Unit Cost | AP22: Landed Cost Unit Cost | AQ22: Stock UOM | AR22: Unit Cost (Stock UOM) | AS22: Ins. WH | AT22: Stock UOM | AU22: Qty Before Post | AV22: Unit Cost Before Post | AW22: Receipt Qty | AX22: Receipt Unit cost | AY22: Qty After Post | AZ22: Unit Cost After Post | BA22: Result (Ok/Not OK) | BB22: Stock Transaction | BC22: Lot / Serial Type | BD22: LOT_NUMBER | BE22: SERIAL_NUMBER | BF22: Lot / Serial Trans | BG22: Locator Trans | BH22: Batch Stocks | BI22: Stock Ledger | BJ22: Stock As on Date (Qty) | BK22: Stock As on Date (Qty & vALUE) | BL22: Sou.WH | BM22: Unitcost Before Post For Source Warehouse | BN22: Qty Before Post For Source WareHouse | BO22: Unit Cost After Post | BP22: Qty After Post forSource Warehouse | BQ22: HSN
A23: 1 | B23: ROAU-RM-KDK-01 | C23: ROAU-RM-KDK-01 | D23: NOS | E23: NOS | F23: 2 | G23: 300 | H23: =F23*G23 -> 600 | I23: 1 | J23: 2 | K23: 3 | L23: =H23 -> 600 | M23: =ROUND(L23*I23%,2) -> 6 | N23: =H23-M23 -> 594 | O23: =ROUND(N23*J23%,2) -> 11.88 | P23: =ROUND(N23-O23,2) -> 582.12 | Q23: =ROUND(P23*K23%,2) -> 17.46 | R23: =M23+O23+Q23 -> 35.34 | S23: =(H23-R23) -> 564.66 | T23: HSN1 | U23: 0.18 | V23: =IF(OR($C$21=1,$C$21=4),ROUND(((S23*U23)/2),2),0) -> 50.82 | W23: =IF($C$21=1,ROUND(((S23*U23)/2),2),0) -> 50.82 | X23: =IF($C$21=2,ROUND(((S23*U23)),2),0) -> 0 | Y23: =IF($C$21=4,ROUND(((S23*U23)/2),2),0) -> 0 | Z23: 0 | AA23: =IF($C21=3,0,S23*Z23) -> 0 | AB23: =V23+W23+X23+Y23+AA23 -> 101.64 | AC23: =IF($V21=1,S23+AB23,S23) -> 666.3 | AD23: 120 | AE23: =IF($P$21=1,(S23/$S$25)*$E$36,AD23/$AD$25*$E$36) -> 0 | AG23: =IF($P$21=1,(S23/$S$25)*$E$38,AD23/$AD$25*$E$38) -> 0 | AH23: =IF($P$21=1,(S23/$S$25)*$E$38,AD23/$AD$25*$E$38) -> 0 | AI23: =S23*$M$21 -> 564.66 | AJ23: =IF($C$21=3,0,AG23+AH23) -> 0 | AK23: =IF($C$21=3,AE23+AG23+AH23,0) -> 0 | AL23: 1 | AM23: =F23/AL23 -> 2 | AN23: =AI23/AM23 -> 282.33 | AO23: =AJ23/AM23 -> 0 | AP23: =AK23/AM23 -> 0 | AQ23: NOS | AR23: =ROUND(AN23+AO23+AP23,5) -> 282.33 | AS23: INS | AT23: NOS | AU23: 0 | AV23: 282.33 | AW23: =AM23 -> 2 | AX23: =AR23 -> 282.33 | AY23: =AU23+AW23 -> 2 | AZ23: =ROUND(((AU23*AV23)+(AW23*AX23))/(AU23+AW23),5) -> 282.33 | BB23: Receipt Qty & Unit cost | BC23: LOT | BD23: RM | BE23: RMS | BL23: RM WH 50 | BM23: 328.02245 | BN23: 878 | BO23: =ROUND((((AW23*AZ23)+(BN23*BM23))/(AW23+BN23)),5) -> 327.9186 | BP23: =BN23+AW23 -> 880 | BQ23: 88363222
A24: 2 | B24: ROAU-RM-KDK-02 | C24: ROAU-RM-KDK-02 | D24: NOS | E24: NOS | F24: 2 | G24: 300 | H24: =F24*G24 -> 600 | I24: 1 | J24: 2 | K24: 3 | L24: =H24 -> 600 | M24: =ROUND(L24*I24%,2) -> 6 | N24: =H24-M24 -> 594 | O24: =ROUND(N24*J24%,2) -> 11.88 | P24: =ROUND(N24-O24,2) -> 582.12 | Q24: =ROUND(P24*K24%,2) -> 17.46 | R24: =M24+O24+Q24 -> 35.34 | S24: =(H24-R24) -> 564.66 | T24: HSN1 | U24: 0.18 | V24: =IF(OR($C$21=1,$C$21=4),ROUND(((S24*U24)/2),2),0) -> 50.82 | W24: =IF($C$21=1,ROUND(((S24*U24)/2),2),0) -> 50.82 | X24: =IF($C$21=2,ROUND(((S24*U24)),2),0) -> 0 | Y24: =IF($C$21=4,ROUND(((S24*U24)/2),2),0) -> 0 | Z24: 0 | AA24: =IF($C22=3,0,S24*Z24) -> 0 | AB24: =V24+W24+X24+Y24+AA24 -> 101.64 | AC24: =IF($V22=1,S24+AB24,S24) -> 564.66 | AD24: 120 | AE24: =IF($P$21=1,(S24/$S$25)*$E$36,AD24/$AD$25*$E$36) -> 0 | AG24: =IF($P$21=1,(S24/$S$25)*$E$38,AD24/$AD$25*$E$38) -> 0 | AH24: =IF($P$21=1,(S24/$S$25)*$E$38,AD24/$AD$25*$E$38) -> 0 | AI24: =S24*$M$21 -> 564.66 | AJ24: =IF($C$21=3,0,AG24+AH24) -> 0 | AK24: =IF($C$21=3,AE24+AG24+AH24,0) -> 0 | AL24: 1 | AM24: =F24/AL24 -> 2 | AN24: =AI24/AM24 -> 282.33 | AO24: =AJ24/AM24 -> 0 | AP24: =AK24/AM24 -> 0 | AQ24: NOS | AR24: =ROUND(AN24+AO24+AP24,5) -> 282.33 | AS24: INS | AT24: NOS | AU24: 0 | AV24: 282.33 | AW24: =AM24 -> 2 | AX24: =AR24 -> 282.33 | AY24: =AU24+AW24 -> 2 | AZ24: =ROUND(((AU24*AV24)+(AW24*AX24))/(AU24+AW24),5) -> 282.33 | BB24: Receipt Qty & Unit cost | BC24: LOT | BD24: RM | BE24: RMS | BL24: RM WH 50 | BM24: 257.49996 | BN24: 294 | BO24: =ROUND((((AW24*AZ24)+(BN24*BM24))/(AW24+BN24)),5) -> 257.66773 | BP24: =BN24+AW24 -> 296 | BQ24: 88363222
D25: Total | H25: =SUM(H23:H24) -> 1200 | R25: =SUM(R23:R24) -> 70.68 | S25: =SUM(S23:S24) -> 1129.32 | V25: =SUM(V23:V24) -> 101.64 | W25: =SUM(W23:W24) -> 101.64 | X25: =SUM(X23:X23) -> 0 | AB25: =SUM(AB23:AB24) -> 203.28 | AC25: =SUM(AC23:AC24) -> 1230.96 | AD25: =SUM(AD23:AD24) -> 240 | AE25: =SUM(AE23:AE23) -> 0 | AG25: =SUM(AG23:AG23) -> 0 | AH25: =SUM(AH23:AH23) -> 0 | AI25: =SUM(AI23:AI24) -> 1129.32 | AJ25: =SUM(AJ23:AJ23) -> 0 | AK25: =SUM(AK23:AK23) -> 0

Sheet DirectGrnGenUD50
A1: Scenario : Local Purchase - Stock UOM and Purchase UOM (Similar)
A2: Purchase Request
A3: S. No. | B3: Item | C3: Item Desc. | D3: Stk. UOM | E3: Pur. UOM | F3: Qty | G3: Unit Cost | H3: Gross Amt.
A4: 1 | B4: RM1001 | C4: Raw Material - 1001 | D4: NOS | E4: NOS | F4: 25 | G4: 257.63 | H4: =F4*G4 -> 6440.75
A5: 2 | B5: RM1002 | C5: Raw Material - 1002 | D5: NOS | E5: NOS | F5: 35 | G5: 125.45 | H5: =F5*G5 -> 4390.75
A6: 3 | B6: RM1003 | C6: Raw Material - 1003 | D6: NOS | E6: NOS | F6: 45 | G6: 125.36 | H6: =F6*G6 -> 5641.2
A7: 4 | B7: RM1004 | C7: Raw Material - 1004 | D7: NOS | E7: NOS | F7: 55 | G7: 45.25 | H7: =F7*G7 -> 2488.75
A8: 5 | B8: RM1005 | C8: Raw Material - 1005 | D8: NOS | E8: NOS | F8: 60 | G8: 45.5 | H8: =F8*G8 -> 2730
A9: 6 | B9: RM1006 | C9: Raw Material - 1006 | D9: NOS | E9: NOS | F9: 75 | G9: 125.25 | H9: =F9*G9 -> 9393.75
A10: 7 | B10: RM1007 | C10: Raw Material - 1007 | D10: NOS | E10: NOS | F10: 28 | G10: 150.5 | H10: =F10*G10 -> 4214
A11: 8 | B11: RM1008 | C11: Raw Material - 1008 | D11: NOS | E11: NOS | F11: 30 | G11: 65.32 | H11: =F11*G11 -> 1959.6
A12: 9 | B12: RM1009 | C12: Raw Material - 1009 | D12: NOS | E12: NOS | F12: 25 | G12: 74.89 | H12: =F12*G12 -> 1872.25
A13: 10 | B13: RM1010 | C13: Raw Material - 1010 | D13: NOS | E13: NOS | F13: 28 | G13: 89.56 | H13: =F13*G13 -> 2507.68
A14: 11 | B14: RM1011 | C14: Raw Material - 1011 | D14: NOS | E14: NOS | F14: 37 | G14: 89.54 | H14: =F14*G14 -> 3312.98
A15: 12 | B15: RM1012 | C15: Raw Material - 1012 | D15: NOS | E15: NOS | F15: 39 | G15: 98.25 | H15: =F15*G15 -> 3831.75
A16: 13 | B16: RM1013 | C16: Raw Material - 1013 | D16: NOS | E16: NOS | F16: 70 | G16: 102.25 | H16: =F16*G16 -> 7157.5
A17: 14 | B17: RM1014 | C17: Raw Material - 1014 | D17: NOS | E17: NOS | F17: 100 | G17: 103.5 | H17: =F17*G17 -> 10350 | S17: 5858.27
A18: 15 | B18: RM1015 | C18: Raw Material - 1015 | D18: NOS | E18: NOS | F18: 85 | G18: 65.48 | H18: =F18*G18 -> 5565.8
B19: Total | H19: =SUM(H4:H18) -> 71856.76
A20: Purchase Order & GRN
A21: GST Purchase | C21: 1 | D21: (1 - Local Purchase,2 Interstate Purchase, 3 Import Purchase,4-UTGST) | I21: Cur. | J21: INR | L21: Ex. Rate | M21: 1 | O21: Apportion Basis | P21: 1 | Q21: 1 - Value Based, 2 Weight/Volume Based | V21: 1 | W21: (1 - Registered, 2 - Unregistered)
A22: S. No. | B22: Item | C22: Item Desc. | D22: Stk. UOM | E22: Pur. UOM | F22: Order Qty (Pur UOM) | G22: Unit Cost | H22: Gross Amt. | I22: TD% | J22: SD% | K22: CD% | L22: TD Asbl. Val. | M22: TD Amt. | N22: SD Asbl. Val. | O22: SD Amt. | P22: CD Asbl. Val. | Q22: CD Amt. | R22: Disc. Amt. | S22: Pur. Val. | T22: HSN | U22: Tax Rate | V22: CGST | W22: SGST | X22: IGST | Y22: UTGST | Z22: Cess% | AA22: CESS | AB22: Tax amt | AC22: Net Amt | AD22: Weight/Vol | AE22: Customs Duty | AF22: IGST (Import) | AG22: Packing & Forwarding | AH22: Freight | AI22: Pur Amt (BC) | AJ22: Chargeable Cost | AK22: Landed Cost | AL22: Conv. Factor | AM22: Eqv. Stock Qty | AN22: Pur. Unit Cost (chr) | AO22: Chrg. Unit Cost | AP22: Landed Cost Unit Cost | AQ22: Stock UOM | AR22: Unit Cost (Stock UOM) | AS22: Ins. WH | AT22: Stock UOM | AU22: Qty Before Post | AV22: Unit Cost Before Post | AW22: Receipt Qty | AX22: Receipt Unit cost | AY22: Qty After Post | AZ22: Unit Cost After Post | BA22: Result (Ok/Not OK) | BB22: Stock Transaction | BC22: Lot / Serial Type | BD22: LOT_NUMBER | BE22: SERIAL_NUMBER | BF22: Lot / Serial Trans | BG22: Locator Trans | BH22: Batch Stocks | BI22: Stock Ledger | BJ22: Stock As on Date (Qty) | BK22: Stock As on Date (Qty & vALUE) | BL22: Sou.WH | BM22: Unitcost Before Post For Source Warehouse | BN22: Qty Before Post For Source WareHouse | BO22: Unit Cost After Post | BP22: Qty After Post forSource Warehouse | BQ22: HSN
A23: 1 | B23: ROAU-RM-KDK-01 | C23: ROAU-RM-KDK-01 | D23: NOS | E23: NOS | F23: 2 | G23: 300 | H23: =F23*G23 -> 600 | I23: 1 | J23: 2 | K23: 3 | L23: =H23 -> 600 | M23: =ROUND(L23*I23%,2) -> 6 | N23: =H23-M23 -> 594 | O23: =ROUND(N23*J23%,2) -> 11.88 | P23: =ROUND(N23-O23,2) -> 582.12 | Q23: =ROUND(P23*K23%,2) -> 17.46 | R23: =M23+O23+Q23 -> 35.34 | S23: =(H23-R23) -> 564.66 | T23: HSN1 | U23: 0.18 | V23: =IF(OR($C$21=1,$C$21=4),ROUND(((S23*U23)/2),2),0) -> 50.82 | W23: =IF($C$21=1,ROUND(((S23*U23)/2),2),0) -> 50.82 | X23: =IF($C$21=2,ROUND(((S23*U23)),2),0) -> 0 | Y23: =IF($C$21=4,ROUND(((S23*U23)/2),2),0) -> 0 | Z23: 0 | AA23: =IF($C21=3,0,S23*Z23) -> 0 | AB23: =V23+W23+X23+Y23+AA23 -> 101.64 | AC23: =IF($V21=1,S23+AB23,S23) -> 666.3 | AD23: 120 | AE23: =IF($P$21=1,(S23/$S$24)*$E$35,AD23/$AD$24*$E$35) -> 0 | AG23: =IF($P$21=1,(S23/$S$24)*$E$37,AD23/$AD$24*$E$37) -> 0 | AH23: =IF($P$21=1,(S23/$S$24)*$E$37,AD23/$AD$24*$E$37) -> 0 | AI23: =S23*$M$21 -> 564.66 | AJ23: =IF($C$21=3,0,AG23+AH23) -> 0 | AK23: =IF($C$21=3,AE23+AG23+AH23,0) -> 0 | AL23: 1 | AM23: =F23/AL23 -> 2 | AN23: =AI23/AM23 -> 282.33 | AO23: =AJ23/AM23 -> 0 | AP23: =AK23/AM23 -> 0 | AQ23: NOS | AR23: =ROUND(AN23+AO23+AP23,5) -> 282.33 | AS23: INS | AT23: NOS | AU23: 0 | AV23: 282.33 | AW23: =AM23 -> 2 | AX23: =AR23 -> 282.33 | AY23: =AU23+AW23 -> 2 | AZ23: =ROUND(((AU23*AV23)+(AW23*AX23))/(AU23+AW23),5) -> 282.33 | BB23: Receipt Qty & Unit cost | BC23: LOT | BD23: RM | BE23: RMS | BL23: RM WH 50 | BM23: 269.95136 | BN23: 220 | BO23: =ROUND((((AW23*AZ23)+(BN23*BM23))/(AW23+BN23)),5) -> 191.55334 | BP23: =BN23+AW23 -> 30 | BQ23: 88363222
D24: Total | H24: =SUM(H23:H23) -> 600 | R24: =SUM(R23:R23) -> 35.34 | S24: =SUM(S23:S23) -> 564.66 | V24: =SUM(V23:V23) -> 50.82 | W24: =SUM(W23:W23) -> 50.82 | X24: =SUM(X23:X23) -> 0 | AB24: =SUM(AB23:AB23) -> 101.64 | AC24: =SUM(AC23:AC23) -> 666.3 | AD24: =SUM(AD23:AD23) -> 120 | AE24: =SUM(AE23:AE23) -> 0 | AG24: =SUM(AG23:AG23) -> 0 | AH24: =SUM(AH23:AH23) -> 0 | AI24: =SUM(AI23:AI23) -> 564.66 | AJ24: =SUM(AJ23:AJ23) -> 0 | AK24: =SUM(AK23:AK23) -> 0

Sheet DirectGrnGenUDMultiIMP
A1: Scenario : Local Purchase - Stock UOM and Purchase UOM (Similar)
A2: Purchase Request
A3: S. No. | B3: Item | C3: Item Desc. | D3: Stk. UOM | E3: Pur. UOM | F3: Qty | G3: Unit Cost | H3: Gross Amt.
A4: 1 | B4: RM1001 | C4: Raw Material - 1001 | D4: NOS | E4: NOS | F4: 25 | G4: 257.63 | H4: =F4*G4 -> 6440.75
A5: 2 | B5: RM1002 | C5: Raw Material - 1002 | D5: NOS | E5: NOS | F5: 35 | G5: 125.45 | H5: =F5*G5 -> 4390.75
A6: 3 | B6: RM1003 | C6: Raw Material - 1003 | D6: NOS | E6: NOS | F6: 45 | G6: 125.36 | H6: =F6*G6 -> 5641.2
A7: 4 | B7: RM1004 | C7: Raw Material - 1004 | D7: NOS | E7: NOS | F7: 55 | G7: 45.25 | H7: =F7*G7 -> 2488.75
A8: 5 | B8: RM1005 | C8: Raw Material - 1005 | D8: NOS | E8: NOS | F8: 60 | G8: 45.5 | H8: =F8*G8 -> 2730
A9: 6 | B9: RM1006 | C9: Raw Material - 1006 | D9: NOS | E9: NOS | F9: 75 | G9: 125.25 | H9: =F9*G9 -> 9393.75
A10: 7 | B10: RM1007 | C10: Raw Material - 1007 | D10: NOS | E10: NOS | F10: 28 | G10: 150.5 | H10: =F10*G10 -> 4214
A11: 8 | B11: RM1008 | C11: Raw Material - 1008 | D11: NOS | E11: NOS | F11: 30 | G11: 65.32 | H11: =F11*G11 -> 1959.6
A12: 9 | B12: RM1009 | C12: Raw Material - 1009 | D12: NOS | E12: NOS | F12: 25 | G12: 74.89 | H12: =F12*G12 -> 1872.25
A13: 10 | B13: RM1010 | C13: Raw Material - 1010 | D13: NOS | E13: NOS | F13: 28 | G13: 89.56 | H13: =F13*G13 -> 2507.68
A14: 11 | B14: RM1011 | C14: Raw Material - 1011 | D14: NOS | E14: NOS | F14: 37 | G14: 89.54 | H14: =F14*G14 -> 3312.98
A15: 12 | B15: RM1012 | C15: Raw Material - 1012 | D15: NOS | E15: NOS | F15: 39 | G15: 98.25 | H15: =F15*G15 -> 3831.75
A16: 13 | B16: RM1013 | C16: Raw Material - 1013 | D16: NOS | E16: NOS | F16: 70 | G16: 102.25 | H16: =F16*G16 -> 7157.5
A17: 14 | B17: RM1014 | C17: Raw Material - 1014 | D17: NOS | E17: NOS | F17: 100 | G17: 103.5 | H17: =F17*G17 -> 10350 | S17: 5858.27
A18: 15 | B18: RM1015 | C18: Raw Material - 1015 | D18: NOS | E18: NOS | F18: 85 | G18: 65.48 | H18: =F18*G18 -> 5565.8
B19: Total | H19: =SUM(H4:H18) -> 71856.76
A20: Purchase Order & GRN
A21: GST Purchase | C21: 3 | D21: (1 - Local Purchase,2 Interstate Purchase, 3 Import Purchase,4-UTGST) | I21: Cur. | J21: INR | L21: Ex. Rate | M21: 1 | O21: Apportion Basis | P21: 1 | Q21: 1 - Value Based, 2 Weight/Volume Based | V21: 1 | W21: (1 - Registered, 2 - Unregistered)
A22: S. No. | B22: Item | C22: Item Desc. | D22: Stk. UOM | E22: Pur. UOM | F22: Order Qty (Pur UOM) | G22: Unit Cost | H22: Gross Amt. | I22: TD% | J22: SD% | K22: CD% | L22: TD Asbl. Val. | M22: TD Amt. | N22: SD Asbl. Val. | O22: SD Amt. | P22: CD Asbl. Val. | Q22: CD Amt. | R22: Disc. Amt. | S22: Pur. Val. | T22: HSN | U22: Tax Rate | V22: CGST | W22: SGST | X22: IGST | Y22: UTGST | Z22: Cess% | AA22: CESS | AB22: Tax amt | AC22: Net Amt | AD22: Weight/Vol | AE22: Customs Duty | AF22: IGST (Import) | AG22: Packing & Forwarding | AH22: Freight | AI22: Pur Amt (BC) | AJ22: Chargeable Cost | AK22: Landed Cost | AL22: Conv. Factor | AM22: Eqv. Stock Qty | AN22: Pur. Unit Cost (chr) | AO22: Chrg. Unit Cost | AP22: Landed Cost Unit Cost | AQ22: Stock UOM | AR22: Unit Cost (Stock UOM) | AS22: Ins. WH | AT22: Stock UOM | AU22: Qty Before Post | AV22: Unit Cost Before Post | AW22: Receipt Qty | AX22: Receipt Unit cost | AY22: Qty After Post | AZ22: Unit Cost After Post | BA22: Result (Ok/Not OK) | BB22: Stock Transaction | BC22: Lot / Serial Type | BD22: LOT_NUMBER | BE22: SERIAL_NUMBER | BF22: Lot / Serial Trans | BG22: Locator Trans | BH22: Batch Stocks | BI22: Stock Ledger | BJ22: Stock As on Date (Qty) | BK22: Stock As on Date (Qty & vALUE) | BL22: Sou.WH | BM22: Unitcost Before Post For Source Warehouse | BN22: Qty Before Post For Source WareHouse | BO22: Unit Cost After Post | BP22: Qty After Post forSource Warehouse | BQ22: HSN
A23: 1 | B23: ROAU-RM-KDK-01 | C23: ROAU-RM-KDK-01 | D23: NOS | E23: NOS | F23: 2 | G23: 300 | H23: =F23*G23 -> 600 | I23: 1 | J23: 2 | K23: 3 | L23: =H23 -> 600 | M23: =ROUND(L23*I23%,2) -> 6 | N23: =H23-M23 -> 594 | O23: =ROUND(N23*J23%,2) -> 11.88 | P23: =ROUND(N23-O23,2) -> 582.12 | Q23: =ROUND(P23*K23%,2) -> 17.46 | R23: =M23+O23+Q23 -> 35.34 | S23: =(H23-R23) -> 564.66 | T23: HSN1 | U23: 0.18 | V23: =IF(OR($C$21=1,$C$21=4),ROUND(((S23*U23)/2),2),0) -> 0 | W23: =IF($C$21=1,ROUND(((S23*U23)/2),2),0) -> 0 | X23: =IF($C$21=2,ROUND(((S23*U23)),2),0) -> 0 | Y23: =IF($C$21=4,ROUND(((S23*U23)/2),2),0) -> 0 | Z23: 0 | AA23: =IF($C21=3,0,S23*Z23) -> 0 | AB23: =V23+W23+X23+Y23+AA23 -> 0 | AC23: =IF($V21=1,S23+AB23,S23) -> 564.66 | AD23: 120 | AE23: =IF($P$21=1,(S23/$S$25)*$E$36,AD23/$AD$25*$E$36) -> 0 | AG23: =IF($P$21=1,(S23/$S$25)*$E$38,AD23/$AD$25*$E$38) -> 0 | AH23: =IF($P$21=1,(S23/$S$25)*$E$38,AD23/$AD$25*$E$38) -> 0 | AI23: =S23*$M$21 -> 564.66 | AJ23: =IF($C$21=3,0,AG23+AH23) -> 0 | AK23: =IF($C$21=3,AE23+AG23+AH23,0) -> 0 | AL23: 1 | AM23: =F23/AL23 -> 2 | AN23: =AI23/AM23 -> 282.33 | AO23: =AJ23/AM23 -> 0 | AP23: =AK23/AM23 -> 0 | AQ23: NOS | AR23: =ROUND(AN23+AO23+AP23,5) -> 282.33 | AS23: INS | AT23: NOS | AU23: 0 | AV23: 2399.55 | AW23: =AM23 -> 2 | AX23: =AR23 -> 282.33 | AY23: =AU23+AW23 -> 2 | AZ23: =ROUND(((AU23*AV23)+(AW23*AX23))/(AU23+AW23),5) -> 282.33 | BB23: Receipt Qty & Unit cost | BC23: LOT | BD23: RM | BE23: RMS | BL23: RM KD | BM23: 1384.29779 | BN23: 4174 | BO23: =ROUND((((AW23*AZ23)+(BN23*BM23))/(AW23+BN23)),5) -> 1383.77 | BP23: =BN23+AW23 -> 4176 | BQ23: 88363222
A24: 2 | B24: ROAU-RM-KDK-02 | C24: ROAU-RM-KDK-02 | D24: NOS | E24: NOS | F24: 2 | G24: 300 | H24: =F24*G24 -> 600 | I24: 1 | J24: 2 | K24: 3 | L24: =H24 -> 600 | M24: =ROUND(L24*I24%,2) -> 6 | N24: =H24-M24 -> 594 | O24: =ROUND(N24*J24%,2) -> 11.88 | P24: =ROUND(N24-O24,2) -> 582.12 | Q24: =ROUND(P24*K24%,2) -> 17.46 | R24: =M24+O24+Q24 -> 35.34 | S24: =(H24-R24) -> 564.66 | T24: HSN1 | U24: 0.18 | V24: =IF(OR($C$21=1,$C$21=4),ROUND(((S24*U24)/2),2),0) -> 0 | W24: =IF($C$21=1,ROUND(((S24*U24)/2),2),0) -> 0 | X24: =IF($C$21=2,ROUND(((S24*U24)),2),0) -> 0 | Y24: =IF($C$21=4,ROUND(((S24*U24)/2),2),0) -> 0 | Z24: 0 | AA24: =IF($C22=3,0,S24*Z24) -> 0 | AB24: =V24+W24+X24+Y24+AA24 -> 0 | AC24: =IF($V22=1,S24+AB24,S24) -> 564.66 | AD24: 120 | AE24: =IF($P$21=1,(S24/$S$25)*$E$36,AD24/$AD$25*$E$36) -> 0 | AG24: =IF($P$21=1,(S24/$S$25)*$E$38,AD24/$AD$25*$E$38) -> 0 | AH24: =IF($P$21=1,(S24/$S$25)*$E$38,AD24/$AD$25*$E$38) -> 0 | AI24: =S24*$M$21 -> 564.66 | AJ24: =IF($C$21=3,0,AG24+AH24) -> 0 | AK24: =IF($C$21=3,AE24+AG24+AH24,0) -> 0 | AL24: 1 | AM24: =F24/AL24 -> 2 | AN24: =AI24/AM24 -> 282.33 | AO24: =AJ24/AM24 -> 0 | AP24: =AK24/AM24 -> 0 | AQ24: NOS | AR24: =ROUND(AN24+AO24+AP24,5) -> 282.33 | AS24: INS | AT24: NOS | AU24: 0 | AV24: 23998.05 | AW24: =AM24 -> 2 | AX24: =AR24 -> 282.33 | AY24: =AU24+AW24 -> 2 | AZ24: =ROUND(((AU24*AV24)+(AW24*AX24))/(AU24+AW24),5) -> 282.33 | BB24: Receipt Qty & Unit cost | BC24: LOT | BD24: RM | BE24: RMS | BL24: RM KD | BM24: 3422.47109 | BN24: 1354 | BO24: =ROUND((((AW24*AZ24)+(BN24*BM24))/(AW24+BN24)),5) -> 3417.8396 | BP24: =BN24+AW24 -> 1356 | BQ24: 88363222
D25: Total | H25: =SUM(H23:H24) -> 1200 | R25: =SUM(R23:R24) -> 70.68 | S25: =SUM(S23:S24) -> 1129.32 | V25: =SUM(V23:V24) -> 0 | W25: =SUM(W23:W24) -> 0 | X25: =SUM(X23:X23) -> 0 | AB25: =SUM(AB23:AB24) -> 0 | AC25: =SUM(AC23:AC24) -> 1129.32 | AD25: =SUM(AD23:AD24) -> 240 | AE25: =SUM(AE23:AE23) -> 0 | AG25: =SUM(AG23:AG23) -> 0 | AH25: =SUM(AH23:AH23) -> 0 | AI25: =SUM(AI23:AI24) -> 1129.32 | AJ25: =SUM(AJ23:AJ23) -> 0 | AK25: =SUM(AK23:AK23) -> 0

Sheet DirectGrnGenUDIMP
A1: Scenario : Local Purchase - Stock UOM and Purchase UOM (Similar)
A2: Purchase Request
A3: S. No. | B3: Item | C3: Item Desc. | D3: Stk. UOM | E3: Pur. UOM | F3: Qty | G3: Unit Cost | H3: Gross Amt.
A4: 1 | B4: RM1001 | C4: Raw Material - 1001 | D4: NOS | E4: NOS | F4: 25 | G4: 257.63 | H4: =F4*G4 -> 6440.75
A5: 2 | B5: RM1002 | C5: Raw Material - 1002 | D5: NOS | E5: NOS | F5: 35 | G5: 125.45 | H5: =F5*G5 -> 4390.75
A6: 3 | B6: RM1003 | C6: Raw Material - 1003 | D6: NOS | E6: NOS | F6: 45 | G6: 125.36 | H6: =F6*G6 -> 5641.2
A7: 4 | B7: RM1004 | C7: Raw Material - 1004 | D7: NOS | E7: NOS | F7: 55 | G7: 45.25 | H7: =F7*G7 -> 2488.75
A8: 5 | B8: RM1005 | C8: Raw Material - 1005 | D8: NOS | E8: NOS | F8: 60 | G8: 45.5 | H8: =F8*G8 -> 2730
A9: 6 | B9: RM1006 | C9: Raw Material - 1006 | D9: NOS | E9: NOS | F9: 75 | G9: 125.25 | H9: =F9*G9 -> 9393.75
A10: 7 | B10: RM1007 | C10: Raw Material - 1007 | D10: NOS | E10: NOS | F10: 28 | G10: 150.5 | H10: =F10*G10 -> 4214
A11: 8 | B11: RM1008 | C11: Raw Material - 1008 | D11: NOS | E11: NOS | F11: 30 | G11: 65.32 | H11: =F11*G11 -> 1959.6
A12: 9 | B12: RM1009 | C12: Raw Material - 1009 | D12: NOS | E12: NOS | F12: 25 | G12: 74.89 | H12: =F12*G12 -> 1872.25
A13: 10 | B13: RM1010 | C13: Raw Material - 1010 | D13: NOS | E13: NOS | F13: 28 | G13: 89.56 | H13: =F13*G13 -> 2507.68
A14: 11 | B14: RM1011 | C14: Raw Material - 1011 | D14: NOS | E14: NOS | F14: 37 | G14: 89.54 | H14: =F14*G14 -> 3312.98
A15: 12 | B15: RM1012 | C15: Raw Material - 1012 | D15: NOS | E15: NOS | F15: 39 | G15: 98.25 | H15: =F15*G15 -> 3831.75
A16: 13 | B16: RM1013 | C16: Raw Material - 1013 | D16: NOS | E16: NOS | F16: 70 | G16: 102.25 | H16: =F16*G16 -> 7157.5
A17: 14 | B17: RM1014 | C17: Raw Material - 1014 | D17: NOS | E17: NOS | F17: 100 | G17: 103.5 | H17: =F17*G17 -> 10350 | S17: 5858.27
A18: 15 | B18: RM1015 | C18: Raw Material - 1015 | D18: NOS | E18: NOS | F18: 85 | G18: 65.48 | H18: =F18*G18 -> 5565.8
B19: Total | H19: =SUM(H4:H18) -> 71856.76
A20: Purchase Order & GRN
A21: GST Purchase | C21: 3 | D21: (1 - Local Purchase,2 Interstate Purchase, 3 Import Purchase,4-UTGST) | I21: Cur. | J21: INR | L21: Ex. Rate | M21: 1 | O21: Apportion Basis | P21: 1 | Q21: 1 - Value Based, 2 Weight/Volume Based | V21: 1 | W21: (1 - Registered, 2 - Unregistered)
A22: S. No. | B22: Item | C22: Item Desc. | D22: Stk. UOM | E22: Pur. UOM | F22: Order Qty (Pur UOM) | G22: Unit Cost | H22: Gross Amt. | I22: TD% | J22: SD% | K22: CD% | L22: TD Asbl. Val. | M22: TD Amt. | N22: SD Asbl. Val. | O22: SD Amt. | P22: CD Asbl. Val. | Q22: CD Amt. | R22: Disc. Amt. | S22: Pur. Val. | T22: HSN | U22: Tax Rate | V22: CGST | W22: SGST | X22: IGST | Y22: UTGST | Z22: Cess% | AA22: CESS | AB22: Tax amt | AC22: Net Amt | AD22: Weight/Vol | AE22: Customs Duty | AF22: IGST (Import) | AG22: Packing & Forwarding | AH22: Freight | AI22: Pur Amt (BC) | AJ22: Chargeable Cost | AK22: Landed Cost | AL22: Conv. Factor | AM22: Eqv. Stock Qty | AN22: Pur. Unit Cost (chr) | AO22: Chrg. Unit Cost | AP22: Landed Cost Unit Cost | AQ22: Stock UOM | AR22: Unit Cost (Stock UOM) | AS22: Ins. WH | AT22: Stock UOM | AU22: Qty Before Post | AV22: Unit Cost Before Post | AW22: Receipt Qty | AX22: Receipt Unit cost | AY22: Qty After Post | AZ22: Unit Cost After Post | BA22: Result (Ok/Not OK) | BB22: Stock Transaction | BC22: Lot / Serial Type | BD22: LOT_NUMBER | BE22: SERIAL_NUMBER | BF22: Lot / Serial Trans | BG22: Locator Trans | BH22: Batch Stocks | BI22: Stock Ledger | BJ22: Stock As on Date (Qty) | BK22: Stock As on Date (Qty & vALUE) | BL22: Sou.WH | BM22: Unitcost Before Post For Source Warehouse | BN22: Qty Before Post For Source WareHouse | BO22: Unit Cost After Post | BP22: Qty After Post forSource Warehouse | BQ22: HSN
A23: 1 | B23: ROAU-RM-KDK-01 | C23: ROAU-RM-KDK-01 | D23: NOS | E23: NOS | F23: 2 | G23: 30 | H23: =F23*G23 -> 60 | I23: 1 | J23: 2 | K23: 3 | L23: =H23 -> 60 | M23: =ROUND(L23*I23%,2) -> 0.6 | N23: =H23-M23 -> 59.4 | O23: =ROUND(N23*J23%,2) -> 1.19 | P23: =ROUND(N23-O23,2) -> 58.21 | Q23: =ROUND(P23*K23%,2) -> 1.75 | R23: =M23+O23+Q23 -> 3.54 | S23: =(H23-R23) -> 56.46 | T23: HSN1 | U23: 0.18 | V23: =IF(OR($C$21=1,$C$21=4),ROUND(((S23*U23)/2),2),0) -> 0 | W23: =IF($C$21=1,ROUND(((S23*U23)/2),2),0) -> 0 | X23: =IF($C$21=2,ROUND(((S23*U23)),2),0) -> 0 | Y23: =IF($C$21=4,ROUND(((S23*U23)/2),2),0) -> 0 | Z23: 0 | AA23: =IF($C21=3,0,S23*Z23) -> 0 | AB23: =V23+W23+X23+Y23+AA23 -> 0 | AC23: =IF($V21=1,S23+AB23,S23) -> 56.46 | AD23: 120 | AE23: =IF($P$21=1,(S23/$S$24)*$E$35,AD23/$AD$24*$E$35) -> 0 | AG23: =IF($P$21=1,(S23/$S$24)*$E$37,AD23/$AD$24*$E$37) -> 0 | AH23: =IF($P$21=1,(S23/$S$24)*$E$37,AD23/$AD$24*$E$37) -> 0 | AI23: =S23*$M$21 -> 56.46 | AJ23: =IF($C$21=3,0,AG23+AH23) -> 0 | AK23: =IF($C$21=3,AE23+AG23+AH23,0) -> 0 | AL23: 1 | AM23: =F23/AL23 -> 2 | AN23: =AI23/AM23 -> 28.23 | AO23: =AJ23/AM23 -> 0 | AP23: =AK23/AM23 -> 0 | AQ23: NOS | AR23: =ROUND(AN23+AO23+AP23,5) -> 28.23 | AS23: INS | AT23: NOS | AU23: 0 | AV23: 282.33 | AW23: =AM23 -> 2 | AX23: =AR23 -> 28.23 | AY23: =AU23+AW23 -> 2 | AZ23: =ROUND(((AU23*AV23)+(AW23*AX23))/(AU23+AW23),5) -> 28.23 | BB23: Receipt Qty & Unit cost | BC23: LOT | BD23: RM | BE23: RMS | BL23: RM KD | BM23: 1240.99749 | BN23: 5230 | BO23: =ROUND((((AW23*AZ23)+(BN23*BM23))/(AW23+BN23)),5) -> 1392.662 | BP23: =BN23+AW23 -> 4226 | BQ23: 88363222
D24: Total | H24: =SUM(H23:H23) -> 60 | R24: =SUM(R23:R23) -> 3.54 | S24: =SUM(S23:S23) -> 56.46 | V24: =SUM(V23:V23) -> 0 | W24: =SUM(W23:W23) -> 0 | X24: =SUM(X23:X23) -> 0 | AB24: =SUM(AB23:AB23) -> 0 | AC24: =SUM(AC23:AC23) -> 56.46 | AD24: =SUM(AD23:AD23) -> 120 | AE24: =SUM(AE23:AE23) -> 0 | AG24: =SUM(AG23:AG23) -> 0 | AH24: =SUM(AH23:AH23) -> 0 | AI24: =SUM(AI23:AI23) -> 56.46 | AJ24: =SUM(AJ23:AJ23) -> 0 | AK24: =SUM(AK23:AK23) -> 0

Sheet Sheet1
A9: 1 | B9: TVS-SER-10001 | C9: Raw Material - 1001 | D9: NOS | E9: NOS | F9: 2 | G9: 250.25 | H9: =F9*G9 -> 500.5 | I9: 2.21 | J9: 1.79 | K9: 2.5 | L9: =H9 -> 500.5 | M9: =ROUND(L9*I9%,2) -> 11.06 | N9: =H9-M9 -> 489.44 | O9: =ROUND(N9*J9%,2) -> 8.76 | P9: =ROUND(N9-O9,2) -> 480.68 | Q9: =ROUND(P9*K9%,2) -> 12.02 | R9: =M9+O9+Q9 -> 31.84 | S9: =(H9-R9) -> 468.66 | T9: HSN1 | U9: 0.18 | V9: =IF(OR($C$19=1,$C$19=4),ROUND(((S9*U9)/2),2),0) -> 0 | W9: =IF($C$19=1,ROUND(((S9*U9)/2),2),0) -> 0 | X9: =IF($C$19=2,ROUND(((S9*U9)),2),0) -> 0 | Y9: =IF($C$19=4,ROUND(((S9*U9)/2),2),0) -> 0 | Z9: 0.06 | AA9: =IF($C7=3,0,S9*Z9) -> 28.1196 | AB9: =V9+W9+X9+Y9+AA9 -> 28.1196 | AC9: =IF($V7=1,S9+AB9,S9) -> 468.66 | AD9: 120 | AE9: =IF($P$19=1,(S9/$S$22)*#REF!,AD9/$AD$22*#REF!) -> #REF! | AG9: =IF($P$19=1,(S9/$S$22)*#REF!,AD9/$AD$22*#REF!) -> #REF! | AH9: =IF($P$19=1,(S9/$S$22)*#REF!,AD9/$AD$22*#REF!) -> #REF! | AI9: =S9*$M$19 -> 0 | AJ9: =IF($C$19=3,0,AG9+AH9) -> #REF! | AK9: =IF($C$19=3,AE9+AG9+AH9,0) -> 0 | AL9: 1 | AM9: =F9/AL9 -> 2 | AN9: =AI9/AM9 -> 0 | AO9: =AJ9/AM9 -> #REF! | AP9: =AK9/AM9 -> 0 | AQ9: NOS | AR9: =AN9+AO9+AP9 -> #REF! | AS9: INS KD | AT9: NOS | AU9: 2 | AV9: 234.33 | AW9: =AM9 -> 2 | AX9: =AR9 -> #REF! | AY9: =AU9+AW9 -> 4 | AZ9: =ROUND(((AU9*AV9)+(AW9*AX9))/(AU9+AW9),5) -> #REF! | BB9: Receipt Qty & Unit cost | BC9: LOT | BD9: RM | BE9: RMS | BL9: R100 | BM9: 4246.0596 | BN9: 10 | BO9: =ROUND((((AW9*AZ9)+(BN9*BM9))/(AW9+BN9)),5) -> #REF! | BP9: =BN9+AW9 -> 12 | BQ9: 123562
A15: 1 | B15: TVS-RM-KDK-200 | C15: Raw Material - 1001 | D15: NOS | E15: NOS | F15: 2 | G15: 300 | H15: =F15*G15 -> 600 | I15: 1 | J15: 2 | K15: 3 | L15: =H15 -> 600 | M15: =ROUND(L15*I15%,2) -> 6 | N15: =H15-M15 -> 594 | O15: =ROUND(N15*J15%,2) -> 11.88 | P15: =ROUND(N15-O15,2) -> 582.12 | Q15: =ROUND(P15*K15%,2) -> 17.46 | R15: =M15+O15+Q15 -> 35.34 | S15: =(H15-R15) -> 564.66 | T15: HSN1 | U15: 0.18 | V15: =IF(OR($C$21=1,$C$21=4),ROUND(((S15*U15)/2),2),0) -> 0 | W15: =IF($C$21=1,ROUND(((S15*U15)/2),2),0) -> 0 | X15: =IF($C$21=2,ROUND(((S15*U15)),2),0) -> 0 | Y15: =IF($C$21=4,ROUND(((S15*U15)/2),2),0) -> 0 | Z15: 0.06 | AA15: =IF($C13=3,0,S15*Z15) -> 33.8796 | AB15: =V15+W15+X15+Y15+AA15 -> 33.8796 | AC15: =IF($V13=1,S15+AB15,S15) -> 564.66 | AD15: 120 | AE15: =IF($P$21=1,(S15/$S$27)*$E$38,AD15/$AD$27*$E$38) -> #DIV/0! | AG15: =IF($P$21=1,(S15/$S$27)*$E$40,AD15/$AD$27*$E$40) -> #DIV/0! | AH15: =IF($P$21=1,(S15/$S$27)*$E$40,AD15/$AD$27*$E$40) -> #DIV/0! | AI15: =S15*$M$21 -> 6775.92 | AJ15: =IF($C$21=3,0,AG15+AH15) -> #DIV/0! | AK15: =IF($C$21=3,AE15+AG15+AH15,0) -> 0 | AL15: 1 | AM15: =F15/AL15 -> 2 | AN15: =AI15/AM15 -> 3387.96 | AO15: =AJ15/AM15 -> #DIV/0! | AP15: =AK15/AM15 -> 0 | AQ15: NOS | AR15: =ROUND(AN15+AO15+AP15,5) -> #DIV/0! | AS15: INS KD | AT15: NOS | AU15: 12 | AV15: 282.33 | AW15: =AM15 -> 2 | AX15: =AR15 -> #DIV/0! | AY15: =AU15+AW15 -> 14 | AZ15: =ROUND(((AU15*AV15)+(AW15*AX15))/(AU15+AW15),5) -> #DIV/0! | BB15: Receipt Qty & Unit cost | BC15: LOT | BD15: RM | BE15: RMS | BL15: RM KD | BM15: 282.33 | BN15: 6 | BO15: =ROUND((((AW15*AZ15)+(BN15*BM15))/(AW15+BN15)),5) -> #DIV/0! | BP15: =BN15+AW15 -> 8 | BQ15: 123562
A16: 2 | B16: HK-FIFO-SER-BATCH-10001 | C16: Raw Material - 1002 | D16: NOS | E16: NOS | F16: 2 | G16: 250.25 | H16: =F16*G16 -> 500.5 | I16: 2.21 | J16: 1.79 | K16: 2.5 | L16: =H16 -> 500.5 | M16: =ROUND(L16*I16%,2) -> 11.06 | N16: =H16-M16 -> 489.44 | O16: =ROUND(N16*J16%,2) -> 8.76 | P16: =ROUND(N16-O16,2) -> 480.68 | Q16: =ROUND(P16*K16%,2) -> 12.02 | R16: =M16+O16+Q16 -> 31.84 | S16: =(H16-R16) -> 468.66 | T16: HSN1 | U16: 0.18 | V16: =IF(OR([1]DirectGrnGenUD!$C$21=1,[1]DirectGrnGenUD!$C$21=4),ROUND(((S16*U16)/2),2),0) -> 42.18 | W16: =IF([1]DirectGrnGenUD!$C$21=1,ROUND(((S16*U16)/2),2),0) -> 42.18 | X16: =IF([1]DirectGrnGenUD!$C$21=2,ROUND(((S16*U16)),2),0) -> 0 | Y16: =IF([1]DirectGrnGenUD!$C$21=4,ROUND(((S16*U16)/2),2),0) -> 0 | Z16: 0.06 | AA16: =IF([1]DirectGrnGenUD!$C22=3,0,S16*Z16) -> 28.1196 | AB16: =V16+W16+X16+Y16+AA16 -> 112.4796 | AC16: =IF([1]DirectGrnGenUD!$V22=1,S16+AB16,S16) -> 468.66 | AD16: 120 | AE16: =IF([1]DirectGrnGenUD!$P$21=1,(S16/[1]DirectGrnGenUD!$S$24)*[1]DirectGrnGenUD!$E$35,AD16/[1]DirectGrnGenUD!$AD$24*[1]DirectGrnGenUD!$E$35) -> 0 | AG16: =IF([1]DirectGrnGenUD!$P$21=1,(S16/[1]DirectGrnGenUD!$S$24)*[1]DirectGrnGenUD!$E$37,AD16/[1]DirectGrnGenUD!$AD$24*[1]DirectGrnGenUD!$E$37) -> 0 | AH16: =IF([1]DirectGrnGenUD!$P$21=1,(S16/[1]DirectGrnGenUD!$S$24)*[1]DirectGrnGenUD!$E$37,AD16/[1]DirectGrnGenUD!$AD$24*[1]DirectGrnGenUD!$E$37) -> 0 | AI16: =S16*[1]DirectGrnGenUD!$M$21 -> 468.66 | AJ16: =IF([1]DirectGrnGenUD!$C$21=3,0,AG16+AH16) -> 0 | AK16: =IF([1]DirectGrnGenUD!$C$21=3,AE16+AG16+AH16,0) -> 0 | AL16: 1 | AM16: =F16/AL16 -> 2 | AN16: =AI16/AM16 -> 234.33 | AO16: =AJ16/AM16 -> 0 | AP16: =AK16/AM16 -> 0 | AQ16: NOS | AR16: =ROUND(AN16+AO16+AP16,5) -> 234.33 | AS16: INS KD | AT16: NOS | AU16: 2159 | AV16: 78.69504 | AW16: =AM16 -> 2 | AX16: =AR16 -> 234.33 | AY16: =AU16+AW16 -> 2161 | AZ16: =ROUND(((AU16*AV16)+(AW16*AX16))/(AU16+AW16),5) -> 78.83908 | BB16: Receipt Qty & Unit cost | BC16: SERIAL | BD16: RM | BE16: RMS | BL16: R100 | BM16: 268.62529 | BN16: 11178 | BO16: =ROUND((((AW16*AZ16)+(BN16*BM16))/(AW16+BN16)),5) -> 268.59134 | BP16: =BN16+AW16 -> 11180 | BQ16: 123562
A17: 3 | B17: TVS-RM-NA-10002 | C17: Raw Material - 1003 | D17: NOS | E17: NOS | F17: 2 | G17: 250.25 | H17: =F17*G17 -> 500.5 | I17: 2.21 | J17: 1.79 | K17: 2.5 | L17: =H17 -> 500.5 | M17: =ROUND(L17*I17%,2) -> 11.06 | N17: =H17-M17 -> 489.44 | O17: =ROUND(N17*J17%,2) -> 8.76 | P17: =ROUND(N17-O17,2) -> 480.68 | Q17: =ROUND(P17*K17%,2) -> 12.02 | R17: =M17+O17+Q17 -> 31.84 | S17: =(H17-R17) -> 468.66 | T17: HSN1 | U17: 0.18 | V17: =IF(OR([1]DirectGrnGenUD!$C$21=1,[1]DirectGrnGenUD!$C$21=4),ROUND(((S17*U17)/2),2),0) -> 42.18 | W17: =IF([1]DirectGrnGenUD!$C$21=1,ROUND(((S17*U17)/2),2),0) -> 42.18 | X17: =IF([1]DirectGrnGenUD!$C$21=2,ROUND(((S17*U17)),2),0) -> 0 | Y17: =IF([1]DirectGrnGenUD!$C$21=4,ROUND(((S17*U17)/2),2),0) -> 0 | Z17: 0.06 | AA17: =IF([1]DirectGrnGenUD!$C28=3,0,S17*Z17) -> 28.1196 | AB17: =V17+W17+X17+Y17+AA17 -> 112.4796 | AC17: =IF([1]DirectGrnGenUD!$V28=1,S17+AB17,S17) -> 468.66 | AD17: 120 | AE17: =IF([1]DirectGrnGenUD!$P$21=1,(S17/[1]DirectGrnGenUD!$S$24)*[1]DirectGrnGenUD!$E$35,AD17/[1]DirectGrnGenUD!$AD$24*[1]DirectGrnGenUD!$E$35) -> 0 | AG17: =IF([1]DirectGrnGenUD!$P$21=1,(S17/[1]DirectGrnGenUD!$S$24)*[1]DirectGrnGenUD!$E$37,AD17/[1]DirectGrnGenUD!$AD$24*[1]DirectGrnGenUD!$E$37) -> 0 | AH17: =IF([1]DirectGrnGenUD!$P$21=1,(S17/[1]DirectGrnGenUD!$S$24)*[1]DirectGrnGenUD!$E$37,AD17/[1]DirectGrnGenUD!$AD$24*[1]DirectGrnGenUD!$E$37) -> 0 | AI17: =S17*[1]DirectGrnGenUD!$M$21 -> 468.66 | AJ17: =IF([1]DirectGrnGenUD!$C$21=3,0,AG17+AH17) -> 0 | AK17: =IF([1]DirectGrnGenUD!$C$21=3,AE17+AG17+AH17,0) -> 0 | AL17: 1 | AM17: =F17/AL17 -> 2 | AN17: =AI17/AM17 -> 234.33 | AO17: =AJ17/AM17 -> 0 | AP17: =AK17/AM17 -> 0 | AQ17: NOS | AR17: =ROUND(AN17+AO17+AP17,5) -> 234.33 | AS17: INS KD | AT17: NOS | AU17: 0 | AV17: 250.25 | AW17: =AM17 -> 2 | AX17: =AR17 -> 234.33 | AY17: =AU17+AW17 -> 2 | AZ17: =ROUND(((AU17*AV17)+(AW17*AX17))/(AU17+AW17),5) -> 234.33 | BB17: Receipt Qty & Unit cost | BC17: NA | BD17: RM | BE17: RMS | BL17: R100 | BO17: =ROUND((((AW17*AZ17)+(BN17*BM17))/(AW17+BN17)),5) -> 234.33 | BP17: =BN17+AW17 -> 2 | BQ17: 123562
A18: 4 | B18: TVS-RM-NA-10001 | C18: Raw Material - 1003 | D18: NOS | E18: NOS | F18: 2 | G18: 250.25 | H18: =F18*G18 -> 500.5 | I18: 2.21 | J18: 1.79 | K18: 2.5 | L18: =H18 -> 500.5 | M18: =ROUND(L18*I18%,2) -> 11.06 | N18: =H18-M18 -> 489.44 | O18: =ROUND(N18*J18%,2) -> 8.76 | P18: =ROUND(N18-O18,2) -> 480.68 | Q18: =ROUND(P18*K18%,2) -> 12.02 | R18: =M18+O18+Q18 -> 31.84 | S18: =(H18-R18) -> 468.66 | T18: HSN1 | U18: 0.18 | V18: =IF(OR([1]DirectGrnGenUD!$C$21=1,[1]DirectGrnGenUD!$C$21=4),ROUND(((S18*U18)/2),2),0) -> 42.18 | W18: =IF([1]DirectGrnGenUD!$C$21=1,ROUND(((S18*U18)/2),2),0) -> 42.18 | X18: =IF([1]DirectGrnGenUD!$C$21=2,ROUND(((S18*U18)),2),0) -> 0 | Y18: =IF([1]DirectGrnGenUD!$C$21=4,ROUND(((S18*U18)/2),2),0) -> 0 | Z18: 0.06 | AA18: =IF([1]DirectGrnGenUD!$C27=3,0,S18*Z18) -> 28.1196 | AB18: =V18+W18+X18+Y18+AA18 -> 112.4796 | AC18: =IF([1]DirectGrnGenUD!$V27=1,S18+AB18,S18) -> 468.66 | AD18: 120 | AE18: =IF([1]DirectGrnGenUD!$P$21=1,(S18/[1]DirectGrnGenUD!$S$24)*[1]DirectGrnGenUD!$E$35,AD18/[1]DirectGrnGenUD!$AD$24*[1]DirectGrnGenUD!$E$35) -> 0 | AG18: =IF([1]DirectGrnGenUD!$P$21=1,(S18/[1]DirectGrnGenUD!$S$24)*[1]DirectGrnGenUD!$E$37,AD18/[1]DirectGrnGenUD!$AD$24*[1]DirectGrnGenUD!$E$37) -> 0 | AH18: =IF([1]DirectGrnGenUD!$P$21=1,(S18/[1]DirectGrnGenUD!$S$24)*[1]DirectGrnGenUD!$E$37,AD18/[1]DirectGrnGenUD!$AD$24*[1]DirectGrnGenUD!$E$37) -> 0 | AI18: =S18*[1]DirectGrnGenUD!$M$21 -> 468.66 | AJ18: =IF([1]DirectGrnGenUD!$C$21=3,0,AG18+AH18) -> 0 | AK18: =IF([1]DirectGrnGenUD!$C$21=3,AE18+AG18+AH18,0) -> 0 | AL18: 1 | AM18: =F18/AL18 -> 2 | AN18: =AI18/AM18 -> 234.33 | AO18: =AJ18/AM18 -> 0 | AP18: =AK18/AM18 -> 0 | AQ18: NOS | AR18: =ROUND(AN18+AO18+AP18,5) -> 234.33 | AS18: INS KD | AT18: NOS | AU18: 4 | AV18: 234.51578 | AW18: =AM18 -> 2 | AX18: =AR18 -> 234.33 | AY18: =AU18+AW18 -> 6 | AZ18: =ROUND(((AU18*AV18)+(AW18*AX18))/(AU18+AW18),5) -> 234.45385 | BB18: Receipt Qty & Unit cost | BC18: NA | BD18: RM | BE18: RMS | BL18: R100 | BM18: 169.49546 | BN18: 2376.6 | BO18: =ROUND((((AW18*AZ18)+(BN18*BM18))/(AW18+BN18)),5) -> 169.55008 | BP18: =BN18+AW18 -> 2378.6 | BQ18: 123562
A20: 1 | B20: TVS-RM-KDK-20 RateContract | C20: TVS-RM-KDK-20 RateContract | D20: NOS | E20: NOS | F20: 2 | G20: 200 | H20: =F20*G20 -> 400 | I20: 2 | J20: 2 | K20: 3 | L20: =H20 -> 400 | M20: =ROUND(L20*I20%,2) -> 8 | N20: =H20-M20 -> 392 | O20: =ROUND(N20*J20%,2) -> 7.84 | P20: =ROUND(N20-O20,2) -> 384.16 | Q20: =ROUND(P20*K20%,2) -> 11.52 | R20: =M20+O20+Q20 -> 27.36 | S20: =(H20-R20) -> 372.64 | T20: HSN1 | U20: 0.18 | V20: =IF(OR($C$21=1,$C$21=4),ROUND(((S20*U20)/2),2),0) -> 0 | W20: =IF($C$21=1,ROUND(((S20*U20)/2),2),0) -> 0 | X20: =IF($C$21=2,ROUND(((S20*U20)),2),0) -> 0 | Y20: =IF($C$21=4,ROUND(((S20*U20)/2),2),0) -> 0 | Z20: 0.06 | AA20: =IF($C18=3,0,S20*Z20) -> 22.3584 | AB20: =V20+W20+X20+Y20+AA20 -> 22.3584 | AC20: =IF($V18=1,S20+AB20,S20) -> 372.64 | AD20: 120 | AE20: =IF($P$21=1,(S20/$S$27)*$E$38,AD20/$AD$27*$E$38) -> #DIV/0! | AG20: =IF($P$21=1,(S20/$S$27)*$E$40,AD20/$AD$27*$E$40) -> #DIV/0! | AH20: =IF($P$21=1,(S20/$S$27)*$E$40,AD20/$AD$27*$E$40) -> #DIV/0! | AI20: =S20*$M$21 -> 4471.68 | AJ20: =IF($C$21=3,0,AG20+AH20) -> #DIV/0! | AK20: =IF($C$21=3,AE20+AG20+AH20,0) -> 0 | AL20: 1 | AM20: =F20/AL20 -> 2 | AN20: =AI20/AM20 -> 2235.84 | AO20: =AJ20/AM20 -> #DIV/0! | AP20: =AK20/AM20 -> 0 | AQ20: NOS | AR20: =ROUND(AN20+AO20+AP20,5) -> #DIV/0! | AS20: INS KD | AT20: NOS | AU20: 8 | AV20: 191.368 | AW20: =AM20 -> 2 | AX20: =AR20 -> #DIV/0! | AY20: =AU20+AW20 -> 10 | AZ20: =ROUND(((AU20*AV20)+(AW20*AX20))/(AU20+AW20),5) -> #DIV/0! | BB20: Receipt Qty & Unit cost | BC20: LOT | BD20: RM | BE20: RMS | BL20: RM KD | BM20: 191.368 | BN20: 2 | BO20: =ROUND((((AW20*AZ20)+(BN20*BM20))/(AW20+BN20)),5) -> #DIV/0! | BP20: =BN20+AW20 -> 4 | BQ20: 123562
A21: 1 | B21: HK-FIFO-SER-BATCH-10001 RateContract | C21: HK-FIFO-SER-BATCH-10001 RateContract | D21: NOS | E21: NOS | F21: 2 | G21: 300 | H21: =F21*G21 -> 600 | I21: 2 | J21: 2 | K21: 3 | L21: =H21 -> 600 | M21: =ROUND(L21*I21%,2) -> 12 | N21: =H21-M21 -> 588 | O21: =ROUND(N21*J21%,2) -> 11.76 | P21: =ROUND(N21-O21,2) -> 576.24 | Q21: =ROUND(P21*K21%,2) -> 17.29 | R21: =M21+O21+Q21 -> 41.05 | S21: =(H21-R21) -> 558.95 | T21: HSN1 | U21: 0.18 | V21: =IF(OR($C$21=1,$C$21=4),ROUND(((S21*U21)/2),2),0) -> 0 | W21: =IF($C$21=1,ROUND(((S21*U21)/2),2),0) -> 0 | X21: =IF($C$21=2,ROUND(((S21*U21)),2),0) -> 0 | Y21: =IF($C$21=4,ROUND(((S21*U21)/2),2),0) -> 0 | Z21: 0.06 | AA21: =IF($C19=3,0,S21*Z21) -> 33.537 | AB21: =V21+W21+X21+Y21+AA21 -> 33.537 | AC21: =IF($V19=1,S21+AB21,S21) -> 558.95 | AD21: 120 | AE21: =IF($P$21=1,(S21/$S$27)*$E$38,AD21/$AD$27*$E$38) -> #DIV/0! | AG21: =IF($P$21=1,(S21/$S$27)*$E$40,AD21/$AD$27*$E$40) -> #DIV/0! | AH21: =IF($P$21=1,(S21/$S$27)*$E$40,AD21/$AD$27*$E$40) -> #DIV/0! | AI21: =S21*$M$21 -> 6707.4 | AJ21: =IF($C$21=3,0,AG21+AH21) -> #DIV/0! | AK21: =IF($C$21=3,AE21+AG21+AH21,0) -> 0 | AL21: 1 | AM21: =F21/AL21 -> 2 | AN21: =AI21/AM21 -> 3353.7 | AO21: =AJ21/AM21 -> #DIV/0! | AP21: =AK21/AM21 -> 0 | AQ21: NOS | AR21: =ROUND(AN21+AO21+AP21,5) -> #DIV/0! | AS21: INS KD | AT21: NOS | AU21: 12 | AV21: 288.945 | AW21: =AM21 -> 2 | AX21: =AR21 -> #DIV/0! | AY21: =AU21+AW21 -> 14 | AZ21: =ROUND(((AU21*AV21)+(AW21*AX21))/(AU21+AW21),5) -> #DIV/0! | BB21: Receipt Qty & Unit cost | BC21: SERIAL | BD21: RM | BE21: RMS | BL21: RM KD | BM21: 0 | BN21: 0 | BO21: =ROUND((((AW21*AZ21)+(BN21*BM21))/(AW21+BN21)),5) -> #DIV/0! | BP21: =BN21+AW21 -> 2 | BQ21: 123562
A22: 1 | B22: TVS-RM-NA-10001 RateContract | C22: TVS-RM-NA-10001 RateContract | D22: NOS | E22: NOS | F22: 2 | G22: 400 | H22: =F22*G22 -> 800 | I22: 2 | J22: 2 | K22: 3 | L22: =H22 -> 800 | M22: =ROUND(L22*I22%,2) -> 16 | N22: =H22-M22 -> 784 | O22: =ROUND(N22*J22%,2) -> 15.68 | P22: =ROUND(N22-O22,2) -> 768.32 | Q22: =ROUND(P22*K22%,2) -> 23.05 | R22: =M22+O22+Q22 -> 54.73 | S22: =(H22-R22) -> 745.27 | T22: HSN1 | U22: 0.18 | V22: =IF(OR($C$21=1,$C$21=4),ROUND(((S22*U22)/2),2),0) -> 0 | W22: =IF($C$21=1,ROUND(((S22*U22)/2),2),0) -> 0 | X22: =IF($C$21=2,ROUND(((S22*U22)),2),0) -> 0 | Y22: =IF($C$21=4,ROUND(((S22*U22)/2),2),0) -> 0 | Z22: 0.06 | AA22: =IF($C20=3,0,S22*Z22) -> 44.7162 | AB22: =V22+W22+X22+Y22+AA22 -> 44.7162 | AC22: =IF($V20=1,S22+AB22,S22) -> 745.27 | AD22: 120 | AE22: =IF($P$21=1,(S22/$S$27)*$E$38,AD22/$AD$27*$E$38) -> #DIV/0! | AG22: =IF($P$21=1,(S22/$S$27)*$E$40,AD22/$AD$27*$E$40) -> #DIV/0! | AH22: =IF($P$21=1,(S22/$S$27)*$E$40,AD22/$AD$27*$E$40) -> #DIV/0! | AI22: =S22*$M$21 -> 8943.24 | AJ22: =IF($C$21=3,0,AG22+AH22) -> #DIV/0! | AK22: =IF($C$21=3,AE22+AG22+AH22,0) -> 0 | AL22: 1 | AM22: =F22/AL22 -> 2 | AN22: =AI22/AM22 -> 4471.62 | AO22: =AJ22/AM22 -> #DIV/0! | AP22: =AK22/AM22 -> 0 | AQ22: NOS | AR22: =ROUND(AN22+AO22+AP22,5) -> #DIV/0! | AS22: INS KD | AT22: NOS | AU22: 16 | AV22: 385.26 | AW22: =AM22 -> 2 | AX22: =AR22 -> #DIV/0! | AY22: =AU22+AW22 -> 18 | AZ22: =ROUND(((AU22*AV22)+(AW22*AX22))/(AU22+AW22),5) -> #DIV/0! | BB22: Receipt Qty & Unit cost | BC22: NA | BD22: RM | BE22: RMS | BL22: RM KD | BM22: 0 | BN22: 0 | BO22: =ROUND((((AW22*AZ22)+(BN22*BM22))/(AW22+BN22)),5) -> #DIV/0! | BP22: =BN22+AW22 -> 2 | BQ22: 123562
A23: 1 | B23: TVS-RM-NA-10002 RateContract | C23: TVS-RM-NA-10002 RateContract | D23: NOS | E23: NOS | F23: 2 | G23: 500 | H23: =F23*G23 -> 1000 | I23: 2 | J23: 2 | K23: 3 | L23: =H23 -> 1000 | M23: =ROUND(L23*I23%,2) -> 20 | N23: =H23-M23 -> 980 | O23: =ROUND(N23*J23%,2) -> 19.6 | P23: =ROUND(N23-O23,2) -> 960.4 | Q23: =ROUND(P23*K23%,2) -> 28.81 | R23: =M23+O23+Q23 -> 68.41 | S23: =(H23-R23) -> 931.59 | T23: HSN1 | U23: 0.18 | V23: =IF(OR($C$21=1,$C$21=4),ROUND(((S23*U23)/2),2),0) -> 0 | W23: =IF($C$21=1,ROUND(((S23*U23)/2),2),0) -> 0 | X23: =IF($C$21=2,ROUND(((S23*U23)),2),0) -> 0 | Y23: =IF($C$21=4,ROUND(((S23*U23)/2),2),0) -> 0 | Z23: 0.06 | AA23: =IF($C21=3,0,S23*Z23) -> 55.8954 | AB23: =V23+W23+X23+Y23+AA23 -> 55.8954 | AC23: =IF($V21=1,S23+AB23,S23) -> 931.59 | AD23: 120 | AE23: =IF($P$21=1,(S23/$S$27)*$E$38,AD23/$AD$27*$E$38) -> #DIV/0! | AG23: =IF($P$21=1,(S23/$S$27)*$E$40,AD23/$AD$27*$E$40) -> #DIV/0! | AH23: =IF($P$21=1,(S23/$S$27)*$E$40,AD23/$AD$27*$E$40) -> #DIV/0! | AI23: =S23*$M$21 -> 11179.08 | AJ23: =IF($C$21=3,0,AG23+AH23) -> #DIV/0! | AK23: =IF($C$21=3,AE23+AG23+AH23,0) -> 0 | AL23: 1 | AM23: =F23/AL23 -> 2 | AN23: =AI23/AM23 -> 5589.54 | AO23: =AJ23/AM23 -> #DIV/0! | AP23: =AK23/AM23 -> 0 | AQ23: NOS | AR23: =ROUND(AN23+AO23+AP23,5) -> #DIV/0! | AS23: INS KD | AT23: NOS | AU23: 0 | AV23: 456.3 | AW23: =AM23 -> 2 | AX23: =AR23 -> #DIV/0! | AY23: =AU23+AW23 -> 2 | AZ23: =ROUND(((AU23*AV23)+(AW23*AX23))/(AU23+AW23),5) -> #DIV/0! | BB23: Receipt Qty & Unit cost | BC23: NA | BD23: RM | BE23: RMS | BL23: RM KD | BM23: 0 | BN23: 0 | BO23: =ROUND((((AW23*AZ23)+(BN23*BM23))/(AW23+BN23)),5) -> #DIV/0! | BP23: =BN23+AW23 -> 2 | BQ23: 123562
B26: TVS-RM-KDK-20 PriceList
B27: HK-FIFO-SER-BATCH-10001 PriceList
B28: TVS-RM-NA-10001 PriceList
B29: TVS-RM-NA-10002 PriceList
A31: 1 | B31: HK-FIFO-SER-BATCH-10001 PriceList | C31: HK-FIFO-SER-BATCH-10001 PriceList | D31: NOS | E31: NOS | F31: 2 | G31: 300 | H31: =F31*G31 -> 600 | I31: 2 | J31: 2 | K31: 3 | L31: =H31 -> 600 | M31: =ROUND(L31*I31%,2) -> 12 | N31: =H31-M31 -> 588 | O31: =ROUND(N31*J31%,2) -> 11.76 | P31: =ROUND(N31-O31,2) -> 576.24 | Q31: =ROUND(P31*K31%,2) -> 17.29 | R31: =M31+O31+Q31 -> 41.05 | S31: =(H31-R31) -> 558.95 | T31: HSN1 | U31: 0.18 | V31: =IF(OR(DirectGrnPriceList!$C$21=1,DirectGrnPriceList!$C$21=4),ROUND(((S31*U31)/2),2),0) -> 50.31 | W31: =IF(DirectGrnPriceList!$C$21=1,ROUND(((S31*U31)/2),2),0) -> 50.31 | X31: =IF(DirectGrnPriceList!$C$21=2,ROUND(((S31*U31)),2),0) -> 0 | Y31: =IF(DirectGrnPriceList!$C$21=4,ROUND(((S31*U31)/2),2),0) -> 0 | Z31: 0.06 | AA31: =IF(DirectGrnPriceList!$C22=3,0,S31*Z31) -> 33.537 | AB31: =V31+W31+X31+Y31+AA31 -> 134.157 | AC31: =IF(DirectGrnPriceList!$V22=1,S31+AB31,S31) -> 558.95 | AD31: 120 | AE31: =IF(DirectGrnPriceList!$P$21=1,(S31/DirectGrnPriceList!$S$24)*DirectGrnPriceList!$E$35,AD31/DirectGrnPriceList!$AD$24*DirectGrnPriceList!$E$35) -> 0 | AG31: =IF(DirectGrnPriceList!$P$21=1,(S31/DirectGrnPriceList!$S$24)*DirectGrnPriceList!$E$37,AD31/DirectGrnPriceList!$AD$24*DirectGrnPriceList!$E$37) -> 0 | AH31: =IF(DirectGrnPriceList!$P$21=1,(S31/DirectGrnPriceList!$S$24)*DirectGrnPriceList!$E$37,AD31/DirectGrnPriceList!$AD$24*DirectGrnPriceList!$E$37) -> 0 | AI31: =S31*DirectGrnPriceList!$M$21 -> 558.95 | AJ31: =IF(DirectGrnPriceList!$C$21=3,0,AG31+AH31) -> 0 | AK31: =IF(DirectGrnPriceList!$C$21=3,AE31+AG31+AH31,0) -> 0 | AL31: 1 | AM31: =F31/AL31 -> 2 | AN31: =AI31/AM31 -> 279.475 | AO31: =AJ31/AM31 -> 0 | AP31: =AK31/AM31 -> 0 | AQ31: NOS | AR31: =ROUND(AN31+AO31+AP31,5) -> 279.475 | AS31: INS KD | AT31: NOS | AU31: 20 | AV31: 274.35 | AW31: =AM31 -> 2 | AX31: =AR31 -> 279.475 | AY31: =AU31+AW31 -> 22 | AZ31: =ROUND(((AU31*AV31)+(AW31*AX31))/(AU31+AW31),5) -> 274.81591 | BB31: Receipt Qty & Unit cost | BC31: SERIAL | BD31: RM | BE31: RMS | BL31: RM KD | BM31: 0 | BN31: 0 | BO31: =ROUND((((AW31*AZ31)+(BN31*BM31))/(AW31+BN31)),5) -> 274.81591 | BP31: =BN31+AW31 -> 2 | BQ31: 123562
