Workbook

Sheet DGSUomWI
A1: Purchase Order & GRN
A2: GST Purchase | C2: 3 | D2: (1 - Local Purchase,2 Interstate Purchase, 3 Import Purchase,4-UTGST) | I2: Cur. | J2: INR | L2: Ex. Rate | M2: 85 | O2: Apportion Basis | P2: 2 | Q2: 1 - Value Based, 2 Weight/Volume Based | V2: 1 | W2: (1 - Registered, 2 - Unregistered)
A3: No. | B3: Item | C3: Item Desc | D3: Stk. UOM | E3: Pur. UOM | F3: Qty | G3: Unit Cost | H3: Gross Amt. | I3: TD% | J3: CD% | K3: SD% | L3: TD Asbl. Val. | M3: TD Amt. | N3: CD Asbl. Val. | O3: CD Amt. | P3: VD Asbl. Val. | Q3: SD Amt. | R3: Disc. Amt. | S3: Pur. Value | T3: HSN | U3: Tax% | V3: CGST | W3: SGST | X3: IGST | Y3: UTGST | Z3: Cess% | AA3: CESS | AB3: Tax amt | AC3: Net Amt | AD3: Weight/Vol | AE3: Customs Duty | AF3: IGST (Import) | AG3: Packing & Forwarding | AH3: Freight | AI3: Pur Amt (BC) | AJ3: Chargeable Cost | AK3: Landed Cost | AL3: Conv. Factor | AM3: Eqv. Stock Qty | AN3: Pur. Unit Cost (chr) | AO3: Chrg. Unit Cost | AP3: Landed Cost Unit Cost | AQ3: Stock UOM | AR3: Unit cost (Stk. UOM) | AS3: Ins. WH | AT3: Stock UOM | AU3: Qty Before Post | AV3: Unit Cost Before Post | AW3: Receipt Qty | AX3: Receipt Unit cost | AY3: Qty After Post | AZ3: Unit Cost After Post | BA3: Result (Ok/Not OK) | BB3: Stock Transaction | BC3: Lot / Serial Type | BD3: LOT_NUMBER | BE3: SERIAL_NUMBER | BF3: Lot / Serial Trans | BG3: Locator Trans | BH3: Batch Stocks | BI3: Stock Ledger | BJ3: Stock As on Date (Qty) | BK3: Stock As on Date (Qty & vALUE) | BL3: Sou.WH | BM3: Unitcost Before Post For Source Warehouse | BN3: Qty Before Post For Source WareHouse | BO3: Unit Cost After Post | BP3: Qty After Post forSource Warehouse | BQ3: HSN
A4: 1 | B4: GWL_Item_Similar_04 | C4: GWL_Item_Similar_04_Desc | D4: NOS | E4: NOS | F4: 5 | G4: 150 | H4: =F4*G4 -> 750 | I4: 5 | J4: 8 | K4: 5 | L4: =IF(OR(I4=0,I4="0"),0,H4) -> 750 | M4: =ROUND(L4*I4%,3) -> 37.5 | N4: =H4-M4 -> 712.5 | O4: =ROUND(N4*J4%,3) -> 57 | P4: =ROUND(N4-O4,2) -> 655.5 | Q4: =ROUND(P4*K4%,2) -> 32.78 | R4: =ROUND(M4+O4+Q4,3) -> 127.28 | S4: =(H4-R4) -> 622.72 | T4: 88363222 | U4: 18 | V4: =IF(OR($C$2=1,$C$2=4),ROUND((((S4*U4)/100)/2),2),0) -> 0 | W4: =IF($C$2=1,ROUND((((S4*U4)/100)/2),2),0) -> 0 | X4: =IF($C$2=2,ROUND(((S4*U4)/100),2),0) -> 0 | Y4: =IF($C$2=4,ROUND((((S4*U4)/100)/2),2),0) -> 0 | Z4: 0 | AA4: =IF($C2=3,0,(S4*Z4)/100) -> 0 | AB4: =V4+W4+X4+Y4+AA4 -> 0 | AC4: =IF($V2=1,S4+AB4,S4) -> 622.72 | AD4: 120 | AE4: =IF($P$2=1,(S4/$S$7)*$E$18,AD4/$AD$7*$E$18) -> 0 | AG4: =IF($P$2=1,(S4/$S$7)*$E$20,AD4/$AD$7*$E$20) -> 0 | AH4: =IF($P$2=1,(S4/$S$7)*$E$21,AD4/$AD$7*$E$21) -> 0 | AI4: =S4*$M2 -> 52931.2 | AJ4: =IF($C$2=3,0,AG4+AH4) -> 0 | AK4: =IF($C$2=3,AE4+AG4+AH4,0) -> 0 | AL4: 1 | AM4: =F4/AL4 -> 5 | AN4: =ROUND(AI4/AM4,5) -> 10586.24 | AO4: =AJ4/AM4 -> 0 | AP4: =AK4/AM4 -> 0 | AQ4: NOS | AR4: =ROUND(AN4+AO4+AP4,5) -> 10586.24 | AS4: INS WH-1 | AT4: NOS | AU4: 375 | AV4: 3578.59301 | AW4: =AM4 -> 5 | AX4: =AR4 -> 10586.24 | AY4: =AU4+AW4 -> 15 | AZ4: =ROUND(((AU4*AV4)+(AW4*AX4))/(AU4+AW4),3) -> 3578.592 | BB4: Receipt Qty & Unit cost | BC4: LOT | BD4: RM | BE4: RMS | BL4: RM WH-49 | BM4: 124.545 | BN4: 80 | BO4: =ROUND((((AW4*AZ4)+(BN4*BM4))/(AW4+BN4)),5) -> 327.72424 | BP4: =ROUND(BN4+AW4,3) -> 5 | BQ4: 123562
A5: 1 | B5: GWL_Item_Similar_2 | C5: GWL_Item_Similar_02 | D5: NOS | E5: NOS | F5: 4 | G5: 100 | H5: =F5*G5 -> 400 | I5: 4 | J5: 9 | K5: 6 | L5: =IF(OR(I5=0,I5="0"),0,H5) -> 400 | M5: =ROUND(L5*I5%,2) -> 16 | N5: =H5-M5 -> 384 | O5: =ROUND(N5*J5%,2) -> 34.56 | P5: =ROUND(N5-O5,2) -> 349.44 | Q5: =ROUND(P5*K5%,2) -> 20.97 | R5: =M5+O5+Q5 -> 71.53 | S5: =(H5-R5) -> 328.47 | T5: 88363222 | U5: 18 | V5: =IF(OR(DGSUomWI!$C$2=1,DGSUomWI!$C$2=4),ROUND((((S5*U5)/100)/2),2),0) -> 0 | W5: =IF(DGSUomWI!$C$2=1,ROUND((((S5*U5)/100)/2),2),0) -> 0 | X5: =IF(DGSUomWI!$C$2=2,ROUND(((S5*U5)/100),2),0) -> 0 | Y5: =IF(DGSUomWI!$C$2=4,ROUND((((S5*U5)/100)/2),2),0) -> 0 | Z5: 0 | AA5: =IF(DGSUomWI!$C3=3,0,(S5*Z5)/100) -> 0 | AB5: =V5+W5+X5+Y5+AA5 -> 0 | AC5: =IF(DGSUomWI!$V3=1,S5+AB5,S5) -> 328.47 | AD5: 120 | AE5: =IF(DGSUomWI!$P$2=1,(S5/DGSUomWI!$S$7)*DGSUomWI!$E$18,AD5/DGSUomWI!$AD$7*DGSUomWI!$E$18) -> 0 | AG5: =IF(DGSUomWI!$P$2=1,(S5/DGSUomWI!$S$7)*DGSUomWI!$E$20,AD5/DGSUomWI!$AD$7*DGSUomWI!$E$20) -> 0 | AH5: =IF(DGSUomWI!$P$2=1,(S5/DGSUomWI!$S$7)*DGSUomWI!$E$21,AD5/DGSUomWI!$AD$7*DGSUomWI!$E$21) -> 0 | AI5: =S5*DGSUomWI!$M$2 -> 27919.95 | AJ5: =IF(DGSUomWI!$C$2=3,0,AG5+AH5) -> 0 | AK5: =IF(DGSUomWI!$C$2=3,AE5+AG5+AH5,0) -> 0 | AL5: 1 | AM5: =F5/AL5 -> 4 | AN5: =ROUND(AI5/AM5,5) -> 6979.9875 | AO5: =AJ5/AM5 -> 0 | AP5: =AK5/AM5 -> 0 | AQ5: NOS | AR5: =ROUND(AN5+AO5+AP5,5) -> 6979.9875 | AS5: INS WH-1 | AT5: NOS | AU5: 188 | AV5: 1972.62723 | AW5: =AM5 -> 4 | AX5: =AR5 -> 6979.9875 | AY5: =AU5+AW5 -> 12 | AZ5: =ROUND(((AU5*AV5)+(AW5*AX5))/(AU5+AW5),2) -> 1972.62 | BB5: Receipt Qty & Unit cost | BC5: LOT | BD5: RM | BE5: RMS | BL5: RM WH-49 | BM5: 82.12 | BN5: 60 | BO5: =ROUND((((AW5*AZ5)+(BN5*BM5))/(AW5+BN5)),5) -> 200.27625 | BP5: =ROUND(BN5+AW5,3) -> 4 | BQ5: 123562
A6: 1 | B6: GWL_Item_Similar_05 | C6: GWL_Item_Similar_05_Desc | D6: NOS | E6: NOS | F6: 20 | G6: 50 | H6: =F6*G6 -> 1000 | I6: 3 | J6: 7 | K6: 4 | L6: =IF(OR(I6=0,I6="0"),0,H6) -> 1000 | M6: =ROUND(L6*I6%,2) -> 30 | N6: =H6-M6 -> 970 | O6: =ROUND(N6*J6%,2) -> 67.9 | P6: =ROUND(N6-O6,2) -> 902.1 | Q6: =ROUND(P6*K6%,2) -> 36.08 | R6: =M6+O6+Q6 -> 133.98 | S6: =(H6-R6) -> 866.02 | T6: 88363222 | U6: 18 | V6: =IF(OR(DGSUomWI!$C$2=1,DGSUomWI!$C$2=4),ROUND((((S6*U6)/100)/2),2),0) -> 0 | W6: =IF(DGSUomWI!$C$2=1,ROUND((((S6*U6)/100)/2),2),0) -> 0 | X6: =IF(DGSUomWI!$C$2=2,ROUND(((S6*U6)/100),2),0) -> 0 | Y6: =IF(DGSUomWI!$C$2=4,ROUND((((S6*U6)/100)/2),2),0) -> 0 | Z6: 0 | AA6: =IF(DGSUomWI!$C4=3,0,(S6*Z6)/100) -> 0 | AB6: =V6+W6+X6+Y6+AA6 -> 0 | AC6: =IF(DGSUomWI!$V4=1,S6+AB6,S6) -> 866.02 | AD6: 120 | AE6: =IF(DGSUomWI!$P$2=1,(S6/DGSUomWI!$S$7)*DGSUomWI!$E$18,AD6/DGSUomWI!$AD$7*DGSUomWI!$E$18) -> 0 | AG6: =IF(DGSUomWI!$P$2=1,(S6/DGSUomWI!$S$7)*DGSUomWI!$E$20,AD6/DGSUomWI!$AD$7*DGSUomWI!$E$20) -> 0 | AH6: =IF(DGSUomWI!$P$2=1,(S6/DGSUomWI!$S$7)*DGSUomWI!$E$21,AD6/DGSUomWI!$AD$7*DGSUomWI!$E$21) -> 0 | AI6: =S6*DGSUomWI!$M$2 -> 73611.7 | AJ6: =IF(DGSUomWI!$C$2=3,0,AG6+AH6) -> 0 | AK6: =IF(DGSUomWI!$C$2=3,AE6+AG6+AH6,0) -> 0 | AL6: 1 | AM6: =F6/AL6 -> 20 | AN6: =ROUND(AI6/AM6,5) -> 3680.585 | AO6: =AJ6/AM6 -> 0 | AP6: =AK6/AM6 -> 0 | AQ6: NOS | AR6: =ROUND(AN6+AO6+AP6,5) -> 3680.585 | AS6: INS WH-1 | AT6: NOS | AU6: 480 | AV6: 1095.12917 | AW6: =AM6 -> 20 | AX6: =AR6 -> 3680.585 | AY6: =AU6+AW6 -> 50 | AZ6: =ROUND(((AU6*AV6)+(AW6*AX6))/(AU6+AW6),1) -> 1095.1 | BB6: Receipt Qty & Unit cost | BC6: LOT | BD6: RM | BE6: RMS | BL6: RM WH-49 | BM6: 43.3 | BN6: 300 | BO6: =ROUND((((AW6*AZ6)+(BN6*BM6))/(AW6+BN6)),5) -> 109.0375 | BP6: =ROUND(BN6+AW6,3) -> 20 | BQ6: 123562
D7: Total | H7: =SUM(H4:H4) -> 750 | R7: =SUM(R4:R4) -> 127.28 | S7: =SUM(S4:S4) -> 622.72 | V7: =SUM(V4:V4) -> 0 | W7: =SUM(W4:W4) -> 0 | X7: =SUM(X4:X4) -> 0 | AB7: =SUM(AB4:AB4) -> 0 | AC7: =SUM(AC4:AC4) -> 622.72 | AD7: =SUM(AD4:AD4) -> 120 | AE7: =SUM(AE4:AE4) -> 0 | AG7: =SUM(AG4:AG4) -> 0 | AH7: =IF($P$2=1,(S7/$S$7)*$E$21,AD7/$AD$7*$E$21) -> 0 | AI7: =SUM(AI4:AI4) -> 52931.2 | AJ7: =SUM(AJ4:AJ4) -> 0 | AK7: =SUM(AK4:AK4) -> 0
G9: Gross Purchase | I9: =H7 -> 750 | M9: Conv factor | BH9: ACPT | BI9: Acpt Qty. * Insp. Unit Cost + OLD. Qty in GRN WH * OLD Unitcost in GRN WH / Acpt. Qty + OLD. Qty in GRN WH
G10: Disc amt | I10: =R7 -> 127.28 | M10: 1 | N10: NOS | O10: 2 | P10: KGS | BH10: REJ | BI10: Rej Qty. * Insp. Unit Cost + OLD. Qty in REJ WH * OLD Unitcost in REJ WH / Acpt. Qty + OLD. Qty in REJ WH
G11: Net Purchase | I11: =S7 -> 622.72 | M11: 1 | N11: NOS | O11: 2.5 | P11: MTR
G12: Tax Amt | I12: =AB7 -> 0 | M12: 1 | N12: KGS | O12: 0.001 | P12: MT
G13: Gross Amont | I13: =I11+I12 -> 622.72
BM14: old | BN14: new
BK15: acpt Qty | BL15: 12.5 | BM15: =BL17*BL18 -> 18277.77 | BN15: =BL15*BL16 -> 6092.59
BK16: Inspection Unit Cost | BL16: 487.4072 | BM16: =BL15+BL17 -> 50
BK17: old Qty | BL17: 37.5
BK18: old UnitCost | BL18: 487.4072
BM19: =BM15+BN15 -> 24370.36 | BN19: =BM19/BM16 -> 487.4072

Sheet DGSUomWoQWI
A1: Purchase Order & GRN
A2: GST Purchase | C2: 3 | D2: (1 - Local Purchase,2 Interstate Purchase, 3 Import Purchase,4-UTGST) | I2: Cur. | J2: INR | L2: Ex. Rate | M2: 85 | O2: Apportion Basis | P2: 2 | Q2: 1 - Value Based, 2 Weight/Volume Based | V2: 1 | W2: (1 - Registered, 2 - Unregistered)
A3: No. | B3: Item | C3: Item Desc | D3: Stk. UOM | E3: Pur. UOM | F3: Qty | G3: Unit Cost | H3: Gross Amt. | I3: TD% | J3: CD% | K3: SD% | L3: TD Asbl. Val. | M3: TD Amt. | N3: CD Asbl. Val. | O3: CD Amt. | P3: VD Asbl. Val. | Q3: SD Amt. | R3: Disc. Amt. | S3: Pur. Value | T3: HSN | U3: Tax% | V3: CGST | W3: SGST | X3: IGST | Y3: UTGST | Z3: Cess% | AA3: CESS | AB3: Tax amt | AC3: Net Amt | AD3: Weight/Vol | AE3: Customs Duty | AF3: IGST (Import) | AG3: Packing & Forwarding | AH3: Freight | AI3: Pur Amt (BC) | AJ3: Chargeable Cost | AK3: Landed Cost | AL3: Conv. Factor | AM3: Eqv. Stock Qty | AN3: Pur. Unit Cost (chr) | AO3: Chrg. Unit Cost | AP3: Landed Cost Unit Cost | AQ3: Stock UOM | AR3: Unit cost (Stk. UOM) | AS3: Ins. WH | AT3: Stock UOM | AU3: Qty Before Post | AV3: Unit Cost Before Post | AW3: Receipt Qty | AX3: Receipt Unit cost | AY3: Qty After Post | AZ3: Unit Cost After Post | BA3: Result (Ok/Not OK) | BB3: Stock Transaction | BC3: Lot / Serial Type | BD3: LOT_NUMBER | BE3: SERIAL_NUMBER | BF3: Lot / Serial Trans | BG3: Locator Trans | BH3: Batch Stocks | BI3: Stock Ledger | BJ3: Stock As on Date (Qty) | BK3: Stock As on Date (Qty & vALUE) | BL3: Sou.WH | BM3: Unitcost Before Post For Source Warehouse | BN3: Qty Before Post For Source WareHouse | BO3: Unit Cost After Post | BP3: Qty After Post forSource Warehouse | BQ3: HSN
A4: 1 | B4: GWL_Item_WoQ_UD_Similar_01 | C4: GWL_Item_WoQ_UD_Similar_01 | D4: NOS | E4: NOS | F4: 5 | G4: 150 | H4: =F4*G4 -> 750 | I4: 5 | J4: 8 | K4: 5 | L4: =IF(OR(I4=0,I4="0"),0,H4) -> 750 | M4: =ROUND(L4*I4%,3) -> 37.5 | N4: =H4-M4 -> 712.5 | O4: =ROUND(N4*J4%,3) -> 57 | P4: =ROUND(N4-O4,2) -> 655.5 | Q4: =ROUND(P4*K4%,2) -> 32.78 | R4: =ROUND(M4+O4+Q4,3) -> 127.28 | S4: =(H4-R4) -> 622.72 | T4: 88363222 | U4: 18 | V4: =IF(OR($C$2=1,$C$2=4),ROUND((((S4*U4)/100)/2),2),0) -> 0 | W4: =IF($C$2=1,ROUND((((S4*U4)/100)/2),2),0) -> 0 | X4: =IF($C$2=2,ROUND(((S4*U4)/100),2),0) -> 0 | Y4: =IF($C$2=4,ROUND((((S4*U4)/100)/2),2),0) -> 0 | Z4: 0 | AA4: =IF($C2=3,0,(S4*Z4)/100) -> 0 | AB4: =V4+W4+X4+Y4+AA4 -> 0 | AC4: =IF($V2=1,S4+AB4,S4) -> 622.72 | AD4: 120 | AE4: =IF($P$2=1,(S4/$S$7)*$E$18,AD4/$AD$7*$E$18) -> 0 | AG4: =IF($P$2=1,(S4/$S$7)*$E$20,AD4/$AD$7*$E$20) -> 0 | AH4: =IF($P$2=1,(S4/$S$7)*$E$21,AD4/$AD$7*$E$21) -> 0 | AI4: =S4*$M2 -> 52931.2 | AJ4: =IF($C$2=3,0,AG4+AH4) -> 0 | AK4: =IF($C$2=3,AE4+AG4+AH4,0) -> 0 | AL4: 1 | AM4: =F4/AL4 -> 5 | AN4: =ROUND(AI4/AM4,5) -> 10586.24 | AO4: =AJ4/AM4 -> 0 | AP4: =AK4/AM4 -> 0 | AQ4: NOS | AR4: =ROUND(AN4+AO4+AP4,5) -> 10586.24 | AS4: INS WH-1 | AT4: NOS | AU4: 0 | AV4: 10586.325 | AW4: =AM4 -> 5 | AX4: =AR4 -> 10586.24 | AY4: =AU4+AW4 -> 5 | AZ4: =ROUND(((AU4*AV4)+(AW4*AX4))/(AU4+AW4),3) -> 10586.24 | BB4: Receipt Qty & Unit cost | BC4: LOT | BD4: RM | BE4: RMS | BL4: RM WH-49 | BM4: 124.545 | BN4: 80 | BO4: =ROUND((((AW4*AZ4)+(BN4*BM4))/(AW4+BN4)),5) -> 739.93882 | BP4: =ROUND(BN4+AW4,3) -> 85 | BQ4: 123562
A5: 1 | B5: GWL_Item_WoQ_UD_Similar_02 | C5: GWL_Item_WoQ_UD_Similar_02 | D5: NOS | E5: NOS | F5: 4 | G5: 100 | H5: =F5*G5 -> 400 | I5: 4 | J5: 9 | K5: 6 | L5: =IF(OR(I5=0,I5="0"),0,H5) -> 400 | M5: =ROUND(L5*I5%,2) -> 16 | N5: =H5-M5 -> 384 | O5: =ROUND(N5*J5%,2) -> 34.56 | P5: =ROUND(N5-O5,2) -> 349.44 | Q5: =ROUND(P5*K5%,2) -> 20.97 | R5: =M5+O5+Q5 -> 71.53 | S5: =(H5-R5) -> 328.47 | T5: 88363222 | U5: 18 | V5: =IF(OR(DGSUomWoQWI!$C$2=1,DGSUomWoQWI!$C$2=4),ROUND((((S5*U5)/100)/2),2),0) -> 0 | W5: =IF(DGSUomWoQWI!$C$2=1,ROUND((((S5*U5)/100)/2),2),0) -> 0 | X5: =IF(DGSUomWoQWI!$C$2=2,ROUND(((S5*U5)/100),2),0) -> 0 | Y5: =IF(DGSUomWoQWI!$C$2=4,ROUND((((S5*U5)/100)/2),2),0) -> 0 | Z5: 0 | AA5: =IF(DGSUomWoQWI!$C3=3,0,(S5*Z5)/100) -> 0 | AB5: =V5+W5+X5+Y5+AA5 -> 0 | AC5: =IF(DGSUomWoQWI!$V3=1,S5+AB5,S5) -> 328.47 | AD5: 120 | AE5: =IF(DGSUomWoQWI!$P$2=1,(S5/DGSUomWoQWI!$S$7)*DGSUomWoQWI!$E$18,AD5/DGSUomWoQWI!$AD$7*DGSUomWoQWI!$E$18) -> 0 | AG5: =IF(DGSUomWoQWI!$P$2=1,(S5/DGSUomWoQWI!$S$7)*DGSUomWoQWI!$E$20,AD5/DGSUomWoQWI!$AD$7*DGSUomWoQWI!$E$20) -> 0 | AH5: =IF(DGSUomWoQWI!$P$2=1,(S5/DGSUomWoQWI!$S$7)*DGSUomWoQWI!$E$21,AD5/DGSUomWoQWI!$AD$7*DGSUomWoQWI!$E$21) -> 0 | AI5: =S5*DGSUomWoQWI!$M$2 -> 27919.95 | AJ5: =IF(DGSUomWoQWI!$C$2=3,0,AG5+AH5) -> 0 | AK5: =IF(DGSUomWoQWI!$C$2=3,AE5+AG5+AH5,0) -> 0 | AL5: 1 | AM5: =F5/AL5 -> 4 | AN5: =ROUND(AI5/AM5,5) -> 6979.9875 | AO5: =AJ5/AM5 -> 0 | AP5: =AK5/AM5 -> 0 | AQ5: NOS | AR5: =ROUND(AN5+AO5+AP5,5) -> 6979.9875 | AS5: INS WH-1 | AT5: NOS | AU5: 0 | AV5: 6980.2 | AW5: =AM5 -> 4 | AX5: =AR5 -> 6979.9875 | AY5: =AU5+AW5 -> 4 | AZ5: =ROUND(((AU5*AV5)+(AW5*AX5))/(AU5+AW5),2) -> 6979.99 | BB5: Receipt Qty & Unit cost | BC5: LOT | BD5: RM | BE5: RMS | BL5: RM WH-49 | BM5: 82.12 | BN5: 60 | BO5: =ROUND((((AW5*AZ5)+(BN5*BM5))/(AW5+BN5)),5) -> 513.23688 | BP5: =ROUND(BN5+AW5,3) -> 64 | BQ5: 123562
A6: 1 | B6: GWL_Item_WoQ_UD_Similar_03 | C6: GWL_Item_WoQ_UD_Similar_03 | D6: NOS | E6: NOS | F6: 20 | G6: 50 | H6: =F6*G6 -> 1000 | I6: 3 | J6: 7 | K6: 4 | L6: =IF(OR(I6=0,I6="0"),0,H6) -> 1000 | M6: =ROUND(L6*I6%,2) -> 30 | N6: =H6-M6 -> 970 | O6: =ROUND(N6*J6%,2) -> 67.9 | P6: =ROUND(N6-O6,2) -> 902.1 | Q6: =ROUND(P6*K6%,2) -> 36.08 | R6: =M6+O6+Q6 -> 133.98 | S6: =(H6-R6) -> 866.02 | T6: 88363222 | U6: 18 | V6: =IF(OR(DGSUomWoQWI!$C$2=1,DGSUomWoQWI!$C$2=4),ROUND((((S6*U6)/100)/2),2),0) -> 0 | W6: =IF(DGSUomWoQWI!$C$2=1,ROUND((((S6*U6)/100)/2),2),0) -> 0 | X6: =IF(DGSUomWoQWI!$C$2=2,ROUND(((S6*U6)/100),2),0) -> 0 | Y6: =IF(DGSUomWoQWI!$C$2=4,ROUND((((S6*U6)/100)/2),2),0) -> 0 | Z6: 0 | AA6: =IF(DGSUomWoQWI!$C4=3,0,(S6*Z6)/100) -> 0 | AB6: =V6+W6+X6+Y6+AA6 -> 0 | AC6: =IF(DGSUomWoQWI!$V4=1,S6+AB6,S6) -> 866.02 | AD6: 120 | AE6: =IF(DGSUomWoQWI!$P$2=1,(S6/DGSUomWoQWI!$S$7)*DGSUomWoQWI!$E$18,AD6/DGSUomWoQWI!$AD$7*DGSUomWoQWI!$E$18) -> 0 | AG6: =IF(DGSUomWoQWI!$P$2=1,(S6/DGSUomWoQWI!$S$7)*DGSUomWoQWI!$E$20,AD6/DGSUomWoQWI!$AD$7*DGSUomWoQWI!$E$20) -> 0 | AH6: =IF(DGSUomWoQWI!$P$2=1,(S6/DGSUomWoQWI!$S$7)*DGSUomWoQWI!$E$21,AD6/DGSUomWoQWI!$AD$7*DGSUomWoQWI!$E$21) -> 0 | AI6: =S6*DGSUomWoQWI!$M$2 -> 73611.7 | AJ6: =IF(DGSUomWoQWI!$C$2=3,0,AG6+AH6) -> 0 | AK6: =IF(DGSUomWoQWI!$C$2=3,AE6+AG6+AH6,0) -> 0 | AL6: 1 | AM6: =F6/AL6 -> 20 | AN6: =ROUND(AI6/AM6,5) -> 3680.585 | AO6: =AJ6/AM6 -> 0 | AP6: =AK6/AM6 -> 0 | AQ6: NOS | AR6: =ROUND(AN6+AO6+AP6,5) -> 3680.585 | AS6: INS WH-1 | AT6: NOS | AU6: 0 | AV6: 3680.5 | AW6: =AM6 -> 20 | AX6: =AR6 -> 3680.585 | AY6: =AU6+AW6 -> 20 | AZ6: =ROUND(((AU6*AV6)+(AW6*AX6))/(AU6+AW6),1) -> 3680.6 | BB6: Receipt Qty & Unit cost | BC6: LOT | BD6: RM | BE6: RMS | BL6: RM WH-49 | BM6: 43.3 | BN6: 300 | BO6: =ROUND((((AW6*AZ6)+(BN6*BM6))/(AW6+BN6)),5) -> 270.63125 | BP6: =ROUND(BN6+AW6,3) -> 320 | BQ6: 123562
D7: Total | H7: =SUM(H4:H4) -> 750 | R7: =SUM(R4:R4) -> 127.28 | S7: =SUM(S4:S4) -> 622.72 | V7: =SUM(V4:V4) -> 0 | W7: =SUM(W4:W4) -> 0 | X7: =SUM(X4:X4) -> 0 | AB7: =SUM(AB4:AB4) -> 0 | AC7: =SUM(AC4:AC4) -> 622.72 | AD7: =SUM(AD4:AD4) -> 120 | AE7: =SUM(AE4:AE4) -> 0 | AG7: =SUM(AG4:AG4) -> 0 | AH7: =IF($P$2=1,(S7/$S$7)*$E$21,AD7/$AD$7*$E$21) -> 0 | AI7: =SUM(AI4:AI4) -> 52931.2 | AJ7: =SUM(AJ4:AJ4) -> 0 | AK7: =SUM(AK4:AK4) -> 0
G9: Gross Purchase | I9: =H7 -> 750 | M9: Conv factor | BH9: ACPT | BI9: Acpt Qty. * Insp. Unit Cost + OLD. Qty in GRN WH * OLD Unitcost in GRN WH / Acpt. Qty + OLD. Qty in GRN WH
G10: Disc amt | I10: =R7 -> 127.28 | M10: 1 | N10: NOS | O10: 2 | P10: KGS | BH10: REJ | BI10: Rej Qty. * Insp. Unit Cost + OLD. Qty in REJ WH * OLD Unitcost in REJ WH / Acpt. Qty + OLD. Qty in REJ WH
G11: Net Purchase | I11: =S7 -> 622.72 | M11: 1 | N11: NOS | O11: 2.5 | P11: MTR
G12: Tax Amt | I12: =AB7 -> 0 | M12: 1 | N12: KGS | O12: 0.001 | P12: MT
G13: Gross Amont | I13: =I11+I12 -> 622.72
BM14: old | BN14: new
BK15: acpt Qty | BL15: 12.5 | BM15: =BL17*BL18 -> 18277.77 | BN15: =BL15*BL16 -> 6092.59
BK16: Inspection Unit Cost | BL16: 487.4072 | BM16: =BL15+BL17 -> 50
BK17: old Qty | BL17: 37.5
BK18: old UnitCost | BL18: 487.4072
BM19: =BM15+BN15 -> 24370.36 | BN19: =BM19/BM16 -> 487.4072

Sheet DGDUomWI
A1: Purchase Order & GRN
A2: GST Purchase | C2: 3 | D2: (1 - Local Purchase,2 Interstate Purchase, 3 Import Purchase,4-UTGST) | I2: Cur. | J2: INR | L2: Ex. Rate | M2: 85 | O2: Apportion Basis | P2: 2 | Q2: 1 - Value Based, 2 Weight/Volume Based | V2: 1 | W2: (1 - Registered, 2 - Unregistered)
A3: No. | B3: Item | C3: Item Desc | D3: Stk. UOM | E3: Pur. UOM | F3: Qty | G3: Unit Cost | H3: Gross Amt. | I3: TD% | J3: CD% | K3: SD% | L3: TD Asbl. Val. | M3: TD Amt. | N3: CD Asbl. Val. | O3: CD Amt. | P3: VD Asbl. Val. | Q3: SD Amt. | R3: Disc. Amt. | S3: Pur. Value | T3: HSN | U3: Tax% | V3: CGST | W3: SGST | X3: IGST | Y3: UTGST | Z3: Cess% | AA3: CESS | AB3: Tax amt | AC3: Net Amt | AD3: Weight/Vol | AE3: Customs Duty | AF3: IGST (Import) | AG3: Packing & Forwarding | AH3: Freight | AI3: Pur Amt (BC) | AJ3: Chargeable Cost | AK3: Landed Cost | AL3: Conv. Factor | AM3: Eqv. Stock Qty | AN3: Pur. Unit Cost (chr) | AO3: Chrg. Unit Cost | AP3: Landed Cost Unit Cost | AQ3: Stock UOM | AR3: Unit cost (Stk. UOM) | AS3: Ins. WH | AT3: Stock UOM | AU3: Qty Before Post | AV3: Unit Cost Before Post | AW3: Receipt Qty | AX3: Receipt Unit cost | AY3: Qty After Post | AZ3: Unit Cost After Post | BA3: Result (Ok/Not OK) | BB3: Stock Transaction | BC3: Lot / Serial Type | BD3: LOT_NUMBER | BE3: SERIAL_NUMBER | BF3: Lot / Serial Trans | BG3: Locator Trans | BH3: Batch Stocks | BI3: Stock Ledger | BJ3: Stock As on Date (Qty) | BK3: Stock As on Date (Qty & vALUE) | BL3: Sou.WH | BM3: Unitcost Before Post For Source Warehouse | BN3: Qty Before Post For Source WareHouse | BO3: Unit Cost After Post | BP3: Qty After Post forSource Warehouse | BQ3: HSN
A4: 1 | B4: GWL_Item_Dissimilar_03 | C4: GWL_Item_Dissimilar_03 | D4: NOS | E4: NOS | F4: 5 | G4: 150 | H4: =F4*G4 -> 750 | I4: 5 | J4: 8 | K4: 5 | L4: =IF(OR(I4=0,I4="0"),0,H4) -> 750 | M4: =ROUND(L4*I4%,3) -> 37.5 | N4: =H4-M4 -> 712.5 | O4: =ROUND(N4*J4%,3) -> 57 | P4: =ROUND(N4-O4,2) -> 655.5 | Q4: =ROUND(P4*K4%,2) -> 32.78 | R4: =ROUND(M4+O4+Q4,3) -> 127.28 | S4: =(H4-R4) -> 622.72 | T4: 88363222 | U4: 18 | V4: =IF(OR($C$2=1,$C$2=4),ROUND((((S4*U4)/100)/2),2),0) -> 0 | W4: =IF($C$2=1,ROUND((((S4*U4)/100)/2),2),0) -> 0 | X4: =IF($C$2=2,ROUND(((S4*U4)/100),2),0) -> 0 | Y4: =IF($C$2=4,ROUND((((S4*U4)/100)/2),2),0) -> 0 | Z4: 0 | AA4: =IF($C2=3,0,(S4*Z4)/100) -> 0 | AB4: =V4+W4+X4+Y4+AA4 -> 0 | AC4: =IF($V2=1,S4+AB4,S4) -> 622.72 | AD4: 120 | AE4: =IF($P$2=1,(S4/$S$7)*$E$18,AD4/$AD$7*$E$18) -> 0 | AG4: =IF($P$2=1,(S4/$S$7)*$E$20,AD4/$AD$7*$E$20) -> 0 | AH4: =IF($P$2=1,(S4/$S$7)*$E$21,AD4/$AD$7*$E$21) -> 0 | AI4: =S4*$M2 -> 52931.2 | AJ4: =IF($C$2=3,0,AG4+AH4) -> 0 | AK4: =IF($C$2=3,AE4+AG4+AH4,0) -> 0 | AL4: 3 | AM4: =F4/AL4 -> 1.6666667 | AN4: =ROUND(AI4/AM4,5) -> 31758.72 | AO4: =AJ4/AM4 -> 0 | AP4: =AK4/AM4 -> 0 | AQ4: NOS | AR4: =ROUND(AN4+AO4+AP4,5) -> 31758.72 | AS4: INS WH-1 | AT4: NOS | AU4: 48.329 | AV4: 12278.62068 | AW4: =AM4 -> 1.6666667 | AX4: =AR4 -> 31758.72 | AY4: =AU4+AW4 -> 376.66667 | AZ4: =ROUND(((AU4*AV4)+(AW4*AX4))/(AU4+AW4),3) -> 3703.284 | BB4: Receipt Qty & Unit cost | BC4: LOT | BD4: RM | BE4: RMS | BL4: RM WH-49 | BM4: 124.545 | BN4: 80 | BO4: =ROUND((((AW4*AZ4)+(BN4*BM4))/(AW4+BN4)),5) -> 197.58049 | BP4: =ROUND(BN4+AW4,3) -> 81.667 | BQ4: 123562
A5: 1 | B5: GWL_Item_Dissimilar_04 | C5: GWL_Item_Dissimilar_04 | D5: NOS | E5: NOS | F5: 4 | G5: 100 | H5: =F5*G5 -> 400 | I5: 4 | J5: 9 | K5: 6 | L5: =IF(OR(I5=0,I5="0"),0,H5) -> 400 | M5: =ROUND(L5*I5%,2) -> 16 | N5: =H5-M5 -> 384 | O5: =ROUND(N5*J5%,2) -> 34.56 | P5: =ROUND(N5-O5,2) -> 349.44 | Q5: =ROUND(P5*K5%,2) -> 20.97 | R5: =M5+O5+Q5 -> 71.53 | S5: =(H5-R5) -> 328.47 | T5: 88363222 | U5: 18 | V5: =IF(OR(DGDUomWI!$C$2=1,DGDUomWI!$C$2=4),ROUND((((S5*U5)/100)/2),2),0) -> 0 | W5: =IF(DGDUomWI!$C$2=1,ROUND((((S5*U5)/100)/2),2),0) -> 0 | X5: =IF(DGDUomWI!$C$2=2,ROUND(((S5*U5)/100),2),0) -> 0 | Y5: =IF(DGDUomWI!$C$2=4,ROUND((((S5*U5)/100)/2),2),0) -> 0 | Z5: 0 | AA5: =IF(DGDUomWI!$C3=3,0,(S5*Z5)/100) -> 0 | AB5: =V5+W5+X5+Y5+AA5 -> 0 | AC5: =IF(DGDUomWI!$V3=1,S5+AB5,S5) -> 328.47 | AD5: 120 | AE5: =IF(DGDUomWI!$P$2=1,(S5/DGDUomWI!$S$7)*DGDUomWI!$E$18,AD5/DGDUomWI!$AD$7*DGDUomWI!$E$18) -> 0 | AG5: =IF(DGDUomWI!$P$2=1,(S5/DGDUomWI!$S$7)*DGDUomWI!$E$20,AD5/DGDUomWI!$AD$7*DGDUomWI!$E$20) -> 0 | AH5: =IF(DGDUomWI!$P$2=1,(S5/DGDUomWI!$S$7)*DGDUomWI!$E$21,AD5/DGDUomWI!$AD$7*DGDUomWI!$E$21) -> 0 | AI5: =S5*DGDUomWI!$M$2 -> 27919.95 | AJ5: =IF(DGDUomWI!$C$2=3,0,AG5+AH5) -> 0 | AK5: =IF(DGDUomWI!$C$2=3,AE5+AG5+AH5,0) -> 0 | AL5: 3 | AM5: =F5/AL5 -> 1.3333333 | AN5: =ROUND(AI5/AM5,5) -> 20939.963 | AO5: =AJ5/AM5 -> 0 | AP5: =AK5/AM5 -> 0 | AQ5: NOS | AR5: =ROUND(AN5+AO5+AP5,5) -> 20939.963 | AS5: INS WH-1 | AT5: NOS | AU5: 22.661 | AV5: 7550.20941 | AW5: =AM5 -> 1.3333333 | AX5: =AR5 -> 20939.963 | AY5: =AU5+AW5 -> 189.33333 | AZ5: =ROUND(((AU5*AV5)+(AW5*AX5))/(AU5+AW5),2) -> 2106.2 | BB5: Receipt Qty & Unit cost | BC5: LOT | BD5: RM | BE5: RMS | BL5: RM WH-49 | BM5: 82.12 | BN5: 60 | BO5: =ROUND((((AW5*AZ5)+(BN5*BM5))/(AW5+BN5)),5) -> 126.12174 | BP5: =ROUND(BN5+AW5,3) -> 61.333 | BQ5: 123562
A6: 1 | B6: GWL_Item_Dissimilar_05 | C6: GWL_Item_Dissimilar_05 | D6: NOS | E6: NOS | F6: 20 | G6: 50 | H6: =F6*G6 -> 1000 | I6: 3 | J6: 7 | K6: 4 | L6: =IF(OR(I6=0,I6="0"),0,H6) -> 1000 | M6: =ROUND(L6*I6%,2) -> 30 | N6: =H6-M6 -> 970 | O6: =ROUND(N6*J6%,2) -> 67.9 | P6: =ROUND(N6-O6,2) -> 902.1 | Q6: =ROUND(P6*K6%,2) -> 36.08 | R6: =M6+O6+Q6 -> 133.98 | S6: =(H6-R6) -> 866.02 | T6: 88363222 | U6: 18 | V6: =IF(OR(DGDUomWI!$C$2=1,DGDUomWI!$C$2=4),ROUND((((S6*U6)/100)/2),2),0) -> 0 | W6: =IF(DGDUomWI!$C$2=1,ROUND((((S6*U6)/100)/2),2),0) -> 0 | X6: =IF(DGDUomWI!$C$2=2,ROUND(((S6*U6)/100),2),0) -> 0 | Y6: =IF(DGDUomWI!$C$2=4,ROUND((((S6*U6)/100)/2),2),0) -> 0 | Z6: 0 | AA6: =IF(DGDUomWI!$C4=3,0,(S6*Z6)/100) -> 0 | AB6: =V6+W6+X6+Y6+AA6 -> 0 | AC6: =IF(DGDUomWI!$V4=1,S6+AB6,S6) -> 866.02 | AD6: 120 | AE6: =IF(DGDUomWI!$P$2=1,(S6/DGDUomWI!$S$7)*DGDUomWI!$E$18,AD6/DGDUomWI!$AD$7*DGDUomWI!$E$18) -> 0 | AG6: =IF(DGDUomWI!$P$2=1,(S6/DGDUomWI!$S$7)*DGDUomWI!$E$20,AD6/DGDUomWI!$AD$7*DGDUomWI!$E$20) -> 0 | AH6: =IF(DGDUomWI!$P$2=1,(S6/DGDUomWI!$S$7)*DGDUomWI!$E$21,AD6/DGDUomWI!$AD$7*DGDUomWI!$E$21) -> 0 | AI6: =S6*DGDUomWI!$M$2 -> 73611.7 | AJ6: =IF(DGDUomWI!$C$2=3,0,AG6+AH6) -> 0 | AK6: =IF(DGDUomWI!$C$2=3,AE6+AG6+AH6,0) -> 0 | AL6: 3 | AM6: =F6/AL6 -> 6.6666667 | AN6: =ROUND(AI6/AM6,5) -> 11041.755 | AO6: =AJ6/AM6 -> 0 | AP6: =AK6/AM6 -> 0 | AQ6: NOS | AR6: =ROUND(AN6+AO6+AP6,5) -> 11041.755 | AS6: INS WH-1 | AT6: NOS | AU6: 59.995 | AV6: 4373.41115 | AW6: =AM6 -> 6.6666667 | AX6: =AR6 -> 11041.755 | AY6: =AU6+AW6 -> 486.66667 | AZ6: =ROUND(((AU6*AV6)+(AW6*AX6))/(AU6+AW6),1) -> 1231.4 | BB6: Receipt Qty & Unit cost | BC6: LOT | BD6: RM | BE6: RMS | BL6: RM WH-49 | BM6: 43.3 | BN6: 300 | BO6: =ROUND((((AW6*AZ6)+(BN6*BM6))/(AW6+BN6)),5) -> 69.12826 | BP6: =ROUND(BN6+AW6,3) -> 306.667 | BQ6: 123562
D7: Total | H7: =SUM(H4:H4) -> 750 | R7: =SUM(R4:R4) -> 127.28 | S7: =SUM(S4:S4) -> 622.72 | V7: =SUM(V4:V4) -> 0 | W7: =SUM(W4:W4) -> 0 | X7: =SUM(X4:X4) -> 0 | AB7: =SUM(AB4:AB4) -> 0 | AC7: =SUM(AC4:AC4) -> 622.72 | AD7: =SUM(AD4:AD4) -> 120 | AE7: =SUM(AE4:AE4) -> 0 | AG7: =SUM(AG4:AG4) -> 0 | AH7: =IF($P$2=1,(S7/$S$7)*$E$21,AD7/$AD$7*$E$21) -> 0 | AI7: =SUM(AI4:AI4) -> 52931.2 | AJ7: =SUM(AJ4:AJ4) -> 0 | AK7: =SUM(AK4:AK4) -> 0
G9: Gross Purchase | I9: =H7 -> 750 | M9: Conv factor | BH9: ACPT | BI9: Acpt Qty. * Insp. Unit Cost + OLD. Qty in GRN WH * OLD Unitcost in GRN WH / Acpt. Qty + OLD. Qty in GRN WH
G10: Disc amt | I10: =R7 -> 127.28 | M10: 1 | N10: NOS | O10: 2 | P10: KGS | BH10: REJ | BI10: Rej Qty. * Insp. Unit Cost + OLD. Qty in REJ WH * OLD Unitcost in REJ WH / Acpt. Qty + OLD. Qty in REJ WH
G11: Net Purchase | I11: =S7 -> 622.72 | M11: 1 | N11: NOS | O11: 2.5 | P11: MTR
G12: Tax Amt | I12: =AB7 -> 0 | M12: 1 | N12: KGS | O12: 0.001 | P12: MT
G13: Gross Amont | I13: =I11+I12 -> 622.72
BM14: old | BN14: new
BK15: acpt Qty | BL15: 12.5 | BM15: =BL17*BL18 -> 18277.77 | BN15: =BL15*BL16 -> 6092.59
BK16: Inspection Unit Cost | BL16: 487.4072 | BM16: =BL15+BL17 -> 50
BK17: old Qty | BL17: 37.5
BK18: old UnitCost | BL18: 487.4072
BM19: =BM15+BN15 -> 24370.36 | BN19: =BM19/BM16 -> 487.4072

Sheet DGDUomWoQWI
A1: Purchase Order & GRN
A2: GST Purchase | C2: 3 | D2: (1 - Local Purchase,2 Interstate Purchase, 3 Import Purchase,4-UTGST) | I2: Cur. | J2: INR | L2: Ex. Rate | M2: 85 | O2: Apportion Basis | P2: 2 | Q2: 1 - Value Based, 2 Weight/Volume Based | V2: 1 | W2: (1 - Registered, 2 - Unregistered)
A3: No. | B3: Item | C3: Item Desc | D3: Stk. UOM | E3: Pur. UOM | F3: Qty | G3: Unit Cost | H3: Gross Amt. | I3: TD% | J3: CD% | K3: SD% | L3: TD Asbl. Val. | M3: TD Amt. | N3: CD Asbl. Val. | O3: CD Amt. | P3: VD Asbl. Val. | Q3: SD Amt. | R3: Disc. Amt. | S3: Pur. Value | T3: HSN | U3: Tax% | V3: CGST | W3: SGST | X3: IGST | Y3: UTGST | Z3: Cess% | AA3: CESS | AB3: Tax amt | AC3: Net Amt | AD3: Weight/Vol | AE3: Customs Duty | AF3: IGST (Import) | AG3: Packing & Forwarding | AH3: Freight | AI3: Pur Amt (BC) | AJ3: Chargeable Cost | AK3: Landed Cost | AL3: Conv. Factor | AM3: Eqv. Stock Qty | AN3: Pur. Unit Cost (chr) | AO3: Chrg. Unit Cost | AP3: Landed Cost Unit Cost | AQ3: Stock UOM | AR3: Unit cost (Stk. UOM) | AS3: Ins. WH | AT3: Stock UOM | AU3: Qty Before Post | AV3: Unit Cost Before Post | AW3: Receipt Qty | AX3: Receipt Unit cost | AY3: Qty After Post | AZ3: Unit Cost After Post | BA3: Result (Ok/Not OK) | BB3: Stock Transaction | BC3: Lot / Serial Type | BD3: LOT_NUMBER | BE3: SERIAL_NUMBER | BF3: Lot / Serial Trans | BG3: Locator Trans | BH3: Batch Stocks | BI3: Stock Ledger | BJ3: Stock As on Date (Qty) | BK3: Stock As on Date (Qty & vALUE) | BL3: Sou.WH | BM3: Unitcost Before Post For Source Warehouse | BN3: Qty Before Post For Source WareHouse | BO3: Unit Cost After Post | BP3: Qty After Post forSource Warehouse | BQ3: HSN
A4: 1 | B4: GWL_Dissimilar_01 | C4: GWL_Dissimilar_01 | D4: NOS | E4: NOS | F4: 5 | G4: 150 | H4: =F4*G4 -> 750 | I4: 5 | J4: 8 | K4: 5 | L4: =IF(OR(I4=0,I4="0"),0,H4) -> 750 | M4: =ROUND(L4*I4%,3) -> 37.5 | N4: =H4-M4 -> 712.5 | O4: =ROUND(N4*J4%,3) -> 57 | P4: =ROUND(N4-O4,2) -> 655.5 | Q4: =ROUND(P4*K4%,2) -> 32.78 | R4: =ROUND(M4+O4+Q4,3) -> 127.28 | S4: =(H4-R4) -> 622.72 | T4: 88363222 | U4: 18 | V4: =IF(OR($C$2=1,$C$2=4),ROUND((((S4*U4)/100)/2),2),0) -> 0 | W4: =IF($C$2=1,ROUND((((S4*U4)/100)/2),2),0) -> 0 | X4: =IF($C$2=2,ROUND(((S4*U4)/100),2),0) -> 0 | Y4: =IF($C$2=4,ROUND((((S4*U4)/100)/2),2),0) -> 0 | Z4: 0 | AA4: =IF($C2=3,0,(S4*Z4)/100) -> 0 | AB4: =V4+W4+X4+Y4+AA4 -> 0 | AC4: =IF($V2=1,S4+AB4,S4) -> 622.72 | AD4: 120 | AE4: =IF($P$2=1,(S4/$S$6)*$E$17,AD4/$AD$6*$E$17) -> 0 | AG4: =IF($P$2=1,(S4/$S$6)*$E$19,AD4/$AD$6*$E$19) -> 0 | AH4: =IF($P$2=1,(S4/$S$6)*$E$20,AD4/$AD$6*$E$20) -> 0 | AI4: =S4*$M2 -> 52931.2 | AJ4: =IF($C$2=3,0,AG4+AH4) -> 0 | AK4: =IF($C$2=3,AE4+AG4+AH4,0) -> 0 | AL4: 3 | AM4: =F4/AL4 -> 1.6666667 | AN4: =ROUND(AI4/AM4,5) -> 31758.72 | AO4: =AJ4/AM4 -> 0 | AP4: =AK4/AM4 -> 0 | AQ4: NOS | AR4: =ROUND(AN4+AO4+AP4,5) -> 31758.72 | AS4: INS WH-1 | AT4: NOS | AU4: 0 | AV4: 31758.975 | AW4: =AM4 -> 1.6666667 | AX4: =AR4 -> 31758.72 | AY4: =AU4+AW4 -> 49.995667 | AZ4: =ROUND(((AU4*AV4)+(AW4*AX4))/(AU4+AW4),3) -> 12928.014 | BB4: Receipt Qty & Unit cost | BC4: LOT | BD4: RM | BE4: RMS | BL4: RM WH-49 | BM4: 124.545 | BN4: 80 | BO4: =ROUND((((AW4*AZ4)+(BN4*BM4))/(AW4+BN4)),5) -> 385.84029 | BP4: =ROUND(BN4+AW4,3) -> 81.667 | BQ4: 123562
A5: 1 | B5: GWL_Dissimilar_02 | C5: GWL_Dissimilar_02 | D5: NOS | E5: NOS | F5: 4 | G5: 100 | H5: =F5*G5 -> 400 | I5: 4 | J5: 9 | K5: 6 | L5: =IF(OR(I5=0,I5="0"),0,H5) -> 400 | M5: =ROUND(L5*I5%,2) -> 16 | N5: =H5-M5 -> 384 | O5: =ROUND(N5*J5%,2) -> 34.56 | P5: =ROUND(N5-O5,2) -> 349.44 | Q5: =ROUND(P5*K5%,2) -> 20.97 | R5: =M5+O5+Q5 -> 71.53 | S5: =(H5-R5) -> 328.47 | T5: 88363222 | U5: 18 | V5: =IF(OR(DGDUomWoQWI!$C$2=1,DGDUomWoQWI!$C$2=4),ROUND((((S5*U5)/100)/2),2),0) -> 0 | W5: =IF(DGDUomWoQWI!$C$2=1,ROUND((((S5*U5)/100)/2),2),0) -> 0 | X5: =IF(DGDUomWoQWI!$C$2=2,ROUND(((S5*U5)/100),2),0) -> 0 | Y5: =IF(DGDUomWoQWI!$C$2=4,ROUND((((S5*U5)/100)/2),2),0) -> 0 | Z5: 0 | AA5: =IF(DGDUomWoQWI!$C3=3,0,(S5*Z5)/100) -> 0 | AB5: =V5+W5+X5+Y5+AA5 -> 0 | AC5: =IF(DGDUomWoQWI!$V3=1,S5+AB5,S5) -> 328.47 | AD5: 120 | AE5: =IF(DGDUomWoQWI!$P$2=1,(S5/DGDUomWoQWI!$S$6)*DGDUomWoQWI!$E$17,AD5/DGDUomWoQWI!$AD$6*DGDUomWoQWI!$E$17) -> 0 | AG5: =IF(DGDUomWoQWI!$P$2=1,(S5/DGDUomWoQWI!$S$6)*DGDUomWoQWI!$E$19,AD5/DGDUomWoQWI!$AD$6*DGDUomWoQWI!$E$19) -> 0 | AH5: =IF(DGDUomWoQWI!$P$2=1,(S5/DGDUomWoQWI!$S$6)*DGDUomWoQWI!$E$20,AD5/DGDUomWoQWI!$AD$6*DGDUomWoQWI!$E$20) -> 0 | AI5: =S5*DGDUomWoQWI!$M$2 -> 27919.95 | AJ5: =IF(DGDUomWoQWI!$C$2=3,0,AG5+AH5) -> 0 | AK5: =IF(DGDUomWoQWI!$C$2=3,AE5+AG5+AH5,0) -> 0 | AL5: 3 | AM5: =F5/AL5 -> 1.3333333 | AN5: =ROUND(AI5/AM5,5) -> 20939.963 | AO5: =AJ5/AM5 -> 0 | AP5: =AK5/AM5 -> 0 | AQ5: NOS | AR5: =ROUND(AN5+AO5+AP5,5) -> 20939.963 | AS5: INS WH-1 | AT5: NOS | AU5: 0 | AV5: 20940.6 | AW5: =AM5 -> 1.3333333 | AX5: =AR5 -> 20939.963 | AY5: =AU5+AW5 -> 23.994333 | AZ5: =ROUND(((AU5*AV5)+(AW5*AX5))/(AU5+AW5),2) -> 8294.26 | BB5: Receipt Qty & Unit cost | BC5: LOT | BD5: RM | BE5: RMS | BL5: RM WH-49 | BM5: 82.12 | BN5: 60 | BO5: =ROUND((((AW5*AZ5)+(BN5*BM5))/(AW5+BN5)),5) -> 260.64478 | BP5: =ROUND(BN5+AW5,3) -> 61.333 | BQ5: 123562
D6: Total | H6: =SUM(H4:H4) -> 750 | R6: =SUM(R4:R4) -> 127.28 | S6: =SUM(S4:S4) -> 622.72 | V6: =SUM(V4:V4) -> 0 | W6: =SUM(W4:W4) -> 0 | X6: =SUM(X4:X4) -> 0 | AB6: =SUM(AB4:AB4) -> 0 | AC6: =SUM(AC4:AC4) -> 622.72 | AD6: =SUM(AD4:AD4) -> 120 | AE6: =SUM(AE4:AE4) -> 0 | AG6: =SUM(AG4:AG4) -> 0 | AH6: =IF($P$2=1,(S6/$S$6)*$E$20,AD6/$AD$6*$E$20) -> 0 | AI6: =SUM(AI4:AI4) -> 52931.2 | AJ6: =SUM(AJ4:AJ4) -> 0 | AK6: =SUM(AK4:AK4) -> 0
G8: Gross Purchase | I8: =H6 -> 750 | M8: Conv factor | BH8: ACPT | BI8: Acpt Qty. * Insp. Unit Cost + OLD. Qty in GRN WH * OLD Unitcost in GRN WH / Acpt. Qty + OLD. Qty in GRN WH
G9: Disc amt | I9: =R6 -> 127.28 | M9: 1 | N9: NOS | O9: 2 | P9: KGS | BH9: REJ | BI9: Rej Qty. * Insp. Unit Cost + OLD. Qty in REJ WH * OLD Unitcost in REJ WH / Acpt. Qty + OLD. Qty in REJ WH
G10: Net Purchase | I10: =S6 -> 622.72 | M10: 1 | N10: NOS | O10: 2.5 | P10: MTR
G11: Tax Amt | I11: =AB6 -> 0 | M11: 1 | N11: KGS | O11: 0.001 | P11: MT
G12: Gross Amont | I12: =I10+I11 -> 622.72
BM13: old | BN13: new
BK14: acpt Qty | BL14: 12.5 | BM14: =BL16*BL17 -> 18277.77 | BN14: =BL14*BL15 -> 6092.59
BK15: Inspection Unit Cost | BL15: 487.4072 | BM15: =BL14+BL16 -> 50
BK16: old Qty | BL16: 37.5
BK17: old UnitCost | BL17: 487.4072
BM18: =BM14+BN14 -> 24370.36 | BN18: =BM18/BM15 -> 487.4072

Sheet DGSUomWISer
A1: Purchase Order & GRN
A2: GST Purchase | C2: 3 | D2: (1 - Local Purchase,2 Interstate Purchase, 3 Import Purchase,4-UTGST) | I2: Cur. | J2: INR | L2: Ex. Rate | M2: 85 | O2: Apportion Basis | P2: 2 | Q2: 1 - Value Based, 2 Weight/Volume Based | V2: 1 | W2: (1 - Registered, 2 - Unregistered)
A3: No. | B3: Item | C3: Item Desc | D3: Stk. UOM | E3: Pur. UOM | F3: Qty | G3: Unit Cost | H3: Gross Amt. | I3: TD% | J3: CD% | K3: SD% | L3: TD Asbl. Val. | M3: TD Amt. | N3: CD Asbl. Val. | O3: CD Amt. | P3: VD Asbl. Val. | Q3: SD Amt. | R3: Disc. Amt. | S3: Pur. Value | T3: HSN | U3: Tax% | V3: CGST | W3: SGST | X3: IGST | Y3: UTGST | Z3: Cess% | AA3: CESS | AB3: Tax amt | AC3: Net Amt | AD3: Weight/Vol | AE3: Customs Duty | AF3: IGST (Import) | AG3: Packing & Forwarding | AH3: Freight | AI3: Pur Amt (BC) | AJ3: Chargeable Cost | AK3: Landed Cost | AL3: Conv. Factor | AM3: Eqv. Stock Qty | AN3: Pur. Unit Cost (chr) | AO3: Chrg. Unit Cost | AP3: Landed Cost Unit Cost | AQ3: Stock UOM | AR3: Unit cost (Stk. UOM) | AS3: Ins. WH | AT3: Stock UOM | AU3: Qty Before Post | AV3: Unit Cost Before Post | AW3: Receipt Qty | AX3: Receipt Unit cost | AY3: Qty After Post | AZ3: Unit Cost After Post | BA3: Result (Ok/Not OK) | BB3: Stock Transaction | BC3: Lot / Serial Type | BD3: LOT_NUMBER | BE3: SERIAL_NUMBER | BF3: Lot / Serial Trans | BG3: Locator Trans | BH3: Batch Stocks | BI3: Stock Ledger | BJ3: Stock As on Date (Qty) | BK3: Stock As on Date (Qty & vALUE) | BL3: Sou.WH | BM3: Unitcost Before Post For Source Warehouse | BN3: Qty Before Post For Source WareHouse | BO3: Unit Cost After Post | BP3: Qty After Post forSource Warehouse | BQ3: HSN
A4: 1 | B4: GWL_ITem_service_03 | C4: GWL_ITem_service_03 | D4: NOS | E4: NOS | F4: 5 | G4: 150 | H4: =F4*G4 -> 750 | I4: 5 | J4: 8 | K4: 5 | L4: =IF(OR(I4=0,I4="0"),0,H4) -> 750 | M4: =ROUND(L4*I4%,3) -> 37.5 | N4: =H4-M4 -> 712.5 | O4: =ROUND(N4*J4%,3) -> 57 | P4: =ROUND(N4-O4,2) -> 655.5 | Q4: =ROUND(P4*K4%,2) -> 32.78 | R4: =ROUND(M4+O4+Q4,3) -> 127.28 | S4: =(H4-R4) -> 622.72 | T4: 88363222 | U4: 18 | V4: =IF(OR($C$2=1,$C$2=4),ROUND((((S4*U4)/100)/2),2),0) -> 0 | W4: =IF($C$2=1,ROUND((((S4*U4)/100)/2),2),0) -> 0 | X4: =IF($C$2=2,ROUND(((S4*U4)/100),2),0) -> 0 | Y4: =IF($C$2=4,ROUND((((S4*U4)/100)/2),2),0) -> 0 | Z4: 0 | AA4: =IF($C2=3,0,(S4*Z4)/100) -> 0 | AB4: =V4+W4+X4+Y4+AA4 -> 0 | AC4: =IF($V2=1,S4+AB4,S4) -> 622.72 | AD4: 120 | AE4: =IF($P$2=1,(S4/$S$7)*$E$18,AD4/$AD$7*$E$18) -> 0 | AG4: =IF($P$2=1,(S4/$S$7)*$E$20,AD4/$AD$7*$E$20) -> 0 | AH4: =IF($P$2=1,(S4/$S$7)*$E$21,AD4/$AD$7*$E$21) -> 0 | AI4: =S4*$M2 -> 52931.2 | AJ4: =IF($C$2=3,0,AG4+AH4) -> 0 | AK4: =IF($C$2=3,AE4+AG4+AH4,0) -> 0 | AL4: 1 | AM4: =F4/AL4 -> 5 | AN4: =ROUND(AI4/AM4,5) -> 10586.24 | AO4: =AJ4/AM4 -> 0 | AP4: =AK4/AM4 -> 0 | AQ4: NOS | AR4: =ROUND(AN4+AO4+AP4,5) -> 10586.24 | AS4: INS WH-1 | AT4: NOS | AU4: 375 | AV4: 3578.59301 | AW4: =AM4 -> 5 | AX4: =AR4 -> 10586.24 | AY4: =AU4+AW4 -> 380 | AZ4: =ROUND(((AU4*AV4)+(AW4*AX4))/(AU4+AW4),3) -> 3670.799 | BB4: Receipt Qty & Unit cost | BC4: LOT | BD4: RM | BE4: RMS | BL4: RM WH-49 | BM4: 124.545 | BN4: 80 | BO4: =ROUND((((AW4*AZ4)+(BN4*BM4))/(AW4+BN4)),5) -> 333.14818 | BP4: =ROUND(BN4+AW4,3) -> 85 | BQ4: 123562
A5: 1 | B5: GWL_Item_service_04 | C5: GWL_Item_service_04 | D5: NOS | E5: NOS | F5: 4 | G5: 100 | H5: =F5*G5 -> 400 | I5: 4 | J5: 9 | K5: 6 | L5: =IF(OR(I5=0,I5="0"),0,H5) -> 400 | M5: =ROUND(L5*I5%,2) -> 16 | N5: =H5-M5 -> 384 | O5: =ROUND(N5*J5%,2) -> 34.56 | P5: =ROUND(N5-O5,2) -> 349.44 | Q5: =ROUND(P5*K5%,2) -> 20.97 | R5: =M5+O5+Q5 -> 71.53 | S5: =(H5-R5) -> 328.47 | T5: 88363222 | U5: 18 | V5: =IF(OR(DGSUomWISer!$C$2=1,DGSUomWISer!$C$2=4),ROUND((((S5*U5)/100)/2),2),0) -> 0 | W5: =IF(DGSUomWISer!$C$2=1,ROUND((((S5*U5)/100)/2),2),0) -> 0 | X5: =IF(DGSUomWISer!$C$2=2,ROUND(((S5*U5)/100),2),0) -> 0 | Y5: =IF(DGSUomWISer!$C$2=4,ROUND((((S5*U5)/100)/2),2),0) -> 0 | Z5: 0 | AA5: =IF(DGSUomWISer!$C3=3,0,(S5*Z5)/100) -> 0 | AB5: =V5+W5+X5+Y5+AA5 -> 0 | AC5: =IF(DGSUomWISer!$V3=1,S5+AB5,S5) -> 328.47 | AD5: 120 | AE5: =IF(DGSUomWISer!$P$2=1,(S5/DGSUomWISer!$S$7)*DGSUomWISer!$E$18,AD5/DGSUomWISer!$AD$7*DGSUomWISer!$E$18) -> 0 | AG5: =IF(DGSUomWISer!$P$2=1,(S5/DGSUomWISer!$S$7)*DGSUomWISer!$E$20,AD5/DGSUomWISer!$AD$7*DGSUomWISer!$E$20) -> 0 | AH5: =IF(DGSUomWISer!$P$2=1,(S5/DGSUomWISer!$S$7)*DGSUomWISer!$E$21,AD5/DGSUomWISer!$AD$7*DGSUomWISer!$E$21) -> 0 | AI5: =S5*DGSUomWISer!$M$2 -> 27919.95 | AJ5: =IF(DGSUomWISer!$C$2=3,0,AG5+AH5) -> 0 | AK5: =IF(DGSUomWISer!$C$2=3,AE5+AG5+AH5,0) -> 0 | AL5: 1 | AM5: =F5/AL5 -> 4 | AN5: =ROUND(AI5/AM5,5) -> 6979.9875 | AO5: =AJ5/AM5 -> 0 | AP5: =AK5/AM5 -> 0 | AQ5: NOS | AR5: =ROUND(AN5+AO5+AP5,5) -> 6979.9875 | AS5: INS WH-1 | AT5: NOS | AU5: 188 | AV5: 1972.62723 | AW5: =AM5 -> 4 | AX5: =AR5 -> 6979.9875 | AY5: =AU5+AW5 -> 192 | AZ5: =ROUND(((AU5*AV5)+(AW5*AX5))/(AU5+AW5),2) -> 2076.95 | BB5: Receipt Qty & Unit cost | BC5: LOT | BD5: RM | BE5: RMS | BL5: RM WH-49 | BM5: 82.12 | BN5: 60 | BO5: =ROUND((((AW5*AZ5)+(BN5*BM5))/(AW5+BN5)),5) -> 206.79688 | BP5: =ROUND(BN5+AW5,3) -> 64 | BQ5: 123562
A6: 1 | B6: GWL_Item_service_05 | C6: GWL_Item_service_05 | D6: NOS | E6: NOS | F6: 20 | G6: 50 | H6: =F6*G6 -> 1000 | I6: 3 | J6: 7 | K6: 4 | L6: =IF(OR(I6=0,I6="0"),0,H6) -> 1000 | M6: =ROUND(L6*I6%,2) -> 30 | N6: =H6-M6 -> 970 | O6: =ROUND(N6*J6%,2) -> 67.9 | P6: =ROUND(N6-O6,2) -> 902.1 | Q6: =ROUND(P6*K6%,2) -> 36.08 | R6: =M6+O6+Q6 -> 133.98 | S6: =(H6-R6) -> 866.02 | T6: 88363222 | U6: 18 | V6: =IF(OR(DGSUomWISer!$C$2=1,DGSUomWISer!$C$2=4),ROUND((((S6*U6)/100)/2),2),0) -> 0 | W6: =IF(DGSUomWISer!$C$2=1,ROUND((((S6*U6)/100)/2),2),0) -> 0 | X6: =IF(DGSUomWISer!$C$2=2,ROUND(((S6*U6)/100),2),0) -> 0 | Y6: =IF(DGSUomWISer!$C$2=4,ROUND((((S6*U6)/100)/2),2),0) -> 0 | Z6: 0 | AA6: =IF(DGSUomWISer!$C4=3,0,(S6*Z6)/100) -> 0 | AB6: =V6+W6+X6+Y6+AA6 -> 0 | AC6: =IF(DGSUomWISer!$V4=1,S6+AB6,S6) -> 866.02 | AD6: 120 | AE6: =IF(DGSUomWISer!$P$2=1,(S6/DGSUomWISer!$S$7)*DGSUomWISer!$E$18,AD6/DGSUomWISer!$AD$7*DGSUomWISer!$E$18) -> 0 | AG6: =IF(DGSUomWISer!$P$2=1,(S6/DGSUomWISer!$S$7)*DGSUomWISer!$E$20,AD6/DGSUomWISer!$AD$7*DGSUomWISer!$E$20) -> 0 | AH6: =IF(DGSUomWISer!$P$2=1,(S6/DGSUomWISer!$S$7)*DGSUomWISer!$E$21,AD6/DGSUomWISer!$AD$7*DGSUomWISer!$E$21) -> 0 | AI6: =S6*DGSUomWISer!$M$2 -> 73611.7 | AJ6: =IF(DGSUomWISer!$C$2=3,0,AG6+AH6) -> 0 | AK6: =IF(DGSUomWISer!$C$2=3,AE6+AG6+AH6,0) -> 0 | AL6: 1 | AM6: =F6/AL6 -> 20 | AN6: =ROUND(AI6/AM6,5) -> 3680.585 | AO6: =AJ6/AM6 -> 0 | AP6: =AK6/AM6 -> 0 | AQ6: NOS | AR6: =ROUND(AN6+AO6+AP6,5) -> 3680.585 | AS6: INS WH-1 | AT6: NOS | AU6: 480 | AV6: 1095.12917 | AW6: =AM6 -> 20 | AX6: =AR6 -> 3680.585 | AY6: =AU6+AW6 -> 500 | AZ6: =ROUND(((AU6*AV6)+(AW6*AX6))/(AU6+AW6),1) -> 1198.5 | BB6: Receipt Qty & Unit cost | BC6: LOT | BD6: RM | BE6: RMS | BL6: RM WH-49 | BM6: 43.3 | BN6: 300 | BO6: =ROUND((((AW6*AZ6)+(BN6*BM6))/(AW6+BN6)),5) -> 115.5 | BP6: =ROUND(BN6+AW6,3) -> 320 | BQ6: 123562
D7: Total | H7: =SUM(H4:H4) -> 750 | R7: =SUM(R4:R4) -> 127.28 | S7: =SUM(S4:S4) -> 622.72 | V7: =SUM(V4:V4) -> 0 | W7: =SUM(W4:W4) -> 0 | X7: =SUM(X4:X4) -> 0 | AB7: =SUM(AB4:AB4) -> 0 | AC7: =SUM(AC4:AC4) -> 622.72 | AD7: =SUM(AD4:AD4) -> 120 | AE7: =SUM(AE4:AE4) -> 0 | AG7: =SUM(AG4:AG4) -> 0 | AH7: =IF($P$2=1,(S7/$S$7)*$E$21,AD7/$AD$7*$E$21) -> 0 | AI7: =SUM(AI4:AI4) -> 52931.2 | AJ7: =SUM(AJ4:AJ4) -> 0 | AK7: =SUM(AK4:AK4) -> 0
G9: Gross Purchase | I9: =H7 -> 750 | M9: Conv factor | BH9: ACPT | BI9: Acpt Qty. * Insp. Unit Cost + OLD. Qty in GRN WH * OLD Unitcost in GRN WH / Acpt. Qty + OLD. Qty in GRN WH
G10: Disc amt | I10: =R7 -> 127.28 | M10: 1 | N10: NOS | O10: 2 | P10: KGS | BH10: REJ | BI10: Rej Qty. * Insp. Unit Cost + OLD. Qty in REJ WH * OLD Unitcost in REJ WH / Acpt. Qty + OLD. Qty in REJ WH
G11: Net Purchase | I11: =S7 -> 622.72 | M11: 1 | N11: NOS | O11: 2.5 | P11: MTR
G12: Tax Amt | I12: =AB7 -> 0 | M12: 1 | N12: KGS | O12: 0.001 | P12: MT
G13: Gross Amont | I13: =I11+I12 -> 622.72
BM14: old | BN14: new
BK15: acpt Qty | BL15: 12.5 | BM15: =BL17*BL18 -> 18277.77 | BN15: =BL15*BL16 -> 6092.59
BK16: Inspection Unit Cost | BL16: 487.4072 | BM16: =BL15+BL17 -> 50
BK17: old Qty | BL17: 37.5
BK18: old UnitCost | BL18: 487.4072
BM19: =BM15+BN15 -> 24370.36 | BN19: =BM19/BM16 -> 487.4072

Sheet DGSUomWoQWISer
A1: Purchase Order & GRN
A2: GST Purchase | C2: 3 | D2: (1 - Local Purchase,2 Interstate Purchase, 3 Import Purchase,4-UTGST) | I2: Cur. | J2: INR | L2: Ex. Rate | M2: 85 | O2: Apportion Basis | P2: 2 | Q2: 1 - Value Based, 2 Weight/Volume Based | V2: 1 | W2: (1 - Registered, 2 - Unregistered)
A3: No. | B3: Item | C3: Item Desc | D3: Stk. UOM | E3: Pur. UOM | F3: Qty | G3: Unit Cost | H3: Gross Amt. | I3: TD% | J3: CD% | K3: SD% | L3: TD Asbl. Val. | M3: TD Amt. | N3: CD Asbl. Val. | O3: CD Amt. | P3: VD Asbl. Val. | Q3: SD Amt. | R3: Disc. Amt. | S3: Pur. Value | T3: HSN | U3: Tax% | V3: CGST | W3: SGST | X3: IGST | Y3: UTGST | Z3: Cess% | AA3: CESS | AB3: Tax amt | AC3: Net Amt | AD3: Weight/Vol | AE3: Customs Duty | AF3: IGST (Import) | AG3: Packing & Forwarding | AH3: Freight | AI3: Pur Amt (BC) | AJ3: Chargeable Cost | AK3: Landed Cost | AL3: Conv. Factor | AM3: Eqv. Stock Qty | AN3: Pur. Unit Cost (chr) | AO3: Chrg. Unit Cost | AP3: Landed Cost Unit Cost | AQ3: Stock UOM | AR3: Unit cost (Stk. UOM) | AS3: Ins. WH | AT3: Stock UOM | AU3: Qty Before Post | AV3: Unit Cost Before Post | AW3: Receipt Qty | AX3: Receipt Unit cost | AY3: Qty After Post | AZ3: Unit Cost After Post | BA3: Result (Ok/Not OK) | BB3: Stock Transaction | BC3: Lot / Serial Type | BD3: LOT_NUMBER | BE3: SERIAL_NUMBER | BF3: Lot / Serial Trans | BG3: Locator Trans | BH3: Batch Stocks | BI3: Stock Ledger | BJ3: Stock As on Date (Qty) | BK3: Stock As on Date (Qty & vALUE) | BL3: Sou.WH | BM3: Unitcost Before Post For Source Warehouse | BN3: Qty Before Post For Source WareHouse | BO3: Unit Cost After Post | BP3: Qty After Post forSource Warehouse | BQ3: HSN
A4: 1 | B4: GWL_Item_FP_service_01 | C4: GWL_Item_FP_service_01 | D4: NOS | E4: NOS | F4: 5 | G4: 150 | H4: =F4*G4 -> 750 | I4: 5 | J4: 8 | K4: 5 | L4: =IF(OR(I4=0,I4="0"),0,H4) -> 750 | M4: =ROUND(L4*I4%,3) -> 37.5 | N4: =H4-M4 -> 712.5 | O4: =ROUND(N4*J4%,3) -> 57 | P4: =ROUND(N4-O4,2) -> 655.5 | Q4: =ROUND(P4*K4%,2) -> 32.78 | R4: =ROUND(M4+O4+Q4,3) -> 127.28 | S4: =(H4-R4) -> 622.72 | T4: 88363222 | U4: 18 | V4: =IF(OR($C$2=1,$C$2=4),ROUND((((S4*U4)/100)/2),2),0) -> 0 | W4: =IF($C$2=1,ROUND((((S4*U4)/100)/2),2),0) -> 0 | X4: =IF($C$2=2,ROUND(((S4*U4)/100),2),0) -> 0 | Y4: =IF($C$2=4,ROUND((((S4*U4)/100)/2),2),0) -> 0 | Z4: 0 | AA4: =IF($C2=3,0,(S4*Z4)/100) -> 0 | AB4: =V4+W4+X4+Y4+AA4 -> 0 | AC4: =IF($V2=1,S4+AB4,S4) -> 622.72 | AD4: 120 | AE4: =IF($P$2=1,(S4/$S$7)*$E$18,AD4/$AD$7*$E$18) -> 0 | AG4: =IF($P$2=1,(S4/$S$7)*$E$20,AD4/$AD$7*$E$20) -> 0 | AH4: =IF($P$2=1,(S4/$S$7)*$E$21,AD4/$AD$7*$E$21) -> 0 | AI4: =S4*$M2 -> 52931.2 | AJ4: =IF($C$2=3,0,AG4+AH4) -> 0 | AK4: =IF($C$2=3,AE4+AG4+AH4,0) -> 0 | AL4: 1 | AM4: =F4/AL4 -> 5 | AN4: =ROUND(AI4/AM4,5) -> 10586.24 | AO4: =AJ4/AM4 -> 0 | AP4: =AK4/AM4 -> 0 | AQ4: NOS | AR4: =ROUND(AN4+AO4+AP4,5) -> 10586.24 | AS4: INS WH-1 | AT4: NOS | AU4: 375 | AV4: 3578.59301 | AW4: =AM4 -> 5 | AX4: =AR4 -> 10586.24 | AY4: =AU4+AW4 -> 380 | AZ4: =ROUND(((AU4*AV4)+(AW4*AX4))/(AU4+AW4),3) -> 3670.799 | BB4: Receipt Qty & Unit cost | BC4: LOT | BD4: RM | BE4: RMS | BL4: RM WH-49 | BM4: 124.545 | BN4: 80 | BO4: =ROUND((((AW4*AZ4)+(BN4*BM4))/(AW4+BN4)),5) -> 333.14818 | BP4: =ROUND(BN4+AW4,3) -> 85 | BQ4: 123562
A5: 1 | B5: GWL_Item_FP_service_02 | C5: GWL_Item_FP_service_02 | D5: NOS | E5: NOS | F5: 4 | G5: 100 | H5: =F5*G5 -> 400 | I5: 4 | J5: 9 | K5: 6 | L5: =IF(OR(I5=0,I5="0"),0,H5) -> 400 | M5: =ROUND(L5*I5%,2) -> 16 | N5: =H5-M5 -> 384 | O5: =ROUND(N5*J5%,2) -> 34.56 | P5: =ROUND(N5-O5,2) -> 349.44 | Q5: =ROUND(P5*K5%,2) -> 20.97 | R5: =M5+O5+Q5 -> 71.53 | S5: =(H5-R5) -> 328.47 | T5: 88363222 | U5: 18 | V5: =IF(OR(DGSUomWoQWISer!$C$2=1,DGSUomWoQWISer!$C$2=4),ROUND((((S5*U5)/100)/2),2),0) -> 0 | W5: =IF(DGSUomWoQWISer!$C$2=1,ROUND((((S5*U5)/100)/2),2),0) -> 0 | X5: =IF(DGSUomWoQWISer!$C$2=2,ROUND(((S5*U5)/100),2),0) -> 0 | Y5: =IF(DGSUomWoQWISer!$C$2=4,ROUND((((S5*U5)/100)/2),2),0) -> 0 | Z5: 0 | AA5: =IF(DGSUomWoQWISer!$C3=3,0,(S5*Z5)/100) -> 0 | AB5: =V5+W5+X5+Y5+AA5 -> 0 | AC5: =IF(DGSUomWoQWISer!$V3=1,S5+AB5,S5) -> 328.47 | AD5: 120 | AE5: =IF(DGSUomWoQWISer!$P$2=1,(S5/DGSUomWoQWISer!$S$7)*DGSUomWoQWISer!$E$18,AD5/DGSUomWoQWISer!$AD$7*DGSUomWoQWISer!$E$18) -> 0 | AG5: =IF(DGSUomWoQWISer!$P$2=1,(S5/DGSUomWoQWISer!$S$7)*DGSUomWoQWISer!$E$20,AD5/DGSUomWoQWISer!$AD$7*DGSUomWoQWISer!$E$20) -> 0 | AH5: =IF(DGSUomWoQWISer!$P$2=1,(S5/DGSUomWoQWISer!$S$7)*DGSUomWoQWISer!$E$21,AD5/DGSUomWoQWISer!$AD$7*DGSUomWoQWISer!$E$21) -> 0 | AI5: =S5*DGSUomWoQWISer!$M$2 -> 27919.95 | AJ5: =IF(DGSUomWoQWISer!$C$2=3,0,AG5+AH5) -> 0 | AK5: =IF(DGSUomWoQWISer!$C$2=3,AE5+AG5+AH5,0) -> 0 | AL5: 1 | AM5: =F5/AL5 -> 4 | AN5: =ROUND(AI5/AM5,5) -> 6979.9875 | AO5: =AJ5/AM5 -> 0 | AP5: =AK5/AM5 -> 0 | AQ5: NOS | AR5: =ROUND(AN5+AO5+AP5,5) -> 6979.9875 | AS5: INS WH-1 | AT5: NOS | AU5: 188 | AV5: 1972.62723 | AW5: =AM5 -> 4 | AX5: =AR5 -> 6979.9875 | AY5: =AU5+AW5 -> 192 | AZ5: =ROUND(((AU5*AV5)+(AW5*AX5))/(AU5+AW5),2) -> 2076.95 | BB5: Receipt Qty & Unit cost | BC5: LOT | BD5: RM | BE5: RMS | BL5: RM WH-49 | BM5: 82.12 | BN5: 60 | BO5: =ROUND((((AW5*AZ5)+(BN5*BM5))/(AW5+BN5)),5) -> 206.79688 | BP5: =ROUND(BN5+AW5,3) -> 64 | BQ5: 123562
A6: 1 | B6: GWL_Item_FP_service_03 | C6: GWL_Item_FP_service_03 | D6: NOS | E6: NOS | F6: 20 | G6: 50 | H6: =F6*G6 -> 1000 | I6: 3 | J6: 7 | K6: 4 | L6: =IF(OR(I6=0,I6="0"),0,H6) -> 1000 | M6: =ROUND(L6*I6%,2) -> 30 | N6: =H6-M6 -> 970 | O6: =ROUND(N6*J6%,2) -> 67.9 | P6: =ROUND(N6-O6,2) -> 902.1 | Q6: =ROUND(P6*K6%,2) -> 36.08 | R6: =M6+O6+Q6 -> 133.98 | S6: =(H6-R6) -> 866.02 | T6: 88363222 | U6: 18 | V6: =IF(OR(DGSUomWoQWISer!$C$2=1,DGSUomWoQWISer!$C$2=4),ROUND((((S6*U6)/100)/2),2),0) -> 0 | W6: =IF(DGSUomWoQWISer!$C$2=1,ROUND((((S6*U6)/100)/2),2),0) -> 0 | X6: =IF(DGSUomWoQWISer!$C$2=2,ROUND(((S6*U6)/100),2),0) -> 0 | Y6: =IF(DGSUomWoQWISer!$C$2=4,ROUND((((S6*U6)/100)/2),2),0) -> 0 | Z6: 0 | AA6: =IF(DGSUomWoQWISer!$C4=3,0,(S6*Z6)/100) -> 0 | AB6: =V6+W6+X6+Y6+AA6 -> 0 | AC6: =IF(DGSUomWoQWISer!$V4=1,S6+AB6,S6) -> 866.02 | AD6: 120 | AE6: =IF(DGSUomWoQWISer!$P$2=1,(S6/DGSUomWoQWISer!$S$7)*DGSUomWoQWISer!$E$18,AD6/DGSUomWoQWISer!$AD$7*DGSUomWoQWISer!$E$18) -> 0 | AG6: =IF(DGSUomWoQWISer!$P$2=1,(S6/DGSUomWoQWISer!$S$7)*DGSUomWoQWISer!$E$20,AD6/DGSUomWoQWISer!$AD$7*DGSUomWoQWISer!$E$20) -> 0 | AH6: =IF(DGSUomWoQWISer!$P$2=1,(S6/DGSUomWoQWISer!$S$7)*DGSUomWoQWISer!$E$21,AD6/DGSUomWoQWISer!$AD$7*DGSUomWoQWISer!$E$21) -> 0 | AI6: =S6*DGSUomWoQWISer!$M$2 -> 73611.7 | AJ6: =IF(DGSUomWoQWISer!$C$2=3,0,AG6+AH6) -> 0 | AK6: =IF(DGSUomWoQWISer!$C$2=3,AE6+AG6+AH6,0) -> 0 | AL6: 1 | AM6: =F6/AL6 -> 20 | AN6: =ROUND(AI6/AM6,5) -> 3680.585 | AO6: =AJ6/AM6 -> 0 | AP6: =AK6/AM6 -> 0 | AQ6: NOS | AR6: =ROUND(AN6+AO6+AP6,5) -> 3680.585 | AS6: INS WH-1 | AT6: NOS | AU6: 480 | AV6: 1095.12917 | AW6: =AM6 -> 20 | AX6: =AR6 -> 3680.585 | AY6: =AU6+AW6 -> 500 | AZ6: =ROUND(((AU6*AV6)+(AW6*AX6))/(AU6+AW6),1) -> 1198.5 | BB6: Receipt Qty & Unit cost | BC6: LOT | BD6: RM | BE6: RMS | BL6: RM WH-49 | BM6: 43.3 | BN6: 300 | BO6: =ROUND((((AW6*AZ6)+(BN6*BM6))/(AW6+BN6)),5) -> 115.5 | BP6: =ROUND(BN6+AW6,3) -> 320 | BQ6: 123562
D7: Total | H7: =SUM(H4:H4) -> 750 | R7: =SUM(R4:R4) -> 127.28 | S7: =SUM(S4:S4) -> 622.72 | V7: =SUM(V4:V4) -> 0 | W7: =SUM(W4:W4) -> 0 | X7: =SUM(X4:X4) -> 0 | AB7: =SUM(AB4:AB4) -> 0 | AC7: =SUM(AC4:AC4) -> 622.72 | AD7: =SUM(AD4:AD4) -> 120 | AE7: =SUM(AE4:AE4) -> 0 | AG7: =SUM(AG4:AG4) -> 0 | AH7: =IF($P$2=1,(S7/$S$7)*$E$21,AD7/$AD$7*$E$21) -> 0 | AI7: =SUM(AI4:AI4) -> 52931.2 | AJ7: =SUM(AJ4:AJ4) -> 0 | AK7: =SUM(AK4:AK4) -> 0
G9: Gross Purchase | I9: =H7 -> 750 | M9: Conv factor | BH9: ACPT | BI9: Acpt Qty. * Insp. Unit Cost + OLD. Qty in GRN WH * OLD Unitcost in GRN WH / Acpt. Qty + OLD. Qty in GRN WH
G10: Disc amt | I10: =R7 -> 127.28 | M10: 1 | N10: NOS | O10: 2 | P10: KGS | BH10: REJ | BI10: Rej Qty. * Insp. Unit Cost + OLD. Qty in REJ WH * OLD Unitcost in REJ WH / Acpt. Qty + OLD. Qty in REJ WH
G11: Net Purchase | I11: =S7 -> 622.72 | M11: 1 | N11: NOS | O11: 2.5 | P11: MTR
G12: Tax Amt | I12: =AB7 -> 0 | M12: 1 | N12: KGS | O12: 0.001 | P12: MT
G13: Gross Amont | I13: =I11+I12 -> 622.72
BM14: old | BN14: new
BK15: acpt Qty | BL15: 12.5 | BM15: =BL17*BL18 -> 18277.77 | BN15: =BL15*BL16 -> 6092.59
BK16: Inspection Unit Cost | BL16: 487.4072 | BM16: =BL15+BL17 -> 50
BK17: old Qty | BL17: 37.5
BK18: old UnitCost | BL18: 487.4072
BM19: =BM15+BN15 -> 24370.36 | BN19: =BM19/BM16 -> 487.4072

Sheet DGSUomWoQRcWISer
A1: Purchase Order & GRN
A2: GST Purchase | C2: 3 | D2: (1 - Local Purchase,2 Interstate Purchase, 3 Import Purchase,4-UTGST) | I2: Cur. | J2: INR | L2: Ex. Rate | M2: 85 | O2: Apportion Basis | P2: 2 | Q2: 1 - Value Based, 2 Weight/Volume Based | V2: 1 | W2: (1 - Registered, 2 - Unregistered)
A3: No. | B3: Item | C3: Item Desc | D3: Stk. UOM | E3: Pur. UOM | F3: Qty | G3: Unit Cost | H3: Gross Amt. | I3: TD% | J3: CD% | K3: SD% | L3: TD Asbl. Val. | M3: TD Amt. | N3: CD Asbl. Val. | O3: CD Amt. | P3: VD Asbl. Val. | Q3: SD Amt. | R3: Disc. Amt. | S3: Pur. Value | T3: HSN | U3: Tax% | V3: CGST | W3: SGST | X3: IGST | Y3: UTGST | Z3: Cess% | AA3: CESS | AB3: Tax amt | AC3: Net Amt | AD3: Weight/Vol | AE3: Customs Duty | AF3: IGST (Import) | AG3: Packing & Forwarding | AH3: Freight | AI3: Pur Amt (BC) | AJ3: Chargeable Cost | AK3: Landed Cost | AL3: Conv. Factor | AM3: Eqv. Stock Qty | AN3: Pur. Unit Cost (chr) | AO3: Chrg. Unit Cost | AP3: Landed Cost Unit Cost | AQ3: Stock UOM | AR3: Unit cost (Stk. UOM) | AS3: Ins. WH | AT3: Stock UOM | AU3: Qty Before Post | AV3: Unit Cost Before Post | AW3: Receipt Qty | AX3: Receipt Unit cost | AY3: Qty After Post | AZ3: Unit Cost After Post | BA3: Result (Ok/Not OK) | BB3: Stock Transaction | BC3: Lot / Serial Type | BD3: LOT_NUMBER | BE3: SERIAL_NUMBER | BF3: Lot / Serial Trans | BG3: Locator Trans | BH3: Batch Stocks | BI3: Stock Ledger | BJ3: Stock As on Date (Qty) | BK3: Stock As on Date (Qty & vALUE) | BL3: Sou.WH | BM3: Unitcost Before Post For Source Warehouse | BN3: Qty Before Post For Source WareHouse | BO3: Unit Cost After Post | BP3: Qty After Post forSource Warehouse | BQ3: HSN
A4: 1 | B4: GWL_Item_FP_Rc_Service_01 | C4: GWL_Item_FP_Rc_Service_01 | D4: NOS | E4: NOS | F4: 5 | G4: 50 | H4: =F4*G4 -> 250 | I4: 0 | J4: 8 | K4: 5 | L4: =IF(OR(I4=0,I4="0"),0,H4) -> 0 | M4: =ROUND(L4*I4%,3) -> 0 | N4: =H4-M4 -> 250 | O4: =ROUND(N4*J4%,3) -> 20 | P4: =ROUND(N4-O4,2) -> 230 | Q4: =ROUND(P4*K4%,2) -> 11.5 | R4: =ROUND(M4+O4+Q4,3) -> 31.5 | S4: =(H4-R4) -> 218.5 | T4: 88363222 | U4: 18 | V4: =IF(OR($C$2=1,$C$2=4),ROUND((((S4*U4)/100)/2),2),0) -> 0 | W4: =IF($C$2=1,ROUND((((S4*U4)/100)/2),2),0) -> 0 | X4: =IF($C$2=2,ROUND(((S4*U4)/100),2),0) -> 0 | Y4: =IF($C$2=4,ROUND((((S4*U4)/100)/2),2),0) -> 0 | Z4: 0 | AA4: =IF($C2=3,0,(S4*Z4)/100) -> 0 | AB4: =V4+W4+X4+Y4+AA4 -> 0 | AC4: =IF($V2=1,S4+AB4,S4) -> 218.5 | AD4: 120 | AE4: =IF($P$2=1,(S4/$S$7)*$E$18,AD4/$AD$7*$E$18) -> 0 | AG4: =IF($P$2=1,(S4/$S$7)*$E$20,AD4/$AD$7*$E$20) -> 0 | AH4: =IF($P$2=1,(S4/$S$7)*$E$21,AD4/$AD$7*$E$21) -> 0 | AI4: =S4*$M2 -> 18572.5 | AJ4: =IF($C$2=3,0,AG4+AH4) -> 0 | AK4: =IF($C$2=3,AE4+AG4+AH4,0) -> 0 | AL4: 1 | AM4: =F4/AL4 -> 5 | AN4: =ROUND(AI4/AM4,5) -> 3714.5 | AO4: =AJ4/AM4 -> 0 | AP4: =AK4/AM4 -> 0 | AQ4: NOS | AR4: =ROUND(AN4+AO4+AP4,5) -> 3714.5 | AS4: INS WH-1 | AT4: NOS | AU4: 375 | AV4: 3578.59301 | AW4: =AM4 -> 5 | AX4: =AR4 -> 3714.5 | AY4: =AU4+AW4 -> 380 | AZ4: =ROUND(((AU4*AV4)+(AW4*AX4))/(AU4+AW4),3) -> 3580.381 | BB4: Receipt Qty & Unit cost | BC4: LOT | BD4: RM | BE4: RMS | BL4: RM WH-49 | BM4: 124.545 | BN4: 80 | BO4: =ROUND((((AW4*AZ4)+(BN4*BM4))/(AW4+BN4)),5) -> 327.82947 | BP4: =ROUND(BN4+AW4,3) -> 85 | BQ4: 123562
A5: 1 | B5: GWL_Item_FP_Rc_Service_02 | C5: GWL_Item_FP_Rc_Service_02 | D5: NOS | E5: NOS | F5: 4 | G5: 100 | H5: =F5*G5 -> 400 | I5: 4 | J5: 9 | K5: 6 | L5: =IF(OR(I5=0,I5="0"),0,H5) -> 400 | M5: =ROUND(L5*I5%,2) -> 16 | N5: =H5-M5 -> 384 | O5: =ROUND(N5*J5%,2) -> 34.56 | P5: =ROUND(N5-O5,2) -> 349.44 | Q5: =ROUND(P5*K5%,2) -> 20.97 | R5: =M5+O5+Q5 -> 71.53 | S5: =(H5-R5) -> 328.47 | T5: 88363222 | U5: 18 | V5: =IF(OR(DGSUomWoQRcWISer!$C$2=1,DGSUomWoQRcWISer!$C$2=4),ROUND((((S5*U5)/100)/2),2),0) -> 0 | W5: =IF(DGSUomWoQRcWISer!$C$2=1,ROUND((((S5*U5)/100)/2),2),0) -> 0 | X5: =IF(DGSUomWoQRcWISer!$C$2=2,ROUND(((S5*U5)/100),2),0) -> 0 | Y5: =IF(DGSUomWoQRcWISer!$C$2=4,ROUND((((S5*U5)/100)/2),2),0) -> 0 | Z5: 0 | AA5: =IF(DGSUomWoQRcWISer!$C3=3,0,(S5*Z5)/100) -> 0 | AB5: =V5+W5+X5+Y5+AA5 -> 0 | AC5: =IF(DGSUomWoQRcWISer!$V3=1,S5+AB5,S5) -> 328.47 | AD5: 120 | AE5: =IF(DGSUomWoQRcWISer!$P$2=1,(S5/DGSUomWoQRcWISer!$S$7)*DGSUomWoQRcWISer!$E$18,AD5/DGSUomWoQRcWISer!$AD$7*DGSUomWoQRcWISer!$E$18) -> 0 | AG5: =IF(DGSUomWoQRcWISer!$P$2=1,(S5/DGSUomWoQRcWISer!$S$7)*DGSUomWoQRcWISer!$E$20,AD5/DGSUomWoQRcWISer!$AD$7*DGSUomWoQRcWISer!$E$20) -> 0 | AH5: =IF(DGSUomWoQRcWISer!$P$2=1,(S5/DGSUomWoQRcWISer!$S$7)*DGSUomWoQRcWISer!$E$21,AD5/DGSUomWoQRcWISer!$AD$7*DGSUomWoQRcWISer!$E$21) -> 0 | AI5: =S5*DGSUomWoQRcWISer!$M$2 -> 27919.95 | AJ5: =IF(DGSUomWoQRcWISer!$C$2=3,0,AG5+AH5) -> 0 | AK5: =IF(DGSUomWoQRcWISer!$C$2=3,AE5+AG5+AH5,0) -> 0 | AL5: 1 | AM5: =F5/AL5 -> 4 | AN5: =ROUND(AI5/AM5,5) -> 6979.9875 | AO5: =AJ5/AM5 -> 0 | AP5: =AK5/AM5 -> 0 | AQ5: NOS | AR5: =ROUND(AN5+AO5+AP5,5) -> 6979.9875 | AS5: INS WH-1 | AT5: NOS | AU5: 188 | AV5: 1972.62723 | AW5: =AM5 -> 4 | AX5: =AR5 -> 6979.9875 | AY5: =AU5+AW5 -> 192 | AZ5: =ROUND(((AU5*AV5)+(AW5*AX5))/(AU5+AW5),2) -> 2076.95 | BB5: Receipt Qty & Unit cost | BC5: LOT | BD5: RM | BE5: RMS | BL5: RM WH-49 | BM5: 82.12 | BN5: 60 | BO5: =ROUND((((AW5*AZ5)+(BN5*BM5))/(AW5+BN5)),5) -> 206.79688 | BP5: =ROUND(BN5+AW5,3) -> 64 | BQ5: 123562
A6: 1 | B6: GWL_Item_FP_Rc_Service_03 | C6: GWL_Item_FP_Rc_Service_03 | D6: NOS | E6: NOS | F6: 20 | G6: 50 | H6: =F6*G6 -> 1000 | I6: 3 | J6: 7 | K6: 4 | L6: =IF(OR(I6=0,I6="0"),0,H6) -> 1000 | M6: =ROUND(L6*I6%,2) -> 30 | N6: =H6-M6 -> 970 | O6: =ROUND(N6*J6%,2) -> 67.9 | P6: =ROUND(N6-O6,2) -> 902.1 | Q6: =ROUND(P6*K6%,2) -> 36.08 | R6: =M6+O6+Q6 -> 133.98 | S6: =(H6-R6) -> 866.02 | T6: 88363222 | U6: 18 | V6: =IF(OR(DGSUomWoQRcWISer!$C$2=1,DGSUomWoQRcWISer!$C$2=4),ROUND((((S6*U6)/100)/2),2),0) -> 0 | W6: =IF(DGSUomWoQRcWISer!$C$2=1,ROUND((((S6*U6)/100)/2),2),0) -> 0 | X6: =IF(DGSUomWoQRcWISer!$C$2=2,ROUND(((S6*U6)/100),2),0) -> 0 | Y6: =IF(DGSUomWoQRcWISer!$C$2=4,ROUND((((S6*U6)/100)/2),2),0) -> 0 | Z6: 0 | AA6: =IF(DGSUomWoQRcWISer!$C4=3,0,(S6*Z6)/100) -> 0 | AB6: =V6+W6+X6+Y6+AA6 -> 0 | AC6: =IF(DGSUomWoQRcWISer!$V4=1,S6+AB6,S6) -> 866.02 | AD6: 120 | AE6: =IF(DGSUomWoQRcWISer!$P$2=1,(S6/DGSUomWoQRcWISer!$S$7)*DGSUomWoQRcWISer!$E$18,AD6/DGSUomWoQRcWISer!$AD$7*DGSUomWoQRcWISer!$E$18) -> 0 | AG6: =IF(DGSUomWoQRcWISer!$P$2=1,(S6/DGSUomWoQRcWISer!$S$7)*DGSUomWoQRcWISer!$E$20,AD6/DGSUomWoQRcWISer!$AD$7*DGSUomWoQRcWISer!$E$20) -> 0 | AH6: =IF(DGSUomWoQRcWISer!$P$2=1,(S6/DGSUomWoQRcWISer!$S$7)*DGSUomWoQRcWISer!$E$21,AD6/DGSUomWoQRcWISer!$AD$7*DGSUomWoQRcWISer!$E$21) -> 0 | AI6: =S6*DGSUomWoQRcWISer!$M$2 -> 73611.7 | AJ6: =IF(DGSUomWoQRcWISer!$C$2=3,0,AG6+AH6) -> 0 | AK6: =IF(DGSUomWoQRcWISer!$C$2=3,AE6+AG6+AH6,0) -> 0 | AL6: 1 | AM6: =F6/AL6 -> 20 | AN6: =ROUND(AI6/AM6,5) -> 3680.585 | AO6: =AJ6/AM6 -> 0 | AP6: =AK6/AM6 -> 0 | AQ6: NOS | AR6: =ROUND(AN6+AO6+AP6,5) -> 3680.585 | AS6: INS WH-1 | AT6: NOS | AU6: 480 | AV6: 1095.12917 | AW6: =AM6 -> 20 | AX6: =AR6 -> 3680.585 | AY6: =AU6+AW6 -> 500 | AZ6: =ROUND(((AU6*AV6)+(AW6*AX6))/(AU6+AW6),1) -> 1198.5 | BB6: Receipt Qty & Unit cost | BC6: LOT | BD6: RM | BE6: RMS | BL6: RM WH-49 | BM6: 43.3 | BN6: 300 | BO6: =ROUND((((AW6*AZ6)+(BN6*BM6))/(AW6+BN6)),5) -> 115.5 | BP6: =ROUND(BN6+AW6,3) -> 320 | BQ6: 123562
D7: Total | H7: =SUM(H4:H4) -> 250 | R7: =SUM(R4:R4) -> 31.5 | S7: =SUM(S4:S4) -> 218.5 | V7: =SUM(V4:V4) -> 0 | W7: =SUM(W4:W4) -> 0 | X7: =SUM(X4:X4) -> 0 | AB7: =SUM(AB4:AB4) -> 0 | AC7: =SUM(AC4:AC4) -> 218.5 | AD7: =SUM(AD4:AD4) -> 120 | AE7: =SUM(AE4:AE4) -> 0 | AG7: =SUM(AG4:AG4) -> 0 | AH7: =IF($P$2=1,(S7/$S$7)*$E$21,AD7/$AD$7*$E$21) -> 0 | AI7: =SUM(AI4:AI4) -> 18572.5 | AJ7: =SUM(AJ4:AJ4) -> 0 | AK7: =SUM(AK4:AK4) -> 0
G9: Gross Purchase | I9: =H7 -> 250 | M9: Conv factor | BH9: ACPT | BI9: Acpt Qty. * Insp. Unit Cost + OLD. Qty in GRN WH * OLD Unitcost in GRN WH / Acpt. Qty + OLD. Qty in GRN WH
G10: Disc amt | I10: =R7 -> 31.5 | M10: 1 | N10: NOS | O10: 2 | P10: KGS | BH10: REJ | BI10: Rej Qty. * Insp. Unit Cost + OLD. Qty in REJ WH * OLD Unitcost in REJ WH / Acpt. Qty + OLD. Qty in REJ WH
G11: Net Purchase | I11: =S7 -> 218.5 | M11: 1 | N11: NOS | O11: 2.5 | P11: MTR
G12: Tax Amt | I12: =AB7 -> 0 | M12: 1 | N12: KGS | O12: 0.001 | P12: MT
G13: Gross Amont | I13: =I11+I12 -> 218.5
BM14: old | BN14: new
BK15: acpt Qty | BL15: 12.5 | BM15: =BL17*BL18 -> 18277.77 | BN15: =BL15*BL16 -> 6092.59
BK16: Inspection Unit Cost | BL16: 487.4072 | BM16: =BL15+BL17 -> 50
BK17: old Qty | BL17: 37.5
BK18: old UnitCost | BL18: 487.4072
BM19: =BM15+BN15 -> 24370.36 | BN19: =BM19/BM16 -> 487.4072

Sheet DGSUomWIRcSer
A1: Purchase Order & GRN
A2: GST Purchase | C2: 3 | D2: (1 - Local Purchase,2 Interstate Purchase, 3 Import Purchase,4-UTGST) | I2: Cur. | J2: INR | L2: Ex. Rate | M2: 85 | O2: Apportion Basis | P2: 2 | Q2: 1 - Value Based, 2 Weight/Volume Based | V2: 1 | W2: (1 - Registered, 2 - Unregistered)
A3: No. | B3: Item | C3: Item Desc | D3: Stk. UOM | E3: Pur. UOM | F3: Qty | G3: Unit Cost | H3: Gross Amt. | I3: TD% | J3: CD% | K3: SD% | L3: TD Asbl. Val. | M3: TD Amt. | N3: CD Asbl. Val. | O3: CD Amt. | P3: VD Asbl. Val. | Q3: SD Amt. | R3: Disc. Amt. | S3: Pur. Value | T3: HSN | U3: Tax% | V3: CGST | W3: SGST | X3: IGST | Y3: UTGST | Z3: Cess% | AA3: CESS | AB3: Tax amt | AC3: Net Amt | AD3: Weight/Vol | AE3: Customs Duty | AF3: IGST (Import) | AG3: Packing & Forwarding | AH3: Freight | AI3: Pur Amt (BC) | AJ3: Chargeable Cost | AK3: Landed Cost | AL3: Conv. Factor | AM3: Eqv. Stock Qty | AN3: Pur. Unit Cost (chr) | AO3: Chrg. Unit Cost | AP3: Landed Cost Unit Cost | AQ3: Stock UOM | AR3: Unit cost (Stk. UOM) | AS3: Ins. WH | AT3: Stock UOM | AU3: Qty Before Post | AV3: Unit Cost Before Post | AW3: Receipt Qty | AX3: Receipt Unit cost | AY3: Qty After Post | AZ3: Unit Cost After Post | BA3: Result (Ok/Not OK) | BB3: Stock Transaction | BC3: Lot / Serial Type | BD3: LOT_NUMBER | BE3: SERIAL_NUMBER | BF3: Lot / Serial Trans | BG3: Locator Trans | BH3: Batch Stocks | BI3: Stock Ledger | BJ3: Stock As on Date (Qty) | BK3: Stock As on Date (Qty & vALUE) | BL3: Sou.WH | BM3: Unitcost Before Post For Source Warehouse | BN3: Qty Before Post For Source WareHouse | BO3: Unit Cost After Post | BP3: Qty After Post forSource Warehouse | BQ3: HSN
A4: 1 | B4: GWL_Item_Service_Rc_04 | C4: GWL_Item_Service_Rc_04 | D4: NOS | E4: NOS | F4: 5 | G4: 150 | H4: =F4*G4 -> 750 | I4: 5 | J4: 8 | K4: 5 | L4: =IF(OR(I4=0,I4="0"),0,H4) -> 750 | M4: =ROUND(L4*I4%,3) -> 37.5 | N4: =H4-M4 -> 712.5 | O4: =ROUND(N4*J4%,3) -> 57 | P4: =ROUND(N4-O4,2) -> 655.5 | Q4: =ROUND(P4*K4%,2) -> 32.78 | R4: =ROUND(M4+O4+Q4,3) -> 127.28 | S4: =(H4-R4) -> 622.72 | T4: 88363222 | U4: 18 | V4: =IF(OR($C$2=1,$C$2=4),ROUND((((S4*U4)/100)/2),2),0) -> 0 | W4: =IF($C$2=1,ROUND((((S4*U4)/100)/2),2),0) -> 0 | X4: =IF($C$2=2,ROUND(((S4*U4)/100),2),0) -> 0 | Y4: =IF($C$2=4,ROUND((((S4*U4)/100)/2),2),0) -> 0 | Z4: 0 | AA4: =IF($C2=3,0,(S4*Z4)/100) -> 0 | AB4: =V4+W4+X4+Y4+AA4 -> 0 | AC4: =IF($V2=1,S4+AB4,S4) -> 622.72 | AD4: 120 | AE4: =IF($P$2=1,(S4/$S$7)*$E$18,AD4/$AD$7*$E$18) -> 0 | AG4: =IF($P$2=1,(S4/$S$7)*$E$20,AD4/$AD$7*$E$20) -> 0 | AH4: =IF($P$2=1,(S4/$S$7)*$E$21,AD4/$AD$7*$E$21) -> 0 | AI4: =S4*$M2 -> 52931.2 | AJ4: =IF($C$2=3,0,AG4+AH4) -> 0 | AK4: =IF($C$2=3,AE4+AG4+AH4,0) -> 0 | AL4: 1 | AM4: =F4/AL4 -> 5 | AN4: =ROUND(AI4/AM4,5) -> 10586.24 | AO4: =AJ4/AM4 -> 0 | AP4: =AK4/AM4 -> 0 | AQ4: NOS | AR4: =ROUND(AN4+AO4+AP4,5) -> 10586.24 | AS4: INS WH-1 | AT4: NOS | AU4: 375 | AV4: 3578.59301 | AW4: =AM4 -> 5 | AX4: =AR4 -> 10586.24 | AY4: =AU4+AW4 -> 380 | AZ4: =ROUND(((AU4*AV4)+(AW4*AX4))/(AU4+AW4),3) -> 3670.799 | BB4: Receipt Qty & Unit cost | BC4: LOT | BD4: RM | BE4: RMS | BL4: RM WH-49 | BM4: 124.545 | BN4: 80 | BO4: =ROUND((((AW4*AZ4)+(BN4*BM4))/(AW4+BN4)),5) -> 333.14818 | BP4: =ROUND(BN4+AW4,3) -> 85 | BQ4: 123562
