Workbook

Sheet PR Details
A1: ITEM_NAME | B1: CLASS | C1: SUBCLASS | D1: WAREHOUSE | E1: CONVENTION_FACTOR | F1: PURCHASE_UOM | G1: GL_ACC_NO | H1: GL_ACC_DESC | I1: CPC_CODE | J1: CPC_DESC
A2: GWL_ITEM - Serial | B2: RAW MATERIAL | C2: RAW MATERIALS | D2: FINISHED GOODS WH U100 | E2: 1 | F2: NOS | G2: 1010301033 | H2: FINISHED GOODS | I2: CPC-100000001 | J2: GENERAL U-100
A3: GWL_ITEM_DISSIMILAR_UOM | B3: RAW MATERIAL | C3: RAW MATERIALS | D3: FG WAREHOUSE 100 | E3: 6 | F3: KGS | G3: 1010301033 | H3: FINISHED GOODS | I3: CPC-100000001 | J3: GENERAL U-100
A4: GWL_SERVICES_02 | B4: SERVICES | C4: SERVICES | D4: PRODUCTION 100 | E4: 1 | F4: NOS | G4: 5010100004 | H4: CHARGES ACCT | I4: CPC-100000001 | J4: GENERAL U-100

Sheet PO Details
A1: ITEMID | B1: ITEM_DESCRIPTION | C1: UOM | D1: HSN_CODE | E1: TAX | F1: SUBCLASS | G1: CLASS | H1: WH_DEPTNAME | I1: COST_BASIS | J1: STOCK_UOM | K1: CONVERSION_FACTOR | L1: GL_ACC_NO | M1: GL_ACC_DESC | N1: CPC_CODE | O1: CPC_DESC | P1: CONTRACT_NO | Q1: CONTRACT_PRFX | R1: CONTRACT_AMEND_NO | S1: PO_CLS_QTY | T1: RCM_CAT_ID
A2: GWL_ITEM_DISSIMILAR_UOM | B2: GWL_ITEM_DISSIMILAR_UOM_DESC | C2: KGS | D2: (740410)-18% | E2: 12 | F2: RAW MATERIALS | G2: RAW MATERIAL | H2: FG WAREHOUSE 100 | I2: User Defined | J2: NOS | K2: 6 | L2: 1010301033 | M2: FINISHED GOODS | N2: CPC-100000001 | O2: GENERAL U-100 | S2: 0
A3: GWL_ITEM - Serial | B3: GWL ITEM SERIAL | C3: NOS | D3: (2022) | E3: 5 | F3: RAW MATERIALS | G3: RAW MATERIAL | H3: FINISHED GOODS WH U100 | I3: User Defined Price | J3: NOS | K3: 1 | L3: 1010301033 | M3: FINISHED GOODS | N3: CPC-100000001 | O3: GENERAL U-100 | S3: 0
A4: GWL_SERVICES_02 | B4: GWL_SERVICES_02_DESCRIPTION | C4: NOS | D4: 123562 | E4: 18 | F4: SERVICES | G4: SERVICES | H4: PRODUCTION 100 | I4: User Defined Price | J4: NOS | K4: 1 | L4: 1011134888 | M4: EXPENSE DOCUMENT 3 | N4: CPC-100000001 | O4: GENERAL U-100 | S4: 0
A5: GWL_CHECKING_ST | B5: GWL_CHECKING_ST | C5: NOS | D5: (740410)-18% | E5: 12 | F5: BICYCLES VARIANTS | G5: TWO WHEELER - AUTOMOBILES | H5: AURANGABAD DEPOT | I5: User Defined Price | J5: NOS | K5: 1 | L5: 1010301001 | M5: INVENTORY - FG | N5: U2L1L2L3L4L5L601 | O5: GENERAL U2 | S5: 0
A6: GWL_Item_Similar_02 | B6: GWL_Item_Similar_02 | C6: NOS | D6: (2022) | E6: 5 | F6: RAW MATERIALS | G6: RAW MATERIAL | H6: FG WAREHOUSE 100 | I6: User Defined Price | J6: NOS | K6: 1 | L6: 1010301033 | M6: FINISHED GOODS | N6: CPC-100000001 | O6: GENERAL U-100 | S6: 0
A7: HK-NA-MAC-10001 | B7: HK-NOTAPPLICABLE-MAC-10001 | C7: KGS | D7: (740410)-18% | E7: 12 | F7: RAW MATERIALS | G7: RAW MATERIAL | H7: RAW MATERIAL WH U100 | I7: User Defined | J7: NOS | K7: 3 | L7: 1010301003 | M7: INVENTORY - RAW MATERIAL | N7: CPC-100000001 | O7: GENERAL U-100 | S7: 0
A8: HK-FIFO-SER-BATCH-10001 | B8: HK-FIFO-SERIAL-BATCH-10001 | C8: NOS | D8: (2022) | E8: 5 | F8: RAW MATERIALS | G8: RAW MATERIAL | H8: RAW MATERIAL WH U100 | I8: User Defined | J8: NOS | K8: 0 | L8: 1010301003 | M8: INVENTORY - RAW MATERIAL | N8: CPC-100000001 | O8: GENERAL U-100 | S8: 0
A9: HK-LOT-FIFO-LOT-10001 | B9: HK-LOT-FIFO-LOT-10001 | C9: NOS | D9: (2022) | E9: 5 | F9: RAW MATERIALS | G9: RAW MATERIAL | H9: RAW MATERIAL WH U100 | I9: User Defined | J9: NOS | K9: 0 | L9: 1010301003 | M9: INVENTORY - RAW MATERIAL | N9: CPC-100000001 | O9: GENERAL U-100 | S9: 0
A10: GWL_ITem_service_03 | B10: GWL_ITem_service_03 | C10: NOS | D10: (2022) | E10: 5 | F10: SERVICES | G10: SERVICES | H10: PRODUCTION 100 | I10: User Defined Price | J10: NOS | K10: 1 | L10: 1000000001 | M10: SBI CC 30498311798 | N10: CPC-100000001 | O10: GENERAL U-100 | S10: 0

Sheet POA Details
A1: ITEMID | B1: ITEM_DESCRIPTION | C1: UOM | D1: GL_ACC_NO | E1: GL_ACC_DESC | F1: CPC_CODE | G1: CPC_DESC | H1: WH_DEPTNAME | I1: HSN_CODE | J1: COST_BASIS | K1: SUPL_UOM | L1: CONVERSION_FACTOR
A2: GWL_Item_Similar_02 | B2: GWL_Item_Similar_02 | C2: NOS | D2: 1010301033 | E2: FINISHED GOODS | F2: CPC-100000001 | G2: GENERAL U-100 | H2: FG WAREHOUSE 100 | I2: (2022) | J2: User Defined Price | K2: NOS | L2: 1
A3: GWL_ITem_service_03 | B3: GWL_ITem_service_03 | C3: NOS | D3: 1000000001 | E3: SBI CC 30498311798 | F3: CPC-100000001 | G3: GENERAL U-100 | H3: PRODUCTION 100 | I3: (2022) | J3: User Defined Price | K3: NOS | L3: 1

Sheet PO _ITEM_MATERIAL
A1: ITEM_NAME | B1: QUANTITY | C1: UNIT_COST | D1: LOT_SERIAL | E1: LOT_NUMBER | F1: SERIAL_NUMBER
A2: HK-FIFO-SER-BATCH-10001 | B2: 2 | C2: 70 | D2: SERIAL | F2: RM1
A3: HK-LOT-FIFO-LOT-10001 | B3: 40 | C3: 26 | D3: LOT | E3: RM | F3: 2

Sheet PO _ITEM_GEN
A1: ITEM_NAME | B1: QUANTITY | C1: UNIT_COST | D1: LOT_SERIAL | E1: LOT_NUMBER | F1: SERIAL_NUMBER
A2: HK-FIFO-SER-BATCH-10001 | B2: 2 | C2: 45 | D2: SERIAL | F2: RMG
A3: HK-NA-MAC-10001 | B3: 40 | C3: 26 | D3: NA | E3: RM | F3: 2
A4: HK-LOT-FIFO-LOT-10001 | B4: 50 | C4: 70 | D4: LOT | E4: RMG

Sheet StockTransferItem
A1: Stock_Transfer_Item | B1: QTY | C1: UnitCost
A2: TVS FG-MAC-NA-USER DEFINED | B2: 100 | C2: 34
A3: TVS-FG-00015 | B3: 50 | C3: 30

Sheet POwithRateContractItem
A1: RateContractItem | B1: Quantity | C1: UnitCost | D1: DiscountPercentage | E1: LOT_SERIAL | F1: LOT_NUMBER | G1: SERIAL_NUMBER
A2: PK-SER-MAC-10001 | B2: 2 | C2: 524 | D2: 2 | E2: SERIAL | F2: RM | G2: RMS
A3: PK-LOT-MAC-10001 | B3: 232 | C3: 232 | D3: 7.9 | E3: LOT | F3: RML
A4: PK-NA-MAC-10001 | B4: 232 | C4: 232 | D4: 2.32 | E4: NA

Sheet POwithRateContractItem_Mat
A1: RateContractItem | B1: Quantity | C1: UnitCost | D1: DiscountPercentage | E1: LOT_SERIAL | F1: LOT_NUMBER | G1: SERIAL_NUMBER
A2: PK-SER-MAC-10001 | B2: 2 | C2: 524 | D2: 2 | E2: SERIAL | F2: RM | G2: RMS
A3: PK-LOT-MAC-10001 | B3: 34 | C3: 232 | D3: 7.9 | E3: LOT | F3: RML
A4: PK-NA-MAC-10001 | B4: 67 | C4: 232 | D4: 2.32 | E4: NA

Sheet SO Details
A1: ITEM_ID | B1: ITEM_REV | C1: ITEM_DESC | D1: SALE_UOM | E1: HSN_CODE | F1: TAX_PCT | G1: PRICE_BASIS_TYPE | H1: CONTRACT_NO | I1: CATALOG_PRICELIST_NO | J1: STOCK_UOM | K1: CONV_FACT | L1: TOLERANCE_TYPE | M1: CUST_ITEM_ID | N1: CUST_ITEM_DESC | O1: WAREHOUSE_DESC | P1: SUB_CLASS | Q1: CLASS | R1: PRICECLASS | S1: PROMOTIONAL
A2: HK-FIFO-LOT-BATCH-10001(FG) | B2: 0 | C2: HK-FIFO-LOT-BATCH-10001(FG) | D2: NOS | E2: (740410)-18% | F2: 12 | G2: User Defined | J2: NOS | K2: 1 | L2: Item Level | O2: FINISHED GOODS WH U100 | P2: FINISHED GOODS | Q2: FINISHED GOODS | R2: DOMESTIC | S2: Sales Regular
A3: HK-FG-DISSIMILAR-10001 | B3: 0 | C3: HK-FG-DISSIMILAR-10001 | D3: NOS | E3: 772213 | F3: 5 | G3: User Defined | J3: KGS | K3: 3 | L3: Item Level | O3: FINISHED GOODS WH U100 | P3: FINISHED GOODS | Q3: FINISHED GOODS | R3: DOMESTIC | S3: Sales Regular
A4: HK-SER-MAC-10001(FG) | B4: 0 | C4: HK-SER-MAC-10001(FG) | D4: NOS | E4: (740410)-18% | F4: 12 | G4: Standard Price | J4: NOS | K4: 1 | L4: Item Level | M4: HK-SER-MAC-10001(FG) | N4: HK-SER-MAC-10001(FG) | O4: FINISHED GOODS WH U100 | P4: FINISHED GOODS | Q4: FINISHED GOODS | R4: DOMESTIC | S4: Sales Regular
A5: HK-FG-STD-PRICE-DISSIMILAR ITEM-10001 | B5: 0 | C5: HK-FG-STD-PRICE-DISSIMILAR ITEM-10001 | D5: NOS | E5: (740410)-18% | F5: 12 | G5: Standard Price | J5: KGS | K5: 2 | L5: Item Level | M5: HK-FG-STD-PRICE-DISSIMILAR ITEM-10001 | N5: HK-FG-STD-PRICE-DISSIMILAR ITEM-10001 | O5: FINISHED GOODS WH U100 | P5: FINISHED GOODS | Q5: FINISHED GOODS | R5: DOMESTIC | S5: Sales Regular
A6: HK-LOT-MAC-10001(FG) | B6: 0 | C6: HK-LOT-MAC-10001(FG) | D6: NOS | E6: (740410)-18% | F6: 12 | G6: Open Order | H6: OPSO1/00094/24-25 | J6: NOS | K6: 1 | L6: Item Level | M6: HK-LOT-MAC-10001(FG) | N6: HK-LOT-MAC-10001(FG) | O6: FINISHED GOODS WH U100 | P6: FINISHED GOODS | Q6: FINISHED GOODS | R6: DOMESTIC | S6: Sales Regular
A7: HK-FG-RC-DISSIMILAR ITEM-10001 | B7: 0 | C7: HK-FG-RC-DISSIMILAR ITEM-10001 | D7: NOS | E7: (740410)-18% | F7: 12 | G7: Open Order | H7: OPSO1/00114/24-25 | J7: KGS | K7: 4 | L7: Item Level | M7: HK-FG-RC-DISSIMILAR ITEM-10001 | N7: HK-FG-RC-DISSIMILAR ITEM-10001 | O7: FINISHED GOODS WH U100 | P7: FINISHED GOODS | Q7: FINISHED GOODS | R7: DOMESTIC | S7: Sales Regular
A8: HK-FIFO-SER-BATCH-10001(FG) | B8: 0 | C8: HK-FIFO-SER-BATCH-10001(FG) | D8: NOS | E8: (2022)5% | F8: 5 | G8: Catalog | I8: 95 | J8: NOS | K8: 1 | L8: Item Level | M8: HK-FIFO-SER-BATCH-10001(FG) | N8: HK-FIFO-SER-BATCH-10001(FG) | O8: FINISHED GOODS WH U100 | P8: FINISHED GOODS | Q8: FINISHED GOODS | R8: DOMESTIC | S8: Sales Regular
A9: HK-FG-CATALOG-DISSIMILAR-10001 | B9: 0 | C9: HK-FG-CATALOG-DISSIMILAR-10001 | D9: NOS | E9: (740410)-18% | F9: 12 | G9: Catalog | I9: 97 | J9: KGS | K9: 4 | L9: Item Level | M9: HK-FG-CATALOG-DISSIMILAR-10001 | N9: HK-FG-CATALOG-DISSIMILAR-10001 | O9: FINISHED GOODS WH U100 | P9: FINISHED GOODS | Q9: FINISHED GOODS | R9: DOMESTIC | S9: Sales Regular
A10: HK-LOT-FIFO-LOT-10001(FG) | B10: 0 | C10: HK-LOT-FIFO-LOT-10001(FG) | D10: NOS | E10: (740410)-18% | F10: 12 | G10: Price List | J10: NOS | K10: 1 | L10: Item Level | M10: HK-LOT-FIFO-LOT-10001(FG) | N10: HK-LOT-FIFO-LOT-10001(FG) | O10: FINISHED GOODS WH U100 | P10: FINISHED GOODS | Q10: FINISHED GOODS | R10: DOMESTIC | S10: Sales Regular
A11: HK-FG-PRICELIST-DISSIMILAR UOM-10001 | B11: 0 | C11: HK-FG-PRICELIST-DISSIMILAR UOM-10001 | D11: NOS | E11: (740410)-18% | F11: 12 | G11: Price List | J11: KGS | K11: 4 | L11: Item Level | M11: HK-FG-PRICELIST-DISSIMILAR UOM-10001 | N11: HK-FG-PRICELIST-DISSIMILAR UOM-10001 | O11: FINISHED GOODS WH U100 | P11: FINISHED GOODS | Q11: FINISHED GOODS | R11: DOMESTIC | S11: Sales Regular
A12: HK-TVS-SCRAP-10001 | B12: 0 | C12: HK-TVS-SCRAP-10001 | D12: NOS | E12: 772213 | F12: 5 | G12: User Defined | J12: NOS | K12: 1 | L12: Item Level | O12: RAW MATERIAL WH U100 | P12: SCRAP | Q12: SCRAP | R12: DOMESTIC | S12: Sales Regular
A13: TVS-SER-10001 | B13: 0 | C13: SERVICE ITEM 10001 | D13: NOS | E13: 772213 | F13: 5 | G13: User Defined | J13: NOS | K13: 1 | L13: Item Level | P13: SERVICES | Q13: SERVICES | R13: DOMESTIC | S13: Sales Regular
A14: PRO-10001 | B14: 0 | C14: PROMOTIONAL ITEM - 10001 | D14: NOS | E14: 772213 | F14: 5 | G14: User Defined | J14: NOS | K14: 1 | L14: Item Level | O14: RAW MATERIAL WH U100 | P14: RAW MATERIALS | Q14: RAW MATERIAL | R14: DOMESTIC | S14: Promotional
A15: HK-USRDFN-10001 | B15: 0 | C15: HK-USERDEFINED-10001 | D15: NOS | E15: 0074 | F15: 12 | G15: User Defined | J15: NOS | K15: 1 | L15: Item Level | O15: FINISHED GOODS WH U100 | P15: RAW MATERIALS | Q15: RAW MATERIAL | R15: DOMESTIC | S15: Sales Regular
A16: HK-TVS-FG-10001 | B16: 0 | C16: HK-TVS-FG-10001 | D16: MTON | E16: 88363222 | F16: 18 | G16: User Defined | J16: NOS | K16: .0001 | L16: Item Level | O16: FINISHED GOODS WH U100 | P16: FINISHED GOODS | Q16: FINISHED GOODS | R16: DOMESTIC | S16: Sales Regular
A17: HK-TVS-FG-10002 | B17: 0 | C17: HK-TVS-FG-10002 | D17: MTON | E17: 88363222 | F17: 18 | G17: User Defined | J17: NOS | K17: .0001 | L17: Item Level | O17: FINISHED GOODS WH U100 | P17: FINISHED GOODS | Q17: FINISHED GOODS | R17: DOMESTIC | S17: Sales Regular

Sheet Customer SO Details
A1: CUST_ID | B1: CUST_DESC | C1: GST_TYPE | D1: SALES_GST_TYPE | E1: GST_CLASSIFICATION | F1: CUST_PRINT_NAME | G1: SALES_ZONE | H1: SALES_REGION | I1: CUST_SUB_GRP | J1: CUST_GRP | K1: SALES_PERSON
A2: CUS0015 | B2: MURUGAN TRADERS | C2: Unregistered | D2: Inter-State | E2: Union Territory | F2: MURUGAN TRADERS | G2: NORTH | H2: INTERSTATE | I2: BPCL | J2: SUNDRY DEBTORS-PART | K2: VIJAIKUMAR
A3: CU0060 | B3: FRANCE FOREIGN TRADERS | C3: Unregistered | D3: Export | E3: Export | F3: FRANCE FOREIGN TRADERS | G3: EXPORT | H3: EXPORT | I3: AASHIRVAD AUTOTECH - PART | J3: SUNDRY DEBTORS-PART | K3: VIJAIKUMAR
A4: CUS10002 | B4: ARUN PVT LTD. | C4: Registered | D4: Local | E4: Local | F4: ARUN PVT LTD. | G4: MADURAI | H4: LOCAL | I4: SUNDRY DEBTORS - RAW MATERIALS | J4: SUNDRY DEBTORS-PART | K4: HARIHARAN
A5: CUS10005 | B5: CHENNAI SEZ | C5: Registered | D5: SEZ-Unit | E5: SEZ-Unit | F5: CHENNAI SEZ | G5: CHENNAI | H5: SOUTH | I5: SUNDRY DEBTORS - RAW MATERIALS | J5: SUNDRY DEBTORS-PART | K5: HARIHARAN
A6: HK-CUS-001 | B6: HARI TRADERS | C6: Registered | D6: Local | E6: Local | F6: HARI TRADERS | G6: TAMILNADU | H6: LOCAL | I6: AASHIRVAD AUTOTECH - PART | J6: SUNDRY DEBTORS-PART | K6: VIJAIKUMAR

Sheet Open Sales
A1: LOCATION_ID | B1: UNIT | C1: CUSTOMER_ID | D1: CUSTOMER_NAME | E1: OSO_NO
A2: L100 | B2: U100 | C2: CUS0015 | D2: MURUGAN TRADERS | E2: OPSO1/00092/24-25
A3: L0001 | B3: U1 | C3: C010 | D3: MAHESH TRADERS | E3: OSOD-2425-00240
A4: L30 | B4: U30 | C4: CUS0007 | D4: ARGOMM S.P.A -EXPORT | E4: OSO30-2425-00005

Sheet SI Details
A1: Customer_Name | B1: Currency | C1: SI_Type | D1: Loc_Id | E1: Unit | F1: GST_Classification | G1: GST_Type
A2: ARUN PVT LTD. | B2: INR | C2: SI - GENERAL | D2: L100 | E2: U100 | F2: Local | G2: Registered
A3: FRANCE FOREIGN TRADERS | B3: USD | C3: SI - GENERAL | D3: L100 | E3: U100 | F3: Export | G3: Unregistered
A4: AJK ENTERPRISES | B4: INR | C4: SI - GENERAL | D4: L100 | E4: U100 | F4: Local | G4: Registered
A5: MURUGAN TRADERS | B5: INR | C5: SI - GENERAL | D5: L100 | E5: U100 | F5: Inter-State | G5: Unregistered
A6: PANDI PVT. LTD | B6: INR | C6: SI - GENERAL | D6: L100 | E6: U100 | F6: Inter-State | G6: Registered
A7: PRAKASH PVT. LTD. | B7: INR | C7: SI - GENERAL | D7: L100 | E7: U100 | F7: Inter-State | G7: Registered
A8: CHENNAI SEZ | B8: INR | C8: SI - GENERAL | D8: L100 | E8: U100 | F8: SEZ-Unit | G8: Registered
A9: INKSPLASH PRINTING | B9: INR | C9: SI - FREE SAMPLE | D9: L100 | E9: U100 | F9: Local | G9: Registered
A10: MALAR TRADERS | B10: INR | C10: SI - FREE REPLACEMENT | D10: L100 | E10: U100 | F10: Local | G10: Registered
A11: URBAN ENTERPRISES | B11: INR | C11: SI - SCRAP | D11: L100 | E11: U100 | F11: Local | G11: Registered
A12: GANESH ENTERPRISE | B12: INR | C12: SI - SERVICE | D12: L100 | E12: U100 | F12: Local | G12: Registered
... A14: WEGA ASSOCIATES | B14: USD | C14: SI - GENERAL | D14: LOC49 | E14: L3 | F14: Export | G14: Unregistered

Sheet MRTOMRV Data
A1: Item | B1: WareHouse | C1: Quantity
A2: GWL_ITEM_STOCK_01 | B2: RM KD | C2: 2
A3: GWL_ITEM_STOCK_04 | B3: RM KD | C3: 2

Sheet MRCustomer
A1: Item | B1: WareHouse | C1: Quantity | D1: Unit Cost | E1: Stock Cost | F1: Line Amount
A2: HK-LOT-MAC-10001 | B2: RM KD | C2: 10 | D2: 84.75 | E2: 84.74822 | F2: =ROUND(C2*E2,2) -> 847.48
A3: HK-LOT-MAC-10001(FG) | B3: F100 | C3: 12 | D3: 13.27 | E3: 13.27173 | F3: =ROUND(C3*E3,2) -> 159.26

Sheet MRTOMRVWip Data
A1: Item | B1: WareHouse | C1: Quantity
A2: GWL_ITEM_STOCK_06 | B2: RM KD | C2: 2
A3: GWL_ITEM_STOCK_07 | B3: RM KD | C3: 2

Sheet RateContract_SER
A1: RateContrac_Ser_tItem | B1: Quantity
A2: PK-SERV-MAC-NA-01 | B2: 10

Sheet PricelistItem
A1: PricelistItem | B1: Quantity | C1: UnitCost | D1: DiscountPercentage | E1: LOT_SERIAL | F1: LOT_NUMBER | G1: SERIAL_NUMBER
A2: TVS-RM-KDK-26 | B2: 22 | C2: 524 | D2: 2 | E2: LOT | F2: RM | G2: RMS
A3: TVS-RM-KDK-25 | B3: 34 | C3: 232 | D3: 7.9 | E3: LOT | F3: RML

Sheet ST_ITEM_RATECONTRACT
A1: PricelistItem | B1: Quantity | C1: UnitCost
A2: TVS-SIM-257793 | B2: 22 | C2: 524
A3: TVS-SIM-395809 | B3: 40 | C3: 450

Sheet ServiceItemPriceList
A1: PriceList_Ser_tItem | B1: Quantity
A2: TVS-SER-10005 | B2: 10

Sheet ST_Item_PriceList
A1: PricelistItem | B1: Quantity | C1: UnitCost
A2: TVS-SIM-599803 | B2: 23
A3: TVS-SIM-050035 | B3: 45

Sheet BankPaymentMultiPartyMultiBills
A1: SNO | B1: GL ACCOUNT DESC | C1: PARTY ID | D1: PARTY NAME | E1: SHEETNAME | F1: ENTITY | G1: CPC DESC | H1: BILL DOC NUMBER | I1: PAY AMOUNT | J1: DR./CR | K1: CURCY | L1: EX.RATE | M1: TRANS CURRENCY | N1: BASE CURRENCY | O1: HSN CODE | P1: TAX PERCENTAGE | Q1: ASSESABLE VALUE | R1: CGST | S1: SGST | T1: IGST | U1: UTGST | V1: CESS PERCENTAGE | W1: CESS AMOUNT
A2: 1 | B2: HARIKRISH PVT LTD(AP) | C2: TAX-FJH | D2: HARIKRISH PVT LTD | E2: DirectGrnGenUDLocal | F2: TVSA | G2: GENERAL U-100 | H2: 00256 | I2: 2000 | J2: DR | K2: INR | L2: 1
A3: 2 | B3: HARIKRISH PVT LTD(AP) | C3: TAX-FJH | D3: HARIKRISH PVT LTD | E3: DirectGrnGenUDLocal | F3: TVSA | G3: GENERAL U-100 | H3: 00256 | I3: 2000 | J3: DR | K3: INR | L3: 1
A4: 3 | B4: JJ AUTOMOBILES | C4: SUP00124 | D4: JJ AUTOMOBILES | E4: DirectGrnGenUD | F4: TVSA | G4: GENERAL U-100 | H4: 00123 | I4: 1000 | J4: DR | K4: INR | L4: 1 | M4: =I4*L4 -> 1000 | N4: =I4 -> 1000 | Q4: =M4 -> 1000
A5: 4 | B5: JJ AUTOMOBILES | C5: SUP00124 | D5: JJ AUTOMOBILES | E5: DirectGrnGenUD | F5: TVSA | G5: GENERAL U-100 | H5: 00123 | I5: 1000 | J5: DR | K5: INR | L5: 1 | M5: =I5*L5 -> 1000 | N5: =I5 -> 1000 | Q5: =M5 -> 1000

Sheet BankPaymentMPMB
A1: SNO | B1: GL ACCOUNT DESC | C1: PARTY ID | D1: PARTY NAME | E1: SHEETNAME | F1: ENTITY | G1: CPC DESC | H1: BILL DOC NUMBER | I1: PAY AMOUNT | J1: DR./CR | K1: CURCY | L1: EX.RATE | M1: TRANS CURRENCY | N1: BASE CURRENCY | O1: HSN CODE | P1: TAX PERCENTAGE | Q1: ASSESABLE VALUE | R1: CGST | S1: SGST | T1: IGST | U1: UTGST | V1: CESS PERCENTAGE | W1: CESS AMOUNT
A2: 1 | B2: HARIKRISH PVT LTD(AP) | C2: TAX-FJH | D2: HARIKRISH PVT LTD | E2: DirectGrnGenUDMulti | F2: TVSA | G2: GENERAL U-100 | H2: 00256 | I2: 2000 | J2: DR | K2: INR | L2: 1
A3: 2 | B3: JJ AUTOMOBILES | C3: SUP00124 | D3: JJ AUTOMOBILES | E3: DirectGrnGenUDLocalMulti | F3: TVSA | G3: GENERAL U-100 | H3: 00123 | I3: 1000 | J3: DR | K3: INR | L3: 1 | M3: =I3*L3 -> 1000 | N3: =I3 -> 1000 | Q3: =M3 -> 1000

Sheet BankPaymentMultiParty
A1: SNO | B1: GL ACCOUNT DESC | C1: PARTY ID | D1: PARTY NAME | E1: SHEETNAME | F1: ENTITY | G1: CPC DESC | H1: BILL DOC NUMBER | I1: PAY AMOUNT | J1: DR./CR | K1: CURCY | L1: EX.RATE | M1: TRANS CURRENCY | N1: BASE CURRENCY | O1: HSN CODE | P1: TAX PERCENTAGE | Q1: ASSESABLE VALUE | R1: CGST | S1: SGST | T1: IGST | U1: UTGST | V1: CESS PERCENTAGE | W1: CESS AMOUNT
A2: 1 | B2: HARIKRISH PVT LTD(AP) | C2: TAX-FJH | D2: HARIKRISH PVT LTD | E2: DirectGrnGenUDLocal | F2: TVSA | G2: GENERAL U-100 | H2: 00256 | I2: 2000 | J2: DR | K2: INR | L2: 1
A3: 2 | B3: JJ AUTOMOBILES | C3: SUP00124 | D3: JJ AUTOMOBILES | E3: DirectGrnGenUD | F3: TVSA | G3: GENERAL U-100 | H3: 00123 | I3: 1000 | J3: DR | K3: INR | L3: 1 | M3: =I3*L3 -> 1000 | N3: =I3 -> 1000 | Q3: =M3 -> 1000

Sheet BankPaymentMultiNewRef
A1: SNO | B1: GL ACCOUNT DESC | C1: PARTY NAME | D1: ENTITY | E1: CPC DESC | F1: BILL DOC NUMBER | G1: PAY AMOUNT | H1: DR./CR | I1: CURCY | J1: EX.RATE | K1: TRANS CURRENCY | L1: BASE CURRENCY | M1: HSN CODE | N1: TAX PERCENTAGE | O1: ASSESABLE VALUE | P1: CGST | Q1: SGST | R1: IGST | S1: UTGST | T1: CESS PERCENTAGE | U1: CESS AMOUNT
A2: 1 | B2: JJ AUTOMOBILES | C2: JJ AUTOMOBILES | D2: TVSA | E2: GENERAL U-100 | F2: 00123 | G2: 1000 | H2: DR | I2: INR | J2: 1 | K2: =G2*J2 -> 1000 | L2: =G2 -> 1000 | O2: =K2 -> 1000
A3: 2 | B3: HARIKRISH PVT LTD(AP) | C3: HARIKRISH PVT LTD | D3: TVSA | E3: GENERAL U-100 | F3: 00768 | G3: 1000 | H3: DR | I3: INR | J3: 1 | K3: =G3*J3 -> 1000 | L3: =G3 -> 1000 | O3: =K3 -> 1000

Sheet BPSPMB
A1: SNO | B1: GL ACCOUNT DESC | C1: PARTY ID | D1: PARTY NAME | E1: SHEETNAME | F1: ENTITY | G1: CPC DESC | H1: BILL DOC NUMBER | I1: PAY AMOUNT | J1: DR./CR | K1: CURCY | L1: EX.RATE | M1: TRANS CURRENCY | N1: BASE CURRENCY | O1: HSN CODE | P1: TAX PERCENTAGE | Q1: ASSESABLE VALUE | R1: CGST | S1: SGST | T1: IGST | U1: UTGST | V1: CESS PERCENTAGE | W1: CESS AMOUNT | X1: UNIT | Y1: DOC TYPE | Z1: BILL NUMBER | AA1: BILL DATE | AB1: BILL AMOUNT | AC1: TAX AMT | AD1: PB DOC NUMBER
A2: 1 | B2: JJ AUTOMOBILES | C2: SUP00124 | D2: JJ AUTOMOBILES | E2: DirectGrnGenUDMulti | F2: TVSA | G2: GENERAL U-100 | H2: 00123 | I2: 1000 | J2: DR | K2: INR | L2: 1 | M2: =I2*L2 -> 1000 | N2: =I2 -> 1000 | Q2: =M2 -> 1000 | X2: U100 | Y2: Supplier Bill

Sheet BankPayment
A1: SNO | B1: GL ACCOUNT DESC | C1: PARTY ID | D1: PARTY NAME | E1: SHEETNAME | F1: ENTITY | G1: CPC DESC | H1: BILL DOC NUMBER | I1: PAY AMOUNT | J1: DR./CR | K1: CURCY | L1: EX.RATE | M1: TRANS CURRENCY | N1: BASE CURRENCY | O1: HSN CODE | P1: TAX PERCENTAGE | Q1: ASSESABLE VALUE | R1: CGST | S1: SGST | T1: IGST | U1: UTGST | V1: CESS PERCENTAGE | W1: CESS AMOUNT | X1: UNIT | Y1: DOC TYPE | Z1: BILL NUMBER | AA1: BILL DATE | AB1: BILL AMOUNT | AC1: TAX AMT | AD1: PB DOC NUMBER
A2: 1 | B2: JJ AUTOMOBILES | C2: SUP00124 | D2: JJ AUTOMOBILES | E2: DirectGrnGenUD | F2: TVSA | G2: GENERAL U-100 | H2: 00123 | I2: 1000 | J2: DR | K2: INR | L2: 1 | M2: =I2*L2 -> 1000 | N2: =I2 -> 1000 | Q2: =M2 -> 1000 | X2: U100 | Y2: Supplier Bill

Sheet BankPaymentUSDMulti
A1: SNO | B1: GL ACCOUNT DESC | C1: PARTY ID | D1: PARTY NAME | E1: SHEETNAME | F1: ENTITY | G1: CPC DESC | H1: BILL DOC NUMBER | I1: PAY AMOUNT | J1: Lines DR./CR | K1: CURCY | L1: EX.RATE | M1: Amt In TC | N1: Amt In BC | O1: HSN CODE | P1: TAX PERCENTAGE | Q1: ASSESABLE VALUE | R1: CGST | S1: SGST | T1: IGST | U1: UTGST | V1: CESS PERCENTAGE | W1: CESS AMOUNT | X1: Location | Y1: Unit | Z1: Pending DR./CR | AA1: Invoice 1 | AB1: Invoice 2 | AC1: Sum Of Both Invoices
A2: 1 | B2: AFT PRIVATE LIMITED(AP) | C2: SUP10388 | D2: AFT PRIVATE LIMITED | E2: DirectGrnGenUDIMP | F2: ROAU | G2: GERERAL | H2: 00123 | I2: 0 | J2: DR | K2: USD | L2: 85 | M2: =ROUND(SUM(AA2+AB2+I2),2) -> 0 | N2: =AC2 -> 0 | Q2: =M2 -> 0 | X2: L0001 | Y2: U1 | Z2: CR | AA2: 0 | AB2: 0 | AC2: =ROUND(SUM((AA2*L2)+(AB2*L2)+(I2*L2)),2) -> 0
M3: =SUM(M2) -> 0 | N3: =SUM(N2) -> 0 | Q3: =SUM(Q2) -> 0 | AC3: =SUM(AC2) -> 0

Sheet BankPaymentUSDMPSB
A1: SNO | B1: GL ACCOUNT DESC | C1: PARTY ID | D1: PARTY NAME | E1: SHEETNAME | F1: ENTITY | G1: CPC DESC | H1: BILL DOC NUMBER | I1: PAY AMOUNT | J1: Lines DR./CR | K1: CURCY | L1: EX.RATE | M1: Amt In TC | N1: Amt In BC | O1: HSN CODE | P1: TAX PERCENTAGE | Q1: ASSESABLE VALUE | R1: CGST | S1: SGST | T1: IGST | U1: UTGST | V1: CESS PERCENTAGE | W1: CESS AMOUNT | X1: Location | Y1: Unit | Z1: Pending DR./CR | AA1: Invoice 1 | AB1: Invoice 2 | AC1: Sum Of Both Invoices
A2: 1 | B2: AFT PRIVATE LIMITED(AP) | C2: SUP10388 | D2: AFT PRIVATE LIMITED | E2: DirectGrnGenUDIMP | F2: ROAU | G2: GERERAL | H2: 00123 | I2: 0 | J2: DR | K2: USD | L2: 85 | M2: =ROUND(SUM(AA2+AB2+I2),2) -> 0 | N2: =AC2 -> 0 | Q2: =M2 -> 0 | X2: L0001 | Y2: U1 | Z2: CR | AA2: 56.46 | AB2: 0 | AC2: =ROUND(SUM((AA2*L2)+(AB2*L2)+(I2*L2)),2) -> 0
A3: 2 | B3: KCG PRIVATE LIMITED(AP) | C3: HKIMPSUP04 | D3: KCG PRIVATE LIMITED | E3: DirectGrnGenUDIMP | F3: ROAU | G3: GERERAL | H3: 00123 | I3: 0 | J3: DR | K3: USD | L3: 85 | M3: =ROUND(SUM(AA3+AB3+I3),2) -> 0 | N3: =AC3 -> 0 | Q3: =M3 -> 0 | X3: L0001 | Y3: U1 | Z3: CR | AA3: 0 | AB3: 56.46 | AC3: =ROUND(SUM((AA3*L3)+(AB3*L3)+(I3*L3)),2) -> 0
I4: =SUM(I2:I3) -> 0 | M4: =SUM(M2:M3) -> 0 | N4: =SUM(N2:N3) -> 0 | Q4: =SUM(Q2:Q3) -> 0 | AC4: =SUM(AC2:AC3) -> 0

Sheet BankPaymentUSDMPMB
A1: SNO | B1: GL ACCOUNT DESC | C1: PARTY ID | D1: PARTY NAME | E1: SHEETNAME | F1: ENTITY | G1: CPC DESC | H1: BILL DOC NUMBER | I1: PAY AMOUNT | J1: Lines DR./CR | K1: CURCY | L1: EX.RATE | M1: Amt In TC | N1: Amt In BC | O1: HSN CODE | P1: TAX PERCENTAGE | Q1: ASSESABLE VALUE | R1: CGST | S1: SGST | T1: IGST | U1: UTGST | V1: CESS PERCENTAGE | W1: CESS AMOUNT | X1: Location | Y1: Unit | Z1: Pending DR./CR | AA1: Invoice 1 | AB1: Invoice 2 | AC1: Sum Of Both Invoices
A2: 1 | B2: AFT PRIVATE LIMITED(AP) | C2: SUP10388 | D2: AFT PRIVATE LIMITED | E2: DirectGrnGenUDIMP | F2: ROAU | G2: GERERAL | H2: 00123 | I2: 0 | J2: DR | K2: USD | L2: 85 | M2: =ROUND(SUM(AA2+AB2+I2),2) -> 0 | N2: =AC2 -> 0 | Q2: =M2 -> 0 | X2: L0001 | Y2: U1 | Z2: CR | AA2: 56.46 | AB2: 56.46 | AC2: =ROUND(SUM((AA2*L2)+(AB2*L2)+(I2*L2)),2) -> 0
A3: 2 | B3: KCG PRIVATE LIMITED(AP) | C3: HKIMPSUP04 | D3: KCG PRIVATE LIMITED | E3: DirectGrnGenUDIMP | F3: ROAU | G3: GERERAL | H3: 00469 | I3: 0 | J3: DR | K3: USD | L3: 85 | M3: =ROUND(SUM(AA3+AB3+I3),2) -> 0 | N3: =AC3 -> 0 | Q3: =M3 -> 0 | X3: L0001 | Y3: U1 | Z3: CR | AA3: 56.46 | AB3: 56.46 | AC3: =ROUND(SUM((AA3*L3)+(AB3*L3)+(I3*L3)),2) -> 0
I4: =SUM(I2:I3) -> 0 | M4: =SUM(M2:M3) -> 0 | N4: =SUM(N2:N3) -> 0 | Q4: =SUM(Q2:Q3) -> 0 | AC4: =SUM(AC2:AC3) -> 0

Sheet BankPaymentUSDMPMBNR
A1: SNO | B1: GL ACCOUNT DESC | C1: PARTY ID | D1: PARTY NAME | E1: SHEETNAME | F1: ENTITY | G1: CPC DESC | H1: BILL DOC NUMBER | I1: PAY AMOUNT | J1: Lines DR./CR | K1: CURCY | L1: EX.RATE | M1: Amt In TC | N1: Amt In BC | O1: HSN CODE | P1: TAX PERCENTAGE | Q1: ASSESABLE VALUE | R1: CGST | S1: SGST | T1: IGST | U1: UTGST | V1: CESS PERCENTAGE | W1: CESS AMOUNT | X1: Location | Y1: Unit | Z1: Pending DR./CR | AA1: Invoice 1 | AB1: Invoice 2 | AC1: Sum Of Both Invoices
A2: 1 | B2: AFT PRIVATE LIMITED(AP) | C2: SUP10388 | D2: AFT PRIVATE LIMITED | E2: DirectGrnGenUDIMP | F2: ROAU | G2: GERERAL | H2: 00123 | I2: 100 | J2: DR | K2: USD | L2: 85 | M2: =ROUND(SUM(AA2+AB2+I2),2) -> 100 | N2: =AC2 -> 100 | Q2: =M2 -> 100 | X2: L0001 | Y2: U1 | Z2: CR | AA2: 0 | AB2: 0 | AC2: =ROUND(SUM((AA2*L2)+(AB2*L2)+(I2*L2)),2) -> 100
A3: 2 | B3: KCG PRIVATE LIMITED(AP) | C3: HKIMPSUP04 | D3: KCG PRIVATE LIMITED | E3: DirectGrnGenUDIMP | F3: ROAU | G3: GERERAL | H3: 00467 | I3: 100 | J3: DR | K3: USD | L3: 85 | M3: =ROUND(SUM(AA3+AB3+I3),2) -> 100 | N3: =AC3 -> 100 | Q3: =M3 -> 100 | X3: L0001 | Y3: U1 | Z3: CR | AA3: 0 | AB3: 0 | AC3: =ROUND(SUM((AA3*L3)+(AB3*L3)+(I3*L3)),2) -> 100
I4: =SUM(I2:I3) -> 200 | M4: =SUM(M2:M3) -> 200 | N4: =SUM(N2:N3) -> 200 | Q4: =SUM(Q2:Q3) -> 200 | AC4: =SUM(AC2:AC3) -> 200

Sheet BPJournalMultiUSD
A1: SNO | B1: UNIT | C1: GL ACCOUNT NUMBER | D1: GL ACCOUNT DESC | E1: CPC CODE | F1: CPC DESC | G1: Document 1 | H1: Document 2 | I1: DEBIT | J1: CREDIT | K1: 85
A2: 1 | B2: U1 | C2: 2000000018 | D2: AFT PRIVATE LIMITED(AP) | G2: 0 | H2: 0 | I2: =ROUND(SUM(G2+H2)*K1,2) -> 0 | J2: 0
A3: 2 | B3: U1 | C3: 2000000124 | D3: KCG PRIVATE LIMITED(AP) | G3: 0 | H3: 0 | I3: =ROUND(SUM(G3+H3)*K1,2) -> 0 | J3: 0
A4: 3 | B4: U1 | C4: 1001002001 | D4: STATE BANK OF INDIA - 30305325953 | G4: 0 | H4: 0 | I4: 0 | J4: =ROUND(SUM(G4+H4)*K1,2) -> 0

Sheet BPJournalMPMIUSD
A1: SNO | B1: UNIT | C1: GL ACCOUNT NUMBER | D1: GL ACCOUNT DESC | E1: CPC CODE | F1: CPC DESC | G1: Document 1 | H1: Document 2 | I1: DEBIT | J1: CREDIT | K1: 85
A2: 1 | B2: U1 | C2: 2000000018 | D2: AFT PRIVATE LIMITED(AP) | G2: 0 | H2: 0 | I2: =ROUND(SUM(G2+H2)*K1,2) -> 0 | J2: 0
A3: 2 | B3: U1 | C3: 2000000124 | D3: KCG PRIVATE LIMITED(AP) | G3: 0 | H3: 0 | I3: =ROUND(SUM(G3+H3)*K1,2) -> 0 | J3: 0
A4: 3 | B4: U1 | C4: 1001002001 | D4: STATE BANK OF INDIA - 30305325953 | G4: =ROUND(SUM(G2+H2),2) -> 0 | H4: =ROUND(SUM(G3+H3),2) -> 0 | I4: 0 | J4: =ROUND(SUM(G4+H4)*K1,2) -> 0

Sheet BPJournalNRUSD
A1: SNO | B1: UNIT | C1: GL ACCOUNT NUMBER | D1: GL ACCOUNT DESC | E1: CPC CODE | F1: CPC DESC | G1: Document 1 | H1: Document 2 | I1: DEBIT | J1: CREDIT | K1: NEW REF | L1: 85
A2: 1 | B2: U1 | C2: 2000000018 | D2: AFT PRIVATE LIMITED(AP) | G2: 0 | H2: 0 | I2: =ROUND(SUM(G2+H2+K2)*L1,2) -> 8500 | J2: 0 | K2: =BankPaymentUSDMPMBNR!I2 -> 100 | L2: 85
A3: 2 | B3: U1 | C3: 2000000124 | D3: KCG PRIVATE LIMITED(AP) | G3: 0 | H3: 0 | I3: =ROUND(SUM(G3+H3+K3)*L1,2) -> 8500 | J3: 0 | K3: =BankPaymentUSDMPMBNR!I3 -> 100 | L3: 85
A4: 3 | B4: U1 | C4: 1001002001 | D4: STATE BANK OF INDIA - 30305325953 | G4: 0 | H4: 0 | I4: 0 | J4: =ROUND(SUM(I3+I2),2) -> 17000 | L4: 85

Sheet BankPaymentChargesUSD
A1: SNO | B1: GL ACCOUNT DESC | C1: PARTY ID | D1: PARTY NAME | E1: SHEETNAME | F1: ENTITY | G1: CPC DESC | H1: BILL DOC NUMBER | I1: PAY AMOUNT | J1: Lines DR./CR | K1: CURCY | L1: EX.RATE | M1: TRANS CURRENCY | N1: BASE CURRENCY | O1: HSN CODE | P1: TAX PERCENTAGE | Q1: ASSESABLE VALUE | R1: CGST | S1: SGST | T1: IGST | U1: UTGST | V1: CESS PERCENTAGE | W1: CESS AMOUNT | X1: Location | Y1: Unit | Z1: Pending DR./CR | AA1: Invoice 1 | AB1: Invoice 2 | AC1: Sum Of Both Invoices | AD1: Charges Flag
A2: 1 | B2: AFT PRIVATE LIMITED(AP) | C2: SUP10388 | D2: AFT PRIVATE LIMITED | E2: DirectGrnGenUDIMP | F2: ROAU | G2: GERERAL | H2: 00123 | I2: 0 | J2: DR | K2: USD | L2: 85 | M2: =ROUND(SUM(AA2+AB2+I2),2) -> 56.46 | N2: =AC2 -> 4799.1 | Q2: =M2 -> 56.46 | X2: L0001 | Y2: U1 | Z2: CR | AA2: 0 | AB2: 0 | AC2: =ROUND(SUM((AA2*L2)+(AB2*L2)+(I2*L2)),2) -> 4799.1 | AD2: N
A3: 2 | B3: BANK CHARGES | F3: ROAU | G3: GERERAL | I3: 10 | J3: DR | K3: INR | L3: 1 | M3: =ROUND(SUM(AA3+AB3+I3),2) -> 10 | N3: =AC3 -> 10 | Q3: =M3 -> 10 | X3: L0001 | Y3: U1 | Z3: DR | AA3: 0 | AB3: 0 | AC3: =ROUND(SUM((AA3*L3)+(AB3*L3)+(I3*L3)),2) -> 10 | AD3: Y
I4: =SUM(I2:I3) -> 10 | M4: =ROUND(M2-M3,2) -> 46.46 | N4: =ROUND(N2-N3,2) -> 4789.1 | Q4: =SUM(Q2:Q3) -> 66.46 | AC4: =ROUND(AC2-AC3,2) -> 4789.1 | AD4: Y

Sheet BPJournalBankUSD
A1: SNO | B1: UNIT | C1: GL ACCOUNT NUMBER | D1: GL ACCOUNT DESC | E1: CPC CODE | F1: CPC DESC | G1: Document 1 | H1: Document 2 | I1: DEBIT | J1: CREDIT | K1: 85
A2: 1 | B2: U1 | C2: 2000000018 | D2: AFT PRIVATE LIMITED(AP) | G2: 0 | H2: 0 | I2: =ROUND(SUM(G2+H2)*K1,2) -> 4799.1 | J2: 0
A3: 2 | B3: U1 | C3: 5060101000 | D3: BANK CHARGES | G3: =BankPaymentChargesUSD!I3 -> 10 | H3: 0 | I3: =ROUND(SUM(G3+H3),2) -> 10 | J3: 0
A4: 3 | B4: U1 | C4: 5050606001 | D4: UNRELIZED GAIN/LOSS | G4: =G3 -> 10 | H4: 0 | I4: 0 | J4: =G4 -> 10
A5: 4 | B5: U1 | C5: 1001002001 | D5: STATE BANK OF INDIA - 30305325953 | G5: 0 | H5: 0 | I5: 0 | J5: =ROUND(I2,2) -> 4799.1

Sheet BankPaymentAdv
A1: SNO | B1: GL ACCOUNT DESC | C1: PARTY ID | D1: PARTY NAME | E1: SHEETNAME | F1: ENTITY | G1: CPC DESC | H1: BILL DOC NUMBER | I1: PAY AMOUNT | J1: Lines DR./CR | K1: CURCY | L1: EX.RATE | M1: Amt In TC | N1: Amt In BC | O1: HSN CODE | P1: TAX PERCENTAGE | Q1: ASSESABLE VALUE | R1: CGST | S1: SGST | T1: IGST | U1: UTGST | V1: CESS PERCENTAGE | W1: CESS AMOUNT | X1: Location | Y1: Unit | Z1: Pending DR./CR | AA1: Purchase Bills 1 | AB1: Purchase Bills 2 | AC1: Sum Of Both Purchase Bills
A2: 1 | B2: HARI ENTERPRISES(AP) | C2: HK1609 | D2: HARI ENTERPRISES | E2: DirectGrnGenUD | F2: ROAU | G2: GERERAL | H2: 00123 | I2: 1000 | J2: DR | K2: INR | L2: 1 | M2: =ROUND(SUM(AA2+AB2+I2),2) -> 1000 | N2: =AC2 -> 1000 | Q2: =M2 -> 1000 | X2: L0001 | Y2: U1 | Z2: CR | AA2: 0 | AB2: 0 | AC2: =ROUND(SUM((AA2*L2)+(AB2*L2)+(I2*L2)),2) -> 1000
M3: =SUM(M2) -> 1000 | N3: =SUM(N2) -> 1000 | Q3: =SUM(Q2) -> 1000 | AA3: 0 | AB3: 0 | AC3: =SUM(AC2) -> 1000

Sheet BPJournalINRAdvNR
A1: SNO | B1: UNIT | C1: GL ACCOUNT NUMBER | D1: GL ACCOUNT DESC | E1: CPC CODE | F1: CPC DESC | G1: Document 1 | H1: Document 2 | I1: DEBIT | J1: CREDIT
A2: 1 | B2: U1 | C2: 2000000098 | D2: HARI ENTERPRISES(AP) | G2: =BankReceiptNewRef!I2 -> 1000 | H2: 0 | I2: =ROUND(SUM(G2+H2),2) -> 1000 | J2: 0
A3: 2 | B3: U1 | C3: 1001002003 | D3: JP MORGAN CHASE(BANK) | G3: =BankReceiptNewRef!I2 -> 1000 | H3: 0 | I3: 0 | J3: =ROUND(SUM(G3+H3),2) -> 1000

Sheet BankPaymentINR
A1: SNO | B1: GL ACCOUNT DESC | C1: PARTY ID | D1: PARTY NAME | E1: SHEETNAME | F1: ENTITY | G1: CPC DESC | H1: BILL DOC NUMBER | I1: PAY AMOUNT | J1: Lines DR./CR | K1: CURCY | L1: EX.RATE | M1: Amt In TC | N1: Amt In BC | O1: HSN CODE | P1: TAX PERCENTAGE | Q1: ASSESABLE VALUE | R1: CGST | S1: SGST | T1: IGST | U1: UTGST | V1: CESS PERCENTAGE | W1: CESS AMOUNT | X1: Location | Y1: Unit | Z1: Pending DR./CR | AA1: Purchase Bills 1 | AB1: Purchase Bills 2 | AC1: Sum Of Both Purchase Bills
A2: 1 | B2: HARI ENTERPRISES(AP) | C2: HK1609 | D2: HARI ENTERPRISES | E2: DirectGrnGenUD | F2: ROAU | G2: GERERAL | H2: 00123 | I2: 0 | J2: DR | K2: INR | L2: 1 | M2: =ROUND(SUM(AA2+AB2+I2),2) -> 0 | N2: =AC2 -> 0 | Q2: =M2 -> 0 | X2: L0001 | Y2: U1 | Z2: CR | AA2: 0 | AB2: 0 | AC2: =ROUND(SUM((AA2*L2)+(AB2*L2)+(I2*L2)),2) -> 0
M3: =SUM(M2) -> 0 | N3: =SUM(N2) -> 0 | Q3: =SUM(Q2) -> 0 | AA3: 0 | AB3: 0 | AC3: =SUM(AC2) -> 0

Sheet BankPaymentINRMulti
A1: SNO | B1: GL ACCOUNT DESC | C1: PARTY ID | D1: PARTY NAME | E1: SHEETNAME | F1: ENTITY | G1: CPC DESC | H1: BILL DOC NUMBER | I1: PAY AMOUNT | J1: Lines DR./CR | K1: CURCY | L1: EX.RATE | M1: Amt In TC | N1: Amt In BC | O1: HSN CODE | P1: TAX PERCENTAGE | Q1: ASSESABLE VALUE | R1: CGST | S1: SGST | T1: IGST | U1: UTGST | V1: CESS PERCENTAGE | W1: CESS AMOUNT | X1: Location | Y1: Unit | Z1: Pending DR./CR | AA1: Invoice 1 | AB1: Invoice 2 | AC1: Sum Of Both Invoices
A2: 1 | B2: HARI ENTERPRISES(AP) | C2: HK1609 | D2: HARI ENTERPRISES | E2: DirectGrnGenUD | F2: ROAU | G2: GERERAL | H2: 00123 | I2: 0 | J2: DR | K2: INR | L2: 1 | M2: =ROUND(SUM(AA2+AB2+I2),2) -> 0 | N2: =AC2 -> 0 | Q2: =M2 -> 0 | X2: L0001 | Y2: U1 | Z2: CR | AA2: 0 | AB2: 0 | AC2: =ROUND(SUM((AA2*L2)+(AB2*L2)+(I2*L2)),2) -> 0
M3: =SUM(M2) -> 0 | N3: =SUM(N2) -> 0 | Q3: =SUM(Q2) -> 0 | AC3: =SUM(AC2) -> 0

Sheet BankPaymentINRMPMBNR
A1: SNO | B1: GL ACCOUNT DESC | C1: PARTY ID | D1: PARTY NAME | E1: SHEETNAME | F1: ENTITY | G1: CPC DESC | H1: BILL DOC NUMBER | I1: PAY AMOUNT | J1: Lines DR./CR | K1: CURCY | L1: EX.RATE | M1: Amt In TC | N1: Amt In BC | O1: HSN CODE | P1: TAX PERCENTAGE | Q1: ASSESABLE VALUE | R1: CGST | S1: SGST | T1: IGST | U1: UTGST | V1: CESS PERCENTAGE | W1: CESS AMOUNT | X1: Location | Y1: Unit | Z1: Pending DR./CR | AA1: Invoice 1 | AB1: Invoice 2 | AC1: Sum Of Both Invoices
A2: 1 | B2: HARI ENTERPRISES(AP) | C2: HK1609 | D2: HARI ENTERPRISES | E2: DirectGrnGenUD | F2: ROAU | G2: GERERAL | H2: 00123 | I2: 1000 | J2: DR | K2: INR | L2: 1 | M2: =ROUND(SUM(AA2+AB2+I2),2) -> 1000 | N2: =AC2 -> 1000 | Q2: =M2 -> 1000 | X2: L0001 | Y2: U1 | Z2: CR | AA2: 666.3 | AB2: 666.3 | AC2: =ROUND(SUM((AA2*L2)+(AB2*L2)+(I2*L2)),2) -> 1000
A3: 2 | B3: DEVA PRIVATE LTD(AP) | C3: TAX-FKI | D3: DEVA PRIVATE LTD | E3: DirectGrnGenUD | F3: ROAU | G3: GERERAL | H3: 00467 | I3: 1000 | J3: DR | K3: INR | L3: 1 | M3: =ROUND(SUM(AA3+AB3+I3),2) -> 1000 | N3: =AC3 -> 1000 | Q3: =M3 -> 1000 | X3: L0001 | Y3: U1 | Z3: CR | AA3: 666.3 | AB3: 666.3 | AC3: =ROUND(SUM((AA3*L3)+(AB3*L3)+(I3*L3)),2) -> 1000
I4: =SUM(I2:I3) -> 2000 | M4: =SUM(M2:M3) -> 2000 | N4: =SUM(N2:N3) -> 2000 | Q4: =SUM(Q2:Q3) -> 2000 | AC4: =SUM(AC2:AC3) -> 2000

Sheet BankPaymentINRMPMBMU
A1: SNO | B1: GL ACCOUNT DESC | C1: PARTY ID | D1: PARTY NAME | E1: SHEETNAME | F1: ENTITY | G1: CPC DESC | H1: BILL DOC NUMBER | I1: PAY AMOUNT | J1: Lines DR./CR | K1: CURCY | L1: EX.RATE | M1: Amt In TC | N1: Amt In BC | O1: HSN CODE | P1: TAX PERCENTAGE | Q1: ASSESABLE VALUE | R1: CGST | S1: SGST | T1: IGST | U1: UTGST | V1: CESS PERCENTAGE | W1: CESS AMOUNT | X1: Location | Y1: Unit | Z1: Pending DR./CR | AA1: Invoice 1 | AB1: Invoice 2 | AC1: Sum Of Both Invoices
A2: 1 | B2: HARI ENTERPRISES(AP) | C2: HK1609 | D2: HARI ENTERPRISES | E2: DirectGrnGenUD | F2: ROAU | G2: GERERAL | H2: 00123 | I2: 0 | J2: DR | K2: INR | L2: 1 | M2: =ROUND(SUM(AA2+AB2+I2),2) -> 0 | N2: =AC2 -> 0 | Q2: =M2 -> 0 | X2: L0001 | Y2: U1 | Z2: CR | AA2: 666.3 | AB2: 666.3 | AC2: =ROUND(SUM((AA2*L2)+(AB2*L2)+(I2*L2)),2) -> 0
A3: 2 | B3: DEVA PRIVATE LTD(AP) | C3: TAX-FKI | D3: DEVA PRIVATE LTD | E3: DirectGrnGenUD50 | F3: ROAU | G3: GERERAL | H3: 00469 | I3: 0 | J3: DR | K3: INR | L3: 1 | M3: =ROUND(SUM(AA3+AB3+I3),2) -> 0 | N3: =AC3 -> 0 | Q3: =M3 -> 0 | X3: L52 | Y3: U50 | Z3: CR | AA3: 666.3 | AB3: 666.3 | AC3: =ROUND(SUM((AA3*L3)+(AB3*L3)+(I3*L3)),2) -> 0
I4: =SUM(I2:I3) -> 0 | M4: =SUM(M2:M3) -> 0 | N4: =SUM(N2:N3) -> 0 | Q4: =SUM(Q2:Q3) -> 0 | AC4: =SUM(AC2:AC3) -> 0

Sheet BankPaymentINRMultiUnits
A1: SNO | B1: GL ACCOUNT DESC | C1: PARTY ID | D1: PARTY NAME | E1: SHEETNAME | F1: ENTITY | G1: CPC DESC | H1: BILL DOC NUMBER | I1: PAY AMOUNT | J1: Lines DR./CR | K1: CURCY | L1: EX.RATE | M1: Amt In TC | N1: Amt In BC | O1: HSN CODE | P1: TAX PERCENTAGE | Q1: ASSESABLE VALUE | R1: CGST | S1: SGST | T1: IGST | U1: UTGST | V1: CESS PERCENTAGE | W1: CESS AMOUNT | X1: Location | Y1: Unit | Z1: Pending DR./CR | AA1: Invoice 1 | AB1: Invoice 2 | AC1: Sum Of Both Invoices
A2: 1 | B2: HARI ENTERPRISES(AP) | C2: HK1609 | D2: HARI ENTERPRISES | E2: DirectGrnGenUD | F2: ROAU | G2: GERERAL | H2: 00123 | I2: 0 | J2: DR | K2: INR | L2: 1 | M2: =ROUND(SUM(AA2+AB2+I2),2) -> 0 | N2: =AC2 -> 0 | Q2: =M2 -> 0 | X2: L0001 | Y2: U1 | Z2: CR | AA2: 0 | AB2: 0 | AC2: =ROUND(SUM((AA2*L2)+(AB2*L2)+(I2*L2)),2) -> 0
A3: 2 | B3: HARI ENTERPRISES(AP) | C3: HK1609 | D3: HARI ENTERPRISES | E3: DirectGrnGenUD50 | F3: ROAU | G3: GERERAL | H3: 00123 | I3: 0 | J3: DR | K3: INR | L3: 1 | M3: =ROUND(SUM(AA3+AB3+I3),2) -> 0 | N3: =AC3 -> 0 | Q3: =M3 -> 0 | X3: L52 | Y3: U50 | Z3: CR | AA3: 0 | AB3: 0 | AC3: =ROUND(SUM((AA3*L3)+(AB3*L3)+(I3*L3)),2) -> 0
M4: =SUM(M2) -> 0 | N4: =SUM(N2) -> 0 | Q4: =SUM(Q2) -> 0 | AC4: =SUM(AC2) -> 0

Sheet BankPaymentINRMPMB
A1: SNO | B1: GL ACCOUNT DESC | C1: PARTY ID | D1: PARTY NAME | E1: SHEETNAME | F1: ENTITY | G1: CPC DESC | H1: BILL DOC NUMBER | I1: PAY AMOUNT | J1: Lines DR./CR | K1: CURCY | L1: EX.RATE | M1: Amt In TC | N1: Amt In BC | O1: HSN CODE | P1: TAX PERCENTAGE | Q1: ASSESABLE VALUE | R1: CGST | S1: SGST | T1: IGST | U1: UTGST | V1: CESS PERCENTAGE | W1: CESS AMOUNT | X1: Location | Y1: Unit | Z1: Pending DR./CR | AA1: Invoice 1 | AB1: Invoice 2 | AC1: Sum Of Both Invoices
A2: 1 | B2: HARI ENTERPRISES(AP) | C2: HK1609 | D2: HARI ENTERPRISES | E2: DirectGrnGenUD | F2: ROAU | G2: GERERAL | H2: 00123 | I2: 0 | J2: DR | K2: INR | L2: 1 | M2: =ROUND(SUM(AA2+AB2+I2),2) -> 0 | N2: =AC2 -> 0 | Q2: =M2 -> 0 | X2: L0001 | Y2: U1 | Z2: CR | AA2: 666.3 | AB2: 666.3 | AC2: =ROUND(SUM((AA2*L2)+(AB2*L2)+(I2*L2)),2) -> 0
A3: 2 | B3: DEVA PRIVATE LTD(AP) | C3: TAX-FKI | D3: DEVA PRIVATE LTD | E3: DirectGrnGenUD | F3: ROAU | G3: GERERAL | H3: 00469 | I3: 0 | J3: DR | K3: INR | L3: 1 | M3: =ROUND(SUM(AA3+AB3+I3),2) -> 0 | N3: =AC3 -> 0 | Q3: =M3 -> 0 | X3: L0001 | Y3: U1 | Z3: CR | AA3: 666.3 | AB3: 666.3 | AC3: =ROUND(SUM((AA3*L3)+(AB3*L3)+(I3*L3)),2) -> 0
I4: =SUM(I2:I3) -> 0 | M4: =SUM(M2:M3) -> 0 | N4: =SUM(N2:N3) -> 0 | Q4: =SUM(Q2:Q3) -> 0 | AC4: =SUM(AC2:AC3) -> 0

Sheet BankPaymentINRMPSB
A1: SNO | B1: GL ACCOUNT DESC | C1: PARTY ID | D1: PARTY NAME | E1: SHEETNAME | F1: ENTITY | G1: CPC DESC | H1: BILL DOC NUMBER | I1: PAY AMOUNT | J1: Lines DR./CR | K1: CURCY | L1: EX.RATE | M1: Amt In TC | N1: Amt In BC | O1: HSN CODE | P1: TAX PERCENTAGE | Q1: ASSESABLE VALUE | R1: CGST | S1: SGST | T1: IGST | U1: UTGST | V1: CESS PERCENTAGE | W1: CESS AMOUNT | X1: Location | Y1: Unit | Z1: Pending DR./CR | AA1: Invoice 1 | AB1: Invoice 2 | AC1: Sum Of Both Invoices
A2: 1 | B2: HARI ENTERPRISES(AP) | C2: HK1609 | D2: HARI ENTERPRISES | E2: DirectGrnGenUD | F2: ROAU | G2: GERERAL | H2: 00123 | I2: 0 | J2: DR | K2: INR | L2: 1 | M2: =ROUND(SUM(AA2+AB2+I2),2) -> 0 | N2: =AC2 -> 0 | Q2: =M2 -> 0 | X2: L0001 | Y2: U1 | Z2: CR | AA2: 0 | AB2: 0 | AC2: =ROUND(SUM((AA2*L2)+(AB2*L2)+(I2*L2)),2) -> 0
A3: 2 | B3: DEVA PRIVATE LTD(AP) | C3: TAX-FKI | D3: DEVA PRIVATE LTD | E3: DirectGrnGenUD | F3: ROAU | G3: GERERAL | H3: 00123 | I3: 0 | J3: DR | K3: INR | L3: 1 | M3: =ROUND(SUM(AA3+AB3+I3),2) -> 0 | N3: =AC3 -> 0 | Q3: =M3 -> 0 | X3: L0001 | Y3: U1 | Z3: CR | AA3: 0 | AB3: 0 | AC3: =ROUND(SUM((AA3*L3)+(AB3*L3)+(I3*L3)),2) -> 0
I4: =SUM(I2:I3) -> 0 | M4: =SUM(M2:M3) -> 0 | N4: =SUM(N2:N3) -> 0 | Q4: =SUM(Q2:Q3) -> 0 | AC4: =SUM(AC2:AC3) -> 0

Sheet BankPaymentUSD
A1: SNO | B1: GL ACCOUNT DESC | C1: PARTY ID | D1: PARTY NAME | E1: SHEETNAME | F1: ENTITY | G1: CPC DESC | H1: BILL DOC NUMBER | I1: PAY AMOUNT | J1: Lines DR./CR | K1: CURCY | L1: EX.RATE | M1: Amt In TC | N1: Amt In BC | O1: HSN CODE | P1: TAX PERCENTAGE | Q1: ASSESABLE VALUE | R1: CGST | S1: SGST | T1: IGST | U1: UTGST | V1: CESS PERCENTAGE | W1: CESS AMOUNT | X1: Location | Y1: Unit | Z1: Pending DR./CR | AA1: Purchase Bills 1 | AB1: Purchase Bills 2 | AC1: Sum Of Both Purchase Bills
A2: 1 | B2: AFT PRIVATE LIMITED(AP) | C2: SUP10388 | D2: AFT PRIVATE LIMITED | E2: DirectGrnGenUDIMP | F2: ROAU | G2: GERERAL | H2: 00123 | I2: 0 | J2: DR | K2: USD | L2: 85 | M2: =ROUND(SUM(AA2+AB2+I2),2) -> 0 | N2: =AC2 -> 0 | Q2: =M2 -> 0 | X2: L0001 | Y2: U1 | Z2: CR | AA2: 0 | AB2: 0 | AC2: =ROUND(SUM((AA2*L2)+(AB2*L2)+(I2*L2)),2) -> 0
M3: =SUM(M2) -> 0 | N3: =SUM(N2) -> 0 | Q3: =SUM(Q2) -> 0 | AA3: 0 | AB3: 0 | AC3: =SUM(AC2) -> 0

Sheet MultiGRN
A1: SNO | B1: SUPPLIER ID | C1: SUPPLIER NAME | D1: SHEETNAME
A2: 1 | B2: TAX-FJH | C2: HARIKRISH PVT LTD | D2: DirectGrnGenUDLocal
A3: 2 | B3: SUP00124 | C3: JJ AUTOMOBILES | D3: DirectGrnGenUD

Sheet BankReceipt (2)
A1: SNO | B1: GL ACCOUNT DESC | C1: PARTY ID | D1: PARTY NAME | E1: SHEETNAME | F1: ENTITY | G1: CPC DESC | H1: BILL DOC NUMBER | I1: PAY AMOUNT | J1: Lines DR./CR | K1: CURCY | L1: EX.RATE | M1: TRANS CURRENCY | N1: BASE CURRENCY | O1: HSN CODE | P1: TAX PERCENTAGE | Q1: ASSESABLE VALUE | R1: CGST | S1: SGST | T1: IGST | U1: UTGST | V1: CESS PERCENTAGE | W1: CESS AMOUNT | X1: Location | Y1: Unit | Z1: Pending DR./CR | AA1: Invoice 1 | AB1: Invoice 2 | AC1: Sum Of Both Invoices
A2: 1 | B2: MURUGAN TRADERS (AR) | C2: CUS0015 | D2: MURUGAN TRADERS | E2: BRSPSI | F2: ROAU | G2: GERERAL | H2: 00123 | I2: 1000 | J2: CR | K2: INR | L2: 1 | M2: =I2*L2 -> 1000 | N2: =I2 -> 1000 | Q2: =M2 -> 1000 | X2: L0001 | Y2: U1 | Z2: DR | AA2: 0 | AB2: 0 | AC2: =ROUND(SUM(AA2+AB2),2) -> 0
AA3: 0 | AB3: 0 | AC3: =SUM(AC2) -> 0

Sheet BankReceiptAdv
A1: SNO | B1: GL ACCOUNT DESC | C1: PARTY ID | D1: PARTY NAME | E1: SHEETNAME | F1: ENTITY | G1: CPC DESC | H1: BILL DOC NUMBER | I1: PAY AMOUNT | J1: Lines DR./CR | K1: CURCY | L1: EX.RATE | M1: TRANS CURRENCY | N1: BASE CURRENCY | O1: HSN CODE | P1: TAX PERCENTAGE | Q1: ASSESABLE VALUE | R1: CGST | S1: SGST | T1: IGST | U1: UTGST | V1: CESS PERCENTAGE | W1: CESS AMOUNT | X1: Location | Y1: Unit | Z1: Pending DR./CR | AA1: Invoice 1 | AB1: Invoice 2 | AC1: Sum Of Both Invoices
A2: 1 | B2: MURUGAN TRADERS (AR) | C2: CUS0015 | D2: MURUGAN TRADERS | E2: BRSPSI | F2: ROAU | G2: GERERAL | H2: 00123 | I2: 0 | J2: CR | K2: INR | L2: 1 | M2: =ROUND(SUM(AA2+AB2+I2),2) -> 0 | N2: =AC2 -> 0 | Q2: =M2 -> 0 | X2: L0001 | Y2: U1 | Z2: DR | AA2: 0 | AB2: 0 | AC2: =ROUND(SUM((AA2*L2)+(AB2*L2)+(I2*L2)),2) -> 0
M3: =SUM(M2) -> 0 | N3: =SUM(N2) -> 0 | Q3: =SUM(Q2) -> 0 | AA3: 0 | AB3: 0 | AC3: =SUM(AC2) -> 0

Sheet BankReceiptMultiNewRef
A1: SNO | B1: GL ACCOUNT DESC | C1: PARTY ID | D1: PARTY NAME | E1: SHEETNAME | F1: ENTITY | G1: CPC DESC | H1: BILL DOC NUMBER | I1: PAY AMOUNT | J1: DR./CR | K1: CURCY | L1: EX.RATE | M1: TRANS CURRENCY | N1: BASE CURRENCY | O1: HSN CODE | P1: TAX PERCENTAGE | Q1: ASSESABLE VALUE | R1: CGST | S1: SGST | T1: IGST | U1: UTGST | V1: CESS PERCENTAGE | W1: CESS AMOUNT | X1: Location | Y1: Unit | Z1: Pending DR./CR | AA1: Invoice 1 | AB1: Invoice 2 | AC1: Sum Of Both Invoices
A2: 1 | B2: MURUGAN TRADERS (AR) | C2: CUS0015 | D2: MURUGAN TRADERS | E2: BRSPSI | F2: ROAU | G2: GERERAL | H2: 00123 | I2: 1000 | J2: CR | K2: INR | L2: 1 | M2: =ROUND(SUM(AA2+AB2+I2),2) -> 1000 | N2: =AC2 -> 1000 | Q2: =M2 -> 1000 | X2: L0001 | Y2: U1 | Z2: DR | AA2: 0 | AB2: 0 | AC2: =ROUND(SUM((AA2*L2)+(AB2*L2)+(I2*L2)),2) -> 1000
A3: 2 | B3: HARI TRADERS (AR) | C3: HK-CUS-001 | D3: HARI TRADERS | E3: BRSPMI | F3: ROAU | G3: GERERAL | H3: 00689 | I3: 1000 | J3: CR | K3: INR | L3: 1 | M3: =ROUND(SUM(AA3+AB3+I3),2) -> 1000 | N3: =AC3 -> 1000 | Q3: =M3 -> 1000 | X3: L0001 | Y3: U1 | Z3: DR | AA3: 0 | AB3: 0 | AC3: =ROUND(SUM((AA3*L3)+(AB3*L3)+(I3*L3)),2) -> 1000
I4: =SUM(I2:I3) -> 2000 | M4: =SUM(M2:M3) -> 2000 | N4: =SUM(N2:N3) -> 2000 | AC4: =SUM(AC2:AC3) -> 2000

Sheet JournalUSD
A1: SNO | B1: UNIT | C1: GL ACCOUNT NUMBER | D1: GL ACCOUNT DESC | E1: CPC CODE | F1: CPC DESC | G1: Document 1 | H1: Document 2 | I1: DEBIT | J1: CREDIT | K1: 110
A2: 1 | B2: U1 | C2: 1001002001 | D2: STATE BANK OF INDIA - 30305325953 | G2: 0 | H2: 0 | I2: =ROUND(SUM(ROUND(G2,2)+ROUND(H2,2))*K1,2) -> 0 | J2: 0
A3: 2 | B3: U1 | C3: 1000000004 | D3: FRANCE FOREIGN TRADERS (AR) | G3: 0 | H3: 0 | I3: 0 | J3: =ROUND(SUM(ROUND(G3,2)+ROUND(H3,2))*K1,2) -> 0

Sheet JournalMultiUSD
A1: SNO | B1: UNIT | C1: GL ACCOUNT NUMBER | D1: GL ACCOUNT DESC | E1: CPC CODE | F1: CPC DESC | G1: Document 1 | H1: Document 2 | I1: DEBIT | J1: CREDIT | K1: 81
A2: 1 | B2: U1 | C2: 1001002001 | D2: STATE BANK OF INDIA - 30305325953 | G2: 0 | H2: 0 | I2: =ROUND(SUM(G2+H2)*K1,2) -> 0 | J2: 0
A3: 2 | B3: U1 | C3: 1000000004 | D3: FRANCE FOREIGN TRADERS (AR) | G3: 0 | H3: 0 | I3: 0 | J3: =ROUND(SUM(G3+H3)*K1,2) -> 0
A4: 3 | B4: U1 | C4: 1000000005 | D4: WEGA ASSOCIATES (AR) | G4: 0 | H4: 0 | I4: 0 | J4: =ROUND(SUM(G4+H4)*K1,2) -> 0

Sheet JournalMPMIUSD
A1: SNO | B1: UNIT | C1: GL ACCOUNT NUMBER | D1: GL ACCOUNT DESC | E1: CPC CODE | F1: CPC DESC | G1: Document 1 | H1: Document 2 | I1: DEBIT | J1: CREDIT | K1: 110
A2: 1 | B2: U1 | C2: 1001002001 | D2: STATE BANK OF INDIA - 30305325953 | G2: =ROUND(SUM(G3+H3)*K1,2) -> 220000 | H2: =ROUND(SUM(G4+H4)*K1,2) -> 220000 | I2: =ROUND(SUM(G2+H2),2) -> 440000 | J2: 0
A3: 2 | B3: U1 | C3: 1000000004 | D3: FRANCE FOREIGN TRADERS (AR) | G3: 1000 | H3: 1000 | I3: 0 | J3: =ROUND(SUM(G3+H3)*K1,2) -> 220000
A4: 3 | B4: U1 | C4: 1000000005 | D4: WEGA ASSOCIATES (AR) | G4: 1000 | H4: 1000 | I4: 0 | J4: =ROUND(SUM(G4+H4)*K1,2) -> 220000

Sheet JournalNRUSD
A1: SNO | B1: UNIT | C1: GL ACCOUNT NUMBER | D1: GL ACCOUNT DESC | E1: CPC CODE | F1: CPC DESC | G1: Document 1 | H1: Document 2 | I1: DEBIT | J1: CREDIT | K1: NEW REF | L1: 110
A2: 1 | B2: U1 | C2: 1001002001 | D2: STATE BANK OF INDIA - 30305325953 | G2: 0 | H2: 0 | I2: =ROUND(SUM(J4+J3),2) -> 44000 | J2: 0
A3: 2 | B3: U1 | C3: 1000000004 | D3: FRANCE FOREIGN TRADERS (AR) | G3: 0 | H3: 0 | I3: 0 | J3: =ROUND(SUM(G3+H3+K4)*L1,2) -> 22000 | K3: =BankReceiptMultiNewRefUSD!I2 -> 200
A4: 3 | B4: U1 | C4: 1000000005 | D4: WEGA ASSOCIATES (AR) | G4: 0 | H4: 0 | I4: 0 | J4: =ROUND(SUM(G4+H4+K4)*L1,2) -> 22000 | K4: =BankReceiptMultiNewRefUSD!I3 -> 200

Sheet BankReceiptMultiNewRefUSD
A1: SNO | B1: GL ACCOUNT DESC | C1: PARTY ID | D1: PARTY NAME | E1: SHEETNAME | F1: ENTITY | G1: CPC DESC | H1: BILL DOC NUMBER | I1: PAY AMOUNT | J1: Lines DR./CR | K1: CURCY | L1: EX.RATE | M1: Amt In TC | N1: Amt In BC | O1: HSN CODE | P1: TAX PERCENTAGE | Q1: ASSESABLE VALUE | R1: CGST | S1: SGST | T1: IGST | U1: UTGST | V1: CESS PERCENTAGE | W1: CESS AMOUNT | X1: Location | Y1: Unit | Z1: Pending DR./CR | AA1: Invoice 1 | AB1: Invoice 2 | AC1: Sum Of Both Invoices
A2: 1 | B2: FRANCE FOREIGN TRADERS (AR) | C2: CU0060 | D2: FRANCE FOREIGN TRADERS | E2: BRSPSIE | F2: ROAU | G2: GERERAL | H2: 00123 | I2: 200 | J2: CR | K2: USD | L2: 110 | M2: =ROUND(SUM(AA2+AB2+I2),2) -> 200 | N2: =AC2 -> 283500 | Q2: =M2 -> 200 | X2: L0001 | Y2: U1 | Z2: DR | AA2: 0 | AB2: 0 | AC2: =ROUND(SUM((AA2*L2)+(AB2*L2)+(I2*L2)),2) -> 16200
A3: 2 | B3: WEGA ASSOCIATES (AR) | C3: CUS200112 | D3: WEGA ASSOCIATES | E3: BRSPSIE | F3: ROAU | G3: GERERAL | H3: 00689 | I3: 200 | J3: CR | K3: USD | L3: 110 | M3: =ROUND(SUM(AA3+AB3+I3),2) -> 200 | N3: =AC3 -> 16200 | Q3: =M3 -> 200 | X3: L0001 | Y3: U1 | Z3: DR | AA3: 0 | AB3: 0 | AC3: =ROUND(SUM((AA3*L3)+(AB3*L3)+(I3*L3)),2) -> 16200
I4: =SUM(I2:I3) -> 400 | M4: =SUM(M2:M3) -> 400 | N4: =SUM(N2:N3) -> 299700 | Q4: =SUM(Q2:Q3) -> 3700 | AA4: =SUM(AA2:AA3) -> 0 | AB4: =SUM(AB2:AB3) -> 0 | AC4: =SUM(AC2:AC3) -> 32400

Sheet JournalINR
A1: SNO | B1: UNIT | C1: GL ACCOUNT NUMBER | D1: GL ACCOUNT DESC | E1: CPC CODE | F1: CPC DESC | G1: Document 1 | H1: Document 2 | I1: DEBIT | J1: CREDIT
A2: 1 | B2: U1 | C2: 1001002003 | D2: JP MORGAN CHASE(BANK) | G2: 0 | H2: 0 | I2: =ROUND(SUM(G2+H2),2) -> 0 | J2: 0
A3: 2 | B3: U1 | C3: 1000000003 | D3: MURUGAN TRADERS (AR) | G3: 0 | H3: 0 | I3: 0 | J3: =ROUND(SUM(G3+H3),2) -> 0

Sheet JournalMultiINR
A1: SNO | B1: UNIT | C1: GL ACCOUNT NUMBER | D1: GL ACCOUNT DESC | E1: CPC CODE | F1: CPC DESC | G1: Document 1 | H1: Document 2 | I1: DEBIT | J1: CREDIT
A2: 1 | B2: U1 | C2: 1001002003 | D2: JP MORGAN CHASE(BANK) | G2: 0 | H2: 0 | I2: =ROUND(SUM(G2+H2),2) -> 0 | J2: 0
A3: 2 | B3: U1 | C3: 1000000003 | D3: MURUGAN TRADERS (AR) | G3: 0 | H3: 0 | I3: 0 | J3: =ROUND(SUM(G3+H3),2) -> 0
A4: 3 | B4: U1 | C4: 1000000010 | D4: HARI TRADERS (AR) | G4: 0 | H4: 0 | I4: 0 | J4: =ROUND(SUM(G4+H4),2) -> 0

Sheet JournalMPMIINR
A1: SNO | B1: UNIT | C1: GL ACCOUNT NUMBER | D1: GL ACCOUNT DESC | E1: CPC CODE | F1: CPC DESC | G1: Document 1 | H1: Document 2 | I1: DEBIT | J1: CREDIT
A2: 1 | B2: U1 | C2: 1001002003 | D2: JP MORGAN CHASE(BANK) | G2: =ROUND(SUM(G3+H3),2) -> 0 | H2: =ROUND(SUM(G4+H4),2) -> 0 | I2: =ROUND(SUM(G2+H2),2) -> 0 | J2: 0
A3: 2 | B3: U1 | C3: 1000000003 | D3: MURUGAN TRADERS (AR) | G3: 0 | H3: 0 | I3: 0 | J3: =ROUND(SUM(G3+H3),2) -> 0
A4: 3 | B4: U1 | C4: 1000000010 | D4: HARI TRADERS (AR) | G4: 0 | H4: 0 | I4: 0 | J4: =ROUND(SUM(G4+H4),2) -> 0

Sheet JournalNRINR
A1: SNO | B1: UNIT | C1: GL ACCOUNT NUMBER | D1: GL ACCOUNT DESC | E1: CPC CODE | F1: CPC DESC | G1: Document 1 | H1: Document 2 | I1: DEBIT | J1: CREDIT | K1: NEW REF
A2: 1 | B2: U1 | C2: 1001002003 | D2: JP MORGAN CHASE(BANK) | G2: 0 | H2: 0 | I2: =ROUND(SUM(J4+J3),2) -> 2000 | J2: 0
A3: 2 | B3: U1 | C3: 1000000003 | D3: MURUGAN TRADERS (AR) | G3: 0 | H3: 0 | I3: 0 | J3: =ROUND(SUM(G3+H3+K4),2) -> 1000 | K3: =BankReceiptMultiNewRef!I2 -> 1000
A4: 3 | B4: U1 | C4: 1000000010 | D4: HARI TRADERS (AR) | G4: 0 | H4: 0 | I4: 0 | J4: =ROUND(SUM(G4+H4+K4),2) -> 1000 | K4: =BankReceiptMultiNewRef!I3 -> 1000

Sheet BPJournalPDC
A1: SNO | B1: UNIT | C1: GL ACCOUNT NUMBER | D1: GL ACCOUNT DESC | E1: CPC CODE | F1: CPC DESC | G1: Document 1 | H1: Document 2 | I1: DEBIT | J1: CREDIT
A2: 1 | B2: U1 | C2: 2000000011 | D2: JJ AUTOMOBILES (AP) | G2: =BankPaymentPDC!I2 -> 10000 | H2: 0 | I2: =ROUND(SUM(G2+H2),2) -> 10000 | J2: 0
A3: 2 | B3: U1 | C3: 1001002001 | D3: STATE BANK OF INDIA - 30305325953 | G3: =BankPaymentPDC!I2 -> 10000 | H3: 0 | I3: 0 | J3: =ROUND(SUM(G3+H3),2) -> 10000

Sheet JournalPDC
A1: SNO | B1: UNIT | C1: GL ACCOUNT NUMBER | D1: GL ACCOUNT DESC | E1: CPC CODE | F1: CPC DESC | G1: Document 1 | H1: Document 2 | I1: DEBIT | J1: CREDIT
A2: 1 | B2: U1 | C2: 1001002001 | D2: STATE BANK OF INDIA - 30305325953 | G2: =BankReceiptPDC!I2 -> 10000 | H2: 0 | I2: =ROUND(SUM(G2+H2),2) -> 10000 | J2: 0
A3: 2 | B3: U1 | C3: 1000000003 | D3: MURUGAN TRADERS (AR) | G3: =BankReceiptPDC!I2 -> 10000 | H3: 0 | I3: 0 | J3: =ROUND(SUM(G3+H3),2) -> 10000

Sheet BPJournalREVGSTTDS
A1: SNO | B1: UNIT | C1: GL ACCOUNT NUMBER | D1: GL ACCOUNT DESC | E1: CPC CODE | F1: CPC DESC | G1: Document 1 | H1: Document 2 | I1: DEBIT | J1: CREDIT
A2: 1 | B2: U1 | C2: 5050100000 | D2: ADMINISTRATION EXPENSES | G2: =BankPaymentExpGST!I2 -> 1000 | H2: 0 | I2: =ROUND(SUM(G2+H2),2) -> 1000 | J2: 0
A3: 4 | B3: U1 | C3: 1000000029 | D3: 194C(TDS) | G3: 0 | H3: 0 | I3: 0 | J3: =ROUND(I2*1%,2) -> 10
A4: 2 | B4: U1 | C4: 2020102002 | D4: INPUT CGST - 9% | G4: 0 | H4: 0 | I4: =(I2)*9% -> 90 | J4: 0
A5: 3 | B5: U1 | C5: 2020102003 | D5: INPUT SGST - 9% | G5: 0 | H5: 0 | I5: =(I2)*9% -> 90 | J5: 0
A6: 5 | B6: U1 | C6: 1001002001 | D6: STATE BANK OF INDIA - 30305325953 | G6: 0 | H6: 0 | I6: 0 | J6: =ROUND(SUM(I4+I5+I2)-J3,2) -> 1170

Sheet BPJournalREVGST
A1: SNO | B1: UNIT | C1: GL ACCOUNT NUMBER | D1: GL ACCOUNT DESC | E1: CPC CODE | F1: CPC DESC | G1: Document 1 | H1: Document 2 | I1: DEBIT | J1: CREDIT
A2: 2 | B2: U1 | C2: 5050100000 | D2: ADMINISTRATION EXPENSES | G2: =BankPaymentExpGST!I2 -> 1000 | H2: 0 | I2: =ROUND(SUM(G2+H2),2) -> 1000 | J2: 0
A3: 4 | B3: U1 | C3: 2020102002 | D3: INPUT CGST - 9% | G3: 0 | H3: 0 | I3: =(I2)*9% -> 90 | J3: 0
A4: 5 | B4: U1 | C4: 2020102003 | D4: INPUT SGST - 9% | G4: 0 | H4: 0 | I4: =(I2)*9% -> 90 | J4: 0
A5: 1 | B5: U1 | C5: 1001002001 | D5: STATE BANK OF INDIA - 30305325953 | G5: 0 | H5: 0 | I5: 0 | J5: =ROUND(SUM(I3+I4+I2),2) -> 1180

Sheet JournalREVGST
A1: SNO | B1: UNIT | C1: GL ACCOUNT NUMBER | D1: GL ACCOUNT DESC | E1: CPC CODE | F1: CPC DESC | G1: Document 1 | H1: Document 2 | I1: DEBIT | J1: CREDIT
A2: 1 | B2: U1 | C2: 1001002001 | D2: STATE BANK OF INDIA - 30305325953 | G2: 0 | H2: 0 | I2: =ROUND(SUM(J5+J6)+(J3-I4),2) -> 10620 | J2: 0
A3: 3 | B3: U1 | C3: 4020102004 | D3: INTEREST INCOME ON LOAN | G3: =BankReceiptRevExpGST!I2 -> 10000 | H3: 0 | I3: 0 | J3: =ROUND(SUM(G3+H3),2) -> 10000
A4: 2 | B4: U1 | C4: 5050100000 | D4: ADMINISTRATION EXPENSES | G4: =BankReceiptRevExpGST!I3 -> 1000 | H4: 0 | I4: =ROUND(SUM(G4+H4),2) -> 1000 | J4: 0
A5: 4 | B5: U1 | C5: 2020102002 | D5: INPUT CGST - 9% | I5: 0 | J5: =(J3-I4)*9% -> 810
A6: 5 | B6: U1 | C6: 2020102003 | D6: INPUT SGST - 9% | I6: 0 | J6: =(J3-I4)*9% -> 810

Sheet BankReceiptRevExpGST
A1: SNO | B1: GL ACCOUNT DESC | C1: PARTY ID | D1: PARTY NAME | E1: SHEETNAME | F1: ENTITY | G1: CPC DESC | H1: BILL DOC NUMBER | I1: PAY AMOUNT | J1: Lines DR./CR | K1: CURCY | L1: EX.RATE | M1: TRANS CURRENCY | N1: BASE CURRENCY | O1: HSN CODE | P1: TAX PERCENTAGE | Q1: ASSESABLE VALUE | R1: CGST | S1: SGST | T1: IGST | U1: UTGST | V1: CESS PERCENTAGE | W1: CESS AMOUNT | X1: Location | Y1: Unit | Z1: Pending DR./CR | AA1: Invoice 1 | AB1: Invoice 2 | AC1: Sum Of Both Invoices | AD1: Charges Flag | AE1: 1 | AF1: GST SUPPLIER NAME | AG1: GSTIN
A2: 1 | B2: INTEREST INCOME ON LOAN | F2: ROAU | G2: GERERAL | H2: 00123 | I2: 10000 | J2: CR | K2: INR | L2: 1 | M2: =ROUND(SUM(AA2+AB2+I2),2) -> 10000 | N2: =AC2 -> 11800 | O2: 88363222 | P2: 0.18 | Q2: =M2 -> 10000 | R2: =IF(OR($AE$1=1,$AE$1=4),ROUND((Q2*P2)/2,2),0) -> 900 | S2: =IF($AE$1=1,ROUND(((Q2*P2)/2),2),0) -> 900 | T2: =IF($AE$1=2,ROUND(((Q2*P2)),2),0) -> 0 | U2: =IF($AE$1=4,ROUND(((Q2*P2)/2),2),0) -> 0 | V2: 0 | W2: 0 | X2: L0001 | Y2: U1 | Z2: Cr. | AA2: 0 | AB2: 0 | AC2: =ROUND(SUM((AA2*L2)+(AB2*L2)+(I2*L2)+R2+S2+T2+U2+W2),2) -> 11800 | AD2: N | AE2: 34 | AF2: HARI TRADERS | AG2: 34AWPPH5612QIJY
A3: 2 | B3: ADMINISTRATION EXPENSES | F3: ROAU | G3: GERERAL | H3: 00856 | I3: 1000 | J3: DR | K3: INR | L3: 1 | M3: =ROUND(SUM(AA3+AB3+I3),2) -> 1000 | N3: =AC3 -> 1180 | O3: 88363222 | P3: 0.18 | Q3: =M3 -> 1000 | R3: =IF(OR($AE$1=1,$AE$1=4),ROUND((Q3*P3)/2,2),0) -> 90 | S3: =IF($AE$1=1,ROUND(((Q3*P3)/2),2),0) -> 90 | T3: =IF($AE$1=2,ROUND(((Q3*P3)),2),0) -> 0 | U3: =IF($AE$1=4,ROUND(((Q3*P3)/2),2),0) -> 0 | V3: 0 | W3: 0 | X3: L0001 | Y3: U1 | Z3: Dr. | AA3: 0 | AB3: 0 | AC3: =ROUND(SUM((AA3*L3)+(AB3*L3)+(I3*L3)+R3+S3+T3+U3+W3),2) -> 1180 | AD3: N | AE3: 34 | AF3: HARITRADERS | AG3: 34AWPPH5612QIJY
I4: =SUM(I2:I3) -> 11000 | M4: =ROUND(M2-M3,2) -> 9000 | N4: =ROUND(N2-N3,2) -> 10620 | Q4: =SUM(Q2:Q3) -> 11000 | R4: =SUM(R2:R3) -> 990 | S4: =SUM(S2:S3) -> 990 | T4: =SUM(T2:T3) -> 0 | U4: =SUM(U2:U3) -> 0 | AC4: =ROUND(AC2-AC3,2) -> 10620 | AD4: N

Sheet JournalREVUSD
A1: SNO | B1: UNIT | C1: GL ACCOUNT NUMBER | D1: GL ACCOUNT DESC | E1: CPC CODE | F1: CPC DESC | G1: Document 1 | H1: Document 2 | I1: DEBIT | J1: CREDIT | K1: 110
A2: 1 | B2: U1 | C2: 1001002001 | D2: STATE BANK OF INDIA - 30305325953 | G2: 0 | H2: 0 | I2: =ROUND((J3-I4),2) -> 990000 | J2: 0
A3: 3 | B3: U1 | C3: 4020102004 | D3: INTEREST INCOME ON LOAN | G3: =BankReceiptRevExp!I2 -> 10000 | H3: 0 | I3: 0 | J3: =ROUND(SUM(G3+H3)*K1,2) -> 1100000
A4: 2 | B4: U1 | C4: 5050100000 | D4: ADMINISTRATION EXPENSES | G4: =BankReceiptRevExp!I3 -> 1000 | H4: 0 | I4: =ROUND(SUM(G4+H4)*K1,2) -> 110000 | J4: 0

Sheet CRJournalREVGST
A1: SNO | B1: UNIT | C1: GL ACCOUNT NUMBER | D1: GL ACCOUNT DESC | E1: CPC CODE | F1: CPC DESC | G1: Document 1 | H1: Document 2 | I1: DEBIT | J1: CREDIT
A2: 1 | B2: U1 | C2: 1000000028 | D2: CASHIER-10001(CASH) | G2: 0 | H2: 0 | I2: =ROUND(SUM(J5+J6)+(J3-I4),2) -> 10620 | J2: 0
A3: 3 | B3: U1 | C3: 4020102004 | D3: INTEREST INCOME ON LOAN | G3: =BankReceiptRevExpGST!I2 -> 10000 | H3: 0 | I3: 0 | J3: =ROUND(SUM(G3+H3),2) -> 10000
A4: 2 | B4: U1 | C4: 5050100000 | D4: ADMINISTRATION EXPENSES | G4: =BankReceiptRevExpGST!I3 -> 1000 | H4: 0 | I4: =ROUND(SUM(G4+H4),2) -> 1000 | J4: 0
A5: 4 | B5: U1 | C5: 2020102002 | D5: INPUT CGST - 9% | I5: 0 | J5: =(J3-I4)*9% -> 810
A6: 5 | B6: U1 | C6: 2020102003 | D6: INPUT SGST - 9% | I6: 0 | J6: =(J3-I4)*9% -> 810

Sheet CRJournalREV
A1: SNO | B1: UNIT | C1: GL ACCOUNT NUMBER | D1: GL ACCOUNT DESC | E1: CPC CODE | F1: CPC DESC | G1: Document 1 | H1: Document 2 | I1: DEBIT | J1: CREDIT
A2: 1 | B2: U1 | C2: 1000000028 | D2: CASHIER-10001(CASH) | G2: 0 | H2: 0 | I2: =ROUND(J3-I4,2) -> 9000 | J2: 0
A3: 3 | B3: U1 | C3: 4020102004 | D3: INTEREST INCOME ON LOAN | G3: =BankReceiptRevExp!I2 -> 10000 | H3: 0 | I3: 0 | J3: =ROUND(SUM(G3+H3),2) -> 10000
A4: 2 | B4: U1 | C4: 5050100000 | D4: ADMINISTRATION EXPENSES | G4: =BankReceiptRevExp!I3 -> 1000 | H4: 0 | I4: =ROUND(SUM(G4+H4),2) -> 1000 | J4: 0

Sheet CPJournalREV
A1: SNO | B1: UNIT | C1: GL ACCOUNT NUMBER | D1: GL ACCOUNT DESC | E1: CPC CODE | F1: CPC DESC | G1: Document 1 | H1: Document 2 | I1: DEBIT | J1: CREDIT
A2: 1 | B2: U1 | C2: 5050100000 | D2: ADMINISTRATION EXPENSES | G2: =BankPaymentExp!I2 -> 1000 | H2: 0 | I2: =ROUND(SUM(G2+H2),2) -> 1000 | J2: 0
A3: 2 | B3: U1 | C3: 1000000028 | D3: CASHIER-10001(CASH) | G3: =BankPaymentExp!I2 -> 1000 | H3: 0 | I3: 0 | J3: =ROUND(G3+H3,2) -> 1000

Sheet CPJournalREVGST
A1: SNO | B1: UNIT | C1: GL ACCOUNT NUMBER | D1: GL ACCOUNT DESC | E1: CPC CODE | F1: CPC DESC | G1: Document 1 | H1: Document 2 | I1: DEBIT | J1: CREDIT
A2: 2 | B2: U1 | C2: 5050100000 | D2: ADMINISTRATION EXPENSES | G2: =BankPaymentExpGST!I2 -> 1000 | H2: 0 | I2: =ROUND(SUM(G2+H2),2) -> 1000 | J2: 0
A3: 4 | B3: U1 | C3: 2020102002 | D3: INPUT CGST - 9% | G3: 0 | H3: 0 | I3: =(I2)*9% -> 90 | J3: 0
A4: 5 | B4: U1 | C4: 2020102003 | D4: INPUT SGST - 9% | G4: 0 | H4: 0 | I4: =(I2)*9% -> 90 | J4: 0
A5: 1 | B5: U1 | C5: 1000000028 | D5: CASHIER-10001(CASH) | G5: 0 | H5: 0 | I5: 0 | J5: =ROUND(SUM(I3+I4+I2),2) -> 1180

Sheet CPJournalREVGSTTDS
A1: SNO | B1: UNIT | C1: GL ACCOUNT NUMBER | D1: GL ACCOUNT DESC | E1: CPC CODE | F1: CPC DESC | G1: Document 1 | H1: Document 2 | I1: DEBIT | J1: CREDIT
A2: 1 | B2: U1 | C2: 5050100000 | D2: ADMINISTRATION EXPENSES | G2: =BankPaymentExpGST!I2 -> 1000 | H2: 0 | I2: =ROUND(SUM(G2+H2),2) -> 1000 | J2: 0
A3: 4 | B3: U1 | C3: 1000000029 | D3: 194C(TDS) | G3: 0 | H3: 0 | I3: 0 | J3: =ROUND(I2*1%,2) -> 10
A4: 2 | B4: U1 | C4: 2020102002 | D4: INPUT CGST - 9% | G4: 0 | H4: 0 | I4: =(I2)*9% -> 90 | J4: 0
A5: 3 | B5: U1 | C5: 2020102003 | D5: INPUT SGST - 9% | G5: 0 | H5: 0 | I5: =(I2)*9% -> 90 | J5: 0
A6: 5 | B6: U1 | C6: 1000000028 | D6: CASHIER-10001(CASH) | G6: 0 | H6: 0 | I6: 0 | J6: =ROUND(SUM(I4+I5+I2)-J3,2) -> 1170

Sheet BPJournalREV
A1: SNO | B1: UNIT | C1: GL ACCOUNT NUMBER | D1: GL ACCOUNT DESC | E1: CPC CODE | F1: CPC DESC | G1: Document 1 | H1: Document 2 | I1: DEBIT | J1: CREDIT
A2: 1 | B2: U1 | C2: 5050100000 | D2: ADMINISTRATION EXPENSES | G2: =BankPaymentExp!I2 -> 1000 | H2: 0 | I2: =ROUND(SUM(G2+H2),2) -> 1000 | J2: 0
A3: 2 | B3: U1 | C3: 1001002001 | D3: STATE BANK OF INDIA - 30305325953 | G3: =BankPaymentExp!I2 -> 1000 | H3: 0 | I3: 0 | J3: =ROUND(G3+H3,2) -> 1000

Sheet JournalREV
A1: SNO | B1: UNIT | C1: GL ACCOUNT NUMBER | D1: GL ACCOUNT DESC | E1: CPC CODE | F1: CPC DESC | G1: Document 1 | H1: Document 2 | I1: DEBIT | J1: CREDIT
A2: 1 | B2: U1 | C2: 1001002001 | D2: STATE BANK OF INDIA - 30305325953 | G2: 0 | H2: 0 | I2: =ROUND(J3-I4,2) -> 9000 | J2: 0
A3: 3 | B3: U1 | C3: 4020102004 | D3: INTEREST INCOME ON LOAN | G3: =BankReceiptRevExp!I2 -> 10000 | H3: 0 | I3: 0 | J3: =ROUND(SUM(G3+H3),2) -> 10000
A4: 2 | B4: U1 | C4: 5050100000 | D4: ADMINISTRATION EXPENSES | G4: =BankReceiptRevExp!I3 -> 1000 | H4: 0 | I4: =ROUND(SUM(G4+H4),2) -> 1000 | J4: 0

Sheet JournalBankUSD
A1: SNO | B1: UNIT | C1: GL ACCOUNT NUMBER | D1: GL ACCOUNT DESC | E1: CPC CODE | F1: CPC DESC | G1: Document 1 | H1: Document 2 | I1: DEBIT | J1: CREDIT | K1: 110
A2: 1 | B2: U1 | C2: 1001002001 | D2: STATE BANK OF INDIA - 30305325953 | G2: 0 | H2: 0 | I2: =ROUND(J3-I4,2) -> -1000 | J2: 0
A3: 3 | B3: U1 | C3: 1000000004 | D3: FRANCE FOREIGN TRADERS (AR) | G3: 0 | H3: 0 | I3: 0 | J3: =ROUND(SUM(G3+H3)*K1,2) -> 0
A4: 2 | B4: U1 | C4: 5060101000 | D4: BANK CHARGES | G4: =BankReceiptChargesUSD!I3 -> 1000 | H4: 0 | I4: =ROUND(SUM(G4+H4),2) -> 1000 | J4: 0

Sheet BPJournalBankINR
A1: SNO | B1: UNIT | C1: GL ACCOUNT NUMBER | D1: GL ACCOUNT DESC | E1: CPC CODE | F1: CPC DESC | G1: Document 1 | H1: Document 2 | I1: DEBIT | J1: CREDIT
A2: 1 | B2: U1 | C2: 2000000098 | D2: HARI ENTERPRISES(AP) | G2: 0 | H2: 0 | I2: =ROUND(SUM(G2+H2),2) -> 0 | J2: 0
