Workbook

Sheet StPoToMRVWFPl
A1: Purchase Order & GRN
A2: GST Purchase | C2: 2 | D2: (1 - Local Purchase,2 Interstate Purchase, 3 Import Purchase,4-UTGST) | I2: Cur. | J2: INR | L2: Ex. Rate | M2: 1 | O2: Apportion Basis | P2: 2 | Q2: 1 - Value Based, 2 Weight/Volume Based | V2: 1 | W2: (1 - Registered, 2 - Unregistered)
A3: No. | B3: Item | C3: Item Desc | D3: Stk. UOM | E3: Pur. UOM | F3: Qty | G3: Unit Cost | H3: Gross Amt. | I3: TD% | J3: CD% | K3: SD% | L3: TD Asbl. Val. | M3: TD Amt. | N3: CD Asbl. Val. | O3: CD Amt. | P3: VD Asbl. Val. | Q3: SD Amt. | R3: Disc. Amt. | S3: Pur. Value | T3: HSN | U3: Tax% | V3: CGST | W3: SGST | X3: IGST | Y3: UTGST | Z3: Cess% | AA3: CESS | AB3: Tax amt | AC3: Net Amt | AD3: Weight/Vol | AE3: Customs Duty | AF3: IGST (Import) | AG3: Packing & Forwarding | AH3: Freight | AI3: Pur Amt (BC) | AJ3: Chargeable Cost | AK3: Landed Cost | AL3: Conv. Factor | AM3: Eqv. Stock Qty | AN3: Pur. Unit Cost (chr) | AO3: Chrg. Unit Cost | AP3: Landed Cost Unit Cost | AQ3: Stock UOM | AR3: Unit cost (Stk. UOM) | AS3: Ins. WH | AT3: Stock UOM | AU3: Qty Before Post | AV3: Unit Cost Before Post | AW3: Receipt Qty | AX3: Receipt Unit cost | AY3: Qty After Post | AZ3: Unit Cost After Post | BA3: Result (Ok/Not OK) | BB3: Stock Transaction | BC3: Lot / Serial Type | BD3: LOT_NUMBER | BE3: SERIAL_NUMBER | BF3: Lot / Serial Trans | BG3: Locator Trans | BH3: Batch Stocks | BI3: Stock Ledger | BJ3: Stock As on Date (Qty) | BK3: Stock As on Date (Qty & vALUE) | BL3: Sou.WH | BM3: Unitcost Before Post For Source Warehouse | BN3: Qty Before Post For Source WareHouse | BO3: Unit Cost After Post | BP3: Qty After Post forSource Warehouse | BQ3: HSN
A4: 1 | B4: GWL_Similar_Wf_Pl_St_01 | C4: GWL_Similar_Wf_Pl_St_01 | D4: NOS | E4: NOS | F4: 5 | G4: 150 | H4: =F4*G4 -> 750 | I4: 5 | J4: 0 | K4: 0 | L4: =IF(OR(I4=0,I4="0"),0,H4) -> 750 | M4: =ROUND(L4*I4%,3) -> 37.5 | N4: 0 | O4: =ROUND(N4*J4%,3) -> 0 | P4: =ROUND(N4-O4,2) -> 0 | Q4: =ROUND(P4*K4%,2) -> 0 | R4: =ROUND(M4+O4+Q4,3) -> 37.5 | S4: =(H4-R4) -> 712.5 | T4: 88363222 | U4: 18 | V4: =IF(OR($C$2=1,$C$2=4),ROUND((((S4*U4)/100)/2),2),0) -> 0 | W4: =IF($C$2=1,ROUND((((S4*U4)/100)/2),2),0) -> 0 | X4: =IF($C$2=2,ROUND(((S4*U4)/100),2),0) -> 128.25 | Y4: =IF($C$2=4,ROUND((((S4*U4)/100)/2),2),0) -> 0 | Z4: 0 | AA4: =IF($C2=3,0,(S4*Z4)/100) -> 0 | AB4: =V4+W4+X4+Y4+AA4 -> 128.25 | AC4: =IF($V2=1,S4+AB4,S4) -> 840.75 | AD4: 120 | AE4: =IF($P$2=1,(S4/$S$6)*$E$17,AD4/$AD$6*$E$17) -> 0 | AG4: =IF($P$2=1,(S4/$S$6)*$E$19,AD4/$AD$6*$E$19) -> 0 | AH4: =IF($P$2=1,(S4/$S$6)*$E$20,AD4/$AD$6*$E$20) -> 0 | AI4: =S4*$M2 -> 712.5 | AJ4: =IF($C$2=3,0,AG4+AH4) -> 0 | AK4: =IF($C$2=3,AE4+AG4+AH4,0) -> 0 | AL4: 1 | AM4: =F4/AL4 -> 5 | AN4: =ROUND(AI4/AM4,5) -> 142.5 | AO4: =AJ4/AM4 -> 0 | AP4: =AK4/AM4 -> 0 | AQ4: NOS | AR4: =ROUND(AN4+AO4+AP4,5) -> 142.5 | AS4: IN WH-7 | AT4: NOS | AW4: =AM4 -> 5 | AX4: =AR4 -> 142.5 | AY4: =AU4+AW4 -> 5 | AZ4: =ROUND(((AU4*AV4)+(AW4*AX4))/(AU4+AW4),5) -> 142.5 | BB4: Receipt Qty & Unit cost | BC4: LOT | BD4: RM | BE4: RMS | BL4: RM WH-7 | BM4: 0 | BN4: 0 | BO4: =ROUND((((AW4*AZ4)+(BN4*BM4))/(AW4+BN4)),5) -> 142.5 | BP4: =ROUND(BN4+AW4,3) -> 5 | BQ4: 123562
A5: 1 | B5: GWL_Similar_Wf_Pl_St_02 | C5: GWL_Similar_Wf_Pl_St_02 | D5: NOS | E5: NOS | F5: 4 | G5: 100 | H5: =F5*G5 -> 400 | I5: 4 | J5: 0 | K5: 0 | L5: =IF(OR(I5=0,I5="0"),0,H5) -> 400 | M5: =ROUND(L5*I5%,2) -> 16 | N5: 0 | O5: =ROUND(N5*J5%,2) -> 0 | P5: =ROUND(N5-O5,2) -> 0 | Q5: =ROUND(P5*K5%,2) -> 0 | R5: =M5+O5+Q5 -> 16 | S5: =(H5-R5) -> 384 | T5: 88363222 | U5: 18 | V5: =IF(OR(StPoToMRVWFPl!$C$2=1,StPoToMRVWFPl!$C$2=4),ROUND((((S5*U5)/100)/2),2),0) -> 0 | W5: =IF(StPoToMRVWFPl!$C$2=1,ROUND((((S5*U5)/100)/2),2),0) -> 0 | X5: =IF(StPoToMRVWFPl!$C$2=2,ROUND(((S5*U5)/100),2),0) -> 69.12 | Y5: =IF(StPoToMRVWFPl!$C$2=4,ROUND((((S5*U5)/100)/2),2),0) -> 0 | Z5: 0 | AA5: =IF(StPoToMRVWFPl!$C3=3,0,(S5*Z5)/100) -> 0 | AB5: =V5+W5+X5+Y5+AA5 -> 69.12 | AC5: =IF(StPoToMRVWFPl!$V3=1,S5+AB5,S5) -> 384 | AD5: 120 | AE5: =IF(StPoToMRVWFPl!$P$2=1,(S5/StPoToMRVWFPl!$S$6)*StPoToMRVWFPl!$E$17,AD5/StPoToMRVWFPl!$AD$6*StPoToMRVWFPl!$E$17) -> 0 | AG5: =IF(StPoToMRVWFPl!$P$2=1,(S5/StPoToMRVWFPl!$S$6)*StPoToMRVWFPl!$E$19,AD5/StPoToMRVWFPl!$AD$6*StPoToMRVWFPl!$E$19) -> 0 | AH5: =IF(StPoToMRVWFPl!$P$2=1,(S5/StPoToMRVWFPl!$S$6)*StPoToMRVWFPl!$E$20,AD5/StPoToMRVWFPl!$AD$6*StPoToMRVWFPl!$E$20) -> 0 | AI5: =S5*StPoToMRVWFPl!$M$2 -> 384 | AJ5: =IF(StPoToMRVWFPl!$C$2=3,0,AG5+AH5) -> 0 | AK5: =IF(StPoToMRVWFPl!$C$2=3,AE5+AG5+AH5,0) -> 0 | AL5: 1 | AM5: =F5/AL5 -> 4 | AN5: =ROUND(AI5/AM5,5) -> 96 | AO5: =AJ5/AM5 -> 0 | AP5: =AK5/AM5 -> 0 | AQ5: NOS | AR5: =ROUND(AN5+AO5+AP5,5) -> 96 | AS5: IN WH-7 | AT5: NOS | AW5: =AM5 -> 4 | AX5: =AR5 -> 96 | AY5: =AU5+AW5 -> 4 | AZ5: =ROUND(((AU5*AV5)+(AW5*AX5))/(AU5+AW5),5) -> 96 | BB5: Receipt Qty & Unit cost | BC5: LOT | BD5: RM | BE5: RMS | BL5: RM WH-7 | BM5: 0 | BN5: 0 | BO5: =ROUND((((AW5*AZ5)+(BN5*BM5))/(AW5+BN5)),5) -> 96 | BP5: =ROUND(BN5+AW5,3) -> 4 | BQ5: 123562
D6: Total | H6: =SUM(H4:H4) -> 750 | R6: =SUM(R4:R4) -> 37.5 | S6: =SUM(S4:S4) -> 712.5 | V6: =SUM(V4:V4) -> 0 | W6: =SUM(W4:W4) -> 0 | X6: =SUM(X4:X4) -> 128.25 | AB6: =SUM(AB4:AB4) -> 128.25 | AC6: =SUM(AC4:AC4) -> 840.75 | AD6: =SUM(AD4:AD4) -> 120 | AE6: =SUM(AE4:AE4) -> 0 | AG6: =SUM(AG4:AG4) -> 0 | AH6: =IF($P$2=1,(S6/$S$6)*$E$20,AD6/$AD$6*$E$20) -> 0 | AI6: =SUM(AI4:AI4) -> 712.5 | AJ6: =SUM(AJ4:AJ4) -> 0 | AK6: =SUM(AK4:AK4) -> 0
G8: Gross Purchase | I8: =H6 -> 750 | M8: Conv factor | BH8: ACPT | BI8: Acpt Qty. * Insp. Unit Cost + OLD. Qty in GRN WH * OLD Unitcost in GRN WH / Acpt. Qty + OLD. Qty in GRN WH
G9: Disc amt | I9: =R6 -> 37.5 | M9: 1 | N9: NOS | O9: 2 | P9: KGS | BH9: REJ | BI9: Rej Qty. * Insp. Unit Cost + OLD. Qty in REJ WH * OLD Unitcost in REJ WH / Acpt. Qty + OLD. Qty in REJ WH
G10: Net Purchase | I10: =S6 -> 712.5 | M10: 1 | N10: NOS | O10: 2.5 | P10: MTR
G11: Tax Amt | I11: =AB6 -> 128.25 | M11: 1 | N11: KGS | O11: 0.001 | P11: MT
G12: Gross Amont | I12: =I10+I11 -> 840.75
BM13: old | BN13: new
BK14: acpt Qty | BL14: 12.5 | BM14: =BL16*BL17 -> 18277.77 | BN14: =BL14*BL15 -> 6092.59
BK15: Inspection Unit Cost | BL15: 487.4072 | BM15: =BL14+BL16 -> 50
BK16: old Qty | BL16: 37.5
BK17: old UnitCost | BL17: 487.4072
BM18: =BM14+BN14 -> 24370.36 | BN18: =BM18/BM15 -> 487.4072

Sheet StPoToMRVWFDURc
A1: Purchase Order & GRN
A2: GST Purchase | C2: 2 | D2: (1 - Local Purchase,2 Interstate Purchase, 3 Import Purchase,4-UTGST) | I2: Cur. | J2: INR | L2: Ex. Rate | M2: 1 | O2: Apportion Basis | P2: 2 | Q2: 1 - Value Based, 2 Weight/Volume Based | V2: 1 | W2: (1 - Registered, 2 - Unregistered)
A3: No. | B3: Item | C3: Item Desc | D3: Stk. UOM | E3: Pur. UOM | F3: Qty | G3: Unit Cost | H3: Gross Amt. | I3: TD% | J3: CD% | K3: SD% | L3: TD Asbl. Val. | M3: TD Amt. | N3: CD Asbl. Val. | O3: CD Amt. | P3: VD Asbl. Val. | Q3: SD Amt. | R3: Disc. Amt. | S3: Pur. Value | T3: HSN | U3: Tax% | V3: CGST | W3: SGST | X3: IGST | Y3: UTGST | Z3: Cess% | AA3: CESS | AB3: Tax amt | AC3: Net Amt | AD3: Weight/Vol | AE3: Customs Duty | AF3: IGST (Import) | AG3: Packing & Forwarding | AH3: Freight | AI3: Pur Amt (BC) | AJ3: Chargeable Cost | AK3: Landed Cost | AL3: Conv. Factor | AM3: Eqv. Stock Qty | AN3: Pur. Unit Cost (chr) | AO3: Chrg. Unit Cost | AP3: Landed Cost Unit Cost | AQ3: Stock UOM | AR3: Unit cost (Stk. UOM) | AS3: Ins. WH | AT3: Stock UOM | AU3: Qty Before Post | AV3: Unit Cost Before Post | AW3: Receipt Qty | AX3: Receipt Unit cost | AY3: Qty After Post | AZ3: Unit Cost After Post | BA3: Result (Ok/Not OK) | BB3: Stock Transaction | BC3: Lot / Serial Type | BD3: LOT_NUMBER | BE3: SERIAL_NUMBER | BF3: Lot / Serial Trans | BG3: Locator Trans | BH3: Batch Stocks | BI3: Stock Ledger | BJ3: Stock As on Date (Qty) | BK3: Stock As on Date (Qty & vALUE) | BL3: Sou.WH | BM3: Unitcost Before Post For Source Warehouse | BN3: Qty Before Post For Source WareHouse | BO3: Unit Cost After Post | BP3: Qty After Post forSource Warehouse | BQ3: HSN
A4: 1 | B4: GWL_Item_St_Fc_DU_Rc_01 | C4: GWL_Item_St_Fc_DU_Rc_01 | D4: NOS | E4: NOS | F4: 5 | G4: 150 | H4: =F4*G4 -> 750 | I4: 5 | J4: 4 | K4: 3 | L4: =IF(OR(I4=0,I4="0"),0,H4) -> 750 | M4: =ROUND(L4*I4%,3) -> 37.5 | N4: =L4-M4 -> 712.5 | O4: =ROUND(N4*J4%,3) -> 28.5 | P4: =ROUND(N4-O4,2) -> 684 | Q4: =ROUND(P4*K4%,2) -> 20.52 | R4: =ROUND(M4+O4+Q4,3) -> 86.52 | S4: =(H4-R4) -> 663.48 | T4: 88363222 | U4: 18 | V4: =IF(OR($C$2=1,$C$2=4),ROUND((((S4*U4)/100)/2),2),0) -> 0 | W4: =IF($C$2=1,ROUND((((S4*U4)/100)/2),2),0) -> 0 | X4: =IF($C$2=2,ROUND(((S4*U4)/100),2),0) -> 119.43 | Y4: =IF($C$2=4,ROUND((((S4*U4)/100)/2),2),0) -> 0 | Z4: 0 | AA4: =IF($C2=3,0,(S4*Z4)/100) -> 0 | AB4: =V4+W4+X4+Y4+AA4 -> 119.43 | AC4: =IF($V2=1,S4+AB4,S4) -> 782.91 | AD4: 120 | AE4: =IF($P$2=1,(S4/$S$6)*$E$17,AD4/$AD$6*$E$17) -> 0 | AG4: =IF($P$2=1,(S4/$S$6)*$E$19,AD4/$AD$6*$E$19) -> 0 | AH4: =IF($P$2=1,(S4/$S$6)*$E$20,AD4/$AD$6*$E$20) -> 0 | AI4: =S4*$M2 -> 663.48 | AJ4: =IF($C$2=3,0,AG4+AH4) -> 0 | AK4: =IF($C$2=3,AE4+AG4+AH4,0) -> 0 | AL4: 1 | AM4: =F4/AL4 -> 5 | AN4: =ROUND(AI4/AM4,5) -> 132.696 | AO4: =AJ4/AM4 -> 0 | AP4: =AK4/AM4 -> 0 | AQ4: NOS | AR4: =ROUND(AN4+AO4+AP4,5) -> 132.696 | AS4: IN WH-7 | AT4: NOS | AW4: =AM4 -> 5 | AX4: =AR4 -> 132.696 | AY4: =AU4+AW4 -> 5 | AZ4: =ROUND(((AU4*AV4)+(AW4*AX4))/(AU4+AW4),5) -> 132.696 | BB4: Receipt Qty & Unit cost | BC4: LOT | BD4: RM | BE4: RMS | BL4: RM WH-7 | BM4: 0 | BN4: 0 | BO4: =ROUND((((AW4*AZ4)+(BN4*BM4))/(AW4+BN4)),5) -> 132.696 | BP4: =ROUND(BN4+AW4,3) -> 5 | BQ4: 123562
A5: 1 | B5: GWL_Item_St_Fc_DU_Rc_02 | C5: GWL_Item_St_Fc_DU_Rc_02 | D5: NOS | E5: NOS | F5: 4 | G5: 100 | H5: =F5*G5 -> 400 | I5: 4 | J5: 5 | K5: 7 | L5: =IF(OR(I5=0,I5="0"),0,H5) -> 400 | M5: =ROUND(L5*I5%,2) -> 16 | N5: =L5-M5 -> 384 | O5: =ROUND(N5*J5%,2) -> 19.2 | P5: =ROUND(N5-O5,2) -> 364.8 | Q5: =ROUND(P5*K5%,2) -> 25.54 | R5: =M5+O5+Q5 -> 60.74 | S5: =(H5-R5) -> 339.26 | T5: 88363222 | U5: 18 | V5: =IF(OR(StPoToMRVWFDURc!$C$2=1,StPoToMRVWFDURc!$C$2=4),ROUND((((S5*U5)/100)/2),2),0) -> 0 | W5: =IF(StPoToMRVWFDURc!$C$2=1,ROUND((((S5*U5)/100)/2),2),0) -> 0 | X5: =IF(StPoToMRVWFDURc!$C$2=2,ROUND(((S5*U5)/100),2),0) -> 61.07 | Y5: =IF(StPoToMRVWFDURc!$C$2=4,ROUND((((S5*U5)/100)/2),2),0) -> 0 | Z5: 0 | AA5: =IF(StPoToMRVWFDURc!$C3=3,0,(S5*Z5)/100) -> 0 | AB5: =V5+W5+X5+Y5+AA5 -> 61.07 | AC5: =IF(StPoToMRVWFDURc!$V3=1,S5+AB5,S5) -> 339.26 | AD5: 120 | AE5: =IF(StPoToMRVWFDURc!$P$2=1,(S5/StPoToMRVWFDURc!$S$6)*StPoToMRVWFDURc!$E$17,AD5/StPoToMRVWFDURc!$AD$6*StPoToMRVWFDURc!$E$17) -> 0 | AG5: =IF(StPoToMRVWFDURc!$P$2=1,(S5/StPoToMRVWFDURc!$S$6)*StPoToMRVWFDURc!$E$19,AD5/StPoToMRVWFDURc!$AD$6*StPoToMRVWFDURc!$E$19) -> 0 | AH5: =IF(StPoToMRVWFDURc!$P$2=1,(S5/StPoToMRVWFDURc!$S$6)*StPoToMRVWFDURc!$E$20,AD5/StPoToMRVWFDURc!$AD$6*StPoToMRVWFDURc!$E$20) -> 0 | AI5: =S5*StPoToMRVWFDURc!$M$2 -> 339.26 | AJ5: =IF(StPoToMRVWFDURc!$C$2=3,0,AG5+AH5) -> 0 | AK5: =IF(StPoToMRVWFDURc!$C$2=3,AE5+AG5+AH5,0) -> 0 | AL5: 1 | AM5: =F5/AL5 -> 4 | AN5: =ROUND(AI5/AM5,5) -> 84.815 | AO5: =AJ5/AM5 -> 0 | AP5: =AK5/AM5 -> 0 | AQ5: NOS | AR5: =ROUND(AN5+AO5+AP5,5) -> 84.815 | AS5: IN WH-7 | AT5: NOS | AW5: =AM5 -> 4 | AX5: =AR5 -> 84.815 | AY5: =AU5+AW5 -> 4 | AZ5: =ROUND(((AU5*AV5)+(AW5*AX5))/(AU5+AW5),5) -> 84.815 | BB5: Receipt Qty & Unit cost | BC5: LOT | BD5: RM | BE5: RMS | BL5: RM WH-7 | BM5: 0 | BN5: 0 | BO5: =ROUND((((AW5*AZ5)+(BN5*BM5))/(AW5+BN5)),5) -> 84.815 | BP5: =ROUND(BN5+AW5,3) -> 4 | BQ5: 123562
D6: Total | H6: =SUM(H4:H4) -> 750 | R6: =SUM(R4:R4) -> 86.52 | S6: =SUM(S4:S4) -> 663.48 | V6: =SUM(V4:V4) -> 0 | W6: =SUM(W4:W4) -> 0 | X6: =SUM(X4:X4) -> 119.43 | AB6: =SUM(AB4:AB4) -> 119.43 | AC6: =SUM(AC4:AC4) -> 782.91 | AD6: =SUM(AD4:AD4) -> 120 | AE6: =SUM(AE4:AE4) -> 0 | AG6: =SUM(AG4:AG4) -> 0 | AH6: =IF($P$2=1,(S6/$S$6)*$E$20,AD6/$AD$6*$E$20) -> 0 | AI6: =SUM(AI4:AI4) -> 663.48 | AJ6: =SUM(AJ4:AJ4) -> 0 | AK6: =SUM(AK4:AK4) -> 0
G8: Gross Purchase | I8: =H6 -> 750 | M8: Conv factor | BH8: ACPT | BI8: Acpt Qty. * Insp. Unit Cost + OLD. Qty in GRN WH * OLD Unitcost in GRN WH / Acpt. Qty + OLD. Qty in GRN WH
G9: Disc amt | I9: =R6 -> 86.52 | M9: 1 | N9: NOS | O9: 2 | P9: KGS | BH9: REJ | BI9: Rej Qty. * Insp. Unit Cost + OLD. Qty in REJ WH * OLD Unitcost in REJ WH / Acpt. Qty + OLD. Qty in REJ WH
G10: Net Purchase | I10: =S6 -> 663.48 | M10: 1 | N10: NOS | O10: 2.5 | P10: MTR
G11: Tax Amt | I11: =AB6 -> 119.43 | M11: 1 | N11: KGS | O11: 0.001 | P11: MT
G12: Gross Amont | I12: =I10+I11 -> 782.91
BM13: old | BN13: new
BK14: acpt Qty | BL14: 12.5 | BM14: =BL16*BL17 -> 18277.77 | BN14: =BL14*BL15 -> 6092.59
BK15: Inspection Unit Cost | BL15: 487.4072 | BM15: =BL14+BL16 -> 50
BK16: old Qty | BL16: 37.5
BK17: old UnitCost | BL17: 487.4072
BM18: =BM14+BN14 -> 24370.36 | BN18: =BM18/BM15 -> 487.4072

Sheet StPoToMRVWFRc
A1: Purchase Order & GRN
A2: GST Purchase | C2: 2 | D2: (1 - Local Purchase,2 Interstate Purchase, 3 Import Purchase,4-UTGST) | I2: Cur. | J2: INR | L2: Ex. Rate | M2: 1 | O2: Apportion Basis | P2: 2 | Q2: 1 - Value Based, 2 Weight/Volume Based | V2: 1 | W2: (1 - Registered, 2 - Unregistered)
A3: No. | B3: Item | C3: Item Desc | D3: Stk. UOM | E3: Pur. UOM | F3: Qty | G3: Unit Cost | H3: Gross Amt. | I3: TD% | J3: CD% | K3: SD% | L3: TD Asbl. Val. | M3: TD Amt. | N3: CD Asbl. Val. | O3: CD Amt. | P3: VD Asbl. Val. | Q3: SD Amt. | R3: Disc. Amt. | S3: Pur. Value | T3: HSN | U3: Tax% | V3: CGST | W3: SGST | X3: IGST | Y3: UTGST | Z3: Cess% | AA3: CESS | AB3: Tax amt | AC3: Net Amt | AD3: Weight/Vol | AE3: Customs Duty | AF3: IGST (Import) | AG3: Packing & Forwarding | AH3: Freight | AI3: Pur Amt (BC) | AJ3: Chargeable Cost | AK3: Landed Cost | AL3: Conv. Factor | AM3: Eqv. Stock Qty | AN3: Pur. Unit Cost (chr) | AO3: Chrg. Unit Cost | AP3: Landed Cost Unit Cost | AQ3: Stock UOM | AR3: Unit cost (Stk. UOM) | AS3: Ins. WH | AT3: Stock UOM | AU3: Qty Before Post | AV3: Unit Cost Before Post | AW3: Receipt Qty | AX3: Receipt Unit cost | AY3: Qty After Post | AZ3: Unit Cost After Post | BA3: Result (Ok/Not OK) | BB3: Stock Transaction | BC3: Lot / Serial Type | BD3: LOT_NUMBER | BE3: SERIAL_NUMBER | BF3: Lot / Serial Trans | BG3: Locator Trans | BH3: Batch Stocks | BI3: Stock Ledger | BJ3: Stock As on Date (Qty) | BK3: Stock As on Date (Qty & vALUE) | BL3: Sou.WH | BM3: Unitcost Before Post For Source Warehouse | BN3: Qty Before Post For Source WareHouse | BO3: Unit Cost After Post | BP3: Qty After Post forSource Warehouse | BQ3: HSN
A4: 1 | B4: GWL_Similar_Wf_Rc_St_01 | C4: GWL_Similar_Wf_Rc_St_01 | D4: NOS | E4: NOS | F4: 5 | G4: 150 | H4: =F4*G4 -> 750 | I4: 5 | J4: 0 | K4: 0 | L4: =IF(OR(I4=0,I4="0"),0,H4) -> 750 | M4: =ROUND(L4*I4%,3) -> 37.5 | N4: 0 | O4: =ROUND(N4*J4%,3) -> 0 | P4: =ROUND(N4-O4,2) -> 0 | Q4: =ROUND(P4*K4%,2) -> 0 | R4: =ROUND(M4+O4+Q4,3) -> 37.5 | S4: =(H4-R4) -> 712.5 | T4: 88363222 | U4: 18 | V4: =IF(OR($C$2=1,$C$2=4),ROUND((((S4*U4)/100)/2),2),0) -> 0 | W4: =IF($C$2=1,ROUND((((S4*U4)/100)/2),2),0) -> 0 | X4: =IF($C$2=2,ROUND(((S4*U4)/100),2),0) -> 128.25 | Y4: =IF($C$2=4,ROUND((((S4*U4)/100)/2),2),0) -> 0 | Z4: 0 | AA4: =IF($C2=3,0,(S4*Z4)/100) -> 0 | AB4: =V4+W4+X4+Y4+AA4 -> 128.25 | AC4: =IF($V2=1,S4+AB4,S4) -> 840.75 | AD4: 120 | AE4: =IF($P$2=1,(S4/$S$6)*$E$17,AD4/$AD$6*$E$17) -> 0 | AG4: =IF($P$2=1,(S4/$S$6)*$E$19,AD4/$AD$6*$E$19) -> 0 | AH4: =IF($P$2=1,(S4/$S$6)*$E$20,AD4/$AD$6*$E$20) -> 0 | AI4: =S4*$M2 -> 712.5 | AJ4: =IF($C$2=3,0,AG4+AH4) -> 0 | AK4: =IF($C$2=3,AE4+AG4+AH4,0) -> 0 | AL4: 1 | AM4: =F4/AL4 -> 5 | AN4: =ROUND(AI4/AM4,5) -> 142.5 | AO4: =AJ4/AM4 -> 0 | AP4: =AK4/AM4 -> 0 | AQ4: NOS | AR4: =ROUND(AN4+AO4+AP4,5) -> 142.5 | AS4: IN WH-7 | AT4: NOS | AU4: 0 | AV4: 142.5 | AW4: =AM4 -> 5 | AX4: =AR4 -> 142.5 | AY4: =AU4+AW4 -> 5 | AZ4: =ROUND(((AU4*AV4)+(AW4*AX4))/(AU4+AW4),5) -> 142.5 | BB4: Receipt Qty & Unit cost | BC4: LOT | BD4: RM | BE4: RMS | BL4: RM WH-7 | BM4: 142.5 | BN4: 5 | BO4: =ROUND((((AW4*AZ4)+(BN4*BM4))/(AW4+BN4)),5) -> 142.5 | BP4: =ROUND(BN4+AW4,3) -> 10 | BQ4: 123562
A5: 1 | B5: GWL_Similar_Wf_Rc_St_02 | C5: GWL_Similar_Wf_Rc_St_02 | D5: NOS | E5: NOS | F5: 4 | G5: 100 | H5: =F5*G5 -> 400 | I5: 4 | J5: 0 | K5: 0 | L5: =IF(OR(I5=0,I5="0"),0,H5) -> 400 | M5: =ROUND(L5*I5%,2) -> 16 | N5: 0 | O5: =ROUND(N5*J5%,2) -> 0 | P5: =ROUND(N5-O5,2) -> 0 | Q5: =ROUND(P5*K5%,2) -> 0 | R5: =M5+O5+Q5 -> 16 | S5: =(H5-R5) -> 384 | T5: 88363222 | U5: 18 | V5: =IF(OR(StPoToMRVWFRc!$C$2=1,StPoToMRVWFRc!$C$2=4),ROUND((((S5*U5)/100)/2),2),0) -> 0 | W5: =IF(StPoToMRVWFRc!$C$2=1,ROUND((((S5*U5)/100)/2),2),0) -> 0 | X5: =IF(StPoToMRVWFRc!$C$2=2,ROUND(((S5*U5)/100),2),0) -> 69.12 | Y5: =IF(StPoToMRVWFRc!$C$2=4,ROUND((((S5*U5)/100)/2),2),0) -> 0 | Z5: 0 | AA5: =IF(StPoToMRVWFRc!$C3=3,0,(S5*Z5)/100) -> 0 | AB5: =V5+W5+X5+Y5+AA5 -> 69.12 | AC5: =IF(StPoToMRVWFRc!$V3=1,S5+AB5,S5) -> 384 | AD5: 120 | AE5: =IF(StPoToMRVWFRc!$P$2=1,(S5/StPoToMRVWFRc!$S$6)*StPoToMRVWFRc!$E$17,AD5/StPoToMRVWFRc!$AD$6*StPoToMRVWFRc!$E$17) -> 0 | AG5: =IF(StPoToMRVWFRc!$P$2=1,(S5/StPoToMRVWFRc!$S$6)*StPoToMRVWFRc!$E$19,AD5/StPoToMRVWFRc!$AD$6*StPoToMRVWFRc!$E$19) -> 0 | AH5: =IF(StPoToMRVWFRc!$P$2=1,(S5/StPoToMRVWFRc!$S$6)*StPoToMRVWFRc!$E$20,AD5/StPoToMRVWFRc!$AD$6*StPoToMRVWFRc!$E$20) -> 0 | AI5: =S5*StPoToMRVWFRc!$M$2 -> 384 | AJ5: =IF(StPoToMRVWFRc!$C$2=3,0,AG5+AH5) -> 0 | AK5: =IF(StPoToMRVWFRc!$C$2=3,AE5+AG5+AH5,0) -> 0 | AL5: 1 | AM5: =F5/AL5 -> 4 | AN5: =ROUND(AI5/AM5,5) -> 96 | AO5: =AJ5/AM5 -> 0 | AP5: =AK5/AM5 -> 0 | AQ5: NOS | AR5: =ROUND(AN5+AO5+AP5,5) -> 96 | AS5: IN WH-7 | AT5: NOS | AU5: 0 | AV5: 96 | AW5: =AM5 -> 4 | AX5: =AR5 -> 96 | AY5: =AU5+AW5 -> 4 | AZ5: =ROUND(((AU5*AV5)+(AW5*AX5))/(AU5+AW5),5) -> 96 | BB5: Receipt Qty & Unit cost | BC5: LOT | BD5: RM | BE5: RMS | BL5: RM WH-7 | BM5: 96 | BN5: 4 | BO5: =ROUND((((AW5*AZ5)+(BN5*BM5))/(AW5+BN5)),5) -> 96 | BP5: =ROUND(BN5+AW5,3) -> 8 | BQ5: 123562
D6: Total | H6: =SUM(H4:H4) -> 750 | R6: =SUM(R4:R4) -> 37.5 | S6: =SUM(S4:S4) -> 712.5 | V6: =SUM(V4:V4) -> 0 | W6: =SUM(W4:W4) -> 0 | X6: =SUM(X4:X4) -> 128.25 | AB6: =SUM(AB4:AB4) -> 128.25 | AC6: =SUM(AC4:AC4) -> 840.75 | AD6: =SUM(AD4:AD4) -> 120 | AE6: =SUM(AE4:AE4) -> 0 | AG6: =SUM(AG4:AG4) -> 0 | AH6: =IF($P$2=1,(S6/$S$6)*$E$20,AD6/$AD$6*$E$20) -> 0 | AI6: =SUM(AI4:AI4) -> 712.5 | AJ6: =SUM(AJ4:AJ4) -> 0 | AK6: =SUM(AK4:AK4) -> 0
G8: Gross Purchase | I8: =H6 -> 750 | M8: Conv factor | BH8: ACPT | BI8: Acpt Qty. * Insp. Unit Cost + OLD. Qty in GRN WH * OLD Unitcost in GRN WH / Acpt. Qty + OLD. Qty in GRN WH
G9: Disc amt | I9: =R6 -> 37.5 | M9: 1 | N9: NOS | O9: 2 | P9: KGS | BH9: REJ | BI9: Rej Qty. * Insp. Unit Cost + OLD. Qty in REJ WH * OLD Unitcost in REJ WH / Acpt. Qty + OLD. Qty in REJ WH
G10: Net Purchase | I10: =S6 -> 712.5 | M10: 1 | N10: NOS | O10: 2.5 | P10: MTR
G11: Tax Amt | I11: =AB6 -> 128.25 | M11: 1 | N11: KGS | O11: 0.001 | P11: MT
G12: Gross Amont | I12: =I10+I11 -> 840.75
BM13: old | BN13: new
BK14: acpt Qty | BL14: 12.5 | BM14: =BL16*BL17 -> 18277.77 | BN14: =BL14*BL15 -> 6092.59
BK15: Inspection Unit Cost | BL15: 487.4072 | BM15: =BL14+BL16 -> 50
BK16: old Qty | BL16: 37.5
BK17: old UnitCost | BL17: 487.4072
BM18: =BM14+BN14 -> 24370.36 | BN18: =BM18/BM15 -> 487.4072

Sheet StPoToMRVWF
A1: Purchase Order & GRN
A2: GST Purchase | C2: 2 | D2: (1 - Local Purchase,2 Interstate Purchase, 3 Import Purchase,4-UTGST) | I2: Cur. | J2: INR | L2: Ex. Rate | M2: 1 | O2: Apportion Basis | P2: 2 | Q2: 1 - Value Based, 2 Weight/Volume Based | V2: 1 | W2: (1 - Registered, 2 - Unregistered)
A3: No. | B3: Item | C3: Item Desc | D3: Stk. UOM | E3: Pur. UOM | F3: Qty | G3: Unit Cost | H3: Gross Amt. | I3: TD% | J3: CD% | K3: SD% | L3: TD Asbl. Val. | M3: TD Amt. | N3: CD Asbl. Val. | O3: CD Amt. | P3: VD Asbl. Val. | Q3: SD Amt. | R3: Disc. Amt. | S3: Pur. Value | T3: HSN | U3: Tax% | V3: CGST | W3: SGST | X3: IGST | Y3: UTGST | Z3: Cess% | AA3: CESS | AB3: Tax amt | AC3: Net Amt | AD3: Weight/Vol | AE3: Customs Duty | AF3: IGST (Import) | AG3: Packing & Forwarding | AH3: Freight | AI3: Pur Amt (BC) | AJ3: Chargeable Cost | AK3: Landed Cost | AL3: Conv. Factor | AM3: Eqv. Stock Qty | AN3: Pur. Unit Cost (chr) | AO3: Chrg. Unit Cost | AP3: Landed Cost Unit Cost | AQ3: Stock UOM | AR3: Unit cost (Stk. UOM) | AS3: Ins. WH | AT3: Stock UOM | AU3: Qty Before Post | AV3: Unit Cost Before Post | AW3: Receipt Qty | AX3: Receipt Unit cost | AY3: Qty After Post | AZ3: Unit Cost After Post | BA3: Result (Ok/Not OK) | BB3: Stock Transaction | BC3: Lot / Serial Type | BD3: LOT_NUMBER | BE3: SERIAL_NUMBER | BF3: Lot / Serial Trans | BG3: Locator Trans | BH3: Batch Stocks | BI3: Stock Ledger | BJ3: Stock As on Date (Qty) | BK3: Stock As on Date (Qty & vALUE) | BL3: Sou.WH | BM3: Unitcost Before Post For Source Warehouse | BN3: Qty Before Post For Source WareHouse | BO3: Unit Cost After Post | BP3: Qty After Post forSource Warehouse | BQ3: HSN
A4: 1 | B4: GWL_Similar_Wf_St_01 | C4: GWL_Similar_Wf_St_01 | D4: NOS | E4: NOS | F4: 5 | G4: 50 | H4: =F4*G4 -> 250 | I4: 5 | J4: 0 | K4: 0 | L4: =IF(OR(I4=0,I4="0"),0,H4) -> 250 | M4: =ROUND(L4*I4%,3) -> 12.5 | N4: 0 | O4: =ROUND(N4*J4%,3) -> 0 | P4: =ROUND(N4-O4,2) -> 0 | Q4: =ROUND(P4*K4%,2) -> 0 | R4: =ROUND(M4+O4+Q4,3) -> 12.5 | S4: =(H4-R4) -> 237.5 | T4: 88363222 | U4: 18 | V4: =IF(OR($C$2=1,$C$2=4),ROUND((((S4*U4)/100)/2),2),0) -> 0 | W4: =IF($C$2=1,ROUND((((S4*U4)/100)/2),2),0) -> 0 | X4: =IF($C$2=2,ROUND(((S4*U4)/100),2),0) -> 42.75 | Y4: =IF($C$2=4,ROUND((((S4*U4)/100)/2),2),0) -> 0 | Z4: 0 | AA4: =IF($C2=3,0,(S4*Z4)/100) -> 0 | AB4: =V4+W4+X4+Y4+AA4 -> 42.75 | AC4: =IF($V2=1,S4+AB4,S4) -> 280.25 | AD4: 120 | AE4: =IF($P$2=1,(S4/$S$6)*$E$17,AD4/$AD$6*$E$17) -> 0 | AG4: =IF($P$2=1,(S4/$S$6)*$E$19,AD4/$AD$6*$E$19) -> 0 | AH4: =IF($P$2=1,(S4/$S$6)*$E$20,AD4/$AD$6*$E$20) -> 0 | AI4: =S4*$M2 -> 237.5 | AJ4: =IF($C$2=3,0,AG4+AH4) -> 0 | AK4: =IF($C$2=3,AE4+AG4+AH4,0) -> 0 | AL4: 1 | AM4: =F4/AL4 -> 5 | AN4: =ROUND(AI4/AM4,5) -> 47.5 | AO4: =AJ4/AM4 -> 0 | AP4: =AK4/AM4 -> 0 | AQ4: NOS | AR4: =ROUND(AN4+AO4+AP4,5) -> 47.5 | AS4: IN WH-7 | AT4: NOS | AU4: 0 | AV4: 47.5 | AW4: =AM4 -> 5 | AX4: =AR4 -> 47.5 | AY4: =AU4+AW4 -> 5 | AZ4: =ROUND(((AU4*AV4)+(AW4*AX4))/(AU4+AW4),5) -> 47.5 | BB4: Receipt Qty & Unit cost | BC4: LOT | BD4: RM | BE4: RMS | BL4: RM WH-7 | BM4: 47.5 | BN4: 5 | BO4: =ROUND((((AW4*AZ4)+(BN4*BM4))/(AW4+BN4)),5) -> 47.5 | BP4: =ROUND(BN4+AW4,3) -> 10 | BQ4: 123562
A5: 1 | B5: GWL_Similar_Wf_St_02 | C5: GWL_Similar_Wf_St_02 | D5: NOS | E5: NOS | F5: 4 | G5: 100 | H5: =F5*G5 -> 400 | I5: 6 | J5: 0 | K5: 0 | L5: =IF(OR(I5=0,I5="0"),0,H5) -> 400 | M5: =ROUND(L5*I5%,2) -> 24 | N5: 0 | O5: =ROUND(N5*J5%,2) -> 0 | P5: =ROUND(N5-O5,2) -> 0 | Q5: =ROUND(P5*K5%,2) -> 0 | R5: =M5+O5+Q5 -> 24 | S5: =(H5-R5) -> 376 | T5: 88363222 | U5: 18 | V5: =IF(OR(StPoToMRVWF!$C$2=1,StPoToMRVWF!$C$2=4),ROUND((((S5*U5)/100)/2),2),0) -> 0 | W5: =IF(StPoToMRVWF!$C$2=1,ROUND((((S5*U5)/100)/2),2),0) -> 0 | X5: =IF(StPoToMRVWF!$C$2=2,ROUND(((S5*U5)/100),2),0) -> 67.68 | Y5: =IF(StPoToMRVWF!$C$2=4,ROUND((((S5*U5)/100)/2),2),0) -> 0 | Z5: 0 | AA5: =IF(StPoToMRVWF!$C3=3,0,(S5*Z5)/100) -> 0 | AB5: =V5+W5+X5+Y5+AA5 -> 67.68 | AC5: =IF(StPoToMRVWF!$V3=1,S5+AB5,S5) -> 376 | AD5: 120 | AE5: =IF(StPoToMRVWF!$P$2=1,(S5/StPoToMRVWF!$S$6)*StPoToMRVWF!$E$17,AD5/StPoToMRVWF!$AD$6*StPoToMRVWF!$E$17) -> 0 | AG5: =IF(StPoToMRVWF!$P$2=1,(S5/StPoToMRVWF!$S$6)*StPoToMRVWF!$E$19,AD5/StPoToMRVWF!$AD$6*StPoToMRVWF!$E$19) -> 0 | AH5: =IF(StPoToMRVWF!$P$2=1,(S5/StPoToMRVWF!$S$6)*StPoToMRVWF!$E$20,AD5/StPoToMRVWF!$AD$6*StPoToMRVWF!$E$20) -> 0 | AI5: =S5*StPoToMRVWF!$M$2 -> 376 | AJ5: =IF(StPoToMRVWF!$C$2=3,0,AG5+AH5) -> 0 | AK5: =IF(StPoToMRVWF!$C$2=3,AE5+AG5+AH5,0) -> 0 | AL5: 1 | AM5: =F5/AL5 -> 4 | AN5: =ROUND(AI5/AM5,5) -> 94 | AO5: =AJ5/AM5 -> 0 | AP5: =AK5/AM5 -> 0 | AQ5: NOS | AR5: =ROUND(AN5+AO5+AP5,5) -> 94 | AS5: IN WH-7 | AT5: NOS | AU5: 0 | AV5: 94 | AW5: =AM5 -> 4 | AX5: =AR5 -> 94 | AY5: =AU5+AW5 -> 4 | AZ5: =ROUND(((AU5*AV5)+(AW5*AX5))/(AU5+AW5),5) -> 94 | BB5: Receipt Qty & Unit cost | BC5: LOT | BD5: RM | BE5: RMS | BL5: RM WH-7 | BM5: 94 | BN5: 4 | BO5: =ROUND((((AW5*AZ5)+(BN5*BM5))/(AW5+BN5)),5) -> 94 | BP5: =ROUND(BN5+AW5,3) -> 8 | BQ5: 123562
D6: Total | H6: =SUM(H4:H4) -> 250 | R6: =SUM(R4:R4) -> 12.5 | S6: =SUM(S4:S4) -> 237.5 | V6: =SUM(V4:V4) -> 0 | W6: =SUM(W4:W4) -> 0 | X6: =SUM(X4:X4) -> 42.75 | AB6: =SUM(AB4:AB4) -> 42.75 | AC6: =SUM(AC4:AC4) -> 280.25 | AD6: =SUM(AD4:AD4) -> 120 | AE6: =SUM(AE4:AE4) -> 0 | AG6: =SUM(AG4:AG4) -> 0 | AH6: =IF($P$2=1,(S6/$S$6)*$E$20,AD6/$AD$6*$E$20) -> 0 | AI6: =SUM(AI4:AI4) -> 237.5 | AJ6: =SUM(AJ4:AJ4) -> 0 | AK6: =SUM(AK4:AK4) -> 0
G8: Gross Purchase | I8: =H6 -> 250 | M8: Conv factor | BH8: ACPT | BI8: Acpt Qty. * Insp. Unit Cost + OLD. Qty in GRN WH * OLD Unitcost in GRN WH / Acpt. Qty + OLD. Qty in GRN WH
G9: Disc amt | I9: =R6 -> 12.5 | M9: 1 | N9: NOS | O9: 2 | P9: KGS | BH9: REJ | BI9: Rej Qty. * Insp. Unit Cost + OLD. Qty in REJ WH * OLD Unitcost in REJ WH / Acpt. Qty + OLD. Qty in REJ WH
G10: Net Purchase | I10: =S6 -> 237.5 | M10: 1 | N10: NOS | O10: 2.5 | P10: MTR
G11: Tax Amt | I11: =AB6 -> 42.75 | M11: 1 | N11: KGS | O11: 0.001 | P11: MT
G12: Gross Amont | I12: =I10+I11 -> 280.25
BM13: old | BN13: new
BK14: acpt Qty | BL14: 12.5 | BM14: =BL16*BL17 -> 18277.77 | BN14: =BL14*BL15 -> 6092.59
BK15: Inspection Unit Cost | BL15: 487.4072 | BM15: =BL14+BL16 -> 50
BK16: old Qty | BL16: 37.5
BK17: old UnitCost | BL17: 487.4072
BM18: =BM14+BN14 -> 24370.36 | BN18: =BM18/BM15 -> 487.4072

Sheet PoToMRVWFDUom
A1: Purchase Order & GRN
A2: GST Purchase | C2: 2 | D2: (1 - Local Purchase,2 Interstate Purchase, 3 Import Purchase,4-UTGST) | I2: Cur. | J2: INR | L2: Ex. Rate | M2: 1 | O2: Apportion Basis | P2: 2 | Q2: 1 - Value Based, 2 Weight/Volume Based | V2: 1 | W2: (1 - Registered, 2 - Unregistered)
A3: No. | B3: Item | C3: Item Desc | D3: Stk. UOM | E3: Pur. UOM | F3: Qty | G3: Unit Cost | H3: Gross Amt. | I3: TD% | J3: CD% | K3: SD% | L3: TD Asbl. Val. | M3: TD Amt. | N3: CD Asbl. Val. | O3: CD Amt. | P3: VD Asbl. Val. | Q3: SD Amt. | R3: Disc. Amt. | S3: Pur. Value | T3: HSN | U3: Tax% | V3: CGST | W3: SGST | X3: IGST | Y3: UTGST | Z3: Cess% | AA3: CESS | AB3: Tax amt | AC3: Net Amt | AD3: Weight/Vol | AE3: Customs Duty | AF3: IGST (Import) | AG3: Packing & Forwarding | AH3: Freight | AI3: Pur Amt (BC) | AJ3: Chargeable Cost | AK3: Landed Cost | AL3: Conv. Factor | AM3: Eqv. Stock Qty | AN3: Pur. Unit Cost (chr) | AO3: Chrg. Unit Cost | AP3: Landed Cost Unit Cost | AQ3: Stock UOM | AR3: Unit cost (Stk. UOM) | AS3: Ins. WH | AT3: Stock UOM | AU3: Qty Before Post | AV3: Unit Cost Before Post | AW3: Receipt Qty | AX3: Receipt Unit cost | AY3: Qty After Post | AZ3: Unit Cost After Post | BA3: Result (Ok/Not OK) | BB3: Stock Transaction | BC3: Lot / Serial Type | BD3: LOT_NUMBER | BE3: SERIAL_NUMBER | BF3: Lot / Serial Trans | BG3: Locator Trans | BH3: Batch Stocks | BI3: Stock Ledger | BJ3: Stock As on Date (Qty) | BK3: Stock As on Date (Qty & vALUE) | BL3: Sou.WH | BM3: Unitcost Before Post For Source Warehouse | BN3: Qty Before Post For Source WareHouse | BO3: Unit Cost After Post | BP3: Qty After Post forSource Warehouse | BQ3: HSN
A4: 1 | B4: GWL_Dissimilar_01 | C4: GWL_Dissimilar_01 | D4: NOS | E4: NOS | F4: 10 | G4: 150 | H4: =F4*G4 -> 1500 | I4: 5 | J4: 8 | K4: 5 | L4: =H4 -> 1500 | M4: =ROUND(L4*I4%,2) -> 75 | N4: =H4-M4 -> 1425 | O4: =ROUND(N4*J4%,2) -> 114 | P4: =ROUND(N4-O4,2) -> 1311 | Q4: =ROUND(P4*K4%,2) -> 65.55 | R4: =M4+O4+Q4 -> 254.55 | S4: =(H4-R4) -> 1245.45 | T4: 88363222 | U4: 18 | V4: =IF(OR($C$2=1,$C$2=4),ROUND((((S4*U4)/100)/2),2),0) -> 0 | W4: =IF($C$2=1,ROUND((((S4*U4)/100)/2),2),0) -> 0 | X4: =IF($C$2=2,ROUND(((S4*U4)/100),2),0) -> 224.18 | Y4: =IF($C$2=4,ROUND((((S4*U4)/100)/2),2),0) -> 0 | Z4: 0 | AA4: =IF($C2=3,0,(S4*Z4)/100) -> 0 | AB4: =V4+W4+X4+Y4+AA4 -> 224.18 | AC4: =IF($V2=1,S4+AB4,S4) -> 1469.63 | AD4: 120 | AE4: =IF($P$2=1,(S4/$S$6)*$E$17,AD4/$AD$6*$E$17) -> 0 | AG4: =IF($P$2=1,(S4/$S$6)*$E$19,AD4/$AD$6*$E$19) -> 0 | AH4: =IF($P$2=1,(S4/$S$6)*$E$20,AD4/$AD$6*$E$20) -> 0 | AI4: =S4*$M$2 -> 1245.45 | AJ4: =IF($C$2=3,0,AG4+AH4) -> 0 | AK4: =IF($C$2=3,AE4+AG4+AH4,0) -> 0 | AL4: 3 | AM4: =F4/AL4 -> 3.3333333 | AN4: =ROUND(AI4/AM4,3) -> 373.635 | AO4: =AJ4/AM4 -> 0 | AP4: =AK4/AM4 -> 0 | AQ4: NOS | AR4: =ROUND(AN4+AO4+AP4,3) -> 373.635 | AS4: INS WH-1 | AT4: NOS | AU4: 0 | AV4: 373.635 | AW4: =AM4 -> 3.3333333 | AX4: =AR4 -> 373.635 | AY4: =AU4+AW4 -> 3.3333333 | AZ4: =ROUND(((AU4*AV4)+(AW4*AX4))/(AU4+AW4),5) -> 373.635 | BB4: Receipt Qty & Unit cost | BC4: LOT | BD4: RM | BE4: RMS | BL4: RM WH-49 | BM4: 373.635 | BN4: 13.332 | BO4: =ROUND((((AW4*AZ4)+(BN4*BM4))/(AW4+BN4)),5) -> 373.635 | BP4: =ROUND(BN4+AW4,3) -> 16.665 | BQ4: 123562
A5: 1 | B5: GWL_Dissimilar_02 | C5: GWL_Dissimilar_02 | D5: NOS | E5: NOS | F5: 20 | G5: 100 | H5: =F5*G5 -> 2000 | I5: 4 | J5: 9 | K5: 6 | L5: =H5 -> 2000 | M5: =ROUND(L5*I5%,2) -> 80 | N5: =H5-M5 -> 1920 | O5: =ROUND(N5*J5%,2) -> 172.8 | P5: =ROUND(N5-O5,2) -> 1747.2 | Q5: =ROUND(P5*K5%,2) -> 104.83 | R5: =M5+O5+Q5 -> 357.63 | S5: =(H5-R5) -> 1642.37 | T5: 88363222 | U5: 18 | V5: =IF(OR(PoToMRVWFDUom!$C$2=1,PoToMRVWFDUom!$C$2=4),ROUND((((S5*U5)/100)/2),2),0) -> 0 | W5: =IF(PoToMRVWFDUom!$C$2=1,ROUND((((S5*U5)/100)/2),2),0) -> 0 | X5: =IF(PoToMRVWFDUom!$C$2=2,ROUND(((S5*U5)/100),2),0) -> 295.63 | Y5: =IF(PoToMRVWFDUom!$C$2=4,ROUND((((S5*U5)/100)/2),2),0) -> 0 | Z5: 0 | AA5: =IF(PoToMRVWFDUom!$C3=3,0,(S5*Z5)/100) -> 0 | AB5: =V5+W5+X5+Y5+AA5 -> 295.63 | AC5: =IF(PoToMRVWFDUom!$V3=1,S5+AB5,S5) -> 1642.37 | AD5: 120 | AE5: =IF(PoToMRVWFDUom!$P$2=1,(S5/PoToMRVWFDUom!$S$6)*PoToMRVWFDUom!$E$17,AD5/PoToMRVWFDUom!$AD$6*PoToMRVWFDUom!$E$17) -> 0 | AG5: =IF(PoToMRVWFDUom!$P$2=1,(S5/PoToMRVWFDUom!$S$6)*PoToMRVWFDUom!$E$19,AD5/PoToMRVWFDUom!$AD$6*PoToMRVWFDUom!$E$19) -> 0 | AH5: =IF(PoToMRVWFDUom!$P$2=1,(S5/PoToMRVWFDUom!$S$6)*PoToMRVWFDUom!$E$20,AD5/PoToMRVWFDUom!$AD$6*PoToMRVWFDUom!$E$20) -> 0 | AI5: =S5*PoToMRVWFDUom!$M$2 -> 1642.37 | AJ5: =IF(PoToMRVWFDUom!$C$2=3,0,AG5+AH5) -> 0 | AK5: =IF(PoToMRVWFDUom!$C$2=3,AE5+AG5+AH5,0) -> 0 | AL5: 3 | AM5: =F5/AL5 -> 6.6666667 | AN5: =ROUND(AI5/AM5,5) -> 246.3555 | AO5: =AJ5/AM5 -> 0 | AP5: =AK5/AM5 -> 0 | AQ5: NOS | AR5: =ROUND(AN5+AO5+AP5,5) -> 246.3555 | AS5: INS WH-1 | AT5: NOS | AU5: 0 | AV5: 246.36 | AW5: =AM5 -> 6.6666667 | AX5: =AR5 -> 246.3555 | AY5: =AU5+AW5 -> 6.6666667 | AZ5: =ROUND(((AU5*AV5)+(AW5*AX5))/(AU5+AW5),2) -> 246.36 | BB5: Receipt Qty & Unit cost | BC5: LOT | BD5: RM | BE5: RMS | BL5: RM WH-49 | BM5: 246.36 | BN5: 12.666 | BO5: =ROUND((((AW5*AZ5)+(BN5*BM5))/(AW5+BN5)),5) -> 246.36 | BP5: =ROUND(BN5+AW5,3) -> 19.333 | BQ5: 123562
D6: Total | H6: =SUM(H4:H4) -> 1500 | R6: =SUM(R4:R4) -> 254.55 | S6: =SUM(S4:S4) -> 1245.45 | V6: =SUM(V4:V4) -> 0 | W6: =SUM(W4:W4) -> 0 | X6: =SUM(X4:X4) -> 224.18 | AB6: =SUM(AB4:AB4) -> 224.18 | AC6: =SUM(AC4:AC4) -> 1469.63 | AD6: =SUM(AD4:AD4) -> 120 | AE6: =SUM(AE4:AE4) -> 0 | AG6: =SUM(AG4:AG4) -> 0 | AH6: =IF($P$2=1,(S6/$S$6)*$E$20,AD6/$AD$6*$E$20) -> 0 | AI6: =SUM(AI4:AI4) -> 1245.45 | AJ6: =SUM(AJ4:AJ4) -> 0 | AK6: =SUM(AK4:AK4) -> 0
G8: Gross Purchase | I8: =H6 -> 1500 | M8: Conv factor | BH8: ACPT | BI8: Acpt Qty. * Insp. Unit Cost + OLD. Qty in GRN WH * OLD Unitcost in GRN WH / Acpt. Qty + OLD. Qty in GRN WH
G9: Disc amt | I9: =R6 -> 254.55 | M9: 1 | N9: NOS | O9: 2 | P9: KGS | BH9: REJ | BI9: Rej Qty. * Insp. Unit Cost + OLD. Qty in REJ WH * OLD Unitcost in REJ WH / Acpt. Qty + OLD. Qty in REJ WH
G10: Net Purchase | I10: =S6 -> 1245.45 | M10: 1 | N10: NOS | O10: 2.5 | P10: MTR
G11: Tax Amt | I11: =AB6 -> 224.18 | M11: 1 | N11: KGS | O11: 0.001 | P11: MT
G12: Gross Amont | I12: =I10+I11 -> 1469.63
BM13: old | BN13: new
BK14: acpt Qty | BL14: 12.5 | BM14: =BL16*BL17 -> 18277.77 | BN14: =BL14*BL15 -> 6092.59
BK15: Inspection Unit Cost | BL15: 487.4072 | BM15: =BL14+BL16 -> 50
BK16: old Qty | BL16: 37.5
BK17: old UnitCost | BL17: 487.4072
BM18: =BM14+BN14 -> 24370.36 | BN18: =BM18/BM15 -> 487.4072

Sheet PoToMRVWoQDUom
A1: Purchase Order & GRN
A2: GST Purchase | C2: 2 | D2: (1 - Local Purchase,2 Interstate Purchase, 3 Import Purchase,4-UTGST) | I2: Cur. | J2: INR | L2: Ex. Rate | M2: 1 | O2: Apportion Basis | P2: 2 | Q2: 1 - Value Based, 2 Weight/Volume Based | V2: 2 | W2: (1 - Registered, 2 - Unregistered)
A3: No. | B3: Item | C3: Item Desc | D3: Stk. UOM | E3: Pur. UOM | F3: Qty | G3: Unit Cost | H3: Gross Amt. | I3: TD% | J3: CD% | K3: SD% | L3: TD Asbl. Val. | M3: TD Amt. | N3: CD Asbl. Val. | O3: CD Amt. | P3: VD Asbl. Val. | Q3: SD Amt. | R3: Disc. Amt. | S3: Pur. Value | T3: HSN | U3: Tax% | V3: CGST | W3: SGST | X3: IGST | Y3: UTGST | Z3: Cess% | AA3: CESS | AB3: Tax amt | AC3: Net Amt | AD3: Weight/Vol | AE3: Customs Duty | AF3: IGST (Import) | AG3: Packing & Forwarding | AH3: Freight | AI3: Pur Amt (BC) | AJ3: Chargeable Cost | AK3: Landed Cost | AL3: Conv. Factor | AM3: Eqv. Stock Qty | AN3: Pur. Unit Cost (chr) | AO3: Chrg. Unit Cost | AP3: Landed Cost Unit Cost | AQ3: Stock UOM | AR3: Unit cost (Stk. UOM) | AS3: Ins. WH | AT3: Stock UOM | AU3: Qty Before Post | AV3: Unit Cost Before Post | AW3: Receipt Qty | AX3: Receipt Unit cost | AY3: Qty After Post | AZ3: Unit Cost After Post | BA3: Result (Ok/Not OK) | BB3: Stock Transaction | BC3: Lot / Serial Type | BD3: LOT_NUMBER | BE3: SERIAL_NUMBER | BF3: Lot / Serial Trans | BG3: Locator Trans | BH3: Batch Stocks | BI3: Stock Ledger | BJ3: Stock As on Date (Qty) | BK3: Stock As on Date (Qty & vALUE) | BL3: Sou.WH | BM3: Unitcost Before Post For Source Warehouse | BN3: Qty Before Post For Source WareHouse | BO3: Unit Cost After Post | BP3: Qty After Post forSource Warehouse | BQ3: HSN
A4: 1 | B4: GWL_Dissimilar_01 | C4: GWL_Dissimilar_01 | D4: NOS | E4: NOS | F4: 10 | G4: 150 | H4: =F4*G4 -> 1500 | I4: 5 | J4: 8 | K4: 5 | L4: =H4 -> 1500 | M4: =ROUND(L4*I4%,2) -> 75 | N4: =H4-M4 -> 1425 | O4: =ROUND(N4*J4%,2) -> 114 | P4: =ROUND(N4-O4,2) -> 1311 | Q4: =ROUND(P4*K4%,2) -> 65.55 | R4: =M4+O4+Q4 -> 254.55 | S4: =(H4-R4) -> 1245.45 | T4: 88363222 | U4: 18 | V4: =IF(OR($C$2=1,$C$2=4),ROUND((((S4*U4)/100)/2),2),0) -> 0 | W4: =IF($C$2=1,ROUND((((S4*U4)/100)/2),2),0) -> 0 | X4: =IF($C$2=2,ROUND(((S4*U4)/100),2),0) -> 224.18 | Y4: =IF($C$2=4,ROUND((((S4*U4)/100)/2),2),0) -> 0 | Z4: 0 | AA4: =IF($C2=3,0,(S4*Z4)/100) -> 0 | AB4: =V4+W4+X4+Y4+AA4 -> 224.18 | AC4: =IF($V2=1,S4+AB4,S4) -> 1245.45 | AD4: 120 | AE4: =IF($P$2=1,(S4/$S$6)*$E$17,AD4/$AD$6*$E$17) -> 0 | AG4: =IF($P$2=1,(S4/$S$6)*$E$19,AD4/$AD$6*$E$19) -> 0 | AH4: =IF($P$2=1,(S4/$S$6)*$E$20,AD4/$AD$6*$E$20) -> 0 | AI4: =S4*$M$2 -> 1245.45 | AJ4: =IF($C$2=3,0,AG4+AH4) -> 0 | AK4: =IF($C$2=3,AE4+AG4+AH4,0) -> 0 | AL4: 3 | AM4: =F4/AL4 -> 3.3333333 | AN4: =ROUND(AI4/AM4,3) -> 373.635 | AO4: =AJ4/AM4 -> 0 | AP4: =AK4/AM4 -> 0 | AQ4: NOS | AR4: =ROUND(AN4+AO4+AP4,3) -> 373.635 | AS4: INS WH-1 | AT4: NOS | AU4: 0 | AV4: 373.635 | AW4: =AM4 -> 3.3333333 | AX4: =AR4 -> 373.635 | AY4: =AU4+AW4 -> 3.3333333 | AZ4: =ROUND(((AU4*AV4)+(AW4*AX4))/(AU4+AW4),5) -> 373.635 | BB4: Receipt Qty & Unit cost | BC4: LOT | BD4: RM | BE4: RMS | BL4: RM WH-49 | BM4: 13816.57773 | BN4: 33.334 | BO4: =ROUND((((AW4*AZ4)+(BN4*BM4))/(AW4+BN4)),5) -> 12594.514 | BP4: =ROUND(BN4+AW4,3) -> 36.667 | BQ4: 123562
A5: 1 | B5: GWL_Dissimilar_02 | C5: GWL_Dissimilar_02 | D5: NOS | E5: NOS | F5: 20 | G5: 100 | H5: =F5*G5 -> 2000 | I5: 4 | J5: 9 | K5: 6 | L5: =H5 -> 2000 | M5: =ROUND(L5*I5%,2) -> 80 | N5: =H5-M5 -> 1920 | O5: =ROUND(N5*J5%,2) -> 172.8 | P5: =ROUND(N5-O5,2) -> 1747.2 | Q5: =ROUND(P5*K5%,2) -> 104.83 | R5: =M5+O5+Q5 -> 357.63 | S5: =(H5-R5) -> 1642.37 | T5: 88363222 | U5: 18 | V5: =IF(OR(PoToMRVWoQDUom!$C$2=1,PoToMRVWoQDUom!$C$2=4),ROUND((((S5*U5)/100)/2),2),0) -> 0 | W5: =IF(PoToMRVWoQDUom!$C$2=1,ROUND((((S5*U5)/100)/2),2),0) -> 0 | X5: =IF(PoToMRVWoQDUom!$C$2=2,ROUND(((S5*U5)/100),2),0) -> 295.63 | Y5: =IF(PoToMRVWoQDUom!$C$2=4,ROUND((((S5*U5)/100)/2),2),0) -> 0 | Z5: 0 | AA5: =IF(PoToMRVWoQDUom!$C3=3,0,(S5*Z5)/100) -> 0 | AB5: =V5+W5+X5+Y5+AA5 -> 295.63 | AC5: =IF(PoToMRVWoQDUom!$V3=1,S5+AB5,S5) -> 1642.37 | AD5: 120 | AE5: =IF(PoToMRVWoQDUom!$P$2=1,(S5/PoToMRVWoQDUom!$S$6)*PoToMRVWoQDUom!$E$17,AD5/PoToMRVWoQDUom!$AD$6*PoToMRVWoQDUom!$E$17) -> 0 | AG5: =IF(PoToMRVWoQDUom!$P$2=1,(S5/PoToMRVWoQDUom!$S$6)*PoToMRVWoQDUom!$E$19,AD5/PoToMRVWoQDUom!$AD$6*PoToMRVWoQDUom!$E$19) -> 0 | AH5: =IF(PoToMRVWoQDUom!$P$2=1,(S5/PoToMRVWoQDUom!$S$6)*PoToMRVWoQDUom!$E$20,AD5/PoToMRVWoQDUom!$AD$6*PoToMRVWoQDUom!$E$20) -> 0 | AI5: =S5*PoToMRVWoQDUom!$M$2 -> 1642.37 | AJ5: =IF(PoToMRVWoQDUom!$C$2=3,0,AG5+AH5) -> 0 | AK5: =IF(PoToMRVWoQDUom!$C$2=3,AE5+AG5+AH5,0) -> 0 | AL5: 3 | AM5: =F5/AL5 -> 6.6666667 | AN5: =ROUND(AI5/AM5,5) -> 246.3555 | AO5: =AJ5/AM5 -> 0 | AP5: =AK5/AM5 -> 0 | AQ5: NOS | AR5: =ROUND(AN5+AO5+AP5,5) -> 246.3555 | AS5: INS WH-1 | AT5: NOS | AU5: 0 | AV5: 246.36 | AW5: =AM5 -> 6.6666667 | AX5: =AR5 -> 246.3555 | AY5: =AU5+AW5 -> 6.6666667 | AZ5: =ROUND(((AU5*AV5)+(AW5*AX5))/(AU5+AW5),2) -> 246.36 | BB5: Receipt Qty & Unit cost | BC5: LOT | BD5: RM | BE5: RMS | BL5: RM WH-49 | BM5: 246.36 | BN5: 26 | BO5: =ROUND((((AW5*AZ5)+(BN5*BM5))/(AW5+BN5)),5) -> 246.36 | BP5: =ROUND(BN5+AW5,3) -> 32.667 | BQ5: 123562
D6: Total | H6: =SUM(H4:H4) -> 1500 | R6: =SUM(R4:R4) -> 254.55 | S6: =SUM(S4:S4) -> 1245.45 | V6: =SUM(V4:V4) -> 0 | W6: =SUM(W4:W4) -> 0 | X6: =SUM(X4:X4) -> 224.18 | AB6: =SUM(AB4:AB4) -> 224.18 | AC6: =SUM(AC4:AC4) -> 1245.45 | AD6: =SUM(AD4:AD4) -> 120 | AE6: =SUM(AE4:AE4) -> 0 | AG6: =SUM(AG4:AG4) -> 0 | AH6: =IF($P$2=1,(S6/$S$6)*$E$20,AD6/$AD$6*$E$20) -> 0 | AI6: =SUM(AI4:AI4) -> 1245.45 | AJ6: =SUM(AJ4:AJ4) -> 0 | AK6: =SUM(AK4:AK4) -> 0
G8: Gross Purchase | I8: =H6 -> 1500 | M8: Conv factor | BH8: ACPT | BI8: Acpt Qty. * Insp. Unit Cost + OLD. Qty in GRN WH * OLD Unitcost in GRN WH / Acpt. Qty + OLD. Qty in GRN WH
G9: Disc amt | I9: =R6 -> 254.55 | M9: 1 | N9: NOS | O9: 2 | P9: KGS | BH9: REJ | BI9: Rej Qty. * Insp. Unit Cost + OLD. Qty in REJ WH * OLD Unitcost in REJ WH / Acpt. Qty + OLD. Qty in REJ WH
G10: Net Purchase | I10: =S6 -> 1245.45 | M10: 1 | N10: NOS | O10: 2.5 | P10: MTR
G11: Tax Amt | I11: =AB6 -> 224.18 | M11: 1 | N11: KGS | O11: 0.001 | P11: MT
G12: Gross Amont | I12: =I10+I11 -> 1469.63
BM13: old | BN13: new
BK14: acpt Qty | BL14: 12.5 | BM14: =BL16*BL17 -> 18277.77 | BN14: =BL14*BL15 -> 6092.59
BK15: Inspection Unit Cost | BL15: 487.4072 | BM15: =BL14+BL16 -> 50
BK16: old Qty | BL16: 37.5
BK17: old UnitCost | BL17: 487.4072
BM18: =BM14+BN14 -> 24370.36 | BN18: =BM18/BM15 -> 487.4072

Sheet PoToMRVWoQDUomImp
A1: Purchase Order & GRN
A2: GST Purchase | C2: 3 | D2: (1 - Local Purchase,2 Interstate Purchase, 3 Import Purchase,4-UTGST) | I2: Cur. | J2: INR | L2: Ex. Rate | M2: 85 | O2: Apportion Basis | P2: 2 | Q2: 1 - Value Based, 2 Weight/Volume Based | V2: 2 | W2: (1 - Registered, 2 - Unregistered)
A3: No. | B3: Item | C3: Item Desc | D3: Stk. UOM | E3: Pur. UOM | F3: Qty | G3: Unit Cost | H3: Gross Amt. | I3: TD% | J3: CD% | K3: SD% | L3: TD Asbl. Val. | M3: TD Amt. | N3: CD Asbl. Val. | O3: CD Amt. | P3: VD Asbl. Val. | Q3: SD Amt. | R3: Disc. Amt. | S3: Pur. Value | T3: HSN | U3: Tax% | V3: CGST | W3: SGST | X3: IGST | Y3: UTGST | Z3: Cess% | AA3: CESS | AB3: Tax amt | AC3: Net Amt | AD3: Weight/Vol | AE3: Customs Duty | AF3: IGST (Import) | AG3: Packing & Forwarding | AH3: Freight | AI3: Pur Amt (BC) | AJ3: Chargeable Cost | AK3: Landed Cost | AL3: Conv. Factor | AM3: Eqv. Stock Qty | AN3: Pur. Unit Cost (chr) | AO3: Chrg. Unit Cost | AP3: Landed Cost Unit Cost | AQ3: Stock UOM | AR3: Unit cost (Stk. UOM) | AS3: Ins. WH | AT3: Stock UOM | AU3: Qty Before Post | AV3: Unit Cost Before Post | AW3: Receipt Qty | AX3: Receipt Unit cost | AY3: Qty After Post | AZ3: Unit Cost After Post | BA3: Result (Ok/Not OK) | BB3: Stock Transaction | BC3: Lot / Serial Type | BD3: LOT_NUMBER | BE3: SERIAL_NUMBER | BF3: Lot / Serial Trans | BG3: Locator Trans | BH3: Batch Stocks | BI3: Stock Ledger | BJ3: Stock As on Date (Qty) | BK3: Stock As on Date (Qty & vALUE) | BL3: Sou.WH | BM3: Unitcost Before Post For Source Warehouse | BN3: Qty Before Post For Source WareHouse | BO3: Unit Cost After Post | BP3: Qty After Post forSource Warehouse | BQ3: HSN
A4: 1 | B4: GWL_Dissimilar_01 | C4: GWL_Dissimilar_01 | D4: NOS | E4: NOS | F4: 10 | G4: 150 | H4: =F4*G4 -> 1500 | I4: 5 | J4: 8 | K4: 5 | L4: =H4 -> 1500 | M4: =ROUND(L4*I4%,2) -> 75 | N4: =H4-M4 -> 1425 | O4: =ROUND(N4*J4%,2) -> 114 | P4: =ROUND(N4-O4,2) -> 1311 | Q4: =ROUND(P4*K4%,2) -> 65.55 | R4: =M4+O4+Q4 -> 254.55 | S4: =(H4-R4) -> 1245.45 | T4: 88363222 | U4: 18 | V4: =IF(OR($C$2=1,$C$2=4),ROUND((((S4*U4)/100)/2),2),0) -> 0 | W4: =IF($C$2=1,ROUND((((S4*U4)/100)/2),2),0) -> 0 | X4: =IF($C$2=2,ROUND(((S4*U4)/100),2),0) -> 0 | Y4: =IF($C$2=4,ROUND((((S4*U4)/100)/2),2),0) -> 0 | Z4: 0 | AA4: =IF($C2=3,0,(S4*Z4)/100) -> 0 | AB4: =V4+W4+X4+Y4+AA4 -> 0 | AC4: =IF($V2=1,S4+AB4,S4) -> 1245.45 | AD4: 120 | AE4: =IF($P$2=1,(S4/$S$6)*$E$17,AD4/$AD$6*$E$17) -> 0 | AG4: =IF($P$2=1,(S4/$S$6)*$E$19,AD4/$AD$6*$E$19) -> 0 | AH4: =IF($P$2=1,(S4/$S$6)*$E$20,AD4/$AD$6*$E$20) -> 0 | AI4: =S4*$M$2 -> 105863.25 | AJ4: =IF($C$2=3,0,AG4+AH4) -> 0 | AK4: =IF($C$2=3,AE4+AG4+AH4,0) -> 0 | AL4: 3 | AM4: =F4/AL4 -> 3.3333333 | AN4: =ROUND(AI4/AM4,3) -> 31758.975 | AO4: =AJ4/AM4 -> 0 | AP4: =AK4/AM4 -> 0 | AQ4: NOS | AR4: =ROUND(AN4+AO4+AP4,3) -> 31758.975 | AS4: INS WH-1 | AT4: NOS | AU4: 0 | AV4: 31758.975 | AW4: =AM4 -> 3.3333333 | AX4: =AR4 -> 31758.975 | AY4: =AU4+AW4 -> 3.3333333 | AZ4: =ROUND(((AU4*AV4)+(AW4*AX4))/(AU4+AW4),5) -> 31758.975 | BB4: Receipt Qty & Unit cost | BC4: LOT | BD4: RM | BE4: RMS | BL4: RM WH-49 | BM4: 9759.23775 | BN4: 151.664 | BO4: =ROUND((((AW4*AZ4)+(BN4*BM4))/(AW4+BN4)),5) -> 15447.675 | BP4: =ROUND(BN4+AW4,3) -> 36.667 | BQ4: 123562
A5: 1 | B5: GWL_Dissimilar_02 | C5: GWL_Dissimilar_02 | D5: NOS | E5: NOS | F5: 20 | G5: 100 | H5: =F5*G5 -> 2000 | I5: 4 | J5: 9 | K5: 6 | L5: =H5 -> 2000 | M5: =ROUND(L5*I5%,2) -> 80 | N5: =H5-M5 -> 1920 | O5: =ROUND(N5*J5%,2) -> 172.8 | P5: =ROUND(N5-O5,2) -> 1747.2 | Q5: =ROUND(P5*K5%,2) -> 104.83 | R5: =M5+O5+Q5 -> 357.63 | S5: =(H5-R5) -> 1642.37 | T5: 88363222 | U5: 18 | V5: =IF(OR(PoToMRVWoQDUomImp!$C$2=1,PoToMRVWoQDUomImp!$C$2=4),ROUND((((S5*U5)/100)/2),2),0) -> 0 | W5: =IF(PoToMRVWoQDUomImp!$C$2=1,ROUND((((S5*U5)/100)/2),2),0) -> 0 | X5: =IF(PoToMRVWoQDUomImp!$C$2=2,ROUND(((S5*U5)/100),2),0) -> 0 | Y5: =IF(PoToMRVWoQDUomImp!$C$2=4,ROUND((((S5*U5)/100)/2),2),0) -> 0 | Z5: 0 | AA5: =IF(PoToMRVWoQDUomImp!$C3=3,0,(S5*Z5)/100) -> 0 | AB5: =V5+W5+X5+Y5+AA5 -> 0 | AC5: =IF(PoToMRVWoQDUomImp!$V3=1,S5+AB5,S5) -> 1642.37 | AD5: 120 | AE5: =IF(PoToMRVWoQDUomImp!$P$2=1,(S5/PoToMRVWoQDUomImp!$S$6)*PoToMRVWoQDUomImp!$E$17,AD5/PoToMRVWoQDUomImp!$AD$6*PoToMRVWoQDUomImp!$E$17) -> 0 | AG5: =IF(PoToMRVWoQDUomImp!$P$2=1,(S5/PoToMRVWoQDUomImp!$S$6)*PoToMRVWoQDUomImp!$E$19,AD5/PoToMRVWoQDUomImp!$AD$6*PoToMRVWoQDUomImp!$E$19) -> 0 | AH5: =IF(PoToMRVWoQDUomImp!$P$2=1,(S5/PoToMRVWoQDUomImp!$S$6)*PoToMRVWoQDUomImp!$E$20,AD5/PoToMRVWoQDUomImp!$AD$6*PoToMRVWoQDUomImp!$E$20) -> 0 | AI5: =S5*PoToMRVWoQDUomImp!$M$2 -> 139601.45 | AJ5: =IF(PoToMRVWoQDUomImp!$C$2=3,0,AG5+AH5) -> 0 | AK5: =IF(PoToMRVWoQDUomImp!$C$2=3,AE5+AG5+AH5,0) -> 0 | AL5: 3 | AM5: =F5/AL5 -> 6.6666667 | AN5: =ROUND(AI5/AM5,5) -> 20940.217 | AO5: =AJ5/AM5 -> 0 | AP5: =AK5/AM5 -> 0 | AQ5: NOS | AR5: =ROUND(AN5+AO5+AP5,5) -> 20940.217 | AS5: INS WH-1 | AT5: NOS | AU5: 0 | AV5: 20940.6 | AW5: =AM5 -> 6.6666667 | AX5: =AR5 -> 20940.217 | AY5: =AU5+AW5 -> 6.6666667 | AZ5: =ROUND(((AU5*AV5)+(AW5*AX5))/(AU5+AW5),2) -> 20940.22 | BB5: Receipt Qty & Unit cost | BC5: LOT | BD5: RM | BE5: RMS | BL5: RM WH-49 | BM5: 916.08073 | BN5: 206.009 | BO5: =ROUND((((AW5*AZ5)+(BN5*BM5))/(AW5+BN5)),5) -> 4469.5967 | BP5: =ROUND(BN5+AW5,3) -> 32.667 | BQ5: 123562
D6: Total | H6: =SUM(H4:H4) -> 1500 | R6: =SUM(R4:R4) -> 254.55 | S6: =SUM(S4:S4) -> 1245.45 | V6: =SUM(V4:V4) -> 0 | W6: =SUM(W4:W4) -> 0 | X6: =SUM(X4:X4) -> 0 | AB6: =SUM(AB4:AB4) -> 0 | AC6: =SUM(AC4:AC4) -> 1245.45 | AD6: =SUM(AD4:AD4) -> 120 | AE6: =SUM(AE4:AE4) -> 0 | AG6: =SUM(AG4:AG4) -> 0 | AH6: =IF($P$2=1,(S6/$S$6)*$E$20,AD6/$AD$6*$E$20) -> 0 | AI6: =SUM(AI4:AI4) -> 105863.25 | AJ6: =SUM(AJ4:AJ4) -> 0 | AK6: =SUM(AK4:AK4) -> 0
G8: Gross Purchase | I8: =H6 -> 1500 | M8: Conv factor | BH8: ACPT | BI8: Acpt Qty. * Insp. Unit Cost + OLD. Qty in GRN WH * OLD Unitcost in GRN WH / Acpt. Qty + OLD. Qty in GRN WH
G9: Disc amt | I9: =R6 -> 254.55 | M9: 1 | N9: NOS | O9: 2 | P9: KGS | BH9: REJ | BI9: Rej Qty. * Insp. Unit Cost + OLD. Qty in REJ WH * OLD Unitcost in REJ WH / Acpt. Qty + OLD. Qty in REJ WH
G10: Net Purchase | I10: =S6 -> 1245.45 | M10: 1 | N10: NOS | O10: 2.5 | P10: MTR
G11: Tax Amt | I11: =AB6 -> 0 | M11: 1 | N11: KGS | O11: 0.001 | P11: MT
G12: Gross Amont | I12: =I10+I11 -> 1245.45
BM13: old | BN13: new
BK14: acpt Qty | BL14: 12.5 | BM14: =BL16*BL17 -> 18277.77 | BN14: =BL14*BL15 -> 6092.59
BK15: Inspection Unit Cost | BL15: 487.4072 | BM15: =BL14+BL16 -> 50
BK16: old Qty | BL16: 37.5
BK17: old UnitCost | BL17: 487.4072
BM18: =BM14+BN14 -> 24370.36 | BN18: =BM18/BM15 -> 487.4072

Sheet PoToGrnUdSWoIpUom
A1: Purchase Order & GRN
A2: GST Purchase | C2: 1 | D2: (1 - Local Purchase,2 Interstate Purchase, 3 Import Purchase,4-UTGST) | I2: Cur. | J2: INR | L2: Ex. Rate | M2: 1 | O2: Apportion Basis | P2: 1 | Q2: 1 - Value Based, 2 Weight/Volume Based | V2: 1 | W2: (1 - Registered, 2 - Unregistered)
A3: S. No. | B3: Item | C3: Item Desc. | D3: Stk. UOM | E3: Pur. UOM | F3: Order Qty (Pur UOM) | G3: Unit Cost | H3: Gross Amt. | I3: TD% | J3: SD% | K3: CD% | L3: TD Asbl. Val. | M3: TD Amt. | N3: SD Asbl. Val. | O3: SD Amt. | P3: CD Asbl. Val. | Q3: CD Amt. | R3: Disc. Amt. | S3: Pur. Val. | T3: HSN | U3: Tax Rate | V3: CGST | W3: SGST | X3: IGST | Y3: UTGST | Z3: Cess% | AA3: CESS | AB3: Tax amt | AC3: Net Amt | AD3: Weight/Vol | AE3: Customs Duty | AF3: IGST (Import) | AG3: Packing & Forwarding | AH3: Freight | AI3: Pur Amt (BC) | AJ3: Chargeable Cost | AK3: Landed Cost | AL3: Conv. Factor | AM3: Eqv. Stock Qty | AN3: Pur. Unit Cost (chr) | AO3: Chrg. Unit Cost | AP3: Landed Cost Unit Cost | AQ3: Stock UOM | AR3: Unit Cost (Stock UOM) | AS3: Ins. WH | AT3: Stock UOM | AU3: Qty Before Post | AV3: Unit Cost Before Post | AW3: Receipt Qty | AX3: Receipt Unit cost | AY3: Qty After Post | AZ3: Unit Cost After Post | BA3: Result (Ok/Not OK) | BB3: Stock Transaction | BC3: Lot / Serial Type | BD3: LOT_NUMBER | BE3: SERIAL_NUMBER | BF3: Lot / Serial Trans | BG3: Locator Trans | BH3: Batch Stocks | BI3: Stock Ledger | BJ3: Stock As on Date (Qty) | BK3: Stock As on Date (Qty & vALUE) | BL3: Sou.WH | BM3: Unitcost Before Post For Source Warehouse | BN3: Qty Before Post For Source WareHouse | BO3: Unit Cost After Post | BP3: Qty After Post forSource Warehouse | BQ3: HSN
A4: 1 | B4: GWL_Item_Similar_04 | C4: GWL_Item_Similar_04_Desc | D4: NOS | E4: NOS | F4: 5 | G4: 150 | H4: =F4*G4 -> 750 | I4: 5 | J4: 8 | K4: 5 | L4: =H4 -> 750 | M4: =ROUND(L4*I4%,2) -> 37.5 | N4: =H4-M4 -> 712.5 | O4: =ROUND(N4*J4%,2) -> 57 | P4: =ROUND(N4-O4,2) -> 655.5 | Q4: =ROUND(P4*K4%,2) -> 32.78 | R4: =M4+O4+Q4 -> 127.28 | S4: =(H4-R4) -> 622.72 | T4: 85080200 | U4: 18 | V4: =IF(OR($C$2=1,$C$2=4),ROUND((((S4*U4)/100)/2),2),0) -> 56.04 | W4: =IF($C$2=1,ROUND((((S4*U4)/100)/2),2),0) -> 56.04 | X4: =IF($C$2=2,ROUND(((S4*U4)/100),2),0) -> 0 | Y4: =IF($C$2=4,ROUND((((S4*U4)/100)/2),2),0) -> 0 | Z4: 4 | AA4: =IF($C2=3,0,(S4*Z4)/100) -> 24.9088 | AB4: =V4+W4+X4+Y4+AA4 -> 136.9888 | AC4: =IF($V2=1,S4+AB4,S4) -> 759.7088 | AD4: 120 | AE4: =IF($P$2=1,(S4/$S$7)*$E$18,AD4/$AD$7*$E$18) -> 0 | AG4: =IF($P$2=1,(S4/$S$7)*$E$20,AD4/$AD$7*$E$20) -> 0 | AH4: =IF($P$2=1,(S4/$S$7)*$E$20,AD4/$AD$7*$E$20) -> 0 | AI4: =S4*$M$2 -> 622.72 | AJ4: =IF($C$2=3,0,AG4+AH4) -> 0 | AK4: =IF($C$2=3,AE4+AG4+AH4,0) -> 0 | AL4: 1 | AM4: =F4/AL4 -> 5 | AN4: =AI4/AM4 -> 124.544 | AO4: =AJ4/AM4 -> 0 | AP4: =AK4/AM4 -> 0 | AQ4: NOS | AR4: =ROUND(AN4+AO4+AP4,5) -> 124.544 | AS4: INS KD | AT4: NOS | AU4: 14090 | AV4: 121.22038 | AW4: =AM4 -> 5 | AX4: =AR4 -> 124.544 | AY4: =AU4+AW4 -> 14095 | AZ4: =ROUND(((AU4*AV4)+(AW4*AX4))/(AU4+AW4),5) -> 121.22156 | BB4: Receipt Qty & Unit cost | BC4: LOT | BD4: RM | BE4: RMS | BL4: RM KD | BM4: 146.85967 | BN4: 691 | BO4: =ROUND((((AW4*AZ4)+(BN4*BM4))/(AW4+BN4)),5) -> 146.67549 | BP4: =BN4+AW4 -> 696 | BQ4: 123562
A5: 1 | B5: GWL_Item_Similar_02 | C5: GWL_Item_Similar_02 | D5: NOS | E5: NOS | F5: 4 | G5: 100 | H5: =F5*G5 -> 400 | I5: 4 | J5: 9 | K5: 6 | L5: =H5 -> 400 | M5: =ROUND(L5*I5%,2) -> 16 | N5: =H5-M5 -> 384 | O5: =ROUND(N5*J5%,2) -> 34.56 | P5: =ROUND(N5-O5,2) -> 349.44 | Q5: =ROUND(P5*K5%,2) -> 20.97 | R5: =M5+O5+Q5 -> 71.53 | S5: =(H5-R5) -> 328.47 | T5: 88363222 | U5: 18 | V5: =IF(OR(PoToMRVWOIp!$C$2=1,PoToMRVWOIp!$C$2=4),ROUND((((S5*U5)/100)/2),2),0) -> 0 | W5: =IF(PoToMRVWOIp!$C$2=1,ROUND((((S5*U5)/100)/2),2),0) -> 0 | X5: =IF(PoToMRVWOIp!$C$2=2,ROUND(((S5*U5)/100),2),0) -> 59.12 | Y5: =IF(PoToMRVWOIp!$C$2=4,ROUND((((S5*U5)/100)/2),2),0) -> 0 | Z5: 0 | AA5: =IF(PoToMRVWOIp!$C3=3,0,(S5*Z5)/100) -> 0 | AB5: =V5+W5+X5+Y5+AA5 -> 59.12 | AC5: =IF(PoToMRVWOIp!$V3=1,S5+AB5,S5) -> 328.47 | AD5: 120 | AE5: =IF(PoToMRVWOIp!$P$2=1,(S5/PoToMRVWOIp!$S$7)*PoToMRVWOIp!$E$18,AD5/PoToMRVWOIp!$AD$7*PoToMRVWOIp!$E$18) -> 0 | AG5: =IF(PoToMRVWOIp!$P$2=1,(S5/PoToMRVWOIp!$S$7)*PoToMRVWOIp!$E$20,AD5/PoToMRVWOIp!$AD$7*PoToMRVWOIp!$E$20) -> 0 | AH5: =IF(PoToMRVWOIp!$P$2=1,(S5/PoToMRVWOIp!$S$7)*PoToMRVWOIp!$E$21,AD5/PoToMRVWOIp!$AD$7*PoToMRVWOIp!$E$21) -> 0 | AI5: =S5*PoToMRVWOIp!$M$2 -> 328.47 | AJ5: =IF(PoToMRVWOIp!$C$2=3,0,AG5+AH5) -> 0 | AK5: =IF(PoToMRVWOIp!$C$2=3,AE5+AG5+AH5,0) -> 0 | AL5: 1 | AM5: =F5/AL5 -> 4 | AN5: =ROUND(AI5/AM5,5) -> 82.1175 | AO5: =AJ5/AM5 -> 0 | AP5: =AK5/AM5 -> 0 | AQ5: NOS | AR5: =ROUND(AN5+AO5+AP5,5) -> 82.1175 | AS5: INS WH-1 | AT5: NOS | AU5: 32 | AV5: 82.12 | AW5: =AM5 -> 4 | AX5: =AR5 -> 82.1175 | AY5: =AU5+AW5 -> 36 | AZ5: =ROUND(((AU5*AV5)+(AW5*AX5))/(AU5+AW5),3) -> 82.12 | BB5: Receipt Qty & Unit cost | BC5: LOT | BD5: RM | BE5: RMS | BL5: RM WH-49 | BM5: 86.37714 | BN5: 21 | BO5: =ROUND((((AW5*AZ5)+(BN5*BM5))/(AW5+BN5)),5) -> 85.696 | BP5: =ROUND(BN5+AW5,3) -> 25 | BQ5: 123562
A6: 1 | B6: GWL_Item_Similar_05 | C6: GWL_Item_Similar_05_Desc | D6: NOS | E6: NOS | F6: 10 | G6: 50 | H6: =F6*G6 -> 500 | I6: 3 | J6: 7 | K6: 4 | L6: =H6 -> 500 | M6: =ROUND(L6*I6%,2) -> 15 | N6: =H6-M6 -> 485 | O6: =ROUND(N6*J6%,2) -> 33.95 | P6: =ROUND(N6-O6,2) -> 451.05 | Q6: =ROUND(P6*K6%,2) -> 18.04 | R6: =M6+O6+Q6 -> 66.99 | S6: =(H6-R6) -> 433.01 | T6: 88363222 | U6: 18 | V6: =IF(OR(PoToMRVWOIp!$C$2=1,PoToMRVWOIp!$C$2=4),ROUND((((S6*U6)/100)/2),2),0) -> 0 | W6: =IF(PoToMRVWOIp!$C$2=1,ROUND((((S6*U6)/100)/2),2),0) -> 0 | X6: =IF(PoToMRVWOIp!$C$2=2,ROUND(((S6*U6)/100),2),0) -> 77.94 | Y6: =IF(PoToMRVWOIp!$C$2=4,ROUND((((S6*U6)/100)/2),2),0) -> 0 | Z6: 0 | AA6: =IF(PoToMRVWOIp!$C4=3,0,(S6*Z6)/100) -> 0 | AB6: =V6+W6+X6+Y6+AA6 -> 77.94 | AC6: =IF(PoToMRVWOIp!$V4=1,S6+AB6,S6) -> 433.01 | AD6: 120 | AE6: =IF(PoToMRVWOIp!$P$2=1,(S6/PoToMRVWOIp!$S$7)*PoToMRVWOIp!$E$18,AD6/PoToMRVWOIp!$AD$7*PoToMRVWOIp!$E$18) -> 0 | AG6: =IF(PoToMRVWOIp!$P$2=1,(S6/PoToMRVWOIp!$S$7)*PoToMRVWOIp!$E$20,AD6/PoToMRVWOIp!$AD$7*PoToMRVWOIp!$E$20) -> 0 | AH6: =IF(PoToMRVWOIp!$P$2=1,(S6/PoToMRVWOIp!$S$7)*PoToMRVWOIp!$E$21,AD6/PoToMRVWOIp!$AD$7*PoToMRVWOIp!$E$21) -> 0 | AI6: =S6*PoToMRVWOIp!$M$2 -> 433.01 | AJ6: =IF(PoToMRVWOIp!$C$2=3,0,AG6+AH6) -> 0 | AK6: =IF(PoToMRVWOIp!$C$2=3,AE6+AG6+AH6,0) -> 0 | AL6: 1 | AM6: =F6/AL6 -> 10 | AN6: =ROUND(AI6/AM6,5) -> 43.301 | AO6: =AJ6/AM6 -> 0 | AP6: =AK6/AM6 -> 0 | AQ6: NOS | AR6: =ROUND(AN6+AO6+AP6,5) -> 43.301 | AS6: INS WH-1 | AT6: NOS | AU6: 120 | AV6: 43.3 | AW6: =AM6 -> 10 | AX6: =AR6 -> 43.301 | AY6: =AU6+AW6 -> 130 | AZ6: =ROUND(((AU6*AV6)+(AW6*AX6))/(AU6+AW6),3) -> 43.3 | BB6: Receipt Qty & Unit cost | BC6: LOT | BD6: RM | BE6: RMS | BL6: RM WH-49-4 | BM6: 0 | BN6: 0 | BO6: =ROUND((((AW6*AZ6)+(BN6*BM6))/(AW6+BN6)),5) -> 43.3 | BP6: =ROUND(BN6+AW6,3) -> 10 | BQ6: 123562
D7: Total | H7: =SUM(H4:H6) -> 1650 | R7: =SUM(R4:R4) -> 127.28 | S7: =SUM(S4:S4) -> 622.72 | V7: =SUM(V4:V4) -> 56.04 | W7: =SUM(W4:W4) -> 56.04 | X7: =SUM(X4:X4) -> 0 | AB7: =SUM(AB4:AB4) -> 136.9888 | AC7: =SUM(AC4:AC4) -> 759.7088 | AD7: =SUM(AD4:AD4) -> 120 | AE7: =SUM(AE4:AE4) -> 0 | AG7: =SUM(AG4:AG4) -> 0 | AH7: =SUM(AH4:AH4) -> 0 | AI7: =SUM(AI4:AI4) -> 622.72 | AJ7: =SUM(AJ4:AJ4) -> 0 | AK7: =SUM(AK4:AK4) -> 0

Sheet PoToMRVWOIpSer
A1: Purchase Order & GRN
A2: GST Purchase | C2: 2 | D2: (1 - Local Purchase,2 Interstate Purchase, 3 Import Purchase,4-UTGST) | I2: Cur. | J2: INR | L2: Ex. Rate | M2: 1 | O2: Apportion Basis | P2: 2 | Q2: 1 - Value Based, 2 Weight/Volume Based | V2: 1 | W2: (1 - Registered, 2 - Unregistered)
A3: No. | B3: Item | C3: Item Desc | D3: Stk. UOM | E3: Pur. UOM | F3: Qty | G3: Unit Cost | H3: Gross Amt. | I3: TD% | J3: CD% | K3: SD% | L3: TD Asbl. Val. | M3: TD Amt. | N3: CD Asbl. Val. | O3: CD Amt. | P3: VD Asbl. Val. | Q3: SD Amt. | R3: Disc. Amt. | S3: Pur. Value | T3: HSN | U3: Tax% | V3: CGST | W3: SGST | X3: IGST | Y3: UTGST | Z3: Cess% | AA3: CESS | AB3: Tax amt | AC3: Net Amt | AD3: Weight/Vol | AE3: Customs Duty | AF3: IGST (Import) | AG3: Packing & Forwarding | AH3: Freight | AI3: Pur Amt (BC) | AJ3: Chargeable Cost | AK3: Landed Cost | AL3: Conv. Factor | AM3: Eqv. Stock Qty | AN3: Pur. Unit Cost (chr) | AO3: Chrg. Unit Cost | AP3: Landed Cost Unit Cost | AQ3: Stock UOM | AR3: Unit cost (Stk. UOM) | AS3: Ins. WH | AT3: Stock UOM | AU3: Qty Before Post | AV3: Unit Cost Before Post | AW3: Receipt Qty | AX3: Receipt Unit cost | AY3: Qty After Post | AZ3: Unit Cost After Post | BA3: Result (Ok/Not OK) | BB3: Stock Transaction | BC3: Lot / Serial Type | BD3: LOT_NUMBER | BE3: SERIAL_NUMBER | BF3: Lot / Serial Trans | BG3: Locator Trans | BH3: Batch Stocks | BI3: Stock Ledger | BJ3: Stock As on Date (Qty) | BK3: Stock As on Date (Qty & vALUE) | BL3: Sou.WH | BM3: Unitcost Before Post For Source Warehouse | BN3: Qty Before Post For Source WareHouse | BO3: Unit Cost After Post | BP3: Qty After Post forSource Warehouse | BQ3: HSN
A4: 1 | B4: GWL_ITem_service_03 | C4: GWL_ITem_service_03 | D4: NOS | E4: NOS | F4: 5 | G4: 150 | H4: =F4*G4 -> 750 | I4: 5 | J4: 8 | K4: 5 | L4: =H4 -> 750 | M4: =ROUND(L4*I4%,2) -> 37.5 | N4: =H4-M4 -> 712.5 | O4: =ROUND(N4*J4%,2) -> 57 | P4: =ROUND(N4-O4,2) -> 655.5 | Q4: =ROUND(P4*K4%,2) -> 32.78 | R4: =M4+O4+Q4 -> 127.28 | S4: =(H4-R4) -> 622.72 | T4: 88363222 | U4: 18 | V4: =IF(OR($C$2=1,$C$2=4),ROUND((((S4*U4)/100)/2),2),0) -> 0 | W4: =IF($C$2=1,ROUND((((S4*U4)/100)/2),2),0) -> 0 | X4: =IF($C$2=2,ROUND(((S4*U4)/100),2),0) -> 112.09 | Y4: =IF($C$2=4,ROUND((((S4*U4)/100)/2),2),0) -> 0 | Z4: 0 | AA4: =IF($C2=3,0,(S4*Z4)/100) -> 0 | AB4: =V4+W4+X4+Y4+AA4 -> 112.09 | AC4: =IF($V2=1,S4+AB4,S4) -> 734.81 | AD4: 120 | AE4: =IF($P$2=1,(S4/$S$7)*$E$18,AD4/$AD$7*$E$18) -> 0 | AG4: =IF($P$2=1,(S4/$S$7)*$E$20,AD4/$AD$7*$E$20) -> 0 | AH4: =IF($P$2=1,(S4/$S$7)*$E$21,AD4/$AD$7*$E$21) -> 0 | AI4: =S4*$M$2 -> 622.72 | AJ4: =IF($C$2=3,0,AG4+AH4) -> 0 | AK4: =IF($C$2=3,AE4+AG4+AH4,0) -> 0 | AL4: 1 | AM4: =F4/AL4 -> 5 | AN4: =ROUND(AI4/AM4,5) -> 124.544 | AO4: =AJ4/AM4 -> 0 | AP4: =AK4/AM4 -> 0 | AQ4: NOS | AR4: =ROUND(AN4+AO4+AP4,5) -> 124.544 | AS4: INS WH-1 | AT4: NOS | AU4: 110 | AV4: 124.545 | AW4: =AM4 -> 5 | AX4: =AR4 -> 124.544 | AY4: =AU4+AW4 -> 115 | AZ4: =ROUND(((AU4*AV4)+(AW4*AX4))/(AU4+AW4),3) -> 124.545 | BB4: Receipt Qty & Unit cost | BC4: LOT | BD4: RM | BE4: RMS | BL4: RM WH-49 | BM4: 124.545 | BN4: 5 | BO4: =ROUND((((AW4*AZ4)+(BN4*BM4))/(AW4+BN4)),5) -> 124.545 | BP4: =ROUND(BN4+AW4,3) -> 10 | BQ4: 123562
A5: 1 | B5: GWL_Item_service_04 | C5: GWL_Item_service_04 | D5: NOS | E5: NOS | F5: 4 | G5: 100 | H5: =F5*G5 -> 400 | I5: 4 | J5: 9 | K5: 6 | L5: =H5 -> 400 | M5: =ROUND(L5*I5%,2) -> 16 | N5: =H5-M5 -> 384 | O5: =ROUND(N5*J5%,2) -> 34.56 | P5: =ROUND(N5-O5,2) -> 349.44 | Q5: =ROUND(P5*K5%,2) -> 20.97 | R5: =M5+O5+Q5 -> 71.53 | S5: =(H5-R5) -> 328.47 | T5: 88363222 | U5: 18 | V5: =IF(OR(PoToMRVWOIpSer!$C$2=1,PoToMRVWOIpSer!$C$2=4),ROUND((((S5*U5)/100)/2),2),0) -> 0 | W5: =IF(PoToMRVWOIpSer!$C$2=1,ROUND((((S5*U5)/100)/2),2),0) -> 0 | X5: =IF(PoToMRVWOIpSer!$C$2=2,ROUND(((S5*U5)/100),2),0) -> 59.12 | Y5: =IF(PoToMRVWOIpSer!$C$2=4,ROUND((((S5*U5)/100)/2),2),0) -> 0 | Z5: 0 | AA5: =IF(PoToMRVWOIpSer!$C3=3,0,(S5*Z5)/100) -> 0 | AB5: =V5+W5+X5+Y5+AA5 -> 59.12 | AC5: =IF(PoToMRVWOIpSer!$V3=1,S5+AB5,S5) -> 328.47 | AD5: 120 | AE5: =IF(PoToMRVWOIpSer!$P$2=1,(S5/PoToMRVWOIpSer!$S$7)*PoToMRVWOIpSer!$E$18,AD5/PoToMRVWOIpSer!$AD$7*PoToMRVWOIpSer!$E$18) -> 0 | AG5: =IF(PoToMRVWOIpSer!$P$2=1,(S5/PoToMRVWOIpSer!$S$7)*PoToMRVWOIpSer!$E$20,AD5/PoToMRVWOIpSer!$AD$7*PoToMRVWOIpSer!$E$20) -> 0 | AH5: =IF(PoToMRVWOIpSer!$P$2=1,(S5/PoToMRVWOIpSer!$S$7)*PoToMRVWOIpSer!$E$21,AD5/PoToMRVWOIpSer!$AD$7*PoToMRVWOIpSer!$E$21) -> 0 | AI5: =S5*PoToMRVWOIpSer!$M$2 -> 328.47 | AJ5: =IF(PoToMRVWOIpSer!$C$2=3,0,AG5+AH5) -> 0 | AK5: =IF(PoToMRVWOIpSer!$C$2=3,AE5+AG5+AH5,0) -> 0 | AL5: 1 | AM5: =F5/AL5 -> 4 | AN5: =ROUND(AI5/AM5,5) -> 82.1175 | AO5: =AJ5/AM5 -> 0 | AP5: =AK5/AM5 -> 0 | AQ5: NOS | AR5: =ROUND(AN5+AO5+AP5,5) -> 82.1175 | AS5: INS WH-1 | AT5: NOS | AU5: 36 | AV5: 82.12 | AW5: =AM5 -> 4 | AX5: =AR5 -> 82.1175 | AY5: =AU5+AW5 -> 40 | AZ5: =ROUND(((AU5*AV5)+(AW5*AX5))/(AU5+AW5),3) -> 82.12 | BB5: Receipt Qty & Unit cost | BC5: LOT | BD5: RM | BE5: RMS | BL5: RM WH-49 | BM5: 83.94449 | BN5: 49 | BO5: =ROUND((((AW5*AZ5)+(BN5*BM5))/(AW5+BN5)),5) -> 83.80679 | BP5: =ROUND(BN5+AW5,3) -> 53 | BQ5: 123562
A6: 1 | B6: GWL_Item_service_05 | C6: GWL_Item_service_05 | D6: NOS | E6: NOS | F6: 10 | G6: 50 | H6: =F6*G6 -> 500 | I6: 3 | J6: 7 | K6: 4 | L6: =H6 -> 500 | M6: =ROUND(L6*I6%,2) -> 15 | N6: =H6-M6 -> 485 | O6: =ROUND(N6*J6%,2) -> 33.95 | P6: =ROUND(N6-O6,2) -> 451.05 | Q6: =ROUND(P6*K6%,2) -> 18.04 | R6: =M6+O6+Q6 -> 66.99 | S6: =(H6-R6) -> 433.01 | T6: 88363222 | U6: 18 | V6: =IF(OR(PoToMRVWOIpSer!$C$2=1,PoToMRVWOIpSer!$C$2=4),ROUND((((S6*U6)/100)/2),2),0) -> 0 | W6: =IF(PoToMRVWOIpSer!$C$2=1,ROUND((((S6*U6)/100)/2),2),0) -> 0 | X6: =IF(PoToMRVWOIpSer!$C$2=2,ROUND(((S6*U6)/100),2),0) -> 77.94 | Y6: =IF(PoToMRVWOIpSer!$C$2=4,ROUND((((S6*U6)/100)/2),2),0) -> 0 | Z6: 0 | AA6: =IF(PoToMRVWOIpSer!$C4=3,0,(S6*Z6)/100) -> 0 | AB6: =V6+W6+X6+Y6+AA6 -> 77.94 | AC6: =IF(PoToMRVWOIpSer!$V4=1,S6+AB6,S6) -> 433.01 | AD6: 120 | AE6: =IF(PoToMRVWOIpSer!$P$2=1,(S6/PoToMRVWOIpSer!$S$7)*PoToMRVWOIpSer!$E$18,AD6/PoToMRVWOIpSer!$AD$7*PoToMRVWOIpSer!$E$18) -> 0 | AG6: =IF(PoToMRVWOIpSer!$P$2=1,(S6/PoToMRVWOIpSer!$S$7)*PoToMRVWOIpSer!$E$20,AD6/PoToMRVWOIpSer!$AD$7*PoToMRVWOIpSer!$E$20) -> 0 | AH6: =IF(PoToMRVWOIpSer!$P$2=1,(S6/PoToMRVWOIpSer!$S$7)*PoToMRVWOIpSer!$E$21,AD6/PoToMRVWOIpSer!$AD$7*PoToMRVWOIpSer!$E$21) -> 0 | AI6: =S6*PoToMRVWOIpSer!$M$2 -> 433.01 | AJ6: =IF(PoToMRVWOIpSer!$C$2=3,0,AG6+AH6) -> 0 | AK6: =IF(PoToMRVWOIpSer!$C$2=3,AE6+AG6+AH6,0) -> 0 | AL6: 1 | AM6: =F6/AL6 -> 10 | AN6: =ROUND(AI6/AM6,5) -> 43.301 | AO6: =AJ6/AM6 -> 0 | AP6: =AK6/AM6 -> 0 | AQ6: NOS | AR6: =ROUND(AN6+AO6+AP6,5) -> 43.301 | AS6: INS WH-1 | AT6: NOS | AU6: 220 | AV6: 43.3 | AW6: =AM6 -> 10 | AX6: =AR6 -> 43.301 | AY6: =AU6+AW6 -> 230 | AZ6: =ROUND(((AU6*AV6)+(AW6*AX6))/(AU6+AW6),3) -> 43.3 | BB6: Receipt Qty & Unit cost | BC6: LOT | BD6: RM | BE6: RMS | BL6: RM WH-49 | BM6: 43.3 | BN6: 10 | BO6: =ROUND((((AW6*AZ6)+(BN6*BM6))/(AW6+BN6)),5) -> 43.3 | BP6: =ROUND(BN6+AW6,3) -> 20 | BQ6: 123562
D7: Total | H7: =SUM(H4:H4) -> 750 | R7: =SUM(R4:R4) -> 127.28 | S7: =SUM(S4:S4) -> 622.72 | V7: =SUM(V4:V4) -> 0 | W7: =SUM(W4:W4) -> 0 | X7: =SUM(X4:X4) -> 112.09 | AB7: =SUM(AB4:AB4) -> 112.09 | AC7: =SUM(AC4:AC4) -> 734.81 | AD7: =SUM(AD4:AD4) -> 120 | AE7: =SUM(AE4:AE4) -> 0 | AG7: =SUM(AG4:AG4) -> 0 | AH7: =IF($P$2=1,(S7/$S$7)*$E$21,AD7/$AD$7*$E$21) -> 0 | AI7: =SUM(AI4:AI4) -> 622.72 | AJ7: =SUM(AJ4:AJ4) -> 0 | AK7: =SUM(AK4:AK4) -> 0
G9: Gross Purchase | I9: =H7 -> 750 | M9: Conv factor | BH9: ACPT | BI9: Acpt Qty. * Insp. Unit Cost + OLD. Qty in GRN WH * OLD Unitcost in GRN WH / Acpt. Qty + OLD. Qty in GRN WH
