Workbook

Sheet SO Domestic PL (S&D)
A1: Scenario : Local Sales - Stock UOM and Sales UOM (Similar) DOC NO : SORD-2425-00089
A2: Sales Order
A3: GST Sales | D3: 2 | E3: (1 - Local Sales,2 Interstate Sales, 3 Export Sales) | J3: Cur. | K3: INR | M3: Ex. Rate | N3: 1
A4: S. No. | B4: Item | C4: Rev | D4: Item Desc. | E4: Stk. UOM | F4: Sale. UOM | G4: Order Qty (Sale UOM) | H4: Unit Price | I4: Gross Amt. | J4: TD% | K4: SD% | L4: CD% | M4: TD Asbl. Val. | N4: TD Amt. | O4: SD Asbl. Val. | P4: SD Amt. | Q4: CD Asbl. Val. | R4: CD Amt. | S4: Disc. Amt. | T4: Disc.Amt.Per.Qty | U4: Sales Val. | V4: HSN | W4: Tax Rate | X4: CGST | Y4: SGST | Z4: IGST | AA4: UTGST | AB4: CESS % | AC4: CESS AMT | AD4: Tax amt | AE4: Net Amt | AF4: Weight/Vol | AG4: Sales Amt (BC) | AH4: Conv. Factor | AI4: Eqv. Stock Qty | AJ4: Before Stock Qty | AK4: Before Stock Cost | AL4: After Stock Qty | AM4: Warehouse | AN4: Promotional Type | AO4: CESS PCT | AP4: CESS AMT | AQ4: PriceClass
A5: 1 | B5: HK-LOT-FIFO-LOT-10001(FG) | C5: 0 | D5: HK-LOT-FIFO-LOT-10001(FG) | E5: NOS | F5: NOS | G5: 44 | H5: 3321 | I5: =G5*H5 -> 187660 | J5: 10 | K5: 2 | L5: 4 | M5: =I5 -> 187660 | N5: =ROUND((M5*J5)/100,2) -> 1876.6 | O5: =I5-N5 -> 185783.4 | P5: =ROUND((O5*K5)/100,2) -> 3715.67 | Q5: =ROUND(O5-P5,2) -> 182067.73 | R5: =ROUND((Q5*L5)/100,2) -> 7282.71 | S5: =N5+P5+R5 -> 12874.98 | T5: =ROUND(S5/G5,2) -> 292.61 | U5: =(I5-S5) -> 174785.02 | V5: HSN1 | W5: 0.12 | X5: =IF(OR($D$3=1,$D$3=4),ROUND((U5*W5)/2,2),0) -> 0 | Y5: =IF($D$3=1,ROUND(((U5*W5)/2),2),0) -> 0 | Z5: =IF($D$3=2,ROUND(((U5*W5)),2),0) -> 20974.2 | AA5: =IF($D$3=4,ROUND(((U5*W5)/2),2),0) -> 0 | AB5: 0.06 | AC5: =IF($D$3=5,ROUND(((U5*AB5)/2),2),0) -> 0 | AD5: =X5+Y5+Z5+AA5+AC5 -> 20974.2 | AE5: =U5+AD5 -> 195759.22 | AF5: 120 | AG5: =U5*$N$3 -> 174785.02 | AH5: 1 | AI5: =G5/AH5 -> 44 | AJ5: 848 | AK5: 235.36857 | AL5: =ROUND(AJ5-G5,0) -> 804 | AM5: F100 | AN5: Sales Regular | AO5: 0 | AP5: =ROUND(((AO5*U5)/100),2) -> 0 | AQ5: DOMESTIC
A6: 2 | B6: HK-FG-PRICELIST-DISSIMILAR UOM-10001 | C6: 0 | D6: HK-FG-PRICELIST-DISSIMILAR UOM-10001 | E6: KGS | F6: NOS | G6: 53 | H6: 5472 | I6: =G6*H6 -> 81779 | J6: 10 | K6: 7 | L6: 9 | M6: =I6 -> 81779 | N6: =ROUND((M6*J6)/100,2) -> 817.79 | O6: =I6-N6 -> 80961.21 | P6: =ROUND((O6*K6)/100,2) -> 5667.28 | Q6: =ROUND(O6-P6,2) -> 75293.93 | R6: =ROUND((Q6*L6)/100,2) -> 6776.45 | S6: =N6+P6+R6 -> 13261.52 | T6: =ROUND(S6/G6,2) -> 250.22 | U6: =(I6-S6) -> 68517.48 | V6: HSN1 | W6: 0.12 | X6: =IF(OR($D$3=1,$D$3=4),ROUND((U6*W6)/2,2),0) -> 0 | Y6: =IF($D$3=1,ROUND(((U6*W6)/2),2),0) -> 0 | Z6: =IF($D$3=2,ROUND(((U6*W6)),2),0) -> 8222.1 | AA6: =IF($D$3=4,ROUND(((U6*W6)/2),2),0) -> 0 | AB6: 0.06 | AC6: =IF($D$3=5,ROUND(((U6*AB6)/2),2),0) -> 0 | AD6: =X6+Y6+Z6+AA6+AC6 -> 8222.1 | AE6: =U6+AD6 -> 76739.58 | AF6: 120 | AG6: =U6*$N$3 -> 68517.48 | AH6: 3 | AI6: =ROUND(G6/AH6,3) -> 17.667 | AJ6: 1375.002 | AK6: 123 | AL6: =ROUND((AJ6-AI6),3) -> 1357.335 | AM6: F100 | AN6: Sales Regular | AO6: 0 | AP6: =ROUND(((AO6*U6)/100),2) -> 0 | AQ6: DOMESTIC
Q7: DISC AMOUNT | Z7: NET AMOUNT | AE7: =SUM(AE5:AE6) -> 272498.8 | AF7: SALES AMOUNT | AG7: =AG5 -> 174785.02

Sheet SO Export PL (S&D)
A1: Scenario : Local Sales - Stock UOM and Sales UOM (Similar) DOC NO : SORD-2425-00089
A2: Sales Order
A3: GST Sales | D3: 3 | E3: (1 - Local Sales,2 Interstate Sales, 3 Export Sales) | J3: Cur. | K3: INR | M3: Ex. Rate | N3: 1
A4: S. No. | B4: Item | C4: Rev | D4: Item Desc. | E4: Stk. UOM | F4: Sale. UOM | G4: Order Qty (Sale UOM) | H4: Unit Price | I4: Gross Amt. | J4: TD% | K4: SD% | L4: CD% | M4: TD Asbl. Val. | N4: TD Amt. | O4: SD Asbl. Val. | P4: SD Amt. | Q4: CD Asbl. Val. | R4: CD Amt. | S4: Disc. Amt. | T4: Disc.Amt.Per.Qty | U4: Sales Val. | V4: HSN | W4: Tax Rate | X4: CGST | Y4: SGST | Z4: IGST | AA4: UTGST | AB4: CESS % | AC4: CESS AMT | AD4: Tax amt | AE4: Net Amt | AF4: Weight/Vol | AG4: Sales Amt (BC) | AH4: Conv. Factor | AI4: Eqv. Stock Qty | AJ4: Before Stock Qty | AK4: Before Stock Cost | AL4: After Stock Qty | AM4: Warehouse | AN4: Promotional Type | AO4: CESS PCT | AP4: CESS AMT | AQ4: PriceClass
A5: 1 | B5: HK-LOT-FIFO-LOT-10001(FG) | C5: 0 | D5: HK-LOT-FIFO-LOT-10001(FG) | E5: NOS | F5: NOS | G5: 5 | H5: 47 | I5: =G5*H5 -> 160 | J5: 10 | K5: 3 | L5: 4 | M5: =I5 -> 160 | N5: =ROUND((M5*J5)/100,2) -> 1.6 | O5: =I5-N5 -> 158.4 | P5: =ROUND((O5*K5)/100,2) -> 4.75 | Q5: =ROUND(O5-P5,2) -> 153.65 | R5: =ROUND((Q5*L5)/100,2) -> 6.15 | S5: =N5+P5+R5 -> 12.5 | T5: =ROUND(S5/G5,2) -> 2.5 | U5: =(I5-S5) -> 147.5 | V5: HSN1 | W5: 0.12 | X5: =IF(OR($D$3=1,$D$3=4),ROUND((U5*W5)/2,2),0) -> 0 | Y5: =IF($D$3=1,ROUND(((U5*W5)/2),2),0) -> 0 | Z5: =IF($D$3=2,ROUND(((U5*W5)),2),0) -> 0 | AA5: =IF($D$3=4,ROUND(((U5*W5)/2),2),0) -> 0 | AB5: 0.06 | AC5: =IF($D$3=5,ROUND(((U5*AB5)/2),2),0) -> 0 | AD5: =X5+Y5+Z5+AA5+AC5 -> 0 | AE5: =U5+AD5 -> 147.5 | AF5: 120 | AG5: =U5*$N$3 -> 147.5 | AH5: 1 | AI5: =G5/AH5 -> 5 | AJ5: 848 | AK5: 235.36857 | AL5: =ROUND(AJ5-G5,0) -> 843 | AM5: F100 | AN5: Sales Regular | AO5: 0 | AP5: =ROUND(((AO5*U5)/100),2) -> 0 | AQ5: DOMESTIC
A6: 2 | B6: HK-FG-PRICELIST-DISSIMILAR UOM-10001 | C6: 0 | D6: HK-FG-PRICELIST-DISSIMILAR UOM-10001 | E6: KGS | F6: NOS | G6: 89 | H6: 27 | I6: =G6*H6 -> 3738 | J6: 10 | K6: 7 | L6: 9 | M6: =I6 -> 3738 | N6: =ROUND((M6*J6)/100,2) -> 37.38 | O6: =I6-N6 -> 3700.62 | P6: =ROUND((O6*K6)/100,2) -> 259.04 | Q6: =ROUND(O6-P6,2) -> 3441.58 | R6: =ROUND((Q6*L6)/100,2) -> 309.74 | S6: =N6+P6+R6 -> 606.16 | T6: =ROUND(S6/G6,2) -> 6.81 | U6: =(I6-S6) -> 3131.84 | V6: HSN1 | W6: 0.05 | X6: =IF(OR($D$3=1,$D$3=4),ROUND((U6*W6)/2,2),0) -> 0 | Y6: =IF($D$3=1,ROUND(((U6*W6)/2),2),0) -> 0 | Z6: =IF($D$3=2,ROUND(((U6*W6)),2),0) -> 0 | AA6: =IF($D$3=4,ROUND(((U6*W6)/2),2),0) -> 0 | AB6: 0.06 | AC6: =IF($D$3=5,ROUND(((U6*AB6)/2),2),0) -> 0 | AD6: =X6+Y6+Z6+AA6+AC6 -> 0 | AE6: =U6+AD6 -> 3131.84 | AF6: 120 | AG6: =U6*$N$3 -> 3131.84 | AH6: 3 | AI6: =ROUND(G6/AH6,3) -> 29.667 | AJ6: 1375.002 | AK6: 123 | AL6: =ROUND((AJ6-AI6),3) -> 1345.335 | AM6: F100 | AN6: Sales Regular | AO6: 0 | AP6: =ROUND(((AO6*U6)/100),2) -> 0 | AQ6: DOMESTIC
Q7: DISC AMOUNT | Z7: NET AMOUNT | AE7: =SUM(AE5:AE6) -> 3279.34 | AF7: SALES AMOUNT | AG7: =AG5 -> 147.5

Sheet SO Domestic CP (S&D)
A1: Scenario : Local Sales - Stock UOM and Sales UOM (Similar) DOC NO : SORD-2425-00089
A2: Sales Order
A3: GST Sales | D3: 2 | E3: (1 - Local Sales,2 Interstate Sales, 3 Export Sales) | J3: Cur. | K3: INR | M3: Ex. Rate | N3: 1
A4: S. No. | B4: Item | C4: Rev | D4: Item Desc. | E4: Stk. UOM | F4: Sale. UOM | G4: Order Qty (Sale UOM) | H4: Unit Price | I4: Gross Amt. | J4: TD% | K4: SD% | L4: CD% | M4: TD Asbl. Val. | N4: TD Amt. | O4: SD Asbl. Val. | P4: SD Amt. | Q4: CD Asbl. Val. | R4: CD Amt. | S4: Disc. Amt. | T4: Disc.Amt.Per.Qty | U4: Sales Val. | V4: HSN | W4: Tax Rate | X4: CGST | Y4: SGST | Z4: IGST | AA4: UTGST | AB4: CESS % | AC4: CESS AMT | AD4: Tax amt | AE4: Net Amt | AF4: Weight/Vol | AG4: Sales Amt (BC) | AH4: Conv. Factor | AI4: Eqv. Stock Qty | AJ4: Before Stock Qty | AK4: Before Stock Cost | AL4: After Stock Qty | AM4: Warehouse | AN4: Promotional Type | AO4: CESS PCT | AP4: CESS AMT | AQ4: PriceClass
A5: 1 | B5: HK-FIFO-SER-BATCH-10001(FG) | C5: 0 | D5: HK-FIFO-SER-BATCH-10001(FG) | E5: NOS | F5: NOS | G5: 21 | H5: 4265 | I5: =G5*H5 -> 86982 | J5: 1 | K5: 2 | L5: 4 | M5: =I5 -> 86982 | N5: =ROUND((M5*J5)/100,2) -> 869.82 | O5: =I5-N5 -> 86112.18 | P5: =ROUND((O5*K5)/100,2) -> 1722.24 | Q5: =ROUND(O5-P5,2) -> 84389.94 | R5: =ROUND((Q5*L5)/100,2) -> 3375.6 | S5: =N5+P5+R5 -> 5967.66 | T5: =ROUND(S5/G5,2) -> 284.17 | U5: =(I5-S5) -> 81014.34 | V5: HSN1 | W5: 0.05 | X5: =IF(OR($D$3=1,$D$3=4),ROUND((U5*W5)/2,2),0) -> 0 | Y5: =IF($D$3=1,ROUND(((U5*W5)/2),2),0) -> 0 | Z5: =IF($D$3=2,ROUND(((U5*W5)),2),0) -> 4050.72 | AA5: =IF($D$3=4,ROUND(((U5*W5)/2),2),0) -> 0 | AB5: 0.06 | AC5: =IF($D$3=5,ROUND(((U5*AB5)/2),2),0) -> 0 | AD5: =X5+Y5+Z5+AA5+AC5 -> 4050.72 | AE5: =U5+AD5 -> 85065.06 | AF5: 120 | AG5: =U5*$N$3 -> 81014.34 | AH5: 1 | AI5: =G5/AH5 -> 21 | AJ5: 848 | AK5: 235.36857 | AL5: =ROUND(AJ5-G5,0) -> 827 | AM5: F100 | AN5: Sales Regular | AO5: 0 | AP5: =ROUND(((AO5*U5)/100),2) -> 0 | AQ5: DOMESTIC
A6: 2 | B6: HK-FG-CATALOG-DISSIMILAR-10001 | C6: 0 | D6: HK-FG-CATALOG-DISSIMILAR-10001 | E6: KGS | F6: NOS | G6: 35 | H6: 1543 | I6: =G6*H6 -> 53970 | J6: 1 | K6: 7 | L6: 9 | M6: =I6 -> 53970 | N6: =ROUND((M6*J6)/100,2) -> 539.7 | O6: =I6-N6 -> 53430.3 | P6: =ROUND((O6*K6)/100,2) -> 3740.12 | Q6: =ROUND(O6-P6,2) -> 49690.18 | R6: =ROUND((Q6*L6)/100,2) -> 4472.12 | S6: =N6+P6+R6 -> 8751.94 | T6: =ROUND(S6/G6,2) -> 250.06 | U6: =(I6-S6) -> 45218.06 | V6: HSN1 | W6: 0.12 | X6: =IF(OR($D$3=1,$D$3=4),ROUND((U6*W6)/2,2),0) -> 0 | Y6: =IF($D$3=1,ROUND(((U6*W6)/2),2),0) -> 0 | Z6: =IF($D$3=2,ROUND(((U6*W6)),2),0) -> 5426.17 | AA6: =IF($D$3=4,ROUND(((U6*W6)/2),2),0) -> 0 | AB6: 0.06 | AC6: =IF($D$3=5,ROUND(((U6*AB6)/2),2),0) -> 0 | AD6: =X6+Y6+Z6+AA6+AC6 -> 5426.17 | AE6: =U6+AD6 -> 50644.23 | AF6: 120 | AG6: =U6*$N$3 -> 45218.06 | AH6: 3 | AI6: =ROUND(G6/AH6,3) -> 11.667 | AJ6: 1375.002 | AK6: 123 | AL6: =ROUND((AJ6-AI6),3) -> 1363.335 | AM6: F100 | AN6: Sales Regular | AO6: 0 | AP6: =ROUND(((AO6*U6)/100),2) -> 0 | AQ6: DOMESTIC
Q7: DISC AMOUNT | Z7: NET AMOUNT | AE7: =SUM(AE5:AE6) -> 135709.29 | AF7: SALES AMOUNT | AG7: =AG5 -> 81014.34

Sheet SO Export CP (S&D)
A1: Scenario : Local Sales - Stock UOM and Sales UOM (Similar) DOC NO : SORD-2425-00089
A2: Sales Order
A3: GST Sales | D3: 3 | E3: (1 - Local Sales,2 Interstate Sales, 3 Export Sales) | J3: Cur. | K3: INR | M3: Ex. Rate | N3: 1
A4: S. No. | B4: Item | C4: Rev | D4: Item Desc. | E4: Stk. UOM | F4: Sale. UOM | G4: Order Qty (Sale UOM) | H4: Unit Price | I4: Gross Amt. | J4: TD% | K4: SD% | L4: CD% | M4: TD Asbl. Val. | N4: TD Amt. | O4: SD Asbl. Val. | P4: SD Amt. | Q4: CD Asbl. Val. | R4: CD Amt. | S4: Disc. Amt. | T4: Disc.Amt.Per.Qty | U4: Sales Val. | V4: HSN | W4: Tax Rate | X4: CGST | Y4: SGST | Z4: IGST | AA4: UTGST | AB4: CESS % | AC4: CESS AMT | AD4: Tax amt | AE4: Net Amt | AF4: Weight/Vol | AG4: Sales Amt (BC) | AH4: Conv. Factor | AI4: Eqv. Stock Qty | AJ4: Before Stock Qty | AK4: Before Stock Cost | AL4: After Stock Qty | AM4: Warehouse | AN4: Promotional Type | AO4: CESS PCT | AP4: CESS AMT | AQ4: PriceClass
A5: 1 | B5: HK-FIFO-SER-BATCH-10001(FG) | C5: 0 | D5: HK-FIFO-SER-BATCH-10001(FG) | E5: NOS | F5: NOS | G5: 11 | H5: 32 | I5: =G5*H5 -> 275 | J5: 1 | K5: 3 | L5: 4 | M5: =I5 -> 275 | N5: =ROUND((M5*J5)/100,2) -> 2.75 | O5: =I5-N5 -> 272.25 | P5: =ROUND((O5*K5)/100,2) -> 8.17 | Q5: =ROUND(O5-P5,2) -> 264.08 | R5: =ROUND((Q5*L5)/100,2) -> 10.56 | S5: =N5+P5+R5 -> 21.48 | T5: =ROUND(S5/G5,2) -> 1.95 | U5: =(I5-S5) -> 253.52 | V5: HSN1 | W5: 0.12 | X5: =IF(OR($D$3=1,$D$3=4),ROUND((U5*W5)/2,2),0) -> 0 | Y5: =IF($D$3=1,ROUND(((U5*W5)/2),2),0) -> 0 | Z5: =IF($D$3=2,ROUND(((U5*W5)),2),0) -> 0 | AA5: =IF($D$3=4,ROUND(((U5*W5)/2),2),0) -> 0 | AB5: 0.06 | AC5: =IF($D$3=5,ROUND(((U5*AB5)/2),2),0) -> 0 | AD5: =X5+Y5+Z5+AA5+AC5 -> 0 | AE5: =U5+AD5 -> 253.52 | AF5: 120 | AG5: =U5*$N$3 -> 253.52 | AH5: 1 | AI5: =G5/AH5 -> 11 | AJ5: 848 | AK5: 235.36857 | AL5: =ROUND(AJ5-G5,0) -> 837 | AM5: F100 | AN5: Sales Regular | AO5: 0 | AP5: =ROUND(((AO5*U5)/100),2) -> 0 | AQ5: DOMESTIC
A6: 2 | B6: HK-FG-CATALOG-DISSIMILAR-10001 | C6: 0 | D6: HK-FG-CATALOG-DISSIMILAR-10001 | E6: KGS | F6: NOS | G6: 15 | H6: 42 | I6: =G6*H6 -> 480 | J6: 1 | K6: 7 | L6: 9 | M6: =I6 -> 480 | N6: =ROUND((M6*J6)/100,2) -> 4.8 | O6: =I6-N6 -> 475.2 | P6: =ROUND((O6*K6)/100,2) -> 33.26 | Q6: =ROUND(O6-P6,2) -> 441.94 | R6: =ROUND((Q6*L6)/100,2) -> 39.77 | S6: =N6+P6+R6 -> 77.83 | T6: =ROUND(S6/G6,2) -> 5.19 | U6: =(I6-S6) -> 402.17 | V6: HSN1 | W6: 0.05 | X6: =IF(OR($D$3=1,$D$3=4),ROUND((U6*W6)/2,2),0) -> 0 | Y6: =IF($D$3=1,ROUND(((U6*W6)/2),2),0) -> 0 | Z6: =IF($D$3=2,ROUND(((U6*W6)),2),0) -> 0 | AA6: =IF($D$3=4,ROUND(((U6*W6)/2),2),0) -> 0 | AB6: 0.06 | AC6: =IF($D$3=5,ROUND(((U6*AB6)/2),2),0) -> 0 | AD6: =X6+Y6+Z6+AA6+AC6 -> 0 | AE6: =U6+AD6 -> 402.17 | AF6: 120 | AG6: =U6*$N$3 -> 402.17 | AH6: 3 | AI6: =ROUND(G6/AH6,3) -> 5 | AJ6: 1375.002 | AK6: 123 | AL6: =ROUND((AJ6-AI6),3) -> 1370.002 | AM6: F100 | AN6: Sales Regular | AO6: 0 | AP6: =ROUND(((AO6*U6)/100),2) -> 0 | AQ6: DOMESTIC
Q7: DISC AMOUNT | Z7: NET AMOUNT | AE7: =SUM(AE5:AE6) -> 655.69 | AF7: SALES AMOUNT | AG7: =AG5 -> 253.52

Sheet SO Export SP (S&D)
A1: Scenario : Local Sales - Stock UOM and Sales UOM (Similar) DOC NO : SORD-2425-00089
A2: Sales Order
A3: GST Sales | D3: 3 | E3: (1 - Local Sales,2 Interstate Sales, 3 Export Sales) | J3: Cur. | K3: INR | M3: Ex. Rate | N3: 1
A4: S. No. | B4: Item | C4: Rev | D4: Item Desc. | E4: Stk. UOM | F4: Sale. UOM | G4: Order Qty (Sale UOM) | H4: Unit Price | I4: Gross Amt. | J4: TD% | K4: SD% | L4: CD% | M4: TD Asbl. Val. | N4: TD Amt. | O4: SD Asbl. Val. | P4: SD Amt. | Q4: CD Asbl. Val. | R4: CD Amt. | S4: Disc. Amt. | T4: Disc.Amt.Per.Qty | U4: Sales Val. | V4: HSN | W4: Tax Rate | X4: CGST | Y4: SGST | Z4: IGST | AA4: UTGST | AB4: CESS % | AC4: CESS AMT | AD4: Tax amt | AE4: Net Amt | AF4: Weight/Vol | AG4: Sales Amt (BC) | AH4: Conv. Factor | AI4: Eqv. Stock Qty | AJ4: Before Stock Qty | AK4: Before Stock Cost | AL4: After Stock Qty | AM4: Warehouse | AN4: Promotional Type | AO4: CESS PCT | AP4: CESS AMT | AQ4: PriceClass
A5: 1 | B5: HK-SER-MAC-10001(FG) | C5: 0 | D5: HK-SER-MAC-10001(FG) | E5: NOS | F5: NOS | G5: 22 | H5: 25 | I5: =G5*H5 -> 792 | J5: 1 | K5: 3 | L5: 4 | M5: =I5 -> 792 | N5: =ROUND((M5*J5)/100,2) -> 7.92 | O5: =I5-N5 -> 784.08 | P5: =ROUND((O5*K5)/100,2) -> 23.52 | Q5: =ROUND(O5-P5,2) -> 760.56 | R5: =ROUND((Q5*L5)/100,2) -> 30.42 | S5: =N5+P5+R5 -> 61.86 | T5: =ROUND(S5/G5,2) -> 2.81 | U5: =(I5-S5) -> 730.14 | V5: HSN1 | W5: 0.12 | X5: =IF(OR($D$3=1,$D$3=4),ROUND((U5*W5)/2,2),0) -> 0 | Y5: =IF($D$3=1,ROUND(((U5*W5)/2),2),0) -> 0 | Z5: =IF($D$3=2,ROUND(((U5*W5)),2),0) -> 0 | AA5: =IF($D$3=4,ROUND(((U5*W5)/2),2),0) -> 0 | AB5: 0.06 | AC5: =IF($D$3=5,ROUND(((U5*AB5)/2),2),0) -> 0 | AD5: =X5+Y5+Z5+AA5+AC5 -> 0 | AE5: =U5+AD5 -> 730.14 | AF5: 120 | AG5: =U5*$N$3 -> 730.14 | AH5: 1 | AI5: =G5/AH5 -> 22 | AJ5: 848 | AK5: 235.36857 | AL5: =ROUND(AJ5-G5,0) -> 826 | AM5: F100 | AN5: Sales Regular | AO5: 0 | AP5: =ROUND(((AO5*U5)/100),2) -> 0 | AQ5: DOMESTIC
A6: 2 | B6: HK-FG-STD-PRICE-DISSIMILAR ITEM-10001 | C6: 0 | D6: HK-FG-STD-PRICE-DISSIMILAR ITEM-10001 | E6: KGS | F6: NOS | G6: 12 | H6: 32 | I6: =G6*H6 -> 204 | J6: 1 | K6: 7 | L6: 9 | M6: =I6 -> 204 | N6: =ROUND((M6*J6)/100,2) -> 2.04 | O6: =I6-N6 -> 201.96 | P6: =ROUND((O6*K6)/100,2) -> 14.14 | Q6: =ROUND(O6-P6,2) -> 187.82 | R6: =ROUND((Q6*L6)/100,2) -> 16.9 | S6: =N6+P6+R6 -> 33.08 | T6: =ROUND(S6/G6,2) -> 2.76 | U6: =(I6-S6) -> 170.92 | V6: HSN1 | W6: 0.05 | X6: =IF(OR($D$3=1,$D$3=4),ROUND((U6*W6)/2,2),0) -> 0 | Y6: =IF($D$3=1,ROUND(((U6*W6)/2),2),0) -> 0 | Z6: =IF($D$3=2,ROUND(((U6*W6)),2),0) -> 0 | AA6: =IF($D$3=4,ROUND(((U6*W6)/2),2),0) -> 0 | AB6: 0.06 | AC6: =IF($D$3=5,ROUND(((U6*AB6)/2),2),0) -> 0 | AD6: =X6+Y6+Z6+AA6+AC6 -> 0 | AE6: =U6+AD6 -> 170.92 | AF6: 120 | AG6: =U6*$N$3 -> 170.92 | AH6: 3 | AI6: =ROUND(G6/AH6,3) -> 4 | AJ6: 1375.002 | AK6: 123 | AL6: =ROUND((AJ6-AI6),3) -> 1371.002 | AM6: F100 | AN6: Sales Regular | AO6: 0 | AP6: =ROUND(((AO6*U6)/100),2) -> 0 | AQ6: DOMESTIC
Q7: DISC AMOUNT | Z7: NET AMOUNT | AE7: =SUM(AE5:AE6) -> 901.06 | AF7: SALES AMOUNT | AG7: =AG5 -> 730.14

Sheet SO Domestic SP (S&D)
A1: Scenario : Local Sales - Stock UOM and Sales UOM (Similar) DOC NO : SORD-2425-00089
A2: Sales Order
A3: GST Sales | D3: 2 | E3: (1 - Local Sales,2 Interstate Sales, 3 Export Sales) | J3: Cur. | K3: INR | M3: Ex. Rate | N3: 1
A4: S. No. | B4: Item | C4: Rev | D4: Item Desc. | E4: Stk. UOM | F4: Sale. UOM | G4: Order Qty (Sale UOM) | H4: Unit Price | I4: Gross Amt. | J4: TD% | K4: SD% | L4: CD% | M4: TD Asbl. Val. | N4: TD Amt. | O4: SD Asbl. Val. | P4: SD Amt. | Q4: CD Asbl. Val. | R4: CD Amt. | S4: Disc. Amt. | T4: Disc.Amt.Per.Qty | U4: Sales Val. | V4: HSN | W4: Tax Rate | X4: CGST | Y4: SGST | Z4: IGST | AA4: UTGST | AB4: CESS % | AC4: CESS AMT | AD4: Tax amt | AE4: Net Amt | AF4: Weight/Vol | AG4: Sales Amt (BC) | AH4: Conv. Factor | AI4: Eqv. Stock Qty | AJ4: Before Stock Qty | AK4: Before Stock Cost | AL4: After Stock Qty | AM4: Warehouse | AN4: Promotional Type | AO4: CESS PCT | AP4: CESS AMT | AQ4: PriceClass
A5: 1 | B5: HK-SER-MAC-10001(FG) | C5: 0 | D5: HK-SER-MAC-10001(FG) | E5: NOS | F5: NOS | G5: 12 | H5: 2135 | I5: =G5*H5 -> 37440 | J5: 1 | K5: 2 | L5: 4 | M5: =I5 -> 37440 | N5: =ROUND((M5*J5)/100,2) -> 374.4 | O5: =I5-N5 -> 37065.6 | P5: =ROUND((O5*K5)/100,2) -> 741.31 | Q5: =ROUND(O5-P5,2) -> 36324.29 | R5: =ROUND((Q5*L5)/100,2) -> 1452.97 | S5: =N5+P5+R5 -> 2568.68 | T5: =ROUND(S5/G5,2) -> 214.06 | U5: =(I5-S5) -> 34871.32 | V5: HSN1 | W5: 0.12 | X5: =IF(OR($D$3=1,$D$3=4),ROUND((U5*W5)/2,2),0) -> 0 | Y5: =IF($D$3=1,ROUND(((U5*W5)/2),2),0) -> 0 | Z5: =IF($D$3=2,ROUND(((U5*W5)),2),0) -> 4184.56 | AA5: =IF($D$3=4,ROUND(((U5*W5)/2),2),0) -> 0 | AB5: 0.06 | AC5: =IF($D$3=5,ROUND(((U5*AB5)/2),2),0) -> 0 | AD5: =X5+Y5+Z5+AA5+AC5 -> 4184.56 | AE5: =U5+AD5 -> 39055.88 | AF5: 120 | AG5: =U5*$N$3 -> 34871.32 | AH5: 1 | AI5: =G5/AH5 -> 12 | AJ5: 848 | AK5: 235.36857 | AL5: =ROUND(AJ5-G5,0) -> 836 | AM5: F100 | AN5: Sales Regular | AO5: 0 | AP5: =ROUND(((AO5*U5)/100),2) -> 0 | AQ5: DOMESTIC
A6: 2 | B6: HK-FG-STD-PRICE-DISSIMILAR ITEM-10001 | C6: 0 | D6: HK-FG-STD-PRICE-DISSIMILAR ITEM-10001 | E6: KGS | F6: NOS | G6: 14 | H6: 1542 | I6: =G6*H6 -> 44184 | J6: 1 | K6: 7 | L6: 9 | M6: =I6 -> 44184 | N6: =ROUND((M6*J6)/100,2) -> 441.84 | O6: =I6-N6 -> 43742.16 | P6: =ROUND((O6*K6)/100,2) -> 3061.95 | Q6: =ROUND(O6-P6,2) -> 40680.21 | R6: =ROUND((Q6*L6)/100,2) -> 3661.22 | S6: =N6+P6+R6 -> 7165.01 | T6: =ROUND(S6/G6,2) -> 511.79 | U6: =(I6-S6) -> 37018.99 | V6: HSN1 | W6: 0.05 | X6: =IF(OR($D$3=1,$D$3=4),ROUND((U6*W6)/2,2),0) -> 0 | Y6: =IF($D$3=1,ROUND(((U6*W6)/2),2),0) -> 0 | Z6: =IF($D$3=2,ROUND(((U6*W6)),2),0) -> 1850.95 | AA6: =IF($D$3=4,ROUND(((U6*W6)/2),2),0) -> 0 | AB6: 0.06 | AC6: =IF($D$3=5,ROUND(((U6*AB6)/2),2),0) -> 0 | AD6: =X6+Y6+Z6+AA6+AC6 -> 1850.95 | AE6: =U6+AD6 -> 38869.94 | AF6: 120 | AG6: =U6*$N$3 -> 37018.99 | AH6: 3 | AI6: =ROUND(G6/AH6,3) -> 4.667 | AJ6: 1375.002 | AK6: 123 | AL6: =ROUND((AJ6-AI6),3) -> 1370.335 | AM6: F100 | AN6: Sales Regular | AO6: 0 | AP6: =ROUND(((AO6*U6)/100),2) -> 0 | AQ6: DOMESTIC
Q7: DISC AMOUNT | Z7: NET AMOUNT | AE7: =SUM(AE5:AE6) -> 77925.82 | AF7: SALES AMOUNT | AG7: =AG5 -> 34871.32

Sheet SO Export RC (S&D)
A1: Scenario : Local Sales - Stock UOM and Sales UOM (Similar) DOC NO : SORD-2425-00089
A2: Sales Order
A3: GST Sales | D3: 3 | E3: (1 - Local Sales,2 Interstate Sales, 3 Export Sales) | J3: Cur. | K3: INR | M3: Ex. Rate | N3: 1
A4: S. No. | B4: Item | C4: Rev | D4: Item Desc. | E4: Stk. UOM | F4: Sale. UOM | G4: Order Qty (Sale UOM) | H4: Unit Price | I4: Gross Amt. | J4: TD% | K4: SD% | L4: CD% | M4: TD Asbl. Val. | N4: TD Amt. | O4: SD Asbl. Val. | P4: SD Amt. | Q4: CD Asbl. Val. | R4: CD Amt. | S4: Disc. Amt. | T4: Disc.Amt.Per.Qty | U4: Sales Val. | V4: HSN | W4: Tax Rate | X4: CGST | Y4: SGST | Z4: IGST | AA4: UTGST | AB4: CESS % | AC4: CESS AMT | AD4: Tax amt | AE4: Net Amt | AF4: Weight/Vol | AG4: Sales Amt (BC) | AH4: Conv. Factor | AI4: Eqv. Stock Qty | AJ4: Before Stock Qty | AK4: Before Stock Cost | AL4: After Stock Qty | AM4: Warehouse | AN4: Promotional Type | AO4: CESS PCT | AP4: CESS AMT | AQ4: PriceClass
A5: 1 | B5: HK-LOT-MAC-10001(FG) | C5: 0 | D5: HK-LOT-MAC-10001(FG) | E5: NOS | F5: NOS | G5: 10 | H5: 36 | I5: =G5*H5 -> 150 | J5: 10 | K5: 2 | L5: 4 | M5: =I5 -> 150 | N5: =ROUND((M5*J5)/100,2) -> 6 | O5: =I5-N5 -> 144 | P5: =ROUND((O5*K5)/100,2) -> 2.88 | Q5: =ROUND(O5-P5,2) -> 141.12 | R5: =ROUND((Q5*L5)/100,2) -> 5.64 | S5: =N5+P5+R5 -> 14.52 | T5: =ROUND(S5/G5,2) -> 1.45 | U5: =(I5-S5) -> 135.48 | V5: HSN1 | W5: 0.12 | X5: =IF(OR($D$3=1,$D$3=4),ROUND((U5*W5)/2,2),0) -> 0 | Y5: =IF($D$3=1,ROUND(((U5*W5)/2),2),0) -> 0 | Z5: =IF($D$3=2,ROUND(((U5*W5)),2),0) -> 0 | AA5: =IF($D$3=4,ROUND(((U5*W5)/2),2),0) -> 0 | AB5: 0.06 | AC5: =IF($D$3=5,ROUND(((U5*AB5)/2),2),0) -> 0 | AD5: =X5+Y5+Z5+AA5+AC5 -> 0 | AE5: =U5+AD5 -> 135.48 | AF5: 120 | AG5: =U5*$N$3 -> 135.48 | AH5: 1 | AI5: =G5/AH5 -> 10 | AJ5: 848 | AK5: 235.36857 | AL5: =ROUND(AJ5-G5,0) -> 838 | AM5: F100 | AN5: Sales Regular | AO5: 0 | AP5: =ROUND(((AO5*U5)/100),2) -> 0 | AQ5: DOMESTIC
A6: 2 | B6: HK-FG-RC-DISSIMILAR ITEM-10001 | C6: 0 | D6: HK-FG-RC-DISSIMILAR ITEM-10001 | E6: KGS | F6: NOS | G6: 10 | H6: 17 | I6: =G6*H6 -> 330 | J6: 12 | K6: 7 | L6: 9 | M6: =I6 -> 330 | N6: =ROUND((M6*J6)/100,2) -> 6.6 | O6: =I6-N6 -> 323.4 | P6: =ROUND((O6*K6)/100,2) -> 22.64 | Q6: =ROUND(O6-P6,2) -> 300.76 | R6: =ROUND((Q6*L6)/100,2) -> 27.07 | S6: =N6+P6+R6 -> 56.31 | T6: =ROUND(S6/G6,2) -> 5.63 | U6: =(I6-S6) -> 273.69 | V6: HSN1 | W6: 0.05 | X6: =IF(OR($D$3=1,$D$3=4),ROUND((U6*W6)/2,2),0) -> 0 | Y6: =IF($D$3=1,ROUND(((U6*W6)/2),2),0) -> 0 | Z6: =IF($D$3=2,ROUND(((U6*W6)),2),0) -> 0 | AA6: =IF($D$3=4,ROUND(((U6*W6)/2),2),0) -> 0 | AB6: 0.06 | AC6: =IF($D$3=5,ROUND(((U6*AB6)/2),2),0) -> 0 | AD6: =X6+Y6+Z6+AA6+AC6 -> 0 | AE6: =U6+AD6 -> 273.69 | AF6: 120 | AG6: =U6*$N$3 -> 273.69 | AH6: 3 | AI6: =ROUND(G6/AH6,3) -> 3.333 | AJ6: 1375.002 | AK6: 123 | AL6: =ROUND((AJ6-AI6),3) -> 1371.669 | AM6: F100 | AN6: Sales Regular | AO6: 0 | AP6: =ROUND(((AO6*U6)/100),2) -> 0 | AQ6: DOMESTIC
Q7: DISC AMOUNT | Z7: NET AMOUNT | AE7: =SUM(AE5:AE6) -> 409.17 | AF7: SALES AMOUNT | AG7: =AG5 -> 135.48

Sheet ShipSet
A1: Scenario : Local Sales - Stock UOM and Sales UOM (Similar) DOC NO : SORD-2425-00089
A2: Sales Order
A3: GST Sales | D3: 2 | E3: (1 - Local Sales,2 Interstate Sales, 3 Export Sales) | J3: Cur. | K3: INR | M3: Ex. Rate | N3: 1
A4: S. No. | B4: Item | C4: Rev | D4: Item Desc. | E4: Stk. UOM | F4: Sale. UOM | G4: Order Qty (Sale UOM) | H4: Unit Price | I4: Gross Amt. | J4: TD% | K4: SD% | L4: CD% | M4: TD Asbl. Val. | N4: TD Amt. | O4: SD Asbl. Val. | P4: SD Amt. | Q4: CD Asbl. Val. | R4: CD Amt. | S4: Disc. Amt. | T4: Disc.Amt.Per.Qty | U4: Sales Val. | V4: HSN | W4: Tax Rate | X4: CGST | Y4: SGST | Z4: IGST | AA4: UTGST | AB4: CESS % | AC4: CESS AMT | AD4: Tax amt | AE4: Net Amt | AF4: Weight/Vol | AG4: Sales Amt (BC) | AH4: Conv. Factor | AI4: Eqv. Stock Qty | AJ4: Before Stock Qty | AK4: Before Stock Cost | AL4: After Stock Qty | AM4: Warehouse | AN4: Promotional Type | AO4: CESS PCT | AP4: CESS AMT | AQ4: PriceClass
A5: 1 | B5: HK-TVS-FG-10001 | C5: 0 | D5: HK-TVS-FG-10001 | E5: NOS | F5: NOS | G5: 10 | H5: 6300 | I5: =G5*H5 -> 63000 | J5: 5 | K5: 2 | L5: 4 | M5: =I5 -> 63000 | N5: =ROUND((M5*J5)/100,2) -> 3150 | O5: =I5-N5 -> 59850 | P5: =ROUND((O5*K5)/100,2) -> 1197 | Q5: =ROUND(O5-P5,2) -> 58653 | R5: =ROUND((Q5*L5)/100,2) -> 2346.12 | S5: =N5+P5+R5 -> 6693.12 | T5: =ROUND(S5/G5,2) -> 669.31 | U5: =(I5-S5) -> 56306.88 | V5: HSN1 | W5: 0.12 | X5: =IF(OR($D$3=1,$D$3=4),ROUND((U5*W5)/2,2),0) -> 0 | Y5: =IF($D$3=1,ROUND(((U5*W5)/2),2),0) -> 0 | Z5: =IF($D$3=2,ROUND(((U5*W5)),2),0) -> 6756.83 | AA5: =IF($D$3=4,ROUND(((U5*W5)/2),2),0) -> 0 | AB5: 0.06 | AC5: =IF($D$3=5,ROUND(((U5*AB5)/2),2),0) -> 0 | AD5: =X5+Y5+Z5+AA5+AC5 -> 6756.83 | AE5: =U5+AD5 -> 63063.71 | AF5: 120 | AG5: =U5*$N$3 -> 56306.88 | AH5: 1 | AI5: =G5/AH5 -> 10 | AJ5: 848 | AK5: 235.36857 | AL5: =ROUND(AJ5-G5,0) -> 838 | AM5: F100 | AN5: Sales Regular | AO5: 0 | AP5: =ROUND(((AO5*U5)/100),2) -> 0 | AQ5: DOMESTIC
A6: 2 | B6: HK-TVS-FG-10002 | C6: 0 | D6: HK-TVS-FG-10002 | E6: KGS | F6: NOS | G6: 10 | H6: 9000 | I6: =G6*H6 -> 90000 | J6: 2 | K6: 7 | L6: 9 | M6: =I6 -> 90000 | N6: =ROUND((M6*J6)/100,2) -> 1800 | O6: =I6-N6 -> 88200 | P6: =ROUND((O6*K6)/100,2) -> 6174 | Q6: =ROUND(O6-P6,2) -> 82026 | R6: =ROUND((Q6*L6)/100,2) -> 7382.34 | S6: =N6+P6+R6 -> 15356.34 | T6: =ROUND(S6/G6,2) -> 1535.63 | U6: =(I6-S6) -> 74643.66 | V6: HSN1 | W6: 0.05 | X6: =IF(OR($D$3=1,$D$3=4),ROUND((U6*W6)/2,2),0) -> 0 | Y6: =IF($D$3=1,ROUND(((U6*W6)/2),2),0) -> 0 | Z6: =IF($D$3=2,ROUND(((U6*W6)),2),0) -> 3732.18 | AA6: =IF($D$3=4,ROUND(((U6*W6)/2),2),0) -> 0 | AB6: 0.06 | AC6: =IF($D$3=5,ROUND(((U6*AB6)/2),2),0) -> 0 | AD6: =X6+Y6+Z6+AA6+AC6 -> 3732.18 | AE6: =U6+AD6 -> 78375.84 | AF6: 120 | AG6: =U6*$N$3 -> 74643.66 | AH6: 3 | AI6: =ROUND(G6/AH6,3) -> 3.333 | AJ6: 1375.002 | AK6: 123 | AL6: =ROUND((AJ6-AI6),3) -> 1371.669 | AM6: F100 | AN6: Sales Regular | AO6: 0 | AP6: =ROUND(((AO6*U6)/100),2) -> 0 | AQ6: DOMESTIC
Q7: DISC AMOUNT | Z7: NET AMOUNT | AE7: =SUM(AE5:AE6) -> 141439.55 | AF7: SALES AMOUNT | AG7: =AG5 -> 56306.88

Sheet Different Price Class (RC)
A1: Scenario : Local Sales - Stock UOM and Sales UOM (Similar) DOC NO : SORD-2425-00089
A2: Sales Order
A3: GST Sales | D3: 2 | E3: (1 - Local Sales,2 Interstate Sales, 3 Export Sales) | J3: Cur. | K3: INR | M3: Ex. Rate | N3: 1
A4: S. No. | B4: Item | C4: Rev | D4: Item Desc. | E4: Stk. UOM | F4: Sale. UOM | G4: Order Qty (Sale UOM) | H4: Unit Price | I4: Gross Amt. | J4: TD% | K4: SD% | L4: CD% | M4: TD Asbl. Val. | N4: TD Amt. | O4: SD Asbl. Val. | P4: SD Amt. | Q4: CD Asbl. Val. | R4: CD Amt. | S4: Disc. Amt. | T4: Disc.Amt.Per.Qty | U4: Sales Val. | V4: HSN | W4: Tax Rate | X4: CGST | Y4: SGST | Z4: IGST | AA4: UTGST | AB4: CESS % | AC4: CESS AMT | AD4: Tax amt | AE4: Net Amt | AF4: Weight/Vol | AG4: Sales Amt (BC) | AH4: Conv. Factor | AI4: Eqv. Stock Qty | AJ4: Before Stock Qty | AK4: Before Stock Cost | AL4: After Stock Qty | AM4: Warehouse | AN4: Promotional Type | AO4: CESS PCT | AP4: CESS AMT | AQ4: PriceClass
A5: 1 | B5: HK-LOT-MAC-10001(FG) | C5: 0 | D5: HK-LOT-MAC-10001(FG) | E5: NOS | F5: NOS | G5: 10 | H5: 9000 | I5: =G5*H5 -> 31200 | J5: 2 | K5: 2 | L5: 4 | M5: =I5 -> 31200 | N5: =ROUND((M5*J5)/100,2) -> 1248 | O5: =I5-N5 -> 29952 | P5: =ROUND((O5*K5)/100,2) -> 599.04 | Q5: =ROUND(O5-P5,2) -> 29352.96 | R5: =ROUND((Q5*L5)/100,2) -> 1174.12 | S5: =N5+P5+R5 -> 3021.16 | T5: =ROUND(S5/G5,2) -> 302.12 | U5: =(I5-S5) -> 28178.84 | V5: HSN1 | W5: 0.12 | X5: =IF(OR($D$3=1,$D$3=4),ROUND((U5*W5)/2,2),0) -> 0 | Y5: =IF($D$3=1,ROUND(((U5*W5)/2),2),0) -> 0 | Z5: =IF($D$3=2,ROUND(((U5*W5)),2),0) -> 3381.46 | AA5: =IF($D$3=4,ROUND(((U5*W5)/2),2),0) -> 0 | AB5: 0.06 | AC5: =IF($D$3=5,ROUND(((U5*AB5)/2),2),0) -> 0 | AD5: =X5+Y5+Z5+AA5+AC5 -> 3381.46 | AE5: =U5+AD5 -> 31560.3 | AF5: 120 | AG5: =U5*$N$3 -> 28178.84 | AH5: 1 | AI5: =G5/AH5 -> 10 | AJ5: 848 | AK5: 235.36857 | AL5: =ROUND(AJ5-G5,0) -> 838 | AM5: F100 | AN5: Sales Regular | AO5: 0 | AP5: =ROUND(((AO5*U5)/100),2) -> 0 | AQ5: SPARE
A6: 2 | B6: HK-FG-RC-DISSIMILAR ITEM-10001 | C6: 0 | D6: HK-FG-RC-DISSIMILAR ITEM-10001 | E6: KGS | F6: NOS | G6: 10 | H6: 6300 | I6: =G6*H6 -> 63000 | J6: 5 | K6: 7 | L6: 9 | M6: =I6 -> 63000 | N6: =ROUND((M6*J6)/100,2) -> 3150 | O6: =I6-N6 -> 59850 | P6: =ROUND((O6*K6)/100,2) -> 4189.5 | Q6: =ROUND(O6-P6,2) -> 55660.5 | R6: =ROUND((Q6*L6)/100,2) -> 5009.45 | S6: =N6+P6+R6 -> 12348.95 | T6: =ROUND(S6/G6,2) -> 1234.9 | U6: =(I6-S6) -> 26175.04 | V6: HSN1 | W6: 0.12 | X6: =IF(OR($D$3=1,$D$3=4),ROUND((U6*W6)/2,2),0) -> 0 | Y6: =IF($D$3=1,ROUND(((U6*W6)/2),2),0) -> 0 | Z6: =IF($D$3=2,ROUND(((U6*W6)),2),0) -> 3141 | AA6: =IF($D$3=4,ROUND(((U6*W6)/2),2),0) -> 0 | AB6: 0.06 | AC6: =IF($D$3=5,ROUND(((U6*AB6)/2),2),0) -> 0 | AD6: =X6+Y6+Z6+AA6+AC6 -> 3141 | AE6: =U6+AD6 -> 29316.04 | AF6: 120 | AG6: =U6*$N$3 -> 26175.04 | AH6: 3 | AI6: =ROUND(G6/AH6,3) -> 3.333 | AJ6: 1375.002 | AK6: 123 | AL6: =ROUND((AJ6-AI6),3) -> 1371.669 | AM6: F100 | AN6: Sales Regular | AO6: 0 | AP6: =ROUND(((AO6*U6)/100),2) -> 0 | AQ6: SPARE
Q7: DISC AMOUNT | Z7: NET AMOUNT | AE7: =SUM(AE5:AE6) -> 60876.34 | AF7: SALES AMOUNT | AG7: =AG5 -> 28178.84

Sheet SO Domestic RC (S&D)
A1: Scenario : Local Sales - Stock UOM and Sales UOM (Similar) DOC NO : SORD-2425-00089
A2: Sales Order
A3: GST Sales | D3: 2 | E3: (1 - Local Sales,2 Interstate Sales, 3 Export Sales) | J3: Cur. | K3: INR | M3: Ex. Rate | N3: 1
A4: S. No. | B4: Item | C4: Rev | D4: Item Desc. | E4: Stk. UOM | F4: Sale. UOM | G4: Order Qty (Sale UOM) | H4: Unit Price | I4: Gross Amt. | J4: TD% | K4: SD% | L4: CD% | M4: TD Asbl. Val. | N4: TD Amt. | O4: SD Asbl. Val. | P4: SD Amt. | Q4: CD Asbl. Val. | R4: CD Amt. | S4: Disc. Amt. | T4: Disc.Amt.Per.Qty | U4: Sales Val. | V4: HSN | W4: Tax Rate | X4: CGST | Y4: SGST | Z4: IGST | AA4: UTGST | AB4: CESS % | AC4: CESS AMT | AD4: Tax amt | AE4: Net Amt | AF4: Weight/Vol | AG4: Sales Amt (BC) | AH4: Conv. Factor | AI4: Eqv. Stock Qty | AJ4: Before Stock Qty | AK4: Before Stock Cost | AL4: After Stock Qty | AM4: Warehouse | AN4: Promotional Type | AO4: CESS PCT | AP4: CESS AMT | AQ4: PriceClass
A5: 1 | B5: HK-LOT-MAC-10001(FG) | C5: 0 | D5: HK-LOT-MAC-10001(FG) | E5: NOS | F5: NOS | G5: 10 | H5: 3120 | I5: =G5*H5 -> 31200 | J5: 4 | K5: 2 | L5: 4 | M5: =I5 -> 31200 | N5: =ROUND((M5*J5)/100,2) -> 1248 | O5: =I5-N5 -> 29952 | P5: =ROUND((O5*K5)/100,2) -> 599.04 | Q5: =ROUND(O5-P5,2) -> 29352.96 | R5: =ROUND((Q5*L5)/100,2) -> 1174.12 | S5: =N5+P5+R5 -> 3021.16 | T5: =ROUND(S5/G5,2) -> 302.12 | U5: =(I5-S5) -> 28178.84 | V5: HSN1 | W5: 0.12 | X5: =IF(OR($D$3=1,$D$3=4),ROUND((U5*W5)/2,2),0) -> 0 | Y5: =IF($D$3=1,ROUND(((U5*W5)/2),2),0) -> 0 | Z5: =IF($D$3=2,ROUND(((U5*W5)),2),0) -> 3381.46 | AA5: =IF($D$3=4,ROUND(((U5*W5)/2),2),0) -> 0 | AB5: 0.06 | AC5: =IF($D$3=5,ROUND(((U5*AB5)/2),2),0) -> 0 | AD5: =X5+Y5+Z5+AA5+AC5 -> 3381.46 | AE5: =U5+AD5 -> 31560.3 | AF5: 120 | AG5: =U5*$N$3 -> 28178.84 | AH5: 1 | AI5: =G5/AH5 -> 10 | AJ5: 848 | AK5: 235.36857 | AL5: =ROUND(AJ5-G5,0) -> 838 | AM5: F100 | AN5: Sales Regular | AO5: 0 | AP5: =ROUND(((AO5*U5)/100),2) -> 0 | AQ5: DOMESTIC
A6: 2 | B6: HK-FG-RC-DISSIMILAR ITEM-10001 | C6: 0 | D6: HK-FG-RC-DISSIMILAR ITEM-10001 | E6: KGS | F6: NOS | G6: 10 | H6: 3156 | I6: =G6*H6 -> 31560 | J6: 2 | K6: 7 | L6: 9 | M6: =I6 -> 31560 | N6: =ROUND((M6*J6)/100,2) -> 631.2 | O6: =I6-N6 -> 30928.8 | P6: =ROUND((O6*K6)/100,2) -> 2165.02 | Q6: =ROUND(O6-P6,2) -> 28763.78 | R6: =ROUND((Q6*L6)/100,2) -> 2588.74 | S6: =N6+P6+R6 -> 5384.96 | T6: =ROUND(S6/G6,2) -> 538.5 | U6: =(I6-S6) -> 26175.04 | V6: HSN1 | W6: 0.12 | X6: =IF(OR($D$3=1,$D$3=4),ROUND((U6*W6)/2,2),0) -> 0 | Y6: =IF($D$3=1,ROUND(((U6*W6)/2),2),0) -> 0 | Z6: =IF($D$3=2,ROUND(((U6*W6)),2),0) -> 3141 | AA6: =IF($D$3=4,ROUND(((U6*W6)/2),2),0) -> 0 | AB6: 0.06 | AC6: =IF($D$3=5,ROUND(((U6*AB6)/2),2),0) -> 0 | AD6: =X6+Y6+Z6+AA6+AC6 -> 3141 | AE6: =U6+AD6 -> 29316.04 | AF6: 120 | AG6: =U6*$N$3 -> 0 | AH6: 3 | AI6: =ROUND(G6/AH6,3) -> 3.333 | AJ6: 1375.002 | AK6: 123 | AL6: =ROUND((AJ6-AI6),3) -> 1371.669 | AM6: F100 | AN6: Sales Regular | AO6: 0 | AP6: =ROUND(((AO6*U6)/100),2) -> 0 | AQ6: DOMESTIC
Q7: DISC AMOUNT | Z7: NET AMOUNT | AE7: =SUM(AE5:AE6) -> 60876.34 | AF7: SALES AMOUNT | AG7: =AG5 -> 0

Sheet SO Export UD (S&D)
A1: Scenario : Local Sales - Stock UOM and Sales UOM (Similar) DOC NO : SORD-2425-00089
A2: Sales Order
A3: GST Sales | D3: 3 | E3: (1 - Local Sales,2 Interstate Sales, 3 Export Sales) | J3: Cur. | K3: INR | M3: Ex. Rate | N3: 1
A4: S. No. | B4: Item | C4: Rev | D4: Item Desc. | E4: Stk. UOM | F4: Sale. UOM | G4: Order Qty (Sale UOM) | H4: Unit Price | I4: Gross Amt. | J4: TD% | K4: SD% | L4: CD% | M4: TD Asbl. Val. | N4: TD Amt. | O4: SD Asbl. Val. | P4: SD Amt. | Q4: CD Asbl. Val. | R4: CD Amt. | S4: Disc. Amt. | T4: Disc.Amt.Per.Qty | U4: Sales Val. | V4: HSN | W4: Tax Rate | X4: CGST | Y4: SGST | Z4: IGST | AA4: UTGST | AB4: CESS % | AC4: CESS AMT | AD4: Tax amt | AE4: Net Amt | AF4: Weight/Vol | AG4: Sales Amt (BC) | AH4: Conv. Factor | AI4: Eqv. Stock Qty | AJ4: Before Stock Qty | AK4: Before Stock Cost | AL4: After Stock Qty | AM4: Warehouse | AN4: Promotional Type | AO4: CESS PCT | AP4: CESS AMT | AQ4: PriceClass
A5: 1 | B5: HK-FIFO-LOT-BATCH-10001(FG) | C5: 0 | D5: HK-FIFO-LOT-BATCH-10001(FG) | E5: NOS | F5: NOS | G5: 12 | H5: 23 | I5: =G5*H5 -> 276 | J5: 1 | K5: 2 | L5: 4 | M5: =I5 -> 276 | N5: =ROUND((M5*J5)/100,2) -> 2.76 | O5: =I5-N5 -> 273.24 | P5: =ROUND((O5*K5)/100,2) -> 5.46 | Q5: =ROUND(O5-P5,2) -> 267.78 | R5: =ROUND((Q5*L5)/100,2) -> 10.71 | S5: =N5+P5+R5 -> 18.93 | T5: =ROUND(S5/G5,2) -> 1.58 | U5: =(I5-S5) -> 257.07 | V5: HSN1 | W5: 0.12 | X5: =IF(OR($D$3=1,$D$3=4),ROUND((U5*W5)/2,2),0) -> 0 | Y5: =IF($D$3=1,ROUND(((U5*W5)/2),2),0) -> 0 | Z5: =IF($D$3=2,ROUND(((U5*W5)),2),0) -> 0 | AA5: =IF($D$3=4,ROUND(((U5*W5)/2),2),0) -> 0 | AB5: 0.06 | AC5: =IF($D$3=5,ROUND(((U5*AB5)/2),2),0) -> 0 | AD5: =X5+Y5+Z5+AA5+AC5 -> 0 | AE5: =U5+AD5 -> 257.07 | AF5: 120 | AG5: =U5*$N$3 -> 257.07 | AH5: 1 | AI5: =G5/AH5 -> 12 | AJ5: 848 | AK5: 235.36857 | AL5: =ROUND(AJ5-G5,0) -> 836 | AM5: F100 | AN5: Sales Regular | AO5: 0 | AP5: =ROUND(((AO5*U5)/100),2) -> 0 | AQ5: DOMESTIC
A6: 2 | B6: HK-FG-DISSIMILAR-10001 | C6: 0 | D6: HK-FG-DISSIMILAR-10001 | E6: KGS | F6: NOS | G6: 13 | H6: 34 | I6: =G6*H6 -> 442 | J6: 2 | K6: 7 | L6: 9 | M6: =I6 -> 442 | N6: =ROUND((M6*J6)/100,2) -> 8.84 | O6: =I6-N6 -> 433.16 | P6: =ROUND((O6*K6)/100,2) -> 30.32 | Q6: =ROUND(O6-P6,2) -> 402.84 | R6: =ROUND((Q6*L6)/100,2) -> 36.26 | S6: =N6+P6+R6 -> 75.42 | T6: =ROUND(S6/G6,2) -> 5.8 | U6: =(I6-S6) -> 366.58 | V6: HSN1 | W6: 0.05 | X6: =IF(OR($D$3=1,$D$3=4),ROUND((U6*W6)/2,2),0) -> 0 | Y6: =IF($D$3=1,ROUND(((U6*W6)/2),2),0) -> 0 | Z6: =IF($D$3=2,ROUND(((U6*W6)),2),0) -> 0 | AA6: =IF($D$3=4,ROUND(((U6*W6)/2),2),0) -> 0 | AB6: 0.06 | AC6: =IF($D$3=5,ROUND(((U6*AB6)/2),2),0) -> 0 | AD6: =X6+Y6+Z6+AA6+AC6 -> 0 | AE6: =U6+AD6 -> 366.58 | AF6: 120 | AG6: =U6*$N$3 -> 366.58 | AH6: 3 | AI6: =ROUND(G6/AH6,3) -> 4.333 | AJ6: 1375.002 | AK6: 123 | AL6: =ROUND((AJ6-AI6),3) -> 1370.669 | AM6: F100 | AN6: Sales Regular | AO6: 0 | AP6: =ROUND(((AO6*U6)/100),2) -> 0 | AQ6: DOMESTIC
Q7: DISC AMOUNT | S7: =SUM(S5:S6) -> 94.35 | Z7: NET AMOUNT | AE7: =SUM(AE5:AE6) -> 623.65 | AF7: SALES AMOUNT | AG7: =AG5 -> 257.07

Sheet SO Domestic UD (S&D)
A1: Scenario : Local Sales - Stock UOM and Sales UOM (Similar) DOC NO : SORD-2425-00089
A2: Sales Order
A3: GST Sales | D3: 2 | E3: (1 - Local Sales,2 Interstate Sales, 3 Export Sales) | J3: Cur. | K3: INR | M3: Ex. Rate | N3: 1
A4: S. No. | B4: Item | C4: Rev | D4: Item Desc. | E4: Stk. UOM | F4: Sale. UOM | G4: Order Qty (Sale UOM) | H4: Unit Price | I4: Gross Amt. | J4: TD% | K4: SD% | L4: CD% | M4: TD Asbl. Val. | N4: TD Amt. | O4: SD Asbl. Val. | P4: SD Amt. | Q4: CD Asbl. Val. | R4: CD Amt. | S4: Disc. Amt. | T4: Disc.Amt.Per.Qty | U4: Sales Val. | V4: HSN | W4: Tax Rate | X4: CGST | Y4: SGST | Z4: IGST | AA4: UTGST | AB4: CESS % | AC4: CESS AMT | AD4: Tax amt | AE4: Net Amt | AF4: Weight/Vol | AG4: Sales Amt (BC) | AH4: Conv. Factor | AI4: Eqv. Stock Qty | AJ4: Before Stock Qty | AK4: Before Stock Cost | AL4: After Stock Qty | AM4: Warehouse | AN4: Promotional Type | AO4: CESS PCT | AP4: CESS AMT | AQ4: PriceClass
A5: 1 | B5: HK-FIFO-LOT-BATCH-10001(FG) | C5: 0 | D5: HK-FIFO-LOT-BATCH-10001(FG) | E5: NOS | F5: NOS | G5: 10 | H5: 1234 | I5: =G5*H5 -> 12340 | J5: 1 | K5: 2 | L5: 4 | M5: =I5 -> 12340 | N5: =ROUND((M5*J5)/100,2) -> 123.4 | O5: =I5-N5 -> 12216.6 | P5: =ROUND((O5*K5)/100,2) -> 244.33 | Q5: =ROUND(O5-P5,2) -> 11972.27 | R5: =ROUND((Q5*L5)/100,2) -> 478.89 | S5: =N5+P5+R5 -> 846.62 | T5: =ROUND(S5/G5,2) -> 84.66 | U5: =(I5-S5) -> 11493.38 | V5: HSN1 | W5: 0.12 | X5: =IF(OR($D$3=1,$D$3=4),ROUND((U5*W5)/2,2),0) -> 0 | Y5: =IF($D$3=1,ROUND(((U5*W5)/2),2),0) -> 0 | Z5: =IF($D$3=2,ROUND(((U5*W5)),2),0) -> 1379.21 | AA5: =IF($D$3=4,ROUND(((U5*W5)/2),2),0) -> 0 | AB5: 0.06 | AC5: =IF($D$3=5,ROUND(((U5*AB5)/2),2),0) -> 0 | AD5: =X5+Y5+Z5+AA5+AC5 -> 1379.21 | AE5: =U5+AD5 -> 12872.59 | AF5: 120 | AG5: =U5*$N$3 -> 11493.38 | AH5: 1 | AI5: =G5/AH5 -> 10 | AJ5: 848 | AK5: 235.36857 | AL5: =ROUND(AJ5-G5,0) -> 838 | AM5: F100 | AN5: Sales Regular | AO5: 0 | AP5: =ROUND(((AO5*U5)/100),2) -> 0 | AQ5: DOMESTIC
A6: 2 | B6: HK-FG-DISSIMILAR-10001 | C6: 0 | D6: HK-FG-DISSIMILAR-10001 | E6: KGS | F6: NOS | G6: 10 | H6: 3214 | I6: =G6*H6 -> 32140 | J6: 2 | K6: 7 | L6: 9 | M6: =I6 -> 32140 | N6: =ROUND((M6*J6)/100,2) -> 642.8 | O6: =I6-N6 -> 31497.2 | P6: =ROUND((O6*K6)/100,2) -> 2204.8 | Q6: =ROUND(O6-P6,2) -> 29292.4 | R6: =ROUND((Q6*L6)/100,2) -> 2636.32 | S6: =N6+P6+R6 -> 5483.92 | T6: =ROUND(S6/G6,2) -> 548.39 | U6: =(I6-S6) -> 26656.08 | V6: HSN1 | W6: 0.05 | X6: =IF(OR($D$3=1,$D$3=4),ROUND((U6*W6)/2,2),0) -> 0 | Y6: =IF($D$3=1,ROUND(((U6*W6)/2),2),0) -> 0 | Z6: =IF($D$3=2,ROUND(((U6*W6)),2),0) -> 1332.8 | AA6: =IF($D$3=4,ROUND(((U6*W6)/2),2),0) -> 0 | AB6: 0.06 | AC6: =IF($D$3=5,ROUND(((U6*AB6)/2),2),0) -> 0 | AD6: =X6+Y6+Z6+AA6+AC6 -> 1332.8 | AE6: =U6+AD6 -> 27988.88 | AF6: 120 | AG6: =U6*$N$3 -> 26656.08 | AH6: 3 | AI6: =ROUND(G6/AH6,3) -> 3.333 | AJ6: 1375.002 | AK6: 123 | AL6: =ROUND((AJ6-AI6),3) -> 1371.669 | AM6: F100 | AN6: Sales Regular | AO6: 0 | AP6: =ROUND(((AO6*U6)/100),2) -> 0 | AQ6: DOMESTIC
Q7: DISC AMOUNT | Z7: NET AMOUNT | AE7: =SUM(AE5:AE6) -> 40861.47 | AF7: SALES AMOUNT | AG7: =AG5 -> 11493.38

Sheet Case 1
A1: Scenario : Local Sales - Stock UOM and Sales UOM (Similar) DOC NO : SORD-2425-00089
A2: Sales Order
A3: GST Sales | D3: 2 | E3: (1 - Local Sales,2 Interstate Sales, 3 Export Sales) | J3: Cur. | K3: INR | M3: Ex. Rate | N3: 1
A4: S. No. | B4: Item | C4: Rev | D4: Item Desc. | E4: Stk. UOM | F4: Sale. UOM | G4: Order Qty (Sale UOM) | H4: Unit Price | I4: Gross Amt. | J4: TD% | K4: SD% | L4: CD% | M4: TD Asbl. Val. | N4: TD Amt. | O4: SD Asbl. Val. | P4: SD Amt. | Q4: CD Asbl. Val. | R4: CD Amt. | S4: Disc. Amt. | T4: Disc.Amt.Per.Qty | U4: Sales Val. | V4: HSN | W4: Tax Rate | X4: CGST | Y4: SGST | Z4: IGST | AA4: UTGST | AB4: CESS % | AC4: CESS AMT | AD4: Tax amt | AE4: Net Amt | AF4: Weight/Vol | AG4: Sales Amt (BC) | AH4: Conv. Factor | AI4: Eqv. Stock Qty | AJ4: Before Stock Qty | AK4: Before Stock Cost | AL4: After Stock Qty | AM4: Warehouse | AN4: Promotional Type | AO4: CESS PCT | AP4: CESS AMT | AQ4: PriceClass
A5: 1 | B5: HK-FIFO-LOT-BATCH-10001(FG) | C5: 0 | D5: HK-FIFO-LOT-BATCH-10001(FG) | E5: NOS | F5: NOS | G5: 10 | H5: 1234 | I5: =G5*H5 -> 12340 | J5: 1 | K5: 2 | L5: 4 | M5: =I5 -> 12340 | N5: =ROUND((M5*J5)/100,2) -> 123.4 | O5: =I5-N5 -> 12216.6 | P5: =ROUND((O5*K5)/100,2) -> 244.33 | Q5: =ROUND(O5-P5,2) -> 11972.27 | R5: =ROUND((Q5*L5)/100,2) -> 478.89 | S5: =N5+P5+R5 -> 846.62 | T5: =ROUND(S5/G5,2) -> 84.66 | U5: =(I5-S5) -> 11493.38 | V5: HSN1 | W5: 0.12 | X5: =IF(OR($D$3=1,$D$3=4),ROUND((U5*W5)/2,2),0) -> 0 | Y5: =IF($D$3=1,ROUND(((U5*W5)/2),2),0) -> 0 | Z5: =IF($D$3=2,ROUND(((U5*W5)),2),0) -> 1379.21 | AA5: =IF($D$3=4,ROUND(((U5*W5)/2),2),0) -> 0 | AB5: 0.06 | AC5: =IF($D$3=5,ROUND(((U5*AB5)/2),2),0) -> 0 | AD5: =X5+Y5+Z5+AA5+AC5 -> 1379.21 | AE5: =U5+AD5 -> 12872.59 | AF5: 120 | AG5: =U5*$N$3 -> 11493.38 | AH5: 1 | AI5: =G5/AH5 -> 10 | AJ5: 848 | AK5: 235.36857 | AL5: =ROUND(AJ5-G5,0) -> 902 | AM5: F100 | AN5: Sales Regular | AO5: 0 | AP5: =ROUND(((AO5*U5)/100),2) -> 0 | AQ5: DOMESTIC
A6: 2 | B6: HK-FG-DISSIMILAR-10001 | C6: 0 | D6: HK-FG-DISSIMILAR-10001 | E6: KGS | F6: NOS | G6: 10 | H6: 3214 | I6: =G6*H6 -> 32140 | J6: 2 | K6: 7 | L6: 9 | M6: =I6 -> 32140 | N6: =ROUND((M6*J6)/100,2) -> 642.8 | O6: =I6-N6 -> 31497.2 | P6: =ROUND((O6*K6)/100,2) -> 2204.8 | Q6: =ROUND(O6-P6,2) -> 29292.4 | R6: =ROUND((Q6*L6)/100,2) -> 2636.32 | S6: =N6+P6+R6 -> 5483.92 | T6: =ROUND(S6/G6,2) -> 548.39 | U6: =(I6-S6) -> 26656.08 | V6: HSN1 | W6: 0.05 | X6: =IF(OR($D$3=1,$D$3=4),ROUND((U6*W6)/2,2),0) -> 0 | Y6: =IF($D$3=1,ROUND(((U6*W6)/2),2),0) -> 0 | Z6: =IF($D$3=2,ROUND(((U6*W6)),2),0) -> 1332.8 | AA6: =IF($D$3=4,ROUND(((U6*W6)/2),2),0) -> 0 | AB6: 0.06 | AC6: =IF($D$3=5,ROUND(((U6*AB6)/2),2),0) -> 0 | AD6: =X6+Y6+Z6+AA6+AC6 -> 1332.8 | AE6: =U6+AD6 -> 27988.88 | AF6: 120 | AG6: =U6*$N$3 -> 26656.08 | AH6: 3 | AI6: =ROUND(G6/AH6,3) -> 3.333 | AJ6: 1375.002 | AK6: 123 | AL6: =ROUND((AJ6-AI6),3) -> 1371.669 | AM6: F100 | AN6: Sales Regular | AO6: 0 | AP6: =ROUND(((AO6*U6)/100),2) -> 0 | AQ6: DOMESTIC
Q7: DISC AMOUNT | Z7: NET AMOUNT | AE7: =SUM(AE5:AE6) -> 40861.47 | AF7: SALES AMOUNT | AG7: =AG5 -> 11493.38

Sheet Item Stocks
A1: S. No. | B1: Item | C1: Rev | D1: Item Desc. | E1: Order Qty | F1: Unit Cost | G1: Before Stock Qty | H1: After Stock Qty
A2: ='Case 1'!A5 -> 1 | B2: ='Case 1'!B5 -> HK-FIFO-LOT-BATCH-10001(FG) | C2: ='Case 1'!C5 -> 0 | D2: ='Case 1'!D5 -> HK-FIFO-LOT-BATCH-10001(FG) | E2: 20 | F2: ='Case 1'!H5 -> 1234 | G2: 2954.00 | H2: =G2-E2 -> 4547
A3: ='Case 1'!A6 -> 2 | B3: ='Case 1'!B6 -> HK-FG-DISSIMILAR-10001 | C3: ='Case 1'!C6 -> 0 | D3: ='Case 1'!D6 -> HK-FG-DISSIMILAR-10001 | E3: 30 | F3: ='Case 1'!H6 -> 3214 | G3: 675 | H3: =G3-E3 -> 645

Sheet SO UTGST
A1: Scenario : Local Sales - Stock UOM and Sales UOM (Similar) DOC NO : SORD-2425-00089
A2: Sales Order
A3: GST Sales | D3: 4 | E3: (1 - Local Sales,2 Interstate Sales, 3 Export Sales) | J3: Cur. | K3: INR | M3: Ex. Rate | N3: 1
A4: S. No. | B4: Item | C4: Rev | D4: Item Desc. | E4: Stk. UOM | F4: Sale. UOM | G4: Order Qty (Sale UOM) | H4: Unit Price | I4: Gross Amt. | J4: TD% | K4: SD% | L4: CD% | M4: TD Asbl. Val. | N4: TD Amt. | O4: SD Asbl. Val. | P4: SD Amt. | Q4: CD Asbl. Val. | R4: CD Amt. | S4: Disc. Amt. | T4: Disc.Amt.Per.Qty | U4: Sales Val. | V4: HSN | W4: Tax Rate | X4: CGST | Y4: SGST | Z4: IGST | AA4: UTGST | AB4: CESS % | AC4: CESS AMT | AD4: Tax amt | AE4: Net Amt | AF4: Weight/Vol | AG4: Sales Amt (BC) | AH4: Conv. Factor | AI4: Eqv. Stock Qty | AJ4: Before Stock Qty | AK4: Before Stock Cost | AL4: After Stock Qty | AM4: Warehouse | AN4: Promotional Type | AO4: CESS PCT | AP4: CESS AMT | AQ4: PriceClass
A5: 1 | B5: HK-FIFO-LOT-BATCH-10001(FG) | C5: 0 | D5: HK-FIFO-LOT-BATCH-10001(FG) | E5: NOS | F5: NOS | G5: 10 | H5: 1234 | I5: =G5*H5 -> 12340 | J5: 1 | K5: 2 | L5: 4 | M5: =I5 -> 12340 | N5: =ROUND((M5*J5)/100,2) -> 123.4 | O5: =I5-N5 -> 12216.6 | P5: =ROUND((O5*K5)/100,2) -> 244.33 | Q5: =ROUND(O5-P5,2) -> 11972.27 | R5: =ROUND((Q5*L5)/100,2) -> 478.89 | S5: =N5+P5+R5 -> 846.62 | T5: =ROUND(S5/G5,2) -> 84.66 | U5: =(I5-S5) -> 11493.38 | V5: (740410)-18% | W5: 0.12 | X5: =IF(OR($D$3=1,$D$3=4),ROUND((U5*W5)/2,2),0) -> 689.6 | Y5: =IF($D$3=1,ROUND(((U5*W5)/2),2),0) -> 0 | Z5: =IF($D$3=2,ROUND(((U5*W5)),2),0) -> 0 | AA5: =IF($D$3=4,ROUND(((U5*W5)/2),2),0) -> 689.6 | AB5: 0.06 | AC5: =IF($D$3=5,ROUND(((U5*AB5)/2),2),0) -> 0 | AD5: =X5+Y5+Z5+AA5+AC5 -> 1379.2 | AE5: =U5+AD5 -> 12872.58 | AF5: 120 | AG5: =U5*$N$3 -> 11493.38 | AH5: 1 | AI5: =G5/AH5 -> 10 | AJ5: 848 | AK5: 235.36857 | AL5: =ROUND(AJ5-G5,0) -> 838 | AM5: F100 | AN5: Sales Regular | AO5: 0 | AP5: =ROUND(((AO5*U5)/100),2) -> 0 | AQ5: DOMESTIC
A6: 2 | B6: HK-FG-DISSIMILAR-10001 | C6: 0 | D6: HK-FG-DISSIMILAR-10001 | E6: KGS | F6: NOS | G6: 20 | H6: 3214 | I6: =G6*H6 -> 64280 | J6: 2 | K6: 7 | L6: 9 | M6: =I6 -> 64280 | N6: =ROUND((M6*J6)/100,2) -> 1285.6 | O6: =I6-N6 -> 62994.4 | P6: =ROUND((O6*K6)/100,2) -> 4409.61 | Q6: =ROUND(O6-P6,2) -> 58584.79 | R6: =ROUND((Q6*L6)/100,2) -> 5272.63 | S6: =N6+P6+R6 -> 10967.84 | T6: =ROUND(S6/G6,2) -> 548.39 | U6: =(I6-S6) -> 53312.16 | V6: 772213 | W6: 0.05 | X6: =IF(OR($D$3=1,$D$3=4),ROUND((U6*W6)/2,2),0) -> 1332.8 | Y6: =IF($D$3=1,ROUND(((U6*W6)/2),2),0) -> 0 | Z6: =IF($D$3=2,ROUND(((U6*W6)),2),0) -> 0 | AA6: =IF($D$3=4,ROUND(((U6*W6)/2),2),0) -> 1332.8 | AB6: 0.06 | AC6: =IF($D$3=5,ROUND(((U6*AB6)/2),2),0) -> 0 | AD6: =X6+Y6+Z6+AA6+AC6 -> 2665.6 | AE6: =U6+AD6 -> 55977.76 | AF6: 120 | AG6: =U6*$N$3 -> 53312.16 | AH6: 3 | AI6: =ROUND(G6/AH6,3) -> 6.667 | AJ6: 1375.002 | AK6: 123 | AL6: =ROUND((AJ6-AI6),3) -> 1368.335 | AM6: F100 | AN6: Sales Regular | AO6: 0 | AP6: =ROUND(((AO6*U6)/100),2) -> 0 | AQ6: DOMESTIC
Q7: DISC AMOUNT | S7: =SUM(S5:S6) -> 11814.46 | Z7: NET AMOUNT | AE7: =SUM(AE5:AE6) -> 68850.34 | AF7: SALES AMOUNT | AG7: =AG5 -> 11493.38

Sheet Free Sample
A1: Scenario : Local Sales - Stock UOM and Sales UOM (Similar) DOC NO : SORD-2425-00089
A2: Sales Order
A3: GST Sales | D3: 2 | E3: (1 - Local Sales,2 Interstate Sales, 3 Export Sales) | J3: Cur. | K3: INR | M3: Ex. Rate | N3: 1
A4: S. No. | B4: Item | C4: Rev | D4: Item Desc. | E4: Stk. UOM | F4: Sale. UOM | G4: Order Qty (Sale UOM) | H4: Unit Price | I4: Gross Amt. | J4: TD% | K4: SD% | L4: CD% | M4: TD Asbl. Val. | N4: TD Amt. | O4: SD Asbl. Val. | P4: SD Amt. | Q4: CD Asbl. Val. | R4: CD Amt. | S4: Disc. Amt. | T4: Disc.Amt.Per.Qty | U4: Sales Val. | V4: HSN | W4: Tax Rate | X4: CGST | Y4: SGST | Z4: IGST | AA4: UTGST | AB4: CESS % | AC4: CESS AMT | AD4: Tax amt | AE4: Net Amt | AF4: Weight/Vol | AG4: Sales Amt (BC) | AH4: Conv. Factor | AI4: Eqv. Stock Qty | AJ4: Before Stock Qty | AK4: Before Stock Cost | AL4: After Stock Qty | AM4: Warehouse | AN4: Promotional Type | AO4: CESS PCT | AP4: CESS AMT | AQ4: PriceClass
A5: 1 | B5: HK-FIFO-LOT-BATCH-10001(FG) | C5: 0 | D5: HK-FIFO-LOT-BATCH-10001(FG) | E5: NOS | F5: NOS | G5: 10 | H5: 2333 | I5: =G5*H5 -> 23330 | J5: 0 | K5: 0 | L5: 0 | M5: =I5 -> 23330 | N5: =ROUND((M5*J5)/100,2) -> 0 | O5: =I5-N5 -> 23330 | P5: =ROUND((O5*K5)/100,2) -> 0 | Q5: =ROUND(O5-P5,2) -> 23330 | R5: =ROUND((Q5*L5)/100,2) -> 0 | S5: =N5+P5+R5 -> 0 | T5: =ROUND(S5/G5,2) -> 0 | U5: =(I5-S5) -> 23330 | V5: HSN1 | W5: 0.12 | X5: =IF(OR($D$3=1,$D$3=4),ROUND((U5*W5)/2,2),0) -> 0 | Y5: =IF($D$3=1,ROUND(((U5*W5)/2),2),0) -> 0 | Z5: =IF($D$3=2,ROUND(((U5*W5)),2),0) -> 2799.6 | AA5: =IF($D$3=4,ROUND(((U5*W5)/2),2),0) -> 0 | AB5: 0.06 | AC5: =IF($D$3=5,ROUND(((U5*AB5)/2),2),0) -> 0 | AD5: =X5+Y5+Z5+AA5+AC5 -> 2799.6 | AE5: =U5+AD5 -> 26129.6 | AF5: 120 | AG5: =U5*$N$3 -> 23330 | AH5: 1 | AI5: =G5/AH5 -> 10 | AJ5: 848 | AK5: 235.36857 | AL5: =ROUND(AJ5-G5,0) -> 838 | AM5: F100 | AN5: Sales Regular | AO5: 0 | AP5: =ROUND(((AO5*U5)/100),2) -> 0 | AQ5: DOMESTIC
A6: 2 | B6: HK-FG-DISSIMILAR-10001 | C6: 0 | D6: HK-FG-DISSIMILAR-10001 | E6: KGS | F6: NOS | G6: 10 | H6: 4319 | I6: =G6*H6 -> 43190 | J6: 0 | K6: 0 | L6: 0 | M6: =I6 -> 43190 | N6: =ROUND((M6*J6)/100,2) -> 0 | O6: =I6-N6 -> 43190 | P6: =ROUND((O6*K6)/100,2) -> 0 | Q6: =ROUND(O6-P6,2) -> 43190 | R6: =ROUND((Q6*L6)/100,2) -> 0 | S6: =N6+P6+R6 -> 0 | T6: =ROUND(S6/G6,2) -> 0 | U6: =(I6-S6) -> 43190 | V6: HSN1 | W6: 0.05 | X6: =IF(OR($D$3=1,$D$3=4),ROUND((U6*W6)/2,2),0) -> 0 | Y6: =IF($D$3=1,ROUND(((U6*W6)/2),2),0) -> 0 | Z6: =IF($D$3=2,ROUND(((U6*W6)),2),0) -> 2159.5 | AA6: =IF($D$3=4,ROUND(((U6*W6)/2),2),0) -> 0 | AB6: 0.06 | AC6: =IF($D$3=5,ROUND(((U6*AB6)/2),2),0) -> 0 | AD6: =X6+Y6+Z6+AA6+AC6 -> 2159.5 | AE6: =U6+AD6 -> 45349.5 | AF6: 120 | AG6: =U6*$N$3 -> 43190 | AH6: 3 | AI6: =ROUND(G6/AH6,3) -> 3.333 | AJ6: 1375.002 | AK6: 123 | AL6: =ROUND((AJ6-AI6),3) -> 1371.669 | AM6: F100 | AN6: Sales Regular | AO6: 0 | AP6: =ROUND(((AO6*U6)/100),2) -> 0 | AQ6: DOMESTIC
Q7: DISC AMOUNT | Z7: NET AMOUNT | AE7: =SUM(AE5:AE6) -> 71479.1 | AF7: SALES AMOUNT | AG7: =AG5 -> 23330

Sheet Free Replacement
A1: Scenario : Local Sales - Stock UOM and Sales UOM (Similar) DOC NO : SORD-2425-00089
A2: Sales Order
A3: GST Sales | D3: 2 | E3: (1 - Local Sales,2 Interstate Sales, 3 Export Sales) | J3: Cur. | K3: INR | M3: Ex. Rate | N3: 1
A4: S. No. | B4: Item | C4: Rev | D4: Item Desc. | E4: Stk. UOM | F4: Sale. UOM | G4: Order Qty (Sale UOM) | H4: Unit Price | I4: Gross Amt. | J4: TD% | K4: SD% | L4: CD% | M4: TD Asbl. Val. | N4: TD Amt. | O4: SD Asbl. Val. | P4: SD Amt. | Q4: CD Asbl. Val. | R4: CD Amt. | S4: Disc. Amt. | T4: Disc.Amt.Per.Qty | U4: Sales Val. | V4: HSN | W4: Tax Rate | X4: CGST | Y4: SGST | Z4: IGST | AA4: UTGST | AB4: CESS % | AC4: CESS AMT | AD4: Tax amt | AE4: Net Amt | AF4: Weight/Vol | AG4: Sales Amt (BC) | AH4: Conv. Factor | AI4: Eqv. Stock Qty | AJ4: Before Stock Qty | AK4: Before Stock Cost | AL4: After Stock Qty | AM4: Warehouse | AN4: Promotional Type | AO4: CESS PCT | AP4: CESS AMT | AQ4: PriceClass
A5: 1 | B5: HK-FIFO-LOT-BATCH-10001(FG) | C5: 0 | D5: HK-FIFO-LOT-BATCH-10001(FG) | E5: NOS | F5: NOS | G5: 10 | H5: 1500 | I5: =G5*H5 -> 15000 | J5: 0 | K5: 0 | L5: 0 | M5: =I5 -> 15000 | N5: =ROUND((M5*J5)/100,2) -> 0 | O5: =I5-N5 -> 15000 | P5: =ROUND((O5*K5)/100,2) -> 0 | Q5: =ROUND(O5-P5,2) -> 15000 | R5: =ROUND((Q5*L5)/100,2) -> 0 | S5: =N5+P5+R5 -> 0 | T5: =ROUND(S5/G5,2) -> 0 | U5: =(I5-S5) -> 15000 | V5: HSN1 | W5: 0.12 | X5: =IF(OR($D$3=1,$D$3=4),ROUND((U5*W5)/2,2),0) -> 0 | Y5: =IF($D$3=1,ROUND(((U5*W5)/2),2),0) -> 0 | Z5: =IF($D$3=2,ROUND(((U5*W5)),2),0) -> 1800 | AA5: =IF($D$3=4,ROUND(((U5*W5)/2),2),0) -> 0 | AB5: 0.06 | AC5: =IF($D$3=5,ROUND(((U5*AB5)/2),2),0) -> 0 | AD5: =X5+Y5+Z5+AA5+AC5 -> 1800 | AE5: =U5+AD5 -> 16800 | AF5: 120 | AG5: =U5*$N$3 -> 15000 | AH5: 1 | AI5: =G5/AH5 -> 10 | AJ5: 848 | AK5: 235.36857 | AL5: =ROUND(AJ5-G5,0) -> 838 | AM5: F100 | AN5: Sales Regular | AO5: 0 | AP5: =ROUND(((AO5*U5)/100),2) -> 0 | AQ5: DOMESTIC
A6: 2 | B6: HK-FG-DISSIMILAR-10001 | C6: 0 | D6: HK-FG-DISSIMILAR-10001 | E6: KGS | F6: NOS | G6: 10 | H6: 2000 | I6: =G6*H6 -> 20000 | J6: 0 | K6: 0 | L6: 0 | M6: =I6 -> 20000 | N6: =ROUND((M6*J6)/100,2) -> 0 | O6: =I6-N6 -> 20000 | P6: =ROUND((O6*K6)/100,2) -> 0 | Q6: =ROUND(O6-P6,2) -> 20000 | R6: =ROUND((Q6*L6)/100,2) -> 0 | S6: =N6+P6+R6 -> 0 | T6: =ROUND(S6/G6,2) -> 0 | U6: =(I6-S6) -> 20000 | V6: HSN1 | W6: 0.05 | X6: =IF(OR($D$3=1,$D$3=4),ROUND((U6*W6)/2,2),0) -> 0 | Y6: =IF($D$3=1,ROUND(((U6*W6)/2),2),0) -> 0 | Z6: =IF($D$3=2,ROUND(((U6*W6)),2),0) -> 1000 | AA6: =IF($D$3=4,ROUND(((U6*W6)/2),2),0) -> 0 | AB6: 0.06 | AC6: =IF($D$3=5,ROUND(((U6*AB6)/2),2),0) -> 0 | AD6: =X6+Y6+Z6+AA6+AC6 -> 1000 | AE6: =U6+AD6 -> 21000 | AF6: 120 | AG6: =U6*$N$3 -> 20000 | AH6: 3 | AI6: =ROUND(G6/AH6,3) -> 3.333 | AJ6: 1375.002 | AK6: 123 | AL6: =ROUND((AJ6-AI6),3) -> 1371.669 | AM6: F100 | AN6: Sales Regular | AO6: 0 | AP6: =ROUND(((AO6*U6)/100),2) -> 0 | AQ6: DOMESTIC
Q7: DISC AMOUNT | Z7: NET AMOUNT | AE7: =SUM(AE5:AE6) -> 37800 | AF7: SALES AMOUNT | AG7: =AG5 -> 15000

Sheet SCRAP
A1: Scenario : Local Sales - Stock UOM and Sales UOM (Similar) DOC NO : SORD-2425-00089
A2: Sales Order
A3: GST Sales | D3: 2 | E3: (1 - Local Sales,2 Interstate Sales, 3 Import Sales) | J3: Cur. | K3: INR | M3: Ex. Rate | N3: 1
A4: S. No. | B4: Item | C4: Rev | D4: Item Desc. | E4: Stk. UOM | F4: Sale. UOM | G4: Order Qty (Sale UOM) | H4: Unit Price | I4: Gross Amt. | J4: TD% | K4: SD% | L4: CD% | M4: TD Asbl. Val. | N4: TD Amt. | O4: SD Asbl. Val. | P4: SD Amt. | Q4: CD Asbl. Val. | R4: CD Amt. | S4: Disc. Amt. | T4: Disc.Amt.Per.Qty | U4: Sales Val. | V4: HSN | W4: Tax Rate | X4: CGST | Y4: SGST | Z4: IGST | AA4: UTGST | AB4: CESS % | AC4: CESS AMT | AD4: Tax amt | AE4: Net Amt | AF4: Weight/Vol | AG4: Sales Amt (BC) | AH4: Conv. Factor | AI4: Eqv. Stock Qty | AJ4: Before Stock Qty | AK4: Before Stock Cost | AL4: After Stock Qty | AM4: Warehouse | AN4: Promotional Type | AO4: CESS PCT | AP4: CESS AMT | AQ4: PriceClass
A5: 1 | B5: HK-TVS-SCRAP-10001 | C5: 0 | D5: HK-TVS-SCRAP-10001 | E5: KGS | F5: KGS | G5: 10 | H5: 1500 | I5: =G5*H5 -> 15000 | J5: 1 | K5: 2 | L5: 9 | M5: =I5 -> 15000 | N5: =ROUND((M5*J5)/100,2) -> 150 | O5: =I5-N5 -> 14850 | P5: =ROUND((O5*K5)/100,2) -> 297 | Q5: =ROUND(O5-P5,2) -> 14553 | R5: =ROUND((Q5*L5)/100,2) -> 1309.77 | S5: =N5+P5+R5 -> 1756.77 | T5: =ROUND(S5/G5,2) -> 175.68 | U5: =(I5-S5) -> 13243.23 | V5: HSN1 | W5: 0.05 | X5: =IF(OR($D$3=1,$D$3=4),ROUND((U5*W5)/2,2),0) -> 0 | Y5: =IF($D$3=1,ROUND(((U5*W5)/2),2),0) -> 0 | Z5: =IF($D$3=2,ROUND(((U5*W5)),2),0) -> 662.16 | AA5: =IF($D$3=4,ROUND(((U5*W5)/2),2),0) -> 0 | AB5: 0.06 | AC5: =IF($D$3=5,ROUND(((U5*AB5)/2),2),0) -> 0 | AD5: =X5+Y5+Z5+AA5+AC5 -> 662.16 | AE5: =U5+AD5 -> 13905.39 | AF5: 120 | AG5: =U5*$N$3 -> 13243.23 | AH5: 1 | AI5: =G5/AH5 -> 10 | AJ5: 848 | AK5: 235.36857 | AL5: =ROUND(AJ5-G5,0) -> 838 | AM5: F100 | AN5: Sales Regular | AO5: 0 | AP5: =ROUND(((AO5*U5)/100),2) -> 0 | AQ5: DOMESTIC
Q6: DISC AMOUNT | Z6: NET AMOUNT | AB6: =SUM(AB5:AB5) -> 0.06 | AC6: SALES AMOUNT | AD6: =AD5 -> 662.16

Sheet SERVICE
A1: Scenario : Local Sales - Stock UOM and Sales UOM (Similar) DOC NO : SORD-2425-00089
A2: Sales Order
A3: GST Sales | D3: 2 | E3: (1 - Local Sales,2 Interstate Sales, 3 Import Sales) | J3: Cur. | K3: INR | M3: Ex. Rate | N3: 1
A4: S. No. | B4: Item | C4: Rev | D4: Item Desc. | E4: Stk. UOM | F4: Sale. UOM | G4: Order Qty (Sale UOM) | H4: Unit Price | I4: Gross Amt. | J4: TD% | K4: SD% | L4: CD% | M4: TD Asbl. Val. | N4: TD Amt. | O4: SD Asbl. Val. | P4: SD Amt. | Q4: CD Asbl. Val. | R4: CD Amt. | S4: Disc. Amt. | T4: Disc.Amt.Per.Qty | U4: Sales Val. | V4: HSN | W4: Tax Rate | X4: CGST | Y4: SGST | Z4: IGST | AA4: UTGST | AB4: CESS % | AC4: CESS AMT | AD4: Tax amt | AE4: Net Amt | AF4: Weight/Vol | AG4: Sales Amt (BC) | AH4: Conv. Factor | AI4: Eqv. Stock Qty | AJ4: Before Stock Qty | AK4: Before Stock Cost | AL4: After Stock Qty | AM4: Warehouse | AN4: Promotional Type | AO4: CESS PCT | AP4: CESS AMT | AQ4: PriceClass
A5: 1 | B5: TVS-SER-10001 | C5: 0 | D5: TVS-SER-10001 | E5: NOS | F5: NOS | G5: 10 | H5: 1500 | I5: =G5*H5 -> 15000 | J5: 2 | K5: 3 | L5: 7 | M5: =I5 -> 15000 | N5: =ROUND((M5*J5)/100,2) -> 300 | O5: =I5-N5 -> 14700 | P5: =ROUND((O5*K5)/100,2) -> 441 | Q5: =ROUND(O5-P5,2) -> 14259 | R5: =ROUND((Q5*L5)/100,2) -> 998.13 | S5: =N5+P5+R5 -> 1739.13 | T5: =ROUND(S5/G5,2) -> 173.91 | U5: =(I5-S5) -> 13260.87 | V5: HSN1 | W5: 0.05 | X5: =IF(OR($D$3=1,$D$3=4),ROUND((U5*W5)/2,2),0) -> 0 | Y5: =IF($D$3=1,ROUND(((U5*W5)/2),2),0) -> 0 | Z5: =IF($D$3=2,ROUND(((U5*W5)),2),0) -> 663.04 | AA5: =IF($D$3=4,ROUND(((U5*W5)/2),2),0) -> 0 | AB5: 0.06 | AC5: =IF($D$3=5,ROUND(((U5*AB5)/2),2),0) -> 0 | AD5: =X5+Y5+Z5+AA5+AC5 -> 663.04 | AE5: =U5+AD5 -> 13923.91 | AF5: 120 | AG5: =U5*$N$3 -> 13260.87 | AH5: 1 | AI5: =G5/AH5 -> 10 | AJ5: 848 | AK5: 235.36857 | AL5: =ROUND(AJ5-G5,0) -> 838 | AM5: F100 | AN5: Sales Regular | AO5: 0 | AP5: =ROUND(((AO5*U5)/100),2) -> 0 | AQ5: DOMESTIC
Q6: DISC AMOUNT | Z6: NET AMOUNT | AB6: =SUM(AB5:AB5) -> 0.06 | AC6: SALES AMOUNT | AD6: =AD5 -> 663.04

Sheet PROMOTIONAL
A1: Scenario : Local Sales - Stock UOM and Sales UOM (Similar) DOC NO : SORD-2425-00089
A2: Sales Order
A3: GST Sales | D3: 2 | E3: (1 - Local Sales,2 Interstate Sales, 3 Import Sales) | J3: Cur. | K3: INR | M3: Ex. Rate | N3: 1
A4: S. No. | B4: Item | C4: Rev | D4: Item Desc. | E4: Stk. UOM | F4: Sale. UOM | G4: Order Qty (Sale UOM) | H4: Unit Price | I4: Gross Amt. | J4: TD% | K4: SD% | L4: CD% | M4: TD Asbl. Val. | N4: TD Amt. | O4: SD Asbl. Val. | P4: SD Amt. | Q4: CD Asbl. Val. | R4: CD Amt. | S4: Disc. Amt. | T4: Disc.Amt.Per.Qty | U4: Sales Val. | V4: HSN | W4: Tax Rate | X4: CGST | Y4: SGST | Z4: IGST | AA4: UTGST | AB4: CESS % | AC4: CESS AMT | AD4: Tax amt | AE4: Net Amt | AF4: Weight/Vol | AG4: Sales Amt (BC) | AH4: Conv. Factor | AI4: Eqv. Stock Qty | AJ4: Before Stock Qty | AK4: Before Stock Cost | AL4: After Stock Qty | AM4: Warehouse | AN4: Promotional Type | AO4: CESS PCT | AP4: CESS AMT | AQ4: PriceClass
A5: 1 | B5: HK-FIFO-LOT-BATCH-10001(FG) | C5: 0 | D5: HK-FIFO-LOT-BATCH-10001(FG) | E5: NOS | F5: NOS | G5: 10 | H5: 1500 | I5: =G5*H5 -> 15000 | J5: 1 | K5: 5 | L5: 7 | M5: =I5 -> 15000 | N5: =ROUND((M5*J5)/100,2) -> 150 | O5: =I5-N5 -> 14850 | P5: =ROUND((O5*K5)/100,2) -> 742.5 | Q5: =ROUND(O5-P5,2) -> 14107.5 | R5: =ROUND((Q5*L5)/100,2) -> 987.53 | S5: =N5+P5+R5 -> 1880.03 | T5: =ROUND(S5/G5,2) -> 188 | U5: =(I5-S5) -> 13119.97 | V5: HSN1 | W5: 0.12 | X5: =IF(OR($D$3=1,$D$3=4),ROUND((U5*W5)/2,2),0) -> 0 | Y5: =IF($D$3=1,ROUND(((U5*W5)/2),2),0) -> 0 | Z5: =IF($D$3=2,ROUND(((U5*W5)),2),0) -> 1574.4 | AA5: =IF($D$3=4,ROUND(((U5*W5)/2),2),0) -> 0 | AB5: 0.06 | AC5: =IF($D$3=5,ROUND(((U5*AB5)/2),2),0) -> 0 | AD5: =X5+Y5+Z5+AA5+AC5 -> 1574.4 | AE5: =U5+AD5 -> 14694.37 | AF5: 120 | AG5: =U5*$N$3 -> 13119.97 | AH5: 1 | AI5: =G5/AH5 -> 10 | AJ5: 848 | AK5: 235.36857 | AL5: =ROUND(AJ5-G5,0) -> 838 | AM5: F100 | AN5: Sales Regular | AO5: 0 | AP5: =ROUND(((AO5*U5)/100),2) -> 0 | AQ5: DOMESTIC
A6: 2 | B6: PRO-10001 | C6: 0 | D6: PROMOTIONAL-10001 | E6: NOS | F6: NOS | G6: 10 | H6: 2000 | I6: =G6*H6 -> 20000 | J6: 0 | K6: 0 | L6: 0 | M6: =I6 -> 20000 | N6: =ROUND((M6*J6)/100,2) -> 0 | O6: =I6-N6 -> 20000 | P6: =ROUND((O6*K6)/100,2) -> 0 | Q6: =ROUND(O6-P6,2) -> 20000 | R6: =ROUND((Q6*L6)/100,2) -> 0 | S6: =N6+P6+R6 -> 0 | T6: =ROUND(S6/G6,2) -> 0 | U6: =(I6-S6) -> 20000 | V6: HSN1 | W6: 0.05 | X6: =IF(OR($D$3=1,$D$3=4),ROUND((U6*W6)/2,2),0) -> 0 | Y6: =IF($D$3=1,ROUND(((U6*W6)/2),2),0) -> 0 | Z6: =IF($D$3=2,ROUND(((U6*W6)),2),0) -> 1000 | AA6: =IF($D$3=4,ROUND(((U6*W6)/2),2),0) -> 0 | AB6: 0.06 | AC6: =IF($D$3=5,ROUND(((U6*AB6)/2),2),0) -> 0 | AD6: =X6+Y6+Z6+AA6+AC6 -> 1000 | AE6: =U6+AD6 -> 21000 | AF6: 120 | AG6: =U6*$N$3 -> 20000 | AH6: 3 | AI6: =ROUND(G6/AH6,3) -> 3.333 | AJ6: 1375.002 | AK6: 123 | AL6: =ROUND((AJ6-AI6),3) -> 1371.669 | AM6: F100 | AN6: Promotional | AO6: 0 | AP6: =ROUND(((AO6*U6)/100),2) -> 0 | AQ6: DOMESTIC
Q7: DISC AMOUNT | Z7: NET AMOUNT | AE7: =AE5 -> 14694.37 | AF7: SALES AMOUNT | AG7: =AG5 -> 13119.97

Sheet Local Customer
A1: Scenario : Local Sales - Stock UOM and Sales UOM (Similar) DOC NO : SORD-2425-00089
A2: Sales Order
A3: GST Sales | D3: 1 | E3: (1 - Local Sales,2 Interstate Sales, 3 Import Sales) | J3: Cur. | K3: INR | M3: Ex. Rate | N3: 1
A4: S. No. | B4: Item | C4: Rev | D4: Item Desc. | E4: Stk. UOM | F4: Sale. UOM | G4: Order Qty (Sale UOM) | H4: Unit Price | I4: Gross Amt. | J4: TD% | K4: SD% | L4: CD% | M4: TD Asbl. Val. | N4: TD Amt. | O4: SD Asbl. Val. | P4: SD Amt. | Q4: CD Asbl. Val. | R4: CD Amt. | S4: Disc. Amt. | T4: Disc.Amt.Per.Qty | U4: Sales Val. | V4: HSN | W4: Tax Rate | X4: CGST | Y4: SGST | Z4: IGST | AA4: UTGST | AB4: CESS % | AC4: CESS AMT | AD4: Tax amt | AE4: Net Amt | AF4: Weight/Vol | AG4: Sales Amt (BC) | AH4: Conv. Factor | AI4: Eqv. Stock Qty | AJ4: Before Stock Qty | AK4: Before Stock Cost | AL4: After Stock Qty | AM4: Warehouse | AN4: Promotional Type | AO4: CESS PCT | AP4: CESS AMT | AQ4: PriceClass
A5: 1 | B5: HK-FIFO-LOT-BATCH-10001(FG) | C5: 0 | D5: HK-FIFO-LOT-BATCH-10001(FG) | E5: NOS | F5: NOS | G5: 10 | H5: 1500 | I5: =G5*H5 -> 15000 | J5: 2 | K5: 3 | L5: 5 | M5: =I5 -> 15000 | N5: =ROUND((M5*J5)/100,2) -> 300 | O5: =I5-N5 -> 14700 | P5: =ROUND((O5*K5)/100,2) -> 441 | Q5: =ROUND(O5-P5,2) -> 14259 | R5: =ROUND((Q5*L5)/100,2) -> 712.95 | S5: =ROUND(N5+P5+R5,2) -> 1453.95 | T5: =ROUND(S5/G5,2) -> 145.4 | U5: =(I5-S5) -> 13546.05 | V5: HSN1 | W5: 0.12 | X5: =IF(OR($D$3=1,$D$3=4),ROUND((U5*W5)/2,2),0) -> 812.76 | Y5: =IF($D$3=1,ROUND(((U5*W5)/2),2),0) -> 812.76 | Z5: =IF($D$3=2,ROUND(((U5*W5)),2),0) -> 0 | AA5: =IF($D$3=4,ROUND(((U5*W5)/2),2),0) -> 0 | AB5: 0.06 | AC5: =IF($D$3=5,ROUND(((U5*AB5)/2),2),0) -> 0 | AD5: =X5+Y5+Z5+AA5+AC5 -> 1625.52 | AE5: =U5+AD5 -> 15171.57 | AF5: 120 | AG5: =U5*$N$3 -> 13546.05 | AH5: 1 | AI5: =G5/AH5 -> 10 | AJ5: 848 | AK5: 235.36857 | AL5: =ROUND(AJ5-G5,0) -> 838 | AM5: F100 | AN5: Sales Regular | AO5: 0 | AP5: =ROUND(((AO5*U5)/100),2) -> 0 | AQ5: DOMESTIC
A6: 2 | B6: HK-FG-DISSIMILAR-10001 | C6: 0 | D6: HK-FG-DISSIMILAR-10001 | E6: KGS | F6: NOS | G6: 10 | H6: 2000 | I6: =G6*H6 -> 20000 | J6: 5 | K6: 7 | L6: 9 | M6: =I6 -> 20000 | N6: =ROUND((M6*J6)/100,2) -> 1000 | O6: =I6-N6 -> 19000 | P6: =ROUND((O6*K6)/100,2) -> 1330 | Q6: =ROUND(O6-P6,2) -> 17670 | R6: =ROUND((Q6*L6)/100,2) -> 1590.3 | S6: =ROUND(N6+P6+R6,2) -> 3920.3 | T6: =ROUND(S6/G6,2) -> 392.03 | U6: =(I6-S6) -> 16079.7 | V6: HSN1 | W6: 0.05 | X6: =IF(OR($D$3=1,$D$3=4),ROUND((U6*W6)/2,2),0) -> 401.99 | Y6: =IF($D$3=1,ROUND(((U6*W6)/2),2),0) -> 401.99 | Z6: =IF($D$3=2,ROUND(((U6*W6)),2),0) -> 0 | AA6: =IF($D$3=4,ROUND(((U6*W6)/2),2),0) -> 0 | AB6: 0.06 | AC6: =IF($D$3=5,ROUND(((U6*AB6)/2),2),0) -> 0 | AD6: =X6+Y6+Z6+AA6+AC6 -> 803.98 | AE6: =U6+AD6 -> 16883.68 | AF6: 120 | AG6: =U6*$N$3 -> 16079.7 | AH6: 3 | AI6: =ROUND(G6/AH6,3) -> 3.333 | AJ6: 1375.002 | AK6: 123 | AL6: =ROUND((AJ6-AI6),3) -> 1371.669 | AM6: F100 | AN6: Sales Regular | AO6: 0 | AP6: =ROUND(((AO6*U6)/100),2) -> 0 | AQ6: DOMESTIC
Q7: DISC AMOUNT | Z7: NET AMOUNT | AE7: =SUM(AE5:AE6) -> 32055.25 | AF7: SALES AMOUNT | AG7: =AG5 -> 13546.05

Sheet SEZ Customer
A1: Scenario : Local Sales - Stock UOM and Sales UOM (Similar) DOC NO : SORD-2425-00089
